2019-12-06T17:47:19|CRITICAL|root|Unhandled exception:Traceback (most recent call last):
  File "C:\Users\Andrea Bassi\Documents\PythonProjects\BassiScopeFoundryMicroscopes\ScopeFoundry\hardware.py", line 182, in read_from_hardware
    lq.read_from_hardware()
  File "C:\Users\Andrea Bassi\Documents\PythonProjects\BassiScopeFoundryMicroscopes\ScopeFoundry\logged_quantity.py", line 163, in read_from_hardware
    val = self.hardware_read_func()
  File "C:\Users\Andrea Bassi\Documents\PythonProjects\BassiScopeFoundryMicroscopes\ScopeFoundryHW\joystick_hardware\joystick_device.py", line 29, in get_axis_values
    return axis[self.index]
AttributeError: 'JoyStickDevice' object has no attribute 'index'

2019-12-06T18:12:00|ERROR|SineWaveJoyStickMeasure|sine_wave_joystick Failed to update figure1: name 'AXIS_L2' is not defined. ['Traceback (most recent call last):\n', '  File "C:\\Users\\Andrea Bassi\\Documents\\PythonProjects\\BassiScopeFoundryMicroscopes\\ScopeFoundry\\measurement.py", line 279, in _on_display_update_timer\n    self.update_display()\n', '  File "C:\\Users\\Andrea Bassi\\Documents\\PythonProjects\\BassiScopeFoundryMicroscopes\\Microscopes\\VirtualMicroscopeJoyStick\\SineGenJoyStick_measure.py", line 82, in update_display\n    self.func_gen.settings[\'amplitude\'] = self.joystick.joystick_dev.get_axis_values(AXIS_L2)\n', "NameError: name 'AXIS_L2' is not defined\n"]
2019-12-06T18:12:00|ERROR|SineWaveJoyStickMeasure|sine_wave_joystick Failed to update figure1: name 'AXIS_L2' is not defined. ['Traceback (most recent call last):\n', '  File "C:\\Users\\Andrea Bassi\\Documents\\PythonProjects\\BassiScopeFoundryMicroscopes\\ScopeFoundry\\measurement.py", line 279, in _on_display_update_timer\n    self.update_display()\n', '  File "C:\\Users\\Andrea Bassi\\Documents\\PythonProjects\\BassiScopeFoundryMicroscopes\\Microscopes\\VirtualMicroscopeJoyStick\\SineGenJoyStick_measure.py", line 82, in update_display\n    self.func_gen.settings[\'amplitude\'] = self.joystick.joystick_dev.get_axis_values(AXIS_L2)\n', "NameError: name 'AXIS_L2' is not defined\n"]
2019-12-06T18:12:01|ERROR|SineWaveJoyStickMeasure|sine_wave_joystick Failed to update figure1: name 'AXIS_L2' is not defined. ['Traceback (most recent call last):\n', '  File "C:\\Users\\Andrea Bassi\\Documents\\PythonProjects\\BassiScopeFoundryMicroscopes\\ScopeFoundry\\measurement.py", line 279, in _on_display_update_timer\n    self.update_display()\n', '  File "C:\\Users\\Andrea Bassi\\Documents\\PythonProjects\\BassiScopeFoundryMicroscopes\\Microscopes\\VirtualMicroscopeJoyStick\\SineGenJoyStick_measure.py", line 82, in update_display\n    self.func_gen.settings[\'amplitude\'] = self.joystick.joystick_dev.get_axis_values(AXIS_L2)\n', "NameError: name 'AXIS_L2' is not defined\n"]
2019-12-06T18:12:01|ERROR|SineWaveJoyStickMeasure|sine_wave_joystick Failed to update figure1: name 'AXIS_L2' is not defined. ['Traceback (most recent call last):\n', '  File "C:\\Users\\Andrea Bassi\\Documents\\PythonProjects\\BassiScopeFoundryMicroscopes\\ScopeFoundry\\measurement.py", line 279, in _on_display_update_timer\n    self.update_display()\n', '  File "C:\\Users\\Andrea Bassi\\Documents\\PythonProjects\\BassiScopeFoundryMicroscopes\\Microscopes\\VirtualMicroscopeJoyStick\\SineGenJoyStick_measure.py", line 82, in update_display\n    self.func_gen.settings[\'amplitude\'] = self.joystick.joystick_dev.get_axis_values(AXIS_L2)\n', "NameError: name 'AXIS_L2' is not defined\n"]
2019-12-06T18:12:01|ERROR|SineWaveJoyStickMeasure|sine_wave_joystick Failed to update figure1: name 'AXIS_L2' is not defined. ['Traceback (most recent call last):\n', '  File "C:\\Users\\Andrea Bassi\\Documents\\PythonProjects\\BassiScopeFoundryMicroscopes\\ScopeFoundry\\measurement.py", line 279, in _on_display_update_timer\n    self.update_display()\n', '  File "C:\\Users\\Andrea Bassi\\Documents\\PythonProjects\\BassiScopeFoundryMicroscopes\\Microscopes\\VirtualMicroscopeJoyStick\\SineGenJoyStick_measure.py", line 82, in update_display\n    self.func_gen.settings[\'amplitude\'] = self.joystick.joystick_dev.get_axis_values(AXIS_L2)\n', "NameError: name 'AXIS_L2' is not defined\n"]
2019-12-06T18:12:01|ERROR|SineWaveJoyStickMeasure|sine_wave_joystick Failed to update figure1: name 'AXIS_L2' is not defined. ['Traceback (most recent call last):\n', '  File "C:\\Users\\Andrea Bassi\\Documents\\PythonProjects\\BassiScopeFoundryMicroscopes\\ScopeFoundry\\measurement.py", line 279, in _on_display_update_timer\n    self.update_display()\n', '  File "C:\\Users\\Andrea Bassi\\Documents\\PythonProjects\\BassiScopeFoundryMicroscopes\\Microscopes\\VirtualMicroscopeJoyStick\\SineGenJoyStick_measure.py", line 82, in update_display\n    self.func_gen.settings[\'amplitude\'] = self.joystick.joystick_dev.get_axis_values(AXIS_L2)\n', "NameError: name 'AXIS_L2' is not defined\n"]
2019-12-06T18:12:01|ERROR|SineWaveJoyStickMeasure|sine_wave_joystick Failed to update figure1: name 'AXIS_L2' is not defined. ['Traceback (most recent call last):\n', '  File "C:\\Users\\Andrea Bassi\\Documents\\PythonProjects\\BassiScopeFoundryMicroscopes\\ScopeFoundry\\measurement.py", line 279, in _on_display_update_timer\n    self.update_display()\n', '  File "C:\\Users\\Andrea Bassi\\Documents\\PythonProjects\\BassiScopeFoundryMicroscopes\\Microscopes\\VirtualMicroscopeJoyStick\\SineGenJoyStick_measure.py", line 82, in update_display\n    self.func_gen.settings[\'amplitude\'] = self.joystick.joystick_dev.get_axis_values(AXIS_L2)\n', "NameError: name 'AXIS_L2' is not defined\n"]
2019-12-06T18:12:01|ERROR|SineWaveJoyStickMeasure|sine_wave_joystick Failed to update figure1: name 'AXIS_L2' is not defined. ['Traceback (most recent call last):\n', '  File "C:\\Users\\Andrea Bassi\\Documents\\PythonProjects\\BassiScopeFoundryMicroscopes\\ScopeFoundry\\measurement.py", line 279, in _on_display_update_timer\n    self.update_display()\n', '  File "C:\\Users\\Andrea Bassi\\Documents\\PythonProjects\\BassiScopeFoundryMicroscopes\\Microscopes\\VirtualMicroscopeJoyStick\\SineGenJoyStick_measure.py", line 82, in update_display\n    self.func_gen.settings[\'amplitude\'] = self.joystick.joystick_dev.get_axis_values(AXIS_L2)\n', "NameError: name 'AXIS_L2' is not defined\n"]
2019-12-06T18:12:01|ERROR|SineWaveJoyStickMeasure|sine_wave_joystick Failed to update figure1: name 'AXIS_L2' is not defined. ['Traceback (most recent call last):\n', '  File "C:\\Users\\Andrea Bassi\\Documents\\PythonProjects\\BassiScopeFoundryMicroscopes\\ScopeFoundry\\measurement.py", line 279, in _on_display_update_timer\n    self.update_display()\n', '  File "C:\\Users\\Andrea Bassi\\Documents\\PythonProjects\\BassiScopeFoundryMicroscopes\\Microscopes\\VirtualMicroscopeJoyStick\\SineGenJoyStick_measure.py", line 82, in update_display\n    self.func_gen.settings[\'amplitude\'] = self.joystick.joystick_dev.get_axis_values(AXIS_L2)\n', "NameError: name 'AXIS_L2' is not defined\n"]
2019-12-06T18:12:01|ERROR|SineWaveJoyStickMeasure|sine_wave_joystick Failed to update figure1: name 'AXIS_L2' is not defined. ['Traceback (most recent call last):\n', '  File "C:\\Users\\Andrea Bassi\\Documents\\PythonProjects\\BassiScopeFoundryMicroscopes\\ScopeFoundry\\measurement.py", line 279, in _on_display_update_timer\n    self.update_display()\n', '  File "C:\\Users\\Andrea Bassi\\Documents\\PythonProjects\\BassiScopeFoundryMicroscopes\\Microscopes\\VirtualMicroscopeJoyStick\\SineGenJoyStick_measure.py", line 82, in update_display\n    self.func_gen.settings[\'amplitude\'] = self.joystick.joystick_dev.get_axis_values(AXIS_L2)\n', "NameError: name 'AXIS_L2' is not defined\n"]
2019-12-06T18:12:01|ERROR|SineWaveJoyStickMeasure|sine_wave_joystick Failed to update figure1: name 'AXIS_L2' is not defined. ['Traceback (most recent call last):\n', '  File "C:\\Users\\Andrea Bassi\\Documents\\PythonProjects\\BassiScopeFoundryMicroscopes\\ScopeFoundry\\measurement.py", line 279, in _on_display_update_timer\n    self.update_display()\n', '  File "C:\\Users\\Andrea Bassi\\Documents\\PythonProjects\\BassiScopeFoundryMicroscopes\\Microscopes\\VirtualMicroscopeJoyStick\\SineGenJoyStick_measure.py", line 82, in update_display\n    self.func_gen.settings[\'amplitude\'] = self.joystick.joystick_dev.get_axis_values(AXIS_L2)\n', "NameError: name 'AXIS_L2' is not defined\n"]
2019-12-06T18:12:02|ERROR|SineWaveJoyStickMeasure|sine_wave_joystick Failed to update figure1: name 'AXIS_L2' is not defined. ['Traceback (most recent call last):\n', '  File "C:\\Users\\Andrea Bassi\\Documents\\PythonProjects\\BassiScopeFoundryMicroscopes\\ScopeFoundry\\measurement.py", line 279, in _on_display_update_timer\n    self.update_display()\n', '  File "C:\\Users\\Andrea Bassi\\Documents\\PythonProjects\\BassiScopeFoundryMicroscopes\\Microscopes\\VirtualMicroscopeJoyStick\\SineGenJoyStick_measure.py", line 82, in update_display\n    self.func_gen.settings[\'amplitude\'] = self.joystick.joystick_dev.get_axis_values(AXIS_L2)\n', "NameError: name 'AXIS_L2' is not defined\n"]
2019-12-06T18:12:02|ERROR|SineWaveJoyStickMeasure|sine_wave_joystick Failed to update figure1: name 'AXIS_L2' is not defined. ['Traceback (most recent call last):\n', '  File "C:\\Users\\Andrea Bassi\\Documents\\PythonProjects\\BassiScopeFoundryMicroscopes\\ScopeFoundry\\measurement.py", line 279, in _on_display_update_timer\n    self.update_display()\n', '  File "C:\\Users\\Andrea Bassi\\Documents\\PythonProjects\\BassiScopeFoundryMicroscopes\\Microscopes\\VirtualMicroscopeJoyStick\\SineGenJoyStick_measure.py", line 82, in update_display\n    self.func_gen.settings[\'amplitude\'] = self.joystick.joystick_dev.get_axis_values(AXIS_L2)\n', "NameError: name 'AXIS_L2' is not defined\n"]
2019-12-06T18:12:02|ERROR|SineWaveJoyStickMeasure|sine_wave_joystick Failed to update figure1: name 'AXIS_L2' is not defined. ['Traceback (most recent call last):\n', '  File "C:\\Users\\Andrea Bassi\\Documents\\PythonProjects\\BassiScopeFoundryMicroscopes\\ScopeFoundry\\measurement.py", line 279, in _on_display_update_timer\n    self.update_display()\n', '  File "C:\\Users\\Andrea Bassi\\Documents\\PythonProjects\\BassiScopeFoundryMicroscopes\\Microscopes\\VirtualMicroscopeJoyStick\\SineGenJoyStick_measure.py", line 82, in update_display\n    self.func_gen.settings[\'amplitude\'] = self.joystick.joystick_dev.get_axis_values(AXIS_L2)\n', "NameError: name 'AXIS_L2' is not defined\n"]
2019-12-06T18:12:02|ERROR|SineWaveJoyStickMeasure|sine_wave_joystick Failed to update figure1: name 'AXIS_L2' is not defined. ['Traceback (most recent call last):\n', '  File "C:\\Users\\Andrea Bassi\\Documents\\PythonProjects\\BassiScopeFoundryMicroscopes\\ScopeFoundry\\measurement.py", line 279, in _on_display_update_timer\n    self.update_display()\n', '  File "C:\\Users\\Andrea Bassi\\Documents\\PythonProjects\\BassiScopeFoundryMicroscopes\\Microscopes\\VirtualMicroscopeJoyStick\\SineGenJoyStick_measure.py", line 82, in update_display\n    self.func_gen.settings[\'amplitude\'] = self.joystick.joystick_dev.get_axis_values(AXIS_L2)\n', "NameError: name 'AXIS_L2' is not defined\n"]
2019-12-06T18:12:02|ERROR|SineWaveJoyStickMeasure|sine_wave_joystick Failed to update figure1: name 'AXIS_L2' is not defined. ['Traceback (most recent call last):\n', '  File "C:\\Users\\Andrea Bassi\\Documents\\PythonProjects\\BassiScopeFoundryMicroscopes\\ScopeFoundry\\measurement.py", line 279, in _on_display_update_timer\n    self.update_display()\n', '  File "C:\\Users\\Andrea Bassi\\Documents\\PythonProjects\\BassiScopeFoundryMicroscopes\\Microscopes\\VirtualMicroscopeJoyStick\\SineGenJoyStick_measure.py", line 82, in update_display\n    self.func_gen.settings[\'amplitude\'] = self.joystick.joystick_dev.get_axis_values(AXIS_L2)\n', "NameError: name 'AXIS_L2' is not defined\n"]
2019-12-06T18:12:02|ERROR|SineWaveJoyStickMeasure|sine_wave_joystick Failed to update figure1: name 'AXIS_L2' is not defined. ['Traceback (most recent call last):\n', '  File "C:\\Users\\Andrea Bassi\\Documents\\PythonProjects\\BassiScopeFoundryMicroscopes\\ScopeFoundry\\measurement.py", line 279, in _on_display_update_timer\n    self.update_display()\n', '  File "C:\\Users\\Andrea Bassi\\Documents\\PythonProjects\\BassiScopeFoundryMicroscopes\\Microscopes\\VirtualMicroscopeJoyStick\\SineGenJoyStick_measure.py", line 82, in update_display\n    self.func_gen.settings[\'amplitude\'] = self.joystick.joystick_dev.get_axis_values(AXIS_L2)\n', "NameError: name 'AXIS_L2' is not defined\n"]
2019-12-06T18:12:02|ERROR|SineWaveJoyStickMeasure|sine_wave_joystick Failed to update figure1: name 'AXIS_L2' is not defined. ['Traceback (most recent call last):\n', '  File "C:\\Users\\Andrea Bassi\\Documents\\PythonProjects\\BassiScopeFoundryMicroscopes\\ScopeFoundry\\measurement.py", line 279, in _on_display_update_timer\n    self.update_display()\n', '  File "C:\\Users\\Andrea Bassi\\Documents\\PythonProjects\\BassiScopeFoundryMicroscopes\\Microscopes\\VirtualMicroscopeJoyStick\\SineGenJoyStick_measure.py", line 82, in update_display\n    self.func_gen.settings[\'amplitude\'] = self.joystick.joystick_dev.get_axis_values(AXIS_L2)\n', "NameError: name 'AXIS_L2' is not defined\n"]
2019-12-06T18:12:02|ERROR|SineWaveJoyStickMeasure|sine_wave_joystick Failed to update figure1: name 'AXIS_L2' is not defined. ['Traceback (most recent call last):\n', '  File "C:\\Users\\Andrea Bassi\\Documents\\PythonProjects\\BassiScopeFoundryMicroscopes\\ScopeFoundry\\measurement.py", line 279, in _on_display_update_timer\n    self.update_display()\n', '  File "C:\\Users\\Andrea Bassi\\Documents\\PythonProjects\\BassiScopeFoundryMicroscopes\\Microscopes\\VirtualMicroscopeJoyStick\\SineGenJoyStick_measure.py", line 82, in update_display\n    self.func_gen.settings[\'amplitude\'] = self.joystick.joystick_dev.get_axis_values(AXIS_L2)\n', "NameError: name 'AXIS_L2' is not defined\n"]
2019-12-06T18:12:02|ERROR|SineWaveJoyStickMeasure|sine_wave_joystick Failed to update figure1: name 'AXIS_L2' is not defined. ['Traceback (most recent call last):\n', '  File "C:\\Users\\Andrea Bassi\\Documents\\PythonProjects\\BassiScopeFoundryMicroscopes\\ScopeFoundry\\measurement.py", line 279, in _on_display_update_timer\n    self.update_display()\n', '  File "C:\\Users\\Andrea Bassi\\Documents\\PythonProjects\\BassiScopeFoundryMicroscopes\\Microscopes\\VirtualMicroscopeJoyStick\\SineGenJoyStick_measure.py", line 82, in update_display\n    self.func_gen.settings[\'amplitude\'] = self.joystick.joystick_dev.get_axis_values(AXIS_L2)\n', "NameError: name 'AXIS_L2' is not defined\n"]
2019-12-06T18:12:03|ERROR|SineWaveJoyStickMeasure|sine_wave_joystick Failed to update figure1: name 'AXIS_L2' is not defined. ['Traceback (most recent call last):\n', '  File "C:\\Users\\Andrea Bassi\\Documents\\PythonProjects\\BassiScopeFoundryMicroscopes\\ScopeFoundry\\measurement.py", line 279, in _on_display_update_timer\n    self.update_display()\n', '  File "C:\\Users\\Andrea Bassi\\Documents\\PythonProjects\\BassiScopeFoundryMicroscopes\\Microscopes\\VirtualMicroscopeJoyStick\\SineGenJoyStick_measure.py", line 82, in update_display\n    self.func_gen.settings[\'amplitude\'] = self.joystick.joystick_dev.get_axis_values(AXIS_L2)\n', "NameError: name 'AXIS_L2' is not defined\n"]
2019-12-06T18:12:03|ERROR|SineWaveJoyStickMeasure|sine_wave_joystick Failed to update figure1: name 'AXIS_L2' is not defined. ['Traceback (most recent call last):\n', '  File "C:\\Users\\Andrea Bassi\\Documents\\PythonProjects\\BassiScopeFoundryMicroscopes\\ScopeFoundry\\measurement.py", line 279, in _on_display_update_timer\n    self.update_display()\n', '  File "C:\\Users\\Andrea Bassi\\Documents\\PythonProjects\\BassiScopeFoundryMicroscopes\\Microscopes\\VirtualMicroscopeJoyStick\\SineGenJoyStick_measure.py", line 82, in update_display\n    self.func_gen.settings[\'amplitude\'] = self.joystick.joystick_dev.get_axis_values(AXIS_L2)\n', "NameError: name 'AXIS_L2' is not defined\n"]
2019-12-06T18:12:03|ERROR|SineWaveJoyStickMeasure|sine_wave_joystick Failed to update figure1: name 'AXIS_L2' is not defined. ['Traceback (most recent call last):\n', '  File "C:\\Users\\Andrea Bassi\\Documents\\PythonProjects\\BassiScopeFoundryMicroscopes\\ScopeFoundry\\measurement.py", line 279, in _on_display_update_timer\n    self.update_display()\n', '  File "C:\\Users\\Andrea Bassi\\Documents\\PythonProjects\\BassiScopeFoundryMicroscopes\\Microscopes\\VirtualMicroscopeJoyStick\\SineGenJoyStick_measure.py", line 82, in update_display\n    self.func_gen.settings[\'amplitude\'] = self.joystick.joystick_dev.get_axis_values(AXIS_L2)\n', "NameError: name 'AXIS_L2' is not defined\n"]
2019-12-06T18:12:03|ERROR|SineWaveJoyStickMeasure|sine_wave_joystick Failed to update figure1: name 'AXIS_L2' is not defined. ['Traceback (most recent call last):\n', '  File "C:\\Users\\Andrea Bassi\\Documents\\PythonProjects\\BassiScopeFoundryMicroscopes\\ScopeFoundry\\measurement.py", line 279, in _on_display_update_timer\n    self.update_display()\n', '  File "C:\\Users\\Andrea Bassi\\Documents\\PythonProjects\\BassiScopeFoundryMicroscopes\\Microscopes\\VirtualMicroscopeJoyStick\\SineGenJoyStick_measure.py", line 82, in update_display\n    self.func_gen.settings[\'amplitude\'] = self.joystick.joystick_dev.get_axis_values(AXIS_L2)\n', "NameError: name 'AXIS_L2' is not defined\n"]
2019-12-06T18:12:03|ERROR|SineWaveJoyStickMeasure|sine_wave_joystick Failed to update figure1: name 'AXIS_L2' is not defined. ['Traceback (most recent call last):\n', '  File "C:\\Users\\Andrea Bassi\\Documents\\PythonProjects\\BassiScopeFoundryMicroscopes\\ScopeFoundry\\measurement.py", line 279, in _on_display_update_timer\n    self.update_display()\n', '  File "C:\\Users\\Andrea Bassi\\Documents\\PythonProjects\\BassiScopeFoundryMicroscopes\\Microscopes\\VirtualMicroscopeJoyStick\\SineGenJoyStick_measure.py", line 82, in update_display\n    self.func_gen.settings[\'amplitude\'] = self.joystick.joystick_dev.get_axis_values(AXIS_L2)\n', "NameError: name 'AXIS_L2' is not defined\n"]
2019-12-06T18:12:03|ERROR|SineWaveJoyStickMeasure|sine_wave_joystick Failed to update figure1: name 'AXIS_L2' is not defined. ['Traceback (most recent call last):\n', '  File "C:\\Users\\Andrea Bassi\\Documents\\PythonProjects\\BassiScopeFoundryMicroscopes\\ScopeFoundry\\measurement.py", line 279, in _on_display_update_timer\n    self.update_display()\n', '  File "C:\\Users\\Andrea Bassi\\Documents\\PythonProjects\\BassiScopeFoundryMicroscopes\\Microscopes\\VirtualMicroscopeJoyStick\\SineGenJoyStick_measure.py", line 82, in update_display\n    self.func_gen.settings[\'amplitude\'] = self.joystick.joystick_dev.get_axis_values(AXIS_L2)\n', "NameError: name 'AXIS_L2' is not defined\n"]
2019-12-06T18:12:03|ERROR|SineWaveJoyStickMeasure|sine_wave_joystick Failed to update figure1: name 'AXIS_L2' is not defined. ['Traceback (most recent call last):\n', '  File "C:\\Users\\Andrea Bassi\\Documents\\PythonProjects\\BassiScopeFoundryMicroscopes\\ScopeFoundry\\measurement.py", line 279, in _on_display_update_timer\n    self.update_display()\n', '  File "C:\\Users\\Andrea Bassi\\Documents\\PythonProjects\\BassiScopeFoundryMicroscopes\\Microscopes\\VirtualMicroscopeJoyStick\\SineGenJoyStick_measure.py", line 82, in update_display\n    self.func_gen.settings[\'amplitude\'] = self.joystick.joystick_dev.get_axis_values(AXIS_L2)\n', "NameError: name 'AXIS_L2' is not defined\n"]
2019-12-06T18:12:03|ERROR|SineWaveJoyStickMeasure|sine_wave_joystick Failed to update figure1: name 'AXIS_L2' is not defined. ['Traceback (most recent call last):\n', '  File "C:\\Users\\Andrea Bassi\\Documents\\PythonProjects\\BassiScopeFoundryMicroscopes\\ScopeFoundry\\measurement.py", line 279, in _on_display_update_timer\n    self.update_display()\n', '  File "C:\\Users\\Andrea Bassi\\Documents\\PythonProjects\\BassiScopeFoundryMicroscopes\\Microscopes\\VirtualMicroscopeJoyStick\\SineGenJoyStick_measure.py", line 82, in update_display\n    self.func_gen.settings[\'amplitude\'] = self.joystick.joystick_dev.get_axis_values(AXIS_L2)\n', "NameError: name 'AXIS_L2' is not defined\n"]
2019-12-06T18:12:03|ERROR|SineWaveJoyStickMeasure|sine_wave_joystick Failed to update figure1: name 'AXIS_L2' is not defined. ['Traceback (most recent call last):\n', '  File "C:\\Users\\Andrea Bassi\\Documents\\PythonProjects\\BassiScopeFoundryMicroscopes\\ScopeFoundry\\measurement.py", line 279, in _on_display_update_timer\n    self.update_display()\n', '  File "C:\\Users\\Andrea Bassi\\Documents\\PythonProjects\\BassiScopeFoundryMicroscopes\\Microscopes\\VirtualMicroscopeJoyStick\\SineGenJoyStick_measure.py", line 82, in update_display\n    self.func_gen.settings[\'amplitude\'] = self.joystick.joystick_dev.get_axis_values(AXIS_L2)\n', "NameError: name 'AXIS_L2' is not defined\n"]
2019-12-06T18:12:04|ERROR|SineWaveJoyStickMeasure|sine_wave_joystick Failed to update figure1: name 'AXIS_L2' is not defined. ['Traceback (most recent call last):\n', '  File "C:\\Users\\Andrea Bassi\\Documents\\PythonProjects\\BassiScopeFoundryMicroscopes\\ScopeFoundry\\measurement.py", line 279, in _on_display_update_timer\n    self.update_display()\n', '  File "C:\\Users\\Andrea Bassi\\Documents\\PythonProjects\\BassiScopeFoundryMicroscopes\\Microscopes\\VirtualMicroscopeJoyStick\\SineGenJoyStick_measure.py", line 82, in update_display\n    self.func_gen.settings[\'amplitude\'] = self.joystick.joystick_dev.get_axis_values(AXIS_L2)\n', "NameError: name 'AXIS_L2' is not defined\n"]
2019-12-06T18:12:04|ERROR|SineWaveJoyStickMeasure|sine_wave_joystick Failed to update figure1: name 'AXIS_L2' is not defined. ['Traceback (most recent call last):\n', '  File "C:\\Users\\Andrea Bassi\\Documents\\PythonProjects\\BassiScopeFoundryMicroscopes\\ScopeFoundry\\measurement.py", line 279, in _on_display_update_timer\n    self.update_display()\n', '  File "C:\\Users\\Andrea Bassi\\Documents\\PythonProjects\\BassiScopeFoundryMicroscopes\\Microscopes\\VirtualMicroscopeJoyStick\\SineGenJoyStick_measure.py", line 82, in update_display\n    self.func_gen.settings[\'amplitude\'] = self.joystick.joystick_dev.get_axis_values(AXIS_L2)\n', "NameError: name 'AXIS_L2' is not defined\n"]
2019-12-06T18:12:04|ERROR|SineWaveJoyStickMeasure|sine_wave_joystick Failed to update figure1: name 'AXIS_L2' is not defined. ['Traceback (most recent call last):\n', '  File "C:\\Users\\Andrea Bassi\\Documents\\PythonProjects\\BassiScopeFoundryMicroscopes\\ScopeFoundry\\measurement.py", line 279, in _on_display_update_timer\n    self.update_display()\n', '  File "C:\\Users\\Andrea Bassi\\Documents\\PythonProjects\\BassiScopeFoundryMicroscopes\\Microscopes\\VirtualMicroscopeJoyStick\\SineGenJoyStick_measure.py", line 82, in update_display\n    self.func_gen.settings[\'amplitude\'] = self.joystick.joystick_dev.get_axis_values(AXIS_L2)\n', "NameError: name 'AXIS_L2' is not defined\n"]
2019-12-06T18:12:04|ERROR|SineWaveJoyStickMeasure|sine_wave_joystick Failed to update figure1: name 'AXIS_L2' is not defined. ['Traceback (most recent call last):\n', '  File "C:\\Users\\Andrea Bassi\\Documents\\PythonProjects\\BassiScopeFoundryMicroscopes\\ScopeFoundry\\measurement.py", line 279, in _on_display_update_timer\n    self.update_display()\n', '  File "C:\\Users\\Andrea Bassi\\Documents\\PythonProjects\\BassiScopeFoundryMicroscopes\\Microscopes\\VirtualMicroscopeJoyStick\\SineGenJoyStick_measure.py", line 82, in update_display\n    self.func_gen.settings[\'amplitude\'] = self.joystick.joystick_dev.get_axis_values(AXIS_L2)\n', "NameError: name 'AXIS_L2' is not defined\n"]
2019-12-06T18:12:04|ERROR|SineWaveJoyStickMeasure|sine_wave_joystick Failed to update figure1: name 'AXIS_L2' is not defined. ['Traceback (most recent call last):\n', '  File "C:\\Users\\Andrea Bassi\\Documents\\PythonProjects\\BassiScopeFoundryMicroscopes\\ScopeFoundry\\measurement.py", line 279, in _on_display_update_timer\n    self.update_display()\n', '  File "C:\\Users\\Andrea Bassi\\Documents\\PythonProjects\\BassiScopeFoundryMicroscopes\\Microscopes\\VirtualMicroscopeJoyStick\\SineGenJoyStick_measure.py", line 82, in update_display\n    self.func_gen.settings[\'amplitude\'] = self.joystick.joystick_dev.get_axis_values(AXIS_L2)\n', "NameError: name 'AXIS_L2' is not defined\n"]
2019-12-06T18:12:04|ERROR|SineWaveJoyStickMeasure|sine_wave_joystick Failed to update figure1: name 'AXIS_L2' is not defined. ['Traceback (most recent call last):\n', '  File "C:\\Users\\Andrea Bassi\\Documents\\PythonProjects\\BassiScopeFoundryMicroscopes\\ScopeFoundry\\measurement.py", line 279, in _on_display_update_timer\n    self.update_display()\n', '  File "C:\\Users\\Andrea Bassi\\Documents\\PythonProjects\\BassiScopeFoundryMicroscopes\\Microscopes\\VirtualMicroscopeJoyStick\\SineGenJoyStick_measure.py", line 82, in update_display\n    self.func_gen.settings[\'amplitude\'] = self.joystick.joystick_dev.get_axis_values(AXIS_L2)\n', "NameError: name 'AXIS_L2' is not defined\n"]
2019-12-06T18:12:04|ERROR|SineWaveJoyStickMeasure|sine_wave_joystick Failed to update figure1: name 'AXIS_L2' is not defined. ['Traceback (most recent call last):\n', '  File "C:\\Users\\Andrea Bassi\\Documents\\PythonProjects\\BassiScopeFoundryMicroscopes\\ScopeFoundry\\measurement.py", line 279, in _on_display_update_timer\n    self.update_display()\n', '  File "C:\\Users\\Andrea Bassi\\Documents\\PythonProjects\\BassiScopeFoundryMicroscopes\\Microscopes\\VirtualMicroscopeJoyStick\\SineGenJoyStick_measure.py", line 82, in update_display\n    self.func_gen.settings[\'amplitude\'] = self.joystick.joystick_dev.get_axis_values(AXIS_L2)\n', "NameError: name 'AXIS_L2' is not defined\n"]
2019-12-06T18:12:04|ERROR|SineWaveJoyStickMeasure|sine_wave_joystick Failed to update figure1: name 'AXIS_L2' is not defined. ['Traceback (most recent call last):\n', '  File "C:\\Users\\Andrea Bassi\\Documents\\PythonProjects\\BassiScopeFoundryMicroscopes\\ScopeFoundry\\measurement.py", line 279, in _on_display_update_timer\n    self.update_display()\n', '  File "C:\\Users\\Andrea Bassi\\Documents\\PythonProjects\\BassiScopeFoundryMicroscopes\\Microscopes\\VirtualMicroscopeJoyStick\\SineGenJoyStick_measure.py", line 82, in update_display\n    self.func_gen.settings[\'amplitude\'] = self.joystick.joystick_dev.get_axis_values(AXIS_L2)\n', "NameError: name 'AXIS_L2' is not defined\n"]
2019-12-06T18:12:04|ERROR|SineWaveJoyStickMeasure|sine_wave_joystick Failed to update figure1: name 'AXIS_L2' is not defined. ['Traceback (most recent call last):\n', '  File "C:\\Users\\Andrea Bassi\\Documents\\PythonProjects\\BassiScopeFoundryMicroscopes\\ScopeFoundry\\measurement.py", line 279, in _on_display_update_timer\n    self.update_display()\n', '  File "C:\\Users\\Andrea Bassi\\Documents\\PythonProjects\\BassiScopeFoundryMicroscopes\\Microscopes\\VirtualMicroscopeJoyStick\\SineGenJoyStick_measure.py", line 82, in update_display\n    self.func_gen.settings[\'amplitude\'] = self.joystick.joystick_dev.get_axis_values(AXIS_L2)\n', "NameError: name 'AXIS_L2' is not defined\n"]
2019-12-06T18:12:05|ERROR|SineWaveJoyStickMeasure|sine_wave_joystick Failed to update figure1: name 'AXIS_L2' is not defined. ['Traceback (most recent call last):\n', '  File "C:\\Users\\Andrea Bassi\\Documents\\PythonProjects\\BassiScopeFoundryMicroscopes\\ScopeFoundry\\measurement.py", line 279, in _on_display_update_timer\n    self.update_display()\n', '  File "C:\\Users\\Andrea Bassi\\Documents\\PythonProjects\\BassiScopeFoundryMicroscopes\\Microscopes\\VirtualMicroscopeJoyStick\\SineGenJoyStick_measure.py", line 82, in update_display\n    self.func_gen.settings[\'amplitude\'] = self.joystick.joystick_dev.get_axis_values(AXIS_L2)\n', "NameError: name 'AXIS_L2' is not defined\n"]
2019-12-06T18:12:05|ERROR|SineWaveJoyStickMeasure|sine_wave_joystick Failed to update figure1: name 'AXIS_L2' is not defined. ['Traceback (most recent call last):\n', '  File "C:\\Users\\Andrea Bassi\\Documents\\PythonProjects\\BassiScopeFoundryMicroscopes\\ScopeFoundry\\measurement.py", line 279, in _on_display_update_timer\n    self.update_display()\n', '  File "C:\\Users\\Andrea Bassi\\Documents\\PythonProjects\\BassiScopeFoundryMicroscopes\\Microscopes\\VirtualMicroscopeJoyStick\\SineGenJoyStick_measure.py", line 82, in update_display\n    self.func_gen.settings[\'amplitude\'] = self.joystick.joystick_dev.get_axis_values(AXIS_L2)\n', "NameError: name 'AXIS_L2' is not defined\n"]
2019-12-06T18:12:05|ERROR|SineWaveJoyStickMeasure|sine_wave_joystick Failed to update figure1: name 'AXIS_L2' is not defined. ['Traceback (most recent call last):\n', '  File "C:\\Users\\Andrea Bassi\\Documents\\PythonProjects\\BassiScopeFoundryMicroscopes\\ScopeFoundry\\measurement.py", line 279, in _on_display_update_timer\n    self.update_display()\n', '  File "C:\\Users\\Andrea Bassi\\Documents\\PythonProjects\\BassiScopeFoundryMicroscopes\\Microscopes\\VirtualMicroscopeJoyStick\\SineGenJoyStick_measure.py", line 82, in update_display\n    self.func_gen.settings[\'amplitude\'] = self.joystick.joystick_dev.get_axis_values(AXIS_L2)\n', "NameError: name 'AXIS_L2' is not defined\n"]
2019-12-06T18:12:05|ERROR|SineWaveJoyStickMeasure|sine_wave_joystick Failed to update figure1: name 'AXIS_L2' is not defined. ['Traceback (most recent call last):\n', '  File "C:\\Users\\Andrea Bassi\\Documents\\PythonProjects\\BassiScopeFoundryMicroscopes\\ScopeFoundry\\measurement.py", line 279, in _on_display_update_timer\n    self.update_display()\n', '  File "C:\\Users\\Andrea Bassi\\Documents\\PythonProjects\\BassiScopeFoundryMicroscopes\\Microscopes\\VirtualMicroscopeJoyStick\\SineGenJoyStick_measure.py", line 82, in update_display\n    self.func_gen.settings[\'amplitude\'] = self.joystick.joystick_dev.get_axis_values(AXIS_L2)\n', "NameError: name 'AXIS_L2' is not defined\n"]
2019-12-06T18:12:05|ERROR|SineWaveJoyStickMeasure|sine_wave_joystick Failed to update figure1: name 'AXIS_L2' is not defined. ['Traceback (most recent call last):\n', '  File "C:\\Users\\Andrea Bassi\\Documents\\PythonProjects\\BassiScopeFoundryMicroscopes\\ScopeFoundry\\measurement.py", line 279, in _on_display_update_timer\n    self.update_display()\n', '  File "C:\\Users\\Andrea Bassi\\Documents\\PythonProjects\\BassiScopeFoundryMicroscopes\\Microscopes\\VirtualMicroscopeJoyStick\\SineGenJoyStick_measure.py", line 82, in update_display\n    self.func_gen.settings[\'amplitude\'] = self.joystick.joystick_dev.get_axis_values(AXIS_L2)\n', "NameError: name 'AXIS_L2' is not defined\n"]
2019-12-06T18:12:05|ERROR|SineWaveJoyStickMeasure|sine_wave_joystick Failed to update figure1: name 'AXIS_L2' is not defined. ['Traceback (most recent call last):\n', '  File "C:\\Users\\Andrea Bassi\\Documents\\PythonProjects\\BassiScopeFoundryMicroscopes\\ScopeFoundry\\measurement.py", line 279, in _on_display_update_timer\n    self.update_display()\n', '  File "C:\\Users\\Andrea Bassi\\Documents\\PythonProjects\\BassiScopeFoundryMicroscopes\\Microscopes\\VirtualMicroscopeJoyStick\\SineGenJoyStick_measure.py", line 82, in update_display\n    self.func_gen.settings[\'amplitude\'] = self.joystick.joystick_dev.get_axis_values(AXIS_L2)\n', "NameError: name 'AXIS_L2' is not defined\n"]
2019-12-06T18:12:05|ERROR|SineWaveJoyStickMeasure|sine_wave_joystick Failed to update figure1: name 'AXIS_L2' is not defined. ['Traceback (most recent call last):\n', '  File "C:\\Users\\Andrea Bassi\\Documents\\PythonProjects\\BassiScopeFoundryMicroscopes\\ScopeFoundry\\measurement.py", line 279, in _on_display_update_timer\n    self.update_display()\n', '  File "C:\\Users\\Andrea Bassi\\Documents\\PythonProjects\\BassiScopeFoundryMicroscopes\\Microscopes\\VirtualMicroscopeJoyStick\\SineGenJoyStick_measure.py", line 82, in update_display\n    self.func_gen.settings[\'amplitude\'] = self.joystick.joystick_dev.get_axis_values(AXIS_L2)\n', "NameError: name 'AXIS_L2' is not defined\n"]
2019-12-06T18:12:05|ERROR|SineWaveJoyStickMeasure|sine_wave_joystick Failed to update figure1: name 'AXIS_L2' is not defined. ['Traceback (most recent call last):\n', '  File "C:\\Users\\Andrea Bassi\\Documents\\PythonProjects\\BassiScopeFoundryMicroscopes\\ScopeFoundry\\measurement.py", line 279, in _on_display_update_timer\n    self.update_display()\n', '  File "C:\\Users\\Andrea Bassi\\Documents\\PythonProjects\\BassiScopeFoundryMicroscopes\\Microscopes\\VirtualMicroscopeJoyStick\\SineGenJoyStick_measure.py", line 82, in update_display\n    self.func_gen.settings[\'amplitude\'] = self.joystick.joystick_dev.get_axis_values(AXIS_L2)\n', "NameError: name 'AXIS_L2' is not defined\n"]
2019-12-06T18:12:05|ERROR|SineWaveJoyStickMeasure|sine_wave_joystick Failed to update figure1: name 'AXIS_L2' is not defined. ['Traceback (most recent call last):\n', '  File "C:\\Users\\Andrea Bassi\\Documents\\PythonProjects\\BassiScopeFoundryMicroscopes\\ScopeFoundry\\measurement.py", line 279, in _on_display_update_timer\n    self.update_display()\n', '  File "C:\\Users\\Andrea Bassi\\Documents\\PythonProjects\\BassiScopeFoundryMicroscopes\\Microscopes\\VirtualMicroscopeJoyStick\\SineGenJoyStick_measure.py", line 82, in update_display\n    self.func_gen.settings[\'amplitude\'] = self.joystick.joystick_dev.get_axis_values(AXIS_L2)\n', "NameError: name 'AXIS_L2' is not defined\n"]
2019-12-06T18:12:06|ERROR|SineWaveJoyStickMeasure|sine_wave_joystick Failed to update figure1: name 'AXIS_L2' is not defined. ['Traceback (most recent call last):\n', '  File "C:\\Users\\Andrea Bassi\\Documents\\PythonProjects\\BassiScopeFoundryMicroscopes\\ScopeFoundry\\measurement.py", line 279, in _on_display_update_timer\n    self.update_display()\n', '  File "C:\\Users\\Andrea Bassi\\Documents\\PythonProjects\\BassiScopeFoundryMicroscopes\\Microscopes\\VirtualMicroscopeJoyStick\\SineGenJoyStick_measure.py", line 82, in update_display\n    self.func_gen.settings[\'amplitude\'] = self.joystick.joystick_dev.get_axis_values(AXIS_L2)\n', "NameError: name 'AXIS_L2' is not defined\n"]
2019-12-06T18:12:06|ERROR|SineWaveJoyStickMeasure|sine_wave_joystick Failed to update figure1: name 'AXIS_L2' is not defined. ['Traceback (most recent call last):\n', '  File "C:\\Users\\Andrea Bassi\\Documents\\PythonProjects\\BassiScopeFoundryMicroscopes\\ScopeFoundry\\measurement.py", line 279, in _on_display_update_timer\n    self.update_display()\n', '  File "C:\\Users\\Andrea Bassi\\Documents\\PythonProjects\\BassiScopeFoundryMicroscopes\\Microscopes\\VirtualMicroscopeJoyStick\\SineGenJoyStick_measure.py", line 82, in update_display\n    self.func_gen.settings[\'amplitude\'] = self.joystick.joystick_dev.get_axis_values(AXIS_L2)\n', "NameError: name 'AXIS_L2' is not defined\n"]
2019-12-06T18:12:06|ERROR|SineWaveJoyStickMeasure|sine_wave_joystick Failed to update figure1: name 'AXIS_L2' is not defined. ['Traceback (most recent call last):\n', '  File "C:\\Users\\Andrea Bassi\\Documents\\PythonProjects\\BassiScopeFoundryMicroscopes\\ScopeFoundry\\measurement.py", line 279, in _on_display_update_timer\n    self.update_display()\n', '  File "C:\\Users\\Andrea Bassi\\Documents\\PythonProjects\\BassiScopeFoundryMicroscopes\\Microscopes\\VirtualMicroscopeJoyStick\\SineGenJoyStick_measure.py", line 82, in update_display\n    self.func_gen.settings[\'amplitude\'] = self.joystick.joystick_dev.get_axis_values(AXIS_L2)\n', "NameError: name 'AXIS_L2' is not defined\n"]
2019-12-06T18:12:06|ERROR|SineWaveJoyStickMeasure|sine_wave_joystick Failed to update figure1: name 'AXIS_L2' is not defined. ['Traceback (most recent call last):\n', '  File "C:\\Users\\Andrea Bassi\\Documents\\PythonProjects\\BassiScopeFoundryMicroscopes\\ScopeFoundry\\measurement.py", line 279, in _on_display_update_timer\n    self.update_display()\n', '  File "C:\\Users\\Andrea Bassi\\Documents\\PythonProjects\\BassiScopeFoundryMicroscopes\\Microscopes\\VirtualMicroscopeJoyStick\\SineGenJoyStick_measure.py", line 82, in update_display\n    self.func_gen.settings[\'amplitude\'] = self.joystick.joystick_dev.get_axis_values(AXIS_L2)\n', "NameError: name 'AXIS_L2' is not defined\n"]
2019-12-06T18:12:06|ERROR|SineWaveJoyStickMeasure|sine_wave_joystick Failed to update figure1: name 'AXIS_L2' is not defined. ['Traceback (most recent call last):\n', '  File "C:\\Users\\Andrea Bassi\\Documents\\PythonProjects\\BassiScopeFoundryMicroscopes\\ScopeFoundry\\measurement.py", line 279, in _on_display_update_timer\n    self.update_display()\n', '  File "C:\\Users\\Andrea Bassi\\Documents\\PythonProjects\\BassiScopeFoundryMicroscopes\\Microscopes\\VirtualMicroscopeJoyStick\\SineGenJoyStick_measure.py", line 82, in update_display\n    self.func_gen.settings[\'amplitude\'] = self.joystick.joystick_dev.get_axis_values(AXIS_L2)\n', "NameError: name 'AXIS_L2' is not defined\n"]
2019-12-06T18:12:06|ERROR|SineWaveJoyStickMeasure|sine_wave_joystick Failed to update figure1: name 'AXIS_L2' is not defined. ['Traceback (most recent call last):\n', '  File "C:\\Users\\Andrea Bassi\\Documents\\PythonProjects\\BassiScopeFoundryMicroscopes\\ScopeFoundry\\measurement.py", line 279, in _on_display_update_timer\n    self.update_display()\n', '  File "C:\\Users\\Andrea Bassi\\Documents\\PythonProjects\\BassiScopeFoundryMicroscopes\\Microscopes\\VirtualMicroscopeJoyStick\\SineGenJoyStick_measure.py", line 82, in update_display\n    self.func_gen.settings[\'amplitude\'] = self.joystick.joystick_dev.get_axis_values(AXIS_L2)\n', "NameError: name 'AXIS_L2' is not defined\n"]
2019-12-06T18:12:06|ERROR|SineWaveJoyStickMeasure|sine_wave_joystick Failed to update figure1: name 'AXIS_L2' is not defined. ['Traceback (most recent call last):\n', '  File "C:\\Users\\Andrea Bassi\\Documents\\PythonProjects\\BassiScopeFoundryMicroscopes\\ScopeFoundry\\measurement.py", line 279, in _on_display_update_timer\n    self.update_display()\n', '  File "C:\\Users\\Andrea Bassi\\Documents\\PythonProjects\\BassiScopeFoundryMicroscopes\\Microscopes\\VirtualMicroscopeJoyStick\\SineGenJoyStick_measure.py", line 82, in update_display\n    self.func_gen.settings[\'amplitude\'] = self.joystick.joystick_dev.get_axis_values(AXIS_L2)\n', "NameError: name 'AXIS_L2' is not defined\n"]
2019-12-06T18:12:06|ERROR|SineWaveJoyStickMeasure|sine_wave_joystick Failed to update figure1: name 'AXIS_L2' is not defined. ['Traceback (most recent call last):\n', '  File "C:\\Users\\Andrea Bassi\\Documents\\PythonProjects\\BassiScopeFoundryMicroscopes\\ScopeFoundry\\measurement.py", line 279, in _on_display_update_timer\n    self.update_display()\n', '  File "C:\\Users\\Andrea Bassi\\Documents\\PythonProjects\\BassiScopeFoundryMicroscopes\\Microscopes\\VirtualMicroscopeJoyStick\\SineGenJoyStick_measure.py", line 82, in update_display\n    self.func_gen.settings[\'amplitude\'] = self.joystick.joystick_dev.get_axis_values(AXIS_L2)\n', "NameError: name 'AXIS_L2' is not defined\n"]
2019-12-06T18:12:07|ERROR|SineWaveJoyStickMeasure|sine_wave_joystick Failed to update figure1: 'JoyStick_HW' object has no attribute 'joystick_dev'. ['Traceback (most recent call last):\n', '  File "C:\\Users\\Andrea Bassi\\Documents\\PythonProjects\\BassiScopeFoundryMicroscopes\\ScopeFoundry\\measurement.py", line 279, in _on_display_update_timer\n    self.update_display()\n', '  File "C:\\Users\\Andrea Bassi\\Documents\\PythonProjects\\BassiScopeFoundryMicroscopes\\Microscopes\\VirtualMicroscopeJoyStick\\SineGenJoyStick_measure.py", line 82, in update_display\n    self.func_gen.settings[\'amplitude\'] = self.joystick.joystick_dev.get_axis_values(AXIS_L2)\n', "AttributeError: 'JoyStick_HW' object has no attribute 'joystick_dev'\n"]
2019-12-06T18:12:07|ERROR|SineWaveJoyStickMeasure|sine_wave_joystick Failed to update figure1: 'JoyStick_HW' object has no attribute 'joystick_dev'. ['Traceback (most recent call last):\n', '  File "C:\\Users\\Andrea Bassi\\Documents\\PythonProjects\\BassiScopeFoundryMicroscopes\\ScopeFoundry\\measurement.py", line 279, in _on_display_update_timer\n    self.update_display()\n', '  File "C:\\Users\\Andrea Bassi\\Documents\\PythonProjects\\BassiScopeFoundryMicroscopes\\Microscopes\\VirtualMicroscopeJoyStick\\SineGenJoyStick_measure.py", line 82, in update_display\n    self.func_gen.settings[\'amplitude\'] = self.joystick.joystick_dev.get_axis_values(AXIS_L2)\n', "AttributeError: 'JoyStick_HW' object has no attribute 'joystick_dev'\n"]
2019-12-06T18:12:07|ERROR|SineWaveJoyStickMeasure|sine_wave_joystick Failed to update figure1: 'JoyStick_HW' object has no attribute 'joystick_dev'. ['Traceback (most recent call last):\n', '  File "C:\\Users\\Andrea Bassi\\Documents\\PythonProjects\\BassiScopeFoundryMicroscopes\\ScopeFoundry\\measurement.py", line 279, in _on_display_update_timer\n    self.update_display()\n', '  File "C:\\Users\\Andrea Bassi\\Documents\\PythonProjects\\BassiScopeFoundryMicroscopes\\Microscopes\\VirtualMicroscopeJoyStick\\SineGenJoyStick_measure.py", line 82, in update_display\n    self.func_gen.settings[\'amplitude\'] = self.joystick.joystick_dev.get_axis_values(AXIS_L2)\n', "AttributeError: 'JoyStick_HW' object has no attribute 'joystick_dev'\n"]
2019-12-06T18:12:07|ERROR|SineWaveJoyStickMeasure|sine_wave_joystick Failed to update figure1: 'JoyStick_HW' object has no attribute 'joystick_dev'. ['Traceback (most recent call last):\n', '  File "C:\\Users\\Andrea Bassi\\Documents\\PythonProjects\\BassiScopeFoundryMicroscopes\\ScopeFoundry\\measurement.py", line 279, in _on_display_update_timer\n    self.update_display()\n', '  File "C:\\Users\\Andrea Bassi\\Documents\\PythonProjects\\BassiScopeFoundryMicroscopes\\Microscopes\\VirtualMicroscopeJoyStick\\SineGenJoyStick_measure.py", line 82, in update_display\n    self.func_gen.settings[\'amplitude\'] = self.joystick.joystick_dev.get_axis_values(AXIS_L2)\n', "AttributeError: 'JoyStick_HW' object has no attribute 'joystick_dev'\n"]
2019-12-06T18:12:07|ERROR|SineWaveJoyStickMeasure|sine_wave_joystick Failed to update figure1: 'JoyStick_HW' object has no attribute 'joystick_dev'. ['Traceback (most recent call last):\n', '  File "C:\\Users\\Andrea Bassi\\Documents\\PythonProjects\\BassiScopeFoundryMicroscopes\\ScopeFoundry\\measurement.py", line 279, in _on_display_update_timer\n    self.update_display()\n', '  File "C:\\Users\\Andrea Bassi\\Documents\\PythonProjects\\BassiScopeFoundryMicroscopes\\Microscopes\\VirtualMicroscopeJoyStick\\SineGenJoyStick_measure.py", line 82, in update_display\n    self.func_gen.settings[\'amplitude\'] = self.joystick.joystick_dev.get_axis_values(AXIS_L2)\n', "AttributeError: 'JoyStick_HW' object has no attribute 'joystick_dev'\n"]
2019-12-06T18:12:07|ERROR|SineWaveJoyStickMeasure|sine_wave_joystick Failed to update figure1: 'JoyStick_HW' object has no attribute 'joystick_dev'. ['Traceback (most recent call last):\n', '  File "C:\\Users\\Andrea Bassi\\Documents\\PythonProjects\\BassiScopeFoundryMicroscopes\\ScopeFoundry\\measurement.py", line 279, in _on_display_update_timer\n    self.update_display()\n', '  File "C:\\Users\\Andrea Bassi\\Documents\\PythonProjects\\BassiScopeFoundryMicroscopes\\Microscopes\\VirtualMicroscopeJoyStick\\SineGenJoyStick_measure.py", line 82, in update_display\n    self.func_gen.settings[\'amplitude\'] = self.joystick.joystick_dev.get_axis_values(AXIS_L2)\n', "AttributeError: 'JoyStick_HW' object has no attribute 'joystick_dev'\n"]
2019-12-06T18:12:07|ERROR|SineWaveJoyStickMeasure|sine_wave_joystick Failed to update figure1: 'JoyStick_HW' object has no attribute 'joystick_dev'. ['Traceback (most recent call last):\n', '  File "C:\\Users\\Andrea Bassi\\Documents\\PythonProjects\\BassiScopeFoundryMicroscopes\\ScopeFoundry\\measurement.py", line 279, in _on_display_update_timer\n    self.update_display()\n', '  File "C:\\Users\\Andrea Bassi\\Documents\\PythonProjects\\BassiScopeFoundryMicroscopes\\Microscopes\\VirtualMicroscopeJoyStick\\SineGenJoyStick_measure.py", line 82, in update_display\n    self.func_gen.settings[\'amplitude\'] = self.joystick.joystick_dev.get_axis_values(AXIS_L2)\n', "AttributeError: 'JoyStick_HW' object has no attribute 'joystick_dev'\n"]
2019-12-06T18:12:07|ERROR|SineWaveJoyStickMeasure|sine_wave_joystick Failed to update figure1: 'JoyStick_HW' object has no attribute 'joystick_dev'. ['Traceback (most recent call last):\n', '  File "C:\\Users\\Andrea Bassi\\Documents\\PythonProjects\\BassiScopeFoundryMicroscopes\\ScopeFoundry\\measurement.py", line 279, in _on_display_update_timer\n    self.update_display()\n', '  File "C:\\Users\\Andrea Bassi\\Documents\\PythonProjects\\BassiScopeFoundryMicroscopes\\Microscopes\\VirtualMicroscopeJoyStick\\SineGenJoyStick_measure.py", line 82, in update_display\n    self.func_gen.settings[\'amplitude\'] = self.joystick.joystick_dev.get_axis_values(AXIS_L2)\n', "AttributeError: 'JoyStick_HW' object has no attribute 'joystick_dev'\n"]
2019-12-06T18:12:07|ERROR|SineWaveJoyStickMeasure|sine_wave_joystick Failed to update figure1: 'JoyStick_HW' object has no attribute 'joystick_dev'. ['Traceback (most recent call last):\n', '  File "C:\\Users\\Andrea Bassi\\Documents\\PythonProjects\\BassiScopeFoundryMicroscopes\\ScopeFoundry\\measurement.py", line 279, in _on_display_update_timer\n    self.update_display()\n', '  File "C:\\Users\\Andrea Bassi\\Documents\\PythonProjects\\BassiScopeFoundryMicroscopes\\Microscopes\\VirtualMicroscopeJoyStick\\SineGenJoyStick_measure.py", line 82, in update_display\n    self.func_gen.settings[\'amplitude\'] = self.joystick.joystick_dev.get_axis_values(AXIS_L2)\n', "AttributeError: 'JoyStick_HW' object has no attribute 'joystick_dev'\n"]
2019-12-06T18:12:08|ERROR|SineWaveJoyStickMeasure|sine_wave_joystick Failed to update figure1: 'JoyStick_HW' object has no attribute 'joystick_dev'. ['Traceback (most recent call last):\n', '  File "C:\\Users\\Andrea Bassi\\Documents\\PythonProjects\\BassiScopeFoundryMicroscopes\\ScopeFoundry\\measurement.py", line 279, in _on_display_update_timer\n    self.update_display()\n', '  File "C:\\Users\\Andrea Bassi\\Documents\\PythonProjects\\BassiScopeFoundryMicroscopes\\Microscopes\\VirtualMicroscopeJoyStick\\SineGenJoyStick_measure.py", line 82, in update_display\n    self.func_gen.settings[\'amplitude\'] = self.joystick.joystick_dev.get_axis_values(AXIS_L2)\n', "AttributeError: 'JoyStick_HW' object has no attribute 'joystick_dev'\n"]
2019-12-06T18:12:08|ERROR|SineWaveJoyStickMeasure|sine_wave_joystick Failed to update figure1: 'JoyStick_HW' object has no attribute 'joystick_dev'. ['Traceback (most recent call last):\n', '  File "C:\\Users\\Andrea Bassi\\Documents\\PythonProjects\\BassiScopeFoundryMicroscopes\\ScopeFoundry\\measurement.py", line 279, in _on_display_update_timer\n    self.update_display()\n', '  File "C:\\Users\\Andrea Bassi\\Documents\\PythonProjects\\BassiScopeFoundryMicroscopes\\Microscopes\\VirtualMicroscopeJoyStick\\SineGenJoyStick_measure.py", line 82, in update_display\n    self.func_gen.settings[\'amplitude\'] = self.joystick.joystick_dev.get_axis_values(AXIS_L2)\n', "AttributeError: 'JoyStick_HW' object has no attribute 'joystick_dev'\n"]
2019-12-06T18:12:08|ERROR|SineWaveJoyStickMeasure|sine_wave_joystick Failed to update figure1: 'JoyStick_HW' object has no attribute 'joystick_dev'. ['Traceback (most recent call last):\n', '  File "C:\\Users\\Andrea Bassi\\Documents\\PythonProjects\\BassiScopeFoundryMicroscopes\\ScopeFoundry\\measurement.py", line 279, in _on_display_update_timer\n    self.update_display()\n', '  File "C:\\Users\\Andrea Bassi\\Documents\\PythonProjects\\BassiScopeFoundryMicroscopes\\Microscopes\\VirtualMicroscopeJoyStick\\SineGenJoyStick_measure.py", line 82, in update_display\n    self.func_gen.settings[\'amplitude\'] = self.joystick.joystick_dev.get_axis_values(AXIS_L2)\n', "AttributeError: 'JoyStick_HW' object has no attribute 'joystick_dev'\n"]
2019-12-06T18:12:08|ERROR|SineWaveJoyStickMeasure|sine_wave_joystick Failed to update figure1: 'JoyStick_HW' object has no attribute 'joystick_dev'. ['Traceback (most recent call last):\n', '  File "C:\\Users\\Andrea Bassi\\Documents\\PythonProjects\\BassiScopeFoundryMicroscopes\\ScopeFoundry\\measurement.py", line 279, in _on_display_update_timer\n    self.update_display()\n', '  File "C:\\Users\\Andrea Bassi\\Documents\\PythonProjects\\BassiScopeFoundryMicroscopes\\Microscopes\\VirtualMicroscopeJoyStick\\SineGenJoyStick_measure.py", line 82, in update_display\n    self.func_gen.settings[\'amplitude\'] = self.joystick.joystick_dev.get_axis_values(AXIS_L2)\n', "AttributeError: 'JoyStick_HW' object has no attribute 'joystick_dev'\n"]
2019-12-06T18:12:08|ERROR|SineWaveJoyStickMeasure|sine_wave_joystick Failed to update figure1: 'JoyStick_HW' object has no attribute 'joystick_dev'. ['Traceback (most recent call last):\n', '  File "C:\\Users\\Andrea Bassi\\Documents\\PythonProjects\\BassiScopeFoundryMicroscopes\\ScopeFoundry\\measurement.py", line 279, in _on_display_update_timer\n    self.update_display()\n', '  File "C:\\Users\\Andrea Bassi\\Documents\\PythonProjects\\BassiScopeFoundryMicroscopes\\Microscopes\\VirtualMicroscopeJoyStick\\SineGenJoyStick_measure.py", line 82, in update_display\n    self.func_gen.settings[\'amplitude\'] = self.joystick.joystick_dev.get_axis_values(AXIS_L2)\n', "AttributeError: 'JoyStick_HW' object has no attribute 'joystick_dev'\n"]
2019-12-06T18:12:08|ERROR|SineWaveJoyStickMeasure|sine_wave_joystick Failed to update figure1: 'JoyStick_HW' object has no attribute 'joystick_dev'. ['Traceback (most recent call last):\n', '  File "C:\\Users\\Andrea Bassi\\Documents\\PythonProjects\\BassiScopeFoundryMicroscopes\\ScopeFoundry\\measurement.py", line 279, in _on_display_update_timer\n    self.update_display()\n', '  File "C:\\Users\\Andrea Bassi\\Documents\\PythonProjects\\BassiScopeFoundryMicroscopes\\Microscopes\\VirtualMicroscopeJoyStick\\SineGenJoyStick_measure.py", line 82, in update_display\n    self.func_gen.settings[\'amplitude\'] = self.joystick.joystick_dev.get_axis_values(AXIS_L2)\n', "AttributeError: 'JoyStick_HW' object has no attribute 'joystick_dev'\n"]
2019-12-06T18:12:08|ERROR|SineWaveJoyStickMeasure|sine_wave_joystick Failed to update figure1: 'JoyStick_HW' object has no attribute 'joystick_dev'. ['Traceback (most recent call last):\n', '  File "C:\\Users\\Andrea Bassi\\Documents\\PythonProjects\\BassiScopeFoundryMicroscopes\\ScopeFoundry\\measurement.py", line 279, in _on_display_update_timer\n    self.update_display()\n', '  File "C:\\Users\\Andrea Bassi\\Documents\\PythonProjects\\BassiScopeFoundryMicroscopes\\Microscopes\\VirtualMicroscopeJoyStick\\SineGenJoyStick_measure.py", line 82, in update_display\n    self.func_gen.settings[\'amplitude\'] = self.joystick.joystick_dev.get_axis_values(AXIS_L2)\n', "AttributeError: 'JoyStick_HW' object has no attribute 'joystick_dev'\n"]
2019-12-06T18:12:08|ERROR|SineWaveJoyStickMeasure|sine_wave_joystick Failed to update figure1: 'JoyStick_HW' object has no attribute 'joystick_dev'. ['Traceback (most recent call last):\n', '  File "C:\\Users\\Andrea Bassi\\Documents\\PythonProjects\\BassiScopeFoundryMicroscopes\\ScopeFoundry\\measurement.py", line 279, in _on_display_update_timer\n    self.update_display()\n', '  File "C:\\Users\\Andrea Bassi\\Documents\\PythonProjects\\BassiScopeFoundryMicroscopes\\Microscopes\\VirtualMicroscopeJoyStick\\SineGenJoyStick_measure.py", line 82, in update_display\n    self.func_gen.settings[\'amplitude\'] = self.joystick.joystick_dev.get_axis_values(AXIS_L2)\n', "AttributeError: 'JoyStick_HW' object has no attribute 'joystick_dev'\n"]
2019-12-06T18:12:09|ERROR|SineWaveJoyStickMeasure|sine_wave_joystick Failed to update figure1: 'JoyStick_HW' object has no attribute 'joystick_dev'. ['Traceback (most recent call last):\n', '  File "C:\\Users\\Andrea Bassi\\Documents\\PythonProjects\\BassiScopeFoundryMicroscopes\\ScopeFoundry\\measurement.py", line 279, in _on_display_update_timer\n    self.update_display()\n', '  File "C:\\Users\\Andrea Bassi\\Documents\\PythonProjects\\BassiScopeFoundryMicroscopes\\Microscopes\\VirtualMicroscopeJoyStick\\SineGenJoyStick_measure.py", line 82, in update_display\n    self.func_gen.settings[\'amplitude\'] = self.joystick.joystick_dev.get_axis_values(AXIS_L2)\n', "AttributeError: 'JoyStick_HW' object has no attribute 'joystick_dev'\n"]
2019-12-06T18:12:09|ERROR|SineWaveJoyStickMeasure|sine_wave_joystick Failed to update figure1: 'JoyStick_HW' object has no attribute 'joystick_dev'. ['Traceback (most recent call last):\n', '  File "C:\\Users\\Andrea Bassi\\Documents\\PythonProjects\\BassiScopeFoundryMicroscopes\\ScopeFoundry\\measurement.py", line 279, in _on_display_update_timer\n    self.update_display()\n', '  File "C:\\Users\\Andrea Bassi\\Documents\\PythonProjects\\BassiScopeFoundryMicroscopes\\Microscopes\\VirtualMicroscopeJoyStick\\SineGenJoyStick_measure.py", line 82, in update_display\n    self.func_gen.settings[\'amplitude\'] = self.joystick.joystick_dev.get_axis_values(AXIS_L2)\n', "AttributeError: 'JoyStick_HW' object has no attribute 'joystick_dev'\n"]
2019-12-06T18:26:21|CRITICAL|root|Unhandled exception:Traceback (most recent call last):
  File "C:\Users\Andrea Bassi\Documents\PythonProjects\BassiScopeFoundryMicroscopes\ScopeFoundry\hardware.py", line 182, in read_from_hardware
    lq.read_from_hardware()
  File "C:\Users\Andrea Bassi\Documents\PythonProjects\BassiScopeFoundryMicroscopes\ScopeFoundry\logged_quantity.py", line 163, in read_from_hardware
    val = self.hardware_read_func()
  File "C:\Users\Andrea Bassi\Documents\PythonProjects\BassiScopeFoundryMicroscopes\ScopeFoundryHW\joystick_hardware\joystick_device.py", line 37, in get_axis_values
    return axis[index]
IndexError: list index out of range

2019-12-06T18:26:25|CRITICAL|root|Unhandled exception:Traceback (most recent call last):
  File "C:\Users\Andrea Bassi\Documents\PythonProjects\BassiScopeFoundryMicroscopes\ScopeFoundry\hardware.py", line 182, in read_from_hardware
    lq.read_from_hardware()
  File "C:\Users\Andrea Bassi\Documents\PythonProjects\BassiScopeFoundryMicroscopes\ScopeFoundry\logged_quantity.py", line 163, in read_from_hardware
    val = self.hardware_read_func()
  File "C:\Users\Andrea Bassi\Documents\PythonProjects\BassiScopeFoundryMicroscopes\ScopeFoundryHW\joystick_hardware\joystick_device.py", line 37, in get_axis_values
    return axis[index]
IndexError: list index out of range

2019-12-06T18:26:26|CRITICAL|root|Unhandled exception:Traceback (most recent call last):
  File "C:\Users\Andrea Bassi\Documents\PythonProjects\BassiScopeFoundryMicroscopes\ScopeFoundry\hardware.py", line 182, in read_from_hardware
    lq.read_from_hardware()
  File "C:\Users\Andrea Bassi\Documents\PythonProjects\BassiScopeFoundryMicroscopes\ScopeFoundry\logged_quantity.py", line 163, in read_from_hardware
    val = self.hardware_read_func()
  File "C:\Users\Andrea Bassi\Documents\PythonProjects\BassiScopeFoundryMicroscopes\ScopeFoundryHW\joystick_hardware\joystick_device.py", line 37, in get_axis_values
    return axis[index]
IndexError: list index out of range

2019-12-06T18:26:29|CRITICAL|root|Unhandled exception:Traceback (most recent call last):
  File "C:\Users\Andrea Bassi\Documents\PythonProjects\BassiScopeFoundryMicroscopes\ScopeFoundry\hardware.py", line 182, in read_from_hardware
    lq.read_from_hardware()
  File "C:\Users\Andrea Bassi\Documents\PythonProjects\BassiScopeFoundryMicroscopes\ScopeFoundry\logged_quantity.py", line 163, in read_from_hardware
    val = self.hardware_read_func()
  File "C:\Users\Andrea Bassi\Documents\PythonProjects\BassiScopeFoundryMicroscopes\ScopeFoundryHW\joystick_hardware\joystick_device.py", line 37, in get_axis_values
    return axis[index]
IndexError: list index out of range

2019-12-06T18:26:30|CRITICAL|root|Unhandled exception:Traceback (most recent call last):
  File "C:\Users\Andrea Bassi\Documents\PythonProjects\BassiScopeFoundryMicroscopes\ScopeFoundry\hardware.py", line 182, in read_from_hardware
    lq.read_from_hardware()
  File "C:\Users\Andrea Bassi\Documents\PythonProjects\BassiScopeFoundryMicroscopes\ScopeFoundry\logged_quantity.py", line 163, in read_from_hardware
    val = self.hardware_read_func()
  File "C:\Users\Andrea Bassi\Documents\PythonProjects\BassiScopeFoundryMicroscopes\ScopeFoundryHW\joystick_hardware\joystick_device.py", line 37, in get_axis_values
    return axis[index]
IndexError: list index out of range

2019-12-06T18:26:51|CRITICAL|root|Unhandled exception:Traceback (most recent call last):
  File "C:\Users\Andrea Bassi\Documents\PythonProjects\BassiScopeFoundryMicroscopes\ScopeFoundry\hardware.py", line 182, in read_from_hardware
    lq.read_from_hardware()
  File "C:\Users\Andrea Bassi\Documents\PythonProjects\BassiScopeFoundryMicroscopes\ScopeFoundry\logged_quantity.py", line 163, in read_from_hardware
    val = self.hardware_read_func()
  File "C:\Users\Andrea Bassi\Documents\PythonProjects\BassiScopeFoundryMicroscopes\ScopeFoundryHW\joystick_hardware\joystick_device.py", line 37, in get_axis_values
    return axis[index]
IndexError: list index out of range

2019-12-06T18:26:52|CRITICAL|root|Unhandled exception:Traceback (most recent call last):
  File "C:\Users\Andrea Bassi\Documents\PythonProjects\BassiScopeFoundryMicroscopes\ScopeFoundry\hardware.py", line 182, in read_from_hardware
    lq.read_from_hardware()
  File "C:\Users\Andrea Bassi\Documents\PythonProjects\BassiScopeFoundryMicroscopes\ScopeFoundry\logged_quantity.py", line 163, in read_from_hardware
    val = self.hardware_read_func()
  File "C:\Users\Andrea Bassi\Documents\PythonProjects\BassiScopeFoundryMicroscopes\ScopeFoundryHW\joystick_hardware\joystick_device.py", line 37, in get_axis_values
    return axis[index]
IndexError: list index out of range

2019-12-06T18:26:55|CRITICAL|root|Unhandled exception:Traceback (most recent call last):
  File "C:\Users\Andrea Bassi\Documents\PythonProjects\BassiScopeFoundryMicroscopes\ScopeFoundry\hardware.py", line 182, in read_from_hardware
    lq.read_from_hardware()
  File "C:\Users\Andrea Bassi\Documents\PythonProjects\BassiScopeFoundryMicroscopes\ScopeFoundry\logged_quantity.py", line 163, in read_from_hardware
    val = self.hardware_read_func()
  File "C:\Users\Andrea Bassi\Documents\PythonProjects\BassiScopeFoundryMicroscopes\ScopeFoundryHW\joystick_hardware\joystick_device.py", line 37, in get_axis_values
    return axis[index]
IndexError: list index out of range

2019-12-06T18:26:56|CRITICAL|root|Unhandled exception:Traceback (most recent call last):
  File "C:\Users\Andrea Bassi\Documents\PythonProjects\BassiScopeFoundryMicroscopes\ScopeFoundry\hardware.py", line 182, in read_from_hardware
    lq.read_from_hardware()
  File "C:\Users\Andrea Bassi\Documents\PythonProjects\BassiScopeFoundryMicroscopes\ScopeFoundry\logged_quantity.py", line 163, in read_from_hardware
    val = self.hardware_read_func()
  File "C:\Users\Andrea Bassi\Documents\PythonProjects\BassiScopeFoundryMicroscopes\ScopeFoundryHW\joystick_hardware\joystick_device.py", line 37, in get_axis_values
    return axis[index]
IndexError: list index out of range

2019-12-06T18:29:23|CRITICAL|root|Unhandled exception:Traceback (most recent call last):
  File "C:\Users\Andrea Bassi\Documents\PythonProjects\BassiScopeFoundryMicroscopes\ScopeFoundry\hardware.py", line 182, in read_from_hardware
    lq.read_from_hardware()
  File "C:\Users\Andrea Bassi\Documents\PythonProjects\BassiScopeFoundryMicroscopes\ScopeFoundry\logged_quantity.py", line 163, in read_from_hardware
    val = self.hardware_read_func()
  File "C:\Users\Andrea Bassi\Documents\PythonProjects\BassiScopeFoundryMicroscopes\ScopeFoundryHW\joystick_hardware\joystick_device.py", line 65, in get_hat_values
    return hats[index][0]
IndexError: list index out of range

2019-12-06T18:29:36|CRITICAL|root|Unhandled exception:Traceback (most recent call last):
  File "C:\Users\Andrea Bassi\Documents\PythonProjects\BassiScopeFoundryMicroscopes\ScopeFoundry\hardware.py", line 182, in read_from_hardware
    lq.read_from_hardware()
  File "C:\Users\Andrea Bassi\Documents\PythonProjects\BassiScopeFoundryMicroscopes\ScopeFoundry\logged_quantity.py", line 163, in read_from_hardware
    val = self.hardware_read_func()
  File "C:\Users\Andrea Bassi\Documents\PythonProjects\BassiScopeFoundryMicroscopes\ScopeFoundryHW\joystick_hardware\joystick_device.py", line 65, in get_hat_values
    return hats[index][0]
IndexError: list index out of range

2019-12-06T18:29:37|CRITICAL|root|Unhandled exception:Traceback (most recent call last):
  File "C:\Users\Andrea Bassi\Documents\PythonProjects\BassiScopeFoundryMicroscopes\ScopeFoundry\hardware.py", line 182, in read_from_hardware
    lq.read_from_hardware()
  File "C:\Users\Andrea Bassi\Documents\PythonProjects\BassiScopeFoundryMicroscopes\ScopeFoundry\logged_quantity.py", line 163, in read_from_hardware
    val = self.hardware_read_func()
  File "C:\Users\Andrea Bassi\Documents\PythonProjects\BassiScopeFoundryMicroscopes\ScopeFoundryHW\joystick_hardware\joystick_device.py", line 65, in get_hat_values
    return hats[index][0]
IndexError: list index out of range

2019-12-06T18:29:42|CRITICAL|root|Unhandled exception:Traceback (most recent call last):
  File "C:\Users\Andrea Bassi\Documents\PythonProjects\BassiScopeFoundryMicroscopes\ScopeFoundry\hardware.py", line 182, in read_from_hardware
    lq.read_from_hardware()
  File "C:\Users\Andrea Bassi\Documents\PythonProjects\BassiScopeFoundryMicroscopes\ScopeFoundry\logged_quantity.py", line 163, in read_from_hardware
    val = self.hardware_read_func()
  File "C:\Users\Andrea Bassi\Documents\PythonProjects\BassiScopeFoundryMicroscopes\ScopeFoundryHW\joystick_hardware\joystick_device.py", line 65, in get_hat_values
    return hats[index][0]
IndexError: list index out of range

2019-12-06T18:29:43|CRITICAL|root|Unhandled exception:Traceback (most recent call last):
  File "C:\Users\Andrea Bassi\Documents\PythonProjects\BassiScopeFoundryMicroscopes\ScopeFoundry\hardware.py", line 182, in read_from_hardware
    lq.read_from_hardware()
  File "C:\Users\Andrea Bassi\Documents\PythonProjects\BassiScopeFoundryMicroscopes\ScopeFoundry\logged_quantity.py", line 163, in read_from_hardware
    val = self.hardware_read_func()
  File "C:\Users\Andrea Bassi\Documents\PythonProjects\BassiScopeFoundryMicroscopes\ScopeFoundryHW\joystick_hardware\joystick_device.py", line 65, in get_hat_values
    return hats[index][0]
IndexError: list index out of range

2019-12-06T18:29:44|CRITICAL|root|Unhandled exception:Traceback (most recent call last):
  File "C:\Users\Andrea Bassi\Documents\PythonProjects\BassiScopeFoundryMicroscopes\ScopeFoundry\hardware.py", line 182, in read_from_hardware
    lq.read_from_hardware()
  File "C:\Users\Andrea Bassi\Documents\PythonProjects\BassiScopeFoundryMicroscopes\ScopeFoundry\logged_quantity.py", line 163, in read_from_hardware
    val = self.hardware_read_func()
  File "C:\Users\Andrea Bassi\Documents\PythonProjects\BassiScopeFoundryMicroscopes\ScopeFoundryHW\joystick_hardware\joystick_device.py", line 65, in get_hat_values
    return hats[index][0]
IndexError: list index out of range

2019-12-06T18:29:46|CRITICAL|root|Unhandled exception:Traceback (most recent call last):
  File "C:\Users\Andrea Bassi\Documents\PythonProjects\BassiScopeFoundryMicroscopes\ScopeFoundry\hardware.py", line 182, in read_from_hardware
    lq.read_from_hardware()
  File "C:\Users\Andrea Bassi\Documents\PythonProjects\BassiScopeFoundryMicroscopes\ScopeFoundry\logged_quantity.py", line 163, in read_from_hardware
    val = self.hardware_read_func()
  File "C:\Users\Andrea Bassi\Documents\PythonProjects\BassiScopeFoundryMicroscopes\ScopeFoundryHW\joystick_hardware\joystick_device.py", line 65, in get_hat_values
    return hats[index][0]
IndexError: list index out of range

2019-12-06T18:29:49|CRITICAL|root|Unhandled exception:Traceback (most recent call last):
  File "C:\Users\Andrea Bassi\Documents\PythonProjects\BassiScopeFoundryMicroscopes\ScopeFoundry\hardware.py", line 182, in read_from_hardware
    lq.read_from_hardware()
  File "C:\Users\Andrea Bassi\Documents\PythonProjects\BassiScopeFoundryMicroscopes\ScopeFoundry\logged_quantity.py", line 163, in read_from_hardware
    val = self.hardware_read_func()
  File "C:\Users\Andrea Bassi\Documents\PythonProjects\BassiScopeFoundryMicroscopes\ScopeFoundryHW\joystick_hardware\joystick_device.py", line 65, in get_hat_values
    return hats[index][0]
IndexError: list index out of range

2019-12-06T18:29:49|CRITICAL|root|Unhandled exception:Traceback (most recent call last):
  File "C:\Users\Andrea Bassi\Documents\PythonProjects\BassiScopeFoundryMicroscopes\ScopeFoundry\hardware.py", line 182, in read_from_hardware
    lq.read_from_hardware()
  File "C:\Users\Andrea Bassi\Documents\PythonProjects\BassiScopeFoundryMicroscopes\ScopeFoundry\logged_quantity.py", line 163, in read_from_hardware
    val = self.hardware_read_func()
  File "C:\Users\Andrea Bassi\Documents\PythonProjects\BassiScopeFoundryMicroscopes\ScopeFoundryHW\joystick_hardware\joystick_device.py", line 65, in get_hat_values
    return hats[index][0]
IndexError: list index out of range

2019-12-06T18:29:50|CRITICAL|root|Unhandled exception:Traceback (most recent call last):
  File "C:\Users\Andrea Bassi\Documents\PythonProjects\BassiScopeFoundryMicroscopes\ScopeFoundry\hardware.py", line 182, in read_from_hardware
    lq.read_from_hardware()
  File "C:\Users\Andrea Bassi\Documents\PythonProjects\BassiScopeFoundryMicroscopes\ScopeFoundry\logged_quantity.py", line 163, in read_from_hardware
    val = self.hardware_read_func()
  File "C:\Users\Andrea Bassi\Documents\PythonProjects\BassiScopeFoundryMicroscopes\ScopeFoundryHW\joystick_hardware\joystick_device.py", line 65, in get_hat_values
    return hats[index][0]
IndexError: list index out of range

2019-12-06T18:29:52|CRITICAL|root|Unhandled exception:Traceback (most recent call last):
  File "C:\Users\Andrea Bassi\Documents\PythonProjects\BassiScopeFoundryMicroscopes\ScopeFoundry\hardware.py", line 182, in read_from_hardware
    lq.read_from_hardware()
  File "C:\Users\Andrea Bassi\Documents\PythonProjects\BassiScopeFoundryMicroscopes\ScopeFoundry\logged_quantity.py", line 163, in read_from_hardware
    val = self.hardware_read_func()
  File "C:\Users\Andrea Bassi\Documents\PythonProjects\BassiScopeFoundryMicroscopes\ScopeFoundryHW\joystick_hardware\joystick_device.py", line 65, in get_hat_values
    return hats[index][0]
IndexError: list index out of range

2019-12-06T18:30:21|CRITICAL|root|Unhandled exception:Traceback (most recent call last):
  File "C:\Users\Andrea Bassi\Documents\PythonProjects\BassiScopeFoundryMicroscopes\ScopeFoundry\hardware.py", line 182, in read_from_hardware
    lq.read_from_hardware()
  File "C:\Users\Andrea Bassi\Documents\PythonProjects\BassiScopeFoundryMicroscopes\ScopeFoundry\logged_quantity.py", line 163, in read_from_hardware
    val = self.hardware_read_func()
  File "C:\Users\Andrea Bassi\Documents\PythonProjects\BassiScopeFoundryMicroscopes\ScopeFoundryHW\joystick_hardware\joystick_device.py", line 65, in get_hat_values
    return hats[index][0]
IndexError: list index out of range

2019-12-06T18:30:23|CRITICAL|root|Unhandled exception:Traceback (most recent call last):
  File "C:\Users\Andrea Bassi\Documents\PythonProjects\BassiScopeFoundryMicroscopes\ScopeFoundry\hardware.py", line 182, in read_from_hardware
    lq.read_from_hardware()
  File "C:\Users\Andrea Bassi\Documents\PythonProjects\BassiScopeFoundryMicroscopes\ScopeFoundry\logged_quantity.py", line 163, in read_from_hardware
    val = self.hardware_read_func()
  File "C:\Users\Andrea Bassi\Documents\PythonProjects\BassiScopeFoundryMicroscopes\ScopeFoundryHW\joystick_hardware\joystick_device.py", line 65, in get_hat_values
    return hats[index][0]
IndexError: list index out of range

2019-12-06T18:30:24|CRITICAL|root|Unhandled exception:Traceback (most recent call last):
  File "C:\Users\Andrea Bassi\Documents\PythonProjects\BassiScopeFoundryMicroscopes\ScopeFoundry\hardware.py", line 182, in read_from_hardware
    lq.read_from_hardware()
  File "C:\Users\Andrea Bassi\Documents\PythonProjects\BassiScopeFoundryMicroscopes\ScopeFoundry\logged_quantity.py", line 163, in read_from_hardware
    val = self.hardware_read_func()
  File "C:\Users\Andrea Bassi\Documents\PythonProjects\BassiScopeFoundryMicroscopes\ScopeFoundryHW\joystick_hardware\joystick_device.py", line 65, in get_hat_values
    return hats[index][0]
IndexError: list index out of range

2019-12-06T18:30:25|CRITICAL|root|Unhandled exception:Traceback (most recent call last):
  File "C:\Users\Andrea Bassi\Documents\PythonProjects\BassiScopeFoundryMicroscopes\ScopeFoundry\hardware.py", line 182, in read_from_hardware
    lq.read_from_hardware()
  File "C:\Users\Andrea Bassi\Documents\PythonProjects\BassiScopeFoundryMicroscopes\ScopeFoundry\logged_quantity.py", line 163, in read_from_hardware
    val = self.hardware_read_func()
  File "C:\Users\Andrea Bassi\Documents\PythonProjects\BassiScopeFoundryMicroscopes\ScopeFoundryHW\joystick_hardware\joystick_device.py", line 65, in get_hat_values
    return hats[index][0]
IndexError: list index out of range

2019-12-06T18:30:27|CRITICAL|root|Unhandled exception:Traceback (most recent call last):
  File "C:\Users\Andrea Bassi\Documents\PythonProjects\BassiScopeFoundryMicroscopes\ScopeFoundry\hardware.py", line 182, in read_from_hardware
    lq.read_from_hardware()
  File "C:\Users\Andrea Bassi\Documents\PythonProjects\BassiScopeFoundryMicroscopes\ScopeFoundry\logged_quantity.py", line 163, in read_from_hardware
    val = self.hardware_read_func()
  File "C:\Users\Andrea Bassi\Documents\PythonProjects\BassiScopeFoundryMicroscopes\ScopeFoundryHW\joystick_hardware\joystick_device.py", line 65, in get_hat_values
    return hats[index][0]
IndexError: list index out of range

2019-12-06T18:30:29|CRITICAL|root|Unhandled exception:Traceback (most recent call last):
  File "C:\Users\Andrea Bassi\Documents\PythonProjects\BassiScopeFoundryMicroscopes\ScopeFoundry\hardware.py", line 182, in read_from_hardware
    lq.read_from_hardware()
  File "C:\Users\Andrea Bassi\Documents\PythonProjects\BassiScopeFoundryMicroscopes\ScopeFoundry\logged_quantity.py", line 163, in read_from_hardware
    val = self.hardware_read_func()
  File "C:\Users\Andrea Bassi\Documents\PythonProjects\BassiScopeFoundryMicroscopes\ScopeFoundryHW\joystick_hardware\joystick_device.py", line 65, in get_hat_values
    return hats[index][0]
IndexError: list index out of range

2019-12-06T18:30:32|CRITICAL|root|Unhandled exception:Traceback (most recent call last):
  File "C:\Users\Andrea Bassi\Documents\PythonProjects\BassiScopeFoundryMicroscopes\ScopeFoundry\hardware.py", line 182, in read_from_hardware
    lq.read_from_hardware()
  File "C:\Users\Andrea Bassi\Documents\PythonProjects\BassiScopeFoundryMicroscopes\ScopeFoundry\logged_quantity.py", line 163, in read_from_hardware
    val = self.hardware_read_func()
  File "C:\Users\Andrea Bassi\Documents\PythonProjects\BassiScopeFoundryMicroscopes\ScopeFoundryHW\joystick_hardware\joystick_device.py", line 65, in get_hat_values
    return hats[index][0]
IndexError: list index out of range

2019-12-06T18:30:41|CRITICAL|root|Unhandled exception:Traceback (most recent call last):
  File "C:\Users\Andrea Bassi\Documents\PythonProjects\BassiScopeFoundryMicroscopes\ScopeFoundry\hardware.py", line 182, in read_from_hardware
    lq.read_from_hardware()
  File "C:\Users\Andrea Bassi\Documents\PythonProjects\BassiScopeFoundryMicroscopes\ScopeFoundry\logged_quantity.py", line 163, in read_from_hardware
    val = self.hardware_read_func()
  File "C:\Users\Andrea Bassi\Documents\PythonProjects\BassiScopeFoundryMicroscopes\ScopeFoundryHW\joystick_hardware\joystick_device.py", line 65, in get_hat_values
    return hats[index][0]
IndexError: list index out of range

2019-12-06T18:30:43|CRITICAL|root|Unhandled exception:Traceback (most recent call last):
  File "C:\Users\Andrea Bassi\Documents\PythonProjects\BassiScopeFoundryMicroscopes\ScopeFoundry\hardware.py", line 182, in read_from_hardware
    lq.read_from_hardware()
  File "C:\Users\Andrea Bassi\Documents\PythonProjects\BassiScopeFoundryMicroscopes\ScopeFoundry\logged_quantity.py", line 163, in read_from_hardware
    val = self.hardware_read_func()
  File "C:\Users\Andrea Bassi\Documents\PythonProjects\BassiScopeFoundryMicroscopes\ScopeFoundryHW\joystick_hardware\joystick_device.py", line 65, in get_hat_values
    return hats[index][0]
IndexError: list index out of range

2019-12-06T18:30:43|CRITICAL|root|Unhandled exception:Traceback (most recent call last):
  File "C:\Users\Andrea Bassi\Documents\PythonProjects\BassiScopeFoundryMicroscopes\ScopeFoundry\hardware.py", line 182, in read_from_hardware
    lq.read_from_hardware()
  File "C:\Users\Andrea Bassi\Documents\PythonProjects\BassiScopeFoundryMicroscopes\ScopeFoundry\logged_quantity.py", line 163, in read_from_hardware
    val = self.hardware_read_func()
  File "C:\Users\Andrea Bassi\Documents\PythonProjects\BassiScopeFoundryMicroscopes\ScopeFoundryHW\joystick_hardware\joystick_device.py", line 65, in get_hat_values
    return hats[index][0]
IndexError: list index out of range

2019-12-06T18:30:45|CRITICAL|root|Unhandled exception:Traceback (most recent call last):
  File "C:\Users\Andrea Bassi\Documents\PythonProjects\BassiScopeFoundryMicroscopes\ScopeFoundry\hardware.py", line 182, in read_from_hardware
    lq.read_from_hardware()
  File "C:\Users\Andrea Bassi\Documents\PythonProjects\BassiScopeFoundryMicroscopes\ScopeFoundry\logged_quantity.py", line 163, in read_from_hardware
    val = self.hardware_read_func()
  File "C:\Users\Andrea Bassi\Documents\PythonProjects\BassiScopeFoundryMicroscopes\ScopeFoundryHW\joystick_hardware\joystick_device.py", line 65, in get_hat_values
    return hats[index][0]
IndexError: list index out of range

2019-12-06T18:30:45|CRITICAL|root|Unhandled exception:Traceback (most recent call last):
  File "C:\Users\Andrea Bassi\Documents\PythonProjects\BassiScopeFoundryMicroscopes\ScopeFoundry\hardware.py", line 182, in read_from_hardware
    lq.read_from_hardware()
  File "C:\Users\Andrea Bassi\Documents\PythonProjects\BassiScopeFoundryMicroscopes\ScopeFoundry\logged_quantity.py", line 163, in read_from_hardware
    val = self.hardware_read_func()
  File "C:\Users\Andrea Bassi\Documents\PythonProjects\BassiScopeFoundryMicroscopes\ScopeFoundryHW\joystick_hardware\joystick_device.py", line 65, in get_hat_values
    return hats[index][0]
IndexError: list index out of range

2019-12-06T18:30:46|CRITICAL|root|Unhandled exception:Traceback (most recent call last):
  File "C:\Users\Andrea Bassi\Documents\PythonProjects\BassiScopeFoundryMicroscopes\ScopeFoundry\hardware.py", line 182, in read_from_hardware
    lq.read_from_hardware()
  File "C:\Users\Andrea Bassi\Documents\PythonProjects\BassiScopeFoundryMicroscopes\ScopeFoundry\logged_quantity.py", line 163, in read_from_hardware
    val = self.hardware_read_func()
  File "C:\Users\Andrea Bassi\Documents\PythonProjects\BassiScopeFoundryMicroscopes\ScopeFoundryHW\joystick_hardware\joystick_device.py", line 65, in get_hat_values
    return hats[index][0]
IndexError: list index out of range

2019-12-06T18:30:48|CRITICAL|root|Unhandled exception:Traceback (most recent call last):
  File "C:\Users\Andrea Bassi\Documents\PythonProjects\BassiScopeFoundryMicroscopes\ScopeFoundry\hardware.py", line 182, in read_from_hardware
    lq.read_from_hardware()
  File "C:\Users\Andrea Bassi\Documents\PythonProjects\BassiScopeFoundryMicroscopes\ScopeFoundry\logged_quantity.py", line 163, in read_from_hardware
    val = self.hardware_read_func()
  File "C:\Users\Andrea Bassi\Documents\PythonProjects\BassiScopeFoundryMicroscopes\ScopeFoundryHW\joystick_hardware\joystick_device.py", line 65, in get_hat_values
    return hats[index][0]
IndexError: list index out of range

2019-12-06T18:30:49|CRITICAL|root|Unhandled exception:Traceback (most recent call last):
  File "C:\Users\Andrea Bassi\Documents\PythonProjects\BassiScopeFoundryMicroscopes\ScopeFoundry\hardware.py", line 182, in read_from_hardware
    lq.read_from_hardware()
  File "C:\Users\Andrea Bassi\Documents\PythonProjects\BassiScopeFoundryMicroscopes\ScopeFoundry\logged_quantity.py", line 163, in read_from_hardware
    val = self.hardware_read_func()
  File "C:\Users\Andrea Bassi\Documents\PythonProjects\BassiScopeFoundryMicroscopes\ScopeFoundryHW\joystick_hardware\joystick_device.py", line 65, in get_hat_values
    return hats[index][0]
IndexError: list index out of range

2019-12-06T18:30:50|CRITICAL|root|Unhandled exception:Traceback (most recent call last):
  File "C:\Users\Andrea Bassi\Documents\PythonProjects\BassiScopeFoundryMicroscopes\ScopeFoundry\hardware.py", line 182, in read_from_hardware
    lq.read_from_hardware()
  File "C:\Users\Andrea Bassi\Documents\PythonProjects\BassiScopeFoundryMicroscopes\ScopeFoundry\logged_quantity.py", line 163, in read_from_hardware
    val = self.hardware_read_func()
  File "C:\Users\Andrea Bassi\Documents\PythonProjects\BassiScopeFoundryMicroscopes\ScopeFoundryHW\joystick_hardware\joystick_device.py", line 65, in get_hat_values
    return hats[index][0]
IndexError: list index out of range

2019-12-06T18:30:50|CRITICAL|root|Unhandled exception:Traceback (most recent call last):
  File "C:\Users\Andrea Bassi\Documents\PythonProjects\BassiScopeFoundryMicroscopes\ScopeFoundry\hardware.py", line 182, in read_from_hardware
    lq.read_from_hardware()
  File "C:\Users\Andrea Bassi\Documents\PythonProjects\BassiScopeFoundryMicroscopes\ScopeFoundry\logged_quantity.py", line 163, in read_from_hardware
    val = self.hardware_read_func()
  File "C:\Users\Andrea Bassi\Documents\PythonProjects\BassiScopeFoundryMicroscopes\ScopeFoundryHW\joystick_hardware\joystick_device.py", line 65, in get_hat_values
    return hats[index][0]
IndexError: list index out of range

2019-12-06T18:30:51|CRITICAL|root|Unhandled exception:Traceback (most recent call last):
  File "C:\Users\Andrea Bassi\Documents\PythonProjects\BassiScopeFoundryMicroscopes\ScopeFoundry\hardware.py", line 182, in read_from_hardware
    lq.read_from_hardware()
  File "C:\Users\Andrea Bassi\Documents\PythonProjects\BassiScopeFoundryMicroscopes\ScopeFoundry\logged_quantity.py", line 163, in read_from_hardware
    val = self.hardware_read_func()
  File "C:\Users\Andrea Bassi\Documents\PythonProjects\BassiScopeFoundryMicroscopes\ScopeFoundryHW\joystick_hardware\joystick_device.py", line 65, in get_hat_values
    return hats[index][0]
IndexError: list index out of range

2019-12-06T18:30:52|CRITICAL|root|Unhandled exception:Traceback (most recent call last):
  File "C:\Users\Andrea Bassi\Documents\PythonProjects\BassiScopeFoundryMicroscopes\ScopeFoundry\hardware.py", line 182, in read_from_hardware
    lq.read_from_hardware()
  File "C:\Users\Andrea Bassi\Documents\PythonProjects\BassiScopeFoundryMicroscopes\ScopeFoundry\logged_quantity.py", line 163, in read_from_hardware
    val = self.hardware_read_func()
  File "C:\Users\Andrea Bassi\Documents\PythonProjects\BassiScopeFoundryMicroscopes\ScopeFoundryHW\joystick_hardware\joystick_device.py", line 65, in get_hat_values
    return hats[index][0]
IndexError: list index out of range

2019-12-06T18:30:53|CRITICAL|root|Unhandled exception:Traceback (most recent call last):
  File "C:\Users\Andrea Bassi\Documents\PythonProjects\BassiScopeFoundryMicroscopes\ScopeFoundry\hardware.py", line 182, in read_from_hardware
    lq.read_from_hardware()
  File "C:\Users\Andrea Bassi\Documents\PythonProjects\BassiScopeFoundryMicroscopes\ScopeFoundry\logged_quantity.py", line 163, in read_from_hardware
    val = self.hardware_read_func()
  File "C:\Users\Andrea Bassi\Documents\PythonProjects\BassiScopeFoundryMicroscopes\ScopeFoundryHW\joystick_hardware\joystick_device.py", line 65, in get_hat_values
    return hats[index][0]
IndexError: list index out of range

2019-12-06T18:30:54|CRITICAL|root|Unhandled exception:Traceback (most recent call last):
  File "C:\Users\Andrea Bassi\Documents\PythonProjects\BassiScopeFoundryMicroscopes\ScopeFoundry\hardware.py", line 182, in read_from_hardware
    lq.read_from_hardware()
  File "C:\Users\Andrea Bassi\Documents\PythonProjects\BassiScopeFoundryMicroscopes\ScopeFoundry\logged_quantity.py", line 163, in read_from_hardware
    val = self.hardware_read_func()
  File "C:\Users\Andrea Bassi\Documents\PythonProjects\BassiScopeFoundryMicroscopes\ScopeFoundryHW\joystick_hardware\joystick_device.py", line 65, in get_hat_values
    return hats[index][0]
IndexError: list index out of range

2019-12-06T18:30:54|CRITICAL|root|Unhandled exception:Traceback (most recent call last):
  File "C:\Users\Andrea Bassi\Documents\PythonProjects\BassiScopeFoundryMicroscopes\ScopeFoundry\hardware.py", line 182, in read_from_hardware
    lq.read_from_hardware()
  File "C:\Users\Andrea Bassi\Documents\PythonProjects\BassiScopeFoundryMicroscopes\ScopeFoundry\logged_quantity.py", line 163, in read_from_hardware
    val = self.hardware_read_func()
  File "C:\Users\Andrea Bassi\Documents\PythonProjects\BassiScopeFoundryMicroscopes\ScopeFoundryHW\joystick_hardware\joystick_device.py", line 65, in get_hat_values
    return hats[index][0]
IndexError: list index out of range

2019-12-06T18:30:55|CRITICAL|root|Unhandled exception:Traceback (most recent call last):
  File "C:\Users\Andrea Bassi\Documents\PythonProjects\BassiScopeFoundryMicroscopes\ScopeFoundry\hardware.py", line 182, in read_from_hardware
    lq.read_from_hardware()
  File "C:\Users\Andrea Bassi\Documents\PythonProjects\BassiScopeFoundryMicroscopes\ScopeFoundry\logged_quantity.py", line 163, in read_from_hardware
    val = self.hardware_read_func()
  File "C:\Users\Andrea Bassi\Documents\PythonProjects\BassiScopeFoundryMicroscopes\ScopeFoundryHW\joystick_hardware\joystick_device.py", line 65, in get_hat_values
    return hats[index][0]
IndexError: list index out of range

2019-12-06T18:30:56|CRITICAL|root|Unhandled exception:Traceback (most recent call last):
  File "C:\Users\Andrea Bassi\Documents\PythonProjects\BassiScopeFoundryMicroscopes\ScopeFoundry\hardware.py", line 182, in read_from_hardware
    lq.read_from_hardware()
  File "C:\Users\Andrea Bassi\Documents\PythonProjects\BassiScopeFoundryMicroscopes\ScopeFoundry\logged_quantity.py", line 163, in read_from_hardware
    val = self.hardware_read_func()
  File "C:\Users\Andrea Bassi\Documents\PythonProjects\BassiScopeFoundryMicroscopes\ScopeFoundryHW\joystick_hardware\joystick_device.py", line 65, in get_hat_values
    return hats[index][0]
IndexError: list index out of range

2019-12-06T18:30:57|CRITICAL|root|Unhandled exception:Traceback (most recent call last):
  File "C:\Users\Andrea Bassi\Documents\PythonProjects\BassiScopeFoundryMicroscopes\ScopeFoundry\hardware.py", line 182, in read_from_hardware
    lq.read_from_hardware()
  File "C:\Users\Andrea Bassi\Documents\PythonProjects\BassiScopeFoundryMicroscopes\ScopeFoundry\logged_quantity.py", line 163, in read_from_hardware
    val = self.hardware_read_func()
  File "C:\Users\Andrea Bassi\Documents\PythonProjects\BassiScopeFoundryMicroscopes\ScopeFoundryHW\joystick_hardware\joystick_device.py", line 65, in get_hat_values
    return hats[index][0]
IndexError: list index out of range

2019-12-06T18:30:57|CRITICAL|root|Unhandled exception:Traceback (most recent call last):
  File "C:\Users\Andrea Bassi\Documents\PythonProjects\BassiScopeFoundryMicroscopes\ScopeFoundry\hardware.py", line 182, in read_from_hardware
    lq.read_from_hardware()
  File "C:\Users\Andrea Bassi\Documents\PythonProjects\BassiScopeFoundryMicroscopes\ScopeFoundry\logged_quantity.py", line 163, in read_from_hardware
    val = self.hardware_read_func()
  File "C:\Users\Andrea Bassi\Documents\PythonProjects\BassiScopeFoundryMicroscopes\ScopeFoundryHW\joystick_hardware\joystick_device.py", line 65, in get_hat_values
    return hats[index][0]
IndexError: list index out of range

2019-12-06T18:30:58|CRITICAL|root|Unhandled exception:Traceback (most recent call last):
  File "C:\Users\Andrea Bassi\Documents\PythonProjects\BassiScopeFoundryMicroscopes\ScopeFoundry\hardware.py", line 182, in read_from_hardware
    lq.read_from_hardware()
  File "C:\Users\Andrea Bassi\Documents\PythonProjects\BassiScopeFoundryMicroscopes\ScopeFoundry\logged_quantity.py", line 163, in read_from_hardware
    val = self.hardware_read_func()
  File "C:\Users\Andrea Bassi\Documents\PythonProjects\BassiScopeFoundryMicroscopes\ScopeFoundryHW\joystick_hardware\joystick_device.py", line 65, in get_hat_values
    return hats[index][0]
IndexError: list index out of range

2019-12-06T18:31:04|CRITICAL|root|Unhandled exception:Traceback (most recent call last):
  File "C:\Users\Andrea Bassi\Documents\PythonProjects\BassiScopeFoundryMicroscopes\ScopeFoundry\hardware.py", line 182, in read_from_hardware
    lq.read_from_hardware()
  File "C:\Users\Andrea Bassi\Documents\PythonProjects\BassiScopeFoundryMicroscopes\ScopeFoundry\logged_quantity.py", line 163, in read_from_hardware
    val = self.hardware_read_func()
  File "C:\Users\Andrea Bassi\Documents\PythonProjects\BassiScopeFoundryMicroscopes\ScopeFoundryHW\joystick_hardware\joystick_device.py", line 65, in get_hat_values
    return hats[index][0]
IndexError: list index out of range

2019-12-06T18:31:05|CRITICAL|root|Unhandled exception:Traceback (most recent call last):
  File "C:\Users\Andrea Bassi\Documents\PythonProjects\BassiScopeFoundryMicroscopes\ScopeFoundry\hardware.py", line 182, in read_from_hardware
    lq.read_from_hardware()
  File "C:\Users\Andrea Bassi\Documents\PythonProjects\BassiScopeFoundryMicroscopes\ScopeFoundry\logged_quantity.py", line 163, in read_from_hardware
    val = self.hardware_read_func()
  File "C:\Users\Andrea Bassi\Documents\PythonProjects\BassiScopeFoundryMicroscopes\ScopeFoundryHW\joystick_hardware\joystick_device.py", line 65, in get_hat_values
    return hats[index][0]
IndexError: list index out of range

2019-12-06T18:31:06|CRITICAL|root|Unhandled exception:Traceback (most recent call last):
  File "C:\Users\Andrea Bassi\Documents\PythonProjects\BassiScopeFoundryMicroscopes\ScopeFoundry\hardware.py", line 182, in read_from_hardware
    lq.read_from_hardware()
  File "C:\Users\Andrea Bassi\Documents\PythonProjects\BassiScopeFoundryMicroscopes\ScopeFoundry\logged_quantity.py", line 163, in read_from_hardware
    val = self.hardware_read_func()
  File "C:\Users\Andrea Bassi\Documents\PythonProjects\BassiScopeFoundryMicroscopes\ScopeFoundryHW\joystick_hardware\joystick_device.py", line 65, in get_hat_values
    return hats[index][0]
IndexError: list index out of range

2019-12-06T18:31:08|CRITICAL|root|Unhandled exception:Traceback (most recent call last):
  File "C:\Users\Andrea Bassi\Documents\PythonProjects\BassiScopeFoundryMicroscopes\ScopeFoundry\hardware.py", line 182, in read_from_hardware
    lq.read_from_hardware()
  File "C:\Users\Andrea Bassi\Documents\PythonProjects\BassiScopeFoundryMicroscopes\ScopeFoundry\logged_quantity.py", line 163, in read_from_hardware
    val = self.hardware_read_func()
  File "C:\Users\Andrea Bassi\Documents\PythonProjects\BassiScopeFoundryMicroscopes\ScopeFoundryHW\joystick_hardware\joystick_device.py", line 65, in get_hat_values
    return hats[index][0]
IndexError: list index out of range

2019-12-06T18:31:10|CRITICAL|root|Unhandled exception:Traceback (most recent call last):
  File "C:\Users\Andrea Bassi\Documents\PythonProjects\BassiScopeFoundryMicroscopes\ScopeFoundry\hardware.py", line 182, in read_from_hardware
    lq.read_from_hardware()
  File "C:\Users\Andrea Bassi\Documents\PythonProjects\BassiScopeFoundryMicroscopes\ScopeFoundry\logged_quantity.py", line 163, in read_from_hardware
    val = self.hardware_read_func()
  File "C:\Users\Andrea Bassi\Documents\PythonProjects\BassiScopeFoundryMicroscopes\ScopeFoundryHW\joystick_hardware\joystick_device.py", line 65, in get_hat_values
    return hats[index][0]
IndexError: list index out of range

2019-12-06T18:31:11|CRITICAL|root|Unhandled exception:Traceback (most recent call last):
  File "C:\Users\Andrea Bassi\Documents\PythonProjects\BassiScopeFoundryMicroscopes\ScopeFoundry\hardware.py", line 182, in read_from_hardware
    lq.read_from_hardware()
  File "C:\Users\Andrea Bassi\Documents\PythonProjects\BassiScopeFoundryMicroscopes\ScopeFoundry\logged_quantity.py", line 163, in read_from_hardware
    val = self.hardware_read_func()
  File "C:\Users\Andrea Bassi\Documents\PythonProjects\BassiScopeFoundryMicroscopes\ScopeFoundryHW\joystick_hardware\joystick_device.py", line 65, in get_hat_values
    return hats[index][0]
IndexError: list index out of range

2019-12-06T18:31:12|CRITICAL|root|Unhandled exception:Traceback (most recent call last):
  File "C:\Users\Andrea Bassi\Documents\PythonProjects\BassiScopeFoundryMicroscopes\ScopeFoundry\hardware.py", line 182, in read_from_hardware
    lq.read_from_hardware()
  File "C:\Users\Andrea Bassi\Documents\PythonProjects\BassiScopeFoundryMicroscopes\ScopeFoundry\logged_quantity.py", line 163, in read_from_hardware
    val = self.hardware_read_func()
  File "C:\Users\Andrea Bassi\Documents\PythonProjects\BassiScopeFoundryMicroscopes\ScopeFoundryHW\joystick_hardware\joystick_device.py", line 65, in get_hat_values
    return hats[index][0]
IndexError: list index out of range

2019-12-06T18:31:13|CRITICAL|root|Unhandled exception:Traceback (most recent call last):
  File "C:\Users\Andrea Bassi\Documents\PythonProjects\BassiScopeFoundryMicroscopes\ScopeFoundry\hardware.py", line 182, in read_from_hardware
    lq.read_from_hardware()
  File "C:\Users\Andrea Bassi\Documents\PythonProjects\BassiScopeFoundryMicroscopes\ScopeFoundry\logged_quantity.py", line 163, in read_from_hardware
    val = self.hardware_read_func()
  File "C:\Users\Andrea Bassi\Documents\PythonProjects\BassiScopeFoundryMicroscopes\ScopeFoundryHW\joystick_hardware\joystick_device.py", line 65, in get_hat_values
    return hats[index][0]
IndexError: list index out of range

2019-12-06T18:31:14|CRITICAL|root|Unhandled exception:Traceback (most recent call last):
  File "C:\Users\Andrea Bassi\Documents\PythonProjects\BassiScopeFoundryMicroscopes\ScopeFoundry\hardware.py", line 182, in read_from_hardware
    lq.read_from_hardware()
  File "C:\Users\Andrea Bassi\Documents\PythonProjects\BassiScopeFoundryMicroscopes\ScopeFoundry\logged_quantity.py", line 163, in read_from_hardware
    val = self.hardware_read_func()
  File "C:\Users\Andrea Bassi\Documents\PythonProjects\BassiScopeFoundryMicroscopes\ScopeFoundryHW\joystick_hardware\joystick_device.py", line 65, in get_hat_values
    return hats[index][0]
IndexError: list index out of range

2019-12-06T18:31:18|CRITICAL|root|Unhandled exception:Traceback (most recent call last):
  File "C:\Users\Andrea Bassi\Documents\PythonProjects\BassiScopeFoundryMicroscopes\ScopeFoundry\hardware.py", line 182, in read_from_hardware
    lq.read_from_hardware()
  File "C:\Users\Andrea Bassi\Documents\PythonProjects\BassiScopeFoundryMicroscopes\ScopeFoundry\logged_quantity.py", line 163, in read_from_hardware
    val = self.hardware_read_func()
  File "C:\Users\Andrea Bassi\Documents\PythonProjects\BassiScopeFoundryMicroscopes\ScopeFoundryHW\joystick_hardware\joystick_device.py", line 65, in get_hat_values
    return hats[index][0]
IndexError: list index out of range

2019-12-06T18:31:19|CRITICAL|root|Unhandled exception:Traceback (most recent call last):
  File "C:\Users\Andrea Bassi\Documents\PythonProjects\BassiScopeFoundryMicroscopes\ScopeFoundry\hardware.py", line 182, in read_from_hardware
    lq.read_from_hardware()
  File "C:\Users\Andrea Bassi\Documents\PythonProjects\BassiScopeFoundryMicroscopes\ScopeFoundry\logged_quantity.py", line 163, in read_from_hardware
    val = self.hardware_read_func()
  File "C:\Users\Andrea Bassi\Documents\PythonProjects\BassiScopeFoundryMicroscopes\ScopeFoundryHW\joystick_hardware\joystick_device.py", line 65, in get_hat_values
    return hats[index][0]
IndexError: list index out of range

2019-12-06T18:31:19|CRITICAL|root|Unhandled exception:Traceback (most recent call last):
  File "C:\Users\Andrea Bassi\Documents\PythonProjects\BassiScopeFoundryMicroscopes\ScopeFoundry\hardware.py", line 182, in read_from_hardware
    lq.read_from_hardware()
  File "C:\Users\Andrea Bassi\Documents\PythonProjects\BassiScopeFoundryMicroscopes\ScopeFoundry\logged_quantity.py", line 163, in read_from_hardware
    val = self.hardware_read_func()
  File "C:\Users\Andrea Bassi\Documents\PythonProjects\BassiScopeFoundryMicroscopes\ScopeFoundryHW\joystick_hardware\joystick_device.py", line 65, in get_hat_values
    return hats[index][0]
IndexError: list index out of range

2019-12-06T18:31:20|CRITICAL|root|Unhandled exception:Traceback (most recent call last):
  File "C:\Users\Andrea Bassi\Documents\PythonProjects\BassiScopeFoundryMicroscopes\ScopeFoundry\hardware.py", line 182, in read_from_hardware
    lq.read_from_hardware()
  File "C:\Users\Andrea Bassi\Documents\PythonProjects\BassiScopeFoundryMicroscopes\ScopeFoundry\logged_quantity.py", line 163, in read_from_hardware
    val = self.hardware_read_func()
  File "C:\Users\Andrea Bassi\Documents\PythonProjects\BassiScopeFoundryMicroscopes\ScopeFoundryHW\joystick_hardware\joystick_device.py", line 65, in get_hat_values
    return hats[index][0]
IndexError: list index out of range

2019-12-06T18:31:20|CRITICAL|root|Unhandled exception:Traceback (most recent call last):
  File "C:\Users\Andrea Bassi\Documents\PythonProjects\BassiScopeFoundryMicroscopes\ScopeFoundry\hardware.py", line 182, in read_from_hardware
    lq.read_from_hardware()
  File "C:\Users\Andrea Bassi\Documents\PythonProjects\BassiScopeFoundryMicroscopes\ScopeFoundry\logged_quantity.py", line 163, in read_from_hardware
    val = self.hardware_read_func()
  File "C:\Users\Andrea Bassi\Documents\PythonProjects\BassiScopeFoundryMicroscopes\ScopeFoundryHW\joystick_hardware\joystick_device.py", line 65, in get_hat_values
    return hats[index][0]
IndexError: list index out of range

2019-12-06T18:31:21|CRITICAL|root|Unhandled exception:Traceback (most recent call last):
  File "C:\Users\Andrea Bassi\Documents\PythonProjects\BassiScopeFoundryMicroscopes\ScopeFoundry\hardware.py", line 182, in read_from_hardware
    lq.read_from_hardware()
  File "C:\Users\Andrea Bassi\Documents\PythonProjects\BassiScopeFoundryMicroscopes\ScopeFoundry\logged_quantity.py", line 163, in read_from_hardware
    val = self.hardware_read_func()
  File "C:\Users\Andrea Bassi\Documents\PythonProjects\BassiScopeFoundryMicroscopes\ScopeFoundryHW\joystick_hardware\joystick_device.py", line 65, in get_hat_values
    return hats[index][0]
IndexError: list index out of range

2019-12-06T18:31:26|CRITICAL|root|Unhandled exception:Traceback (most recent call last):
  File "C:\Users\Andrea Bassi\Documents\PythonProjects\BassiScopeFoundryMicroscopes\ScopeFoundry\hardware.py", line 182, in read_from_hardware
    lq.read_from_hardware()
  File "C:\Users\Andrea Bassi\Documents\PythonProjects\BassiScopeFoundryMicroscopes\ScopeFoundry\logged_quantity.py", line 163, in read_from_hardware
    val = self.hardware_read_func()
  File "C:\Users\Andrea Bassi\Documents\PythonProjects\BassiScopeFoundryMicroscopes\ScopeFoundryHW\joystick_hardware\joystick_device.py", line 65, in get_hat_values
    return hats[index][0]
IndexError: list index out of range

2019-12-06T18:31:26|CRITICAL|root|Unhandled exception:Traceback (most recent call last):
  File "C:\Users\Andrea Bassi\Documents\PythonProjects\BassiScopeFoundryMicroscopes\ScopeFoundry\hardware.py", line 182, in read_from_hardware
    lq.read_from_hardware()
  File "C:\Users\Andrea Bassi\Documents\PythonProjects\BassiScopeFoundryMicroscopes\ScopeFoundry\logged_quantity.py", line 163, in read_from_hardware
    val = self.hardware_read_func()
  File "C:\Users\Andrea Bassi\Documents\PythonProjects\BassiScopeFoundryMicroscopes\ScopeFoundryHW\joystick_hardware\joystick_device.py", line 65, in get_hat_values
    return hats[index][0]
IndexError: list index out of range

2019-12-06T18:31:27|CRITICAL|root|Unhandled exception:Traceback (most recent call last):
  File "C:\Users\Andrea Bassi\Documents\PythonProjects\BassiScopeFoundryMicroscopes\ScopeFoundry\hardware.py", line 182, in read_from_hardware
    lq.read_from_hardware()
  File "C:\Users\Andrea Bassi\Documents\PythonProjects\BassiScopeFoundryMicroscopes\ScopeFoundry\logged_quantity.py", line 163, in read_from_hardware
    val = self.hardware_read_func()
  File "C:\Users\Andrea Bassi\Documents\PythonProjects\BassiScopeFoundryMicroscopes\ScopeFoundryHW\joystick_hardware\joystick_device.py", line 65, in get_hat_values
    return hats[index][0]
IndexError: list index out of range

2019-12-06T18:31:28|CRITICAL|root|Unhandled exception:Traceback (most recent call last):
  File "C:\Users\Andrea Bassi\Documents\PythonProjects\BassiScopeFoundryMicroscopes\ScopeFoundry\hardware.py", line 182, in read_from_hardware
    lq.read_from_hardware()
  File "C:\Users\Andrea Bassi\Documents\PythonProjects\BassiScopeFoundryMicroscopes\ScopeFoundry\logged_quantity.py", line 163, in read_from_hardware
    val = self.hardware_read_func()
  File "C:\Users\Andrea Bassi\Documents\PythonProjects\BassiScopeFoundryMicroscopes\ScopeFoundryHW\joystick_hardware\joystick_device.py", line 65, in get_hat_values
    return hats[index][0]
IndexError: list index out of range

2019-12-06T18:31:28|CRITICAL|root|Unhandled exception:Traceback (most recent call last):
  File "C:\Users\Andrea Bassi\Documents\PythonProjects\BassiScopeFoundryMicroscopes\ScopeFoundry\hardware.py", line 182, in read_from_hardware
    lq.read_from_hardware()
  File "C:\Users\Andrea Bassi\Documents\PythonProjects\BassiScopeFoundryMicroscopes\ScopeFoundry\logged_quantity.py", line 163, in read_from_hardware
    val = self.hardware_read_func()
  File "C:\Users\Andrea Bassi\Documents\PythonProjects\BassiScopeFoundryMicroscopes\ScopeFoundryHW\joystick_hardware\joystick_device.py", line 65, in get_hat_values
    return hats[index][0]
IndexError: list index out of range

2019-12-06T18:31:29|CRITICAL|root|Unhandled exception:Traceback (most recent call last):
  File "C:\Users\Andrea Bassi\Documents\PythonProjects\BassiScopeFoundryMicroscopes\ScopeFoundry\hardware.py", line 182, in read_from_hardware
    lq.read_from_hardware()
  File "C:\Users\Andrea Bassi\Documents\PythonProjects\BassiScopeFoundryMicroscopes\ScopeFoundry\logged_quantity.py", line 163, in read_from_hardware
    val = self.hardware_read_func()
  File "C:\Users\Andrea Bassi\Documents\PythonProjects\BassiScopeFoundryMicroscopes\ScopeFoundryHW\joystick_hardware\joystick_device.py", line 65, in get_hat_values
    return hats[index][0]
IndexError: list index out of range

2019-12-06T18:31:33|CRITICAL|root|Unhandled exception:Traceback (most recent call last):
  File "C:\Users\Andrea Bassi\Documents\PythonProjects\BassiScopeFoundryMicroscopes\ScopeFoundry\hardware.py", line 182, in read_from_hardware
    lq.read_from_hardware()
  File "C:\Users\Andrea Bassi\Documents\PythonProjects\BassiScopeFoundryMicroscopes\ScopeFoundry\logged_quantity.py", line 163, in read_from_hardware
    val = self.hardware_read_func()
  File "C:\Users\Andrea Bassi\Documents\PythonProjects\BassiScopeFoundryMicroscopes\ScopeFoundryHW\joystick_hardware\joystick_device.py", line 65, in get_hat_values
    return hats[index][0]
IndexError: list index out of range

2019-12-06T18:31:34|CRITICAL|root|Unhandled exception:Traceback (most recent call last):
  File "C:\Users\Andrea Bassi\Documents\PythonProjects\BassiScopeFoundryMicroscopes\ScopeFoundry\hardware.py", line 182, in read_from_hardware
    lq.read_from_hardware()
  File "C:\Users\Andrea Bassi\Documents\PythonProjects\BassiScopeFoundryMicroscopes\ScopeFoundry\logged_quantity.py", line 163, in read_from_hardware
    val = self.hardware_read_func()
  File "C:\Users\Andrea Bassi\Documents\PythonProjects\BassiScopeFoundryMicroscopes\ScopeFoundryHW\joystick_hardware\joystick_device.py", line 65, in get_hat_values
    return hats[index][0]
IndexError: list index out of range

2019-12-06T18:31:35|CRITICAL|root|Unhandled exception:Traceback (most recent call last):
  File "C:\Users\Andrea Bassi\Documents\PythonProjects\BassiScopeFoundryMicroscopes\ScopeFoundry\hardware.py", line 182, in read_from_hardware
    lq.read_from_hardware()
  File "C:\Users\Andrea Bassi\Documents\PythonProjects\BassiScopeFoundryMicroscopes\ScopeFoundry\logged_quantity.py", line 163, in read_from_hardware
    val = self.hardware_read_func()
  File "C:\Users\Andrea Bassi\Documents\PythonProjects\BassiScopeFoundryMicroscopes\ScopeFoundryHW\joystick_hardware\joystick_device.py", line 65, in get_hat_values
    return hats[index][0]
IndexError: list index out of range

2019-12-06T18:31:38|CRITICAL|root|Unhandled exception:Traceback (most recent call last):
  File "C:\Users\Andrea Bassi\Documents\PythonProjects\BassiScopeFoundryMicroscopes\ScopeFoundry\hardware.py", line 182, in read_from_hardware
    lq.read_from_hardware()
  File "C:\Users\Andrea Bassi\Documents\PythonProjects\BassiScopeFoundryMicroscopes\ScopeFoundry\logged_quantity.py", line 163, in read_from_hardware
    val = self.hardware_read_func()
  File "C:\Users\Andrea Bassi\Documents\PythonProjects\BassiScopeFoundryMicroscopes\ScopeFoundryHW\joystick_hardware\joystick_device.py", line 65, in get_hat_values
    return hats[index][0]
IndexError: list index out of range

2019-12-06T18:31:39|CRITICAL|root|Unhandled exception:Traceback (most recent call last):
  File "C:\Users\Andrea Bassi\Documents\PythonProjects\BassiScopeFoundryMicroscopes\ScopeFoundry\hardware.py", line 182, in read_from_hardware
    lq.read_from_hardware()
  File "C:\Users\Andrea Bassi\Documents\PythonProjects\BassiScopeFoundryMicroscopes\ScopeFoundry\logged_quantity.py", line 163, in read_from_hardware
    val = self.hardware_read_func()
  File "C:\Users\Andrea Bassi\Documents\PythonProjects\BassiScopeFoundryMicroscopes\ScopeFoundryHW\joystick_hardware\joystick_device.py", line 65, in get_hat_values
    return hats[index][0]
IndexError: list index out of range

2019-12-06T18:31:40|CRITICAL|root|Unhandled exception:Traceback (most recent call last):
  File "C:\Users\Andrea Bassi\Documents\PythonProjects\BassiScopeFoundryMicroscopes\ScopeFoundry\hardware.py", line 182, in read_from_hardware
    lq.read_from_hardware()
  File "C:\Users\Andrea Bassi\Documents\PythonProjects\BassiScopeFoundryMicroscopes\ScopeFoundry\logged_quantity.py", line 163, in read_from_hardware
    val = self.hardware_read_func()
  File "C:\Users\Andrea Bassi\Documents\PythonProjects\BassiScopeFoundryMicroscopes\ScopeFoundryHW\joystick_hardware\joystick_device.py", line 65, in get_hat_values
    return hats[index][0]
IndexError: list index out of range

2019-12-06T18:31:40|CRITICAL|root|Unhandled exception:Traceback (most recent call last):
  File "C:\Users\Andrea Bassi\Documents\PythonProjects\BassiScopeFoundryMicroscopes\ScopeFoundry\hardware.py", line 182, in read_from_hardware
    lq.read_from_hardware()
  File "C:\Users\Andrea Bassi\Documents\PythonProjects\BassiScopeFoundryMicroscopes\ScopeFoundry\logged_quantity.py", line 163, in read_from_hardware
    val = self.hardware_read_func()
  File "C:\Users\Andrea Bassi\Documents\PythonProjects\BassiScopeFoundryMicroscopes\ScopeFoundryHW\joystick_hardware\joystick_device.py", line 65, in get_hat_values
    return hats[index][0]
IndexError: list index out of range

2019-12-06T18:31:41|CRITICAL|root|Unhandled exception:Traceback (most recent call last):
  File "C:\Users\Andrea Bassi\Documents\PythonProjects\BassiScopeFoundryMicroscopes\ScopeFoundry\hardware.py", line 182, in read_from_hardware
    lq.read_from_hardware()
  File "C:\Users\Andrea Bassi\Documents\PythonProjects\BassiScopeFoundryMicroscopes\ScopeFoundry\logged_quantity.py", line 163, in read_from_hardware
    val = self.hardware_read_func()
  File "C:\Users\Andrea Bassi\Documents\PythonProjects\BassiScopeFoundryMicroscopes\ScopeFoundryHW\joystick_hardware\joystick_device.py", line 65, in get_hat_values
    return hats[index][0]
IndexError: list index out of range

2019-12-06T18:31:42|CRITICAL|root|Unhandled exception:Traceback (most recent call last):
  File "C:\Users\Andrea Bassi\Documents\PythonProjects\BassiScopeFoundryMicroscopes\ScopeFoundry\hardware.py", line 182, in read_from_hardware
    lq.read_from_hardware()
  File "C:\Users\Andrea Bassi\Documents\PythonProjects\BassiScopeFoundryMicroscopes\ScopeFoundry\logged_quantity.py", line 163, in read_from_hardware
    val = self.hardware_read_func()
  File "C:\Users\Andrea Bassi\Documents\PythonProjects\BassiScopeFoundryMicroscopes\ScopeFoundryHW\joystick_hardware\joystick_device.py", line 65, in get_hat_values
    return hats[index][0]
IndexError: list index out of range

2019-12-06T18:31:42|CRITICAL|root|Unhandled exception:Traceback (most recent call last):
  File "C:\Users\Andrea Bassi\Documents\PythonProjects\BassiScopeFoundryMicroscopes\ScopeFoundry\hardware.py", line 182, in read_from_hardware
    lq.read_from_hardware()
  File "C:\Users\Andrea Bassi\Documents\PythonProjects\BassiScopeFoundryMicroscopes\ScopeFoundry\logged_quantity.py", line 163, in read_from_hardware
    val = self.hardware_read_func()
  File "C:\Users\Andrea Bassi\Documents\PythonProjects\BassiScopeFoundryMicroscopes\ScopeFoundryHW\joystick_hardware\joystick_device.py", line 65, in get_hat_values
    return hats[index][0]
IndexError: list index out of range

2019-12-06T18:31:42|CRITICAL|root|Unhandled exception:Traceback (most recent call last):
  File "C:\Users\Andrea Bassi\Documents\PythonProjects\BassiScopeFoundryMicroscopes\ScopeFoundry\hardware.py", line 182, in read_from_hardware
    lq.read_from_hardware()
  File "C:\Users\Andrea Bassi\Documents\PythonProjects\BassiScopeFoundryMicroscopes\ScopeFoundry\logged_quantity.py", line 163, in read_from_hardware
    val = self.hardware_read_func()
  File "C:\Users\Andrea Bassi\Documents\PythonProjects\BassiScopeFoundryMicroscopes\ScopeFoundryHW\joystick_hardware\joystick_device.py", line 65, in get_hat_values
    return hats[index][0]
IndexError: list index out of range

2019-12-06T18:31:43|CRITICAL|root|Unhandled exception:Traceback (most recent call last):
  File "C:\Users\Andrea Bassi\Documents\PythonProjects\BassiScopeFoundryMicroscopes\ScopeFoundry\hardware.py", line 182, in read_from_hardware
    lq.read_from_hardware()
  File "C:\Users\Andrea Bassi\Documents\PythonProjects\BassiScopeFoundryMicroscopes\ScopeFoundry\logged_quantity.py", line 163, in read_from_hardware
    val = self.hardware_read_func()
  File "C:\Users\Andrea Bassi\Documents\PythonProjects\BassiScopeFoundryMicroscopes\ScopeFoundryHW\joystick_hardware\joystick_device.py", line 65, in get_hat_values
    return hats[index][0]
IndexError: list index out of range

2019-12-06T18:31:43|CRITICAL|root|Unhandled exception:Traceback (most recent call last):
  File "C:\Users\Andrea Bassi\Documents\PythonProjects\BassiScopeFoundryMicroscopes\ScopeFoundry\hardware.py", line 182, in read_from_hardware
    lq.read_from_hardware()
  File "C:\Users\Andrea Bassi\Documents\PythonProjects\BassiScopeFoundryMicroscopes\ScopeFoundry\logged_quantity.py", line 163, in read_from_hardware
    val = self.hardware_read_func()
  File "C:\Users\Andrea Bassi\Documents\PythonProjects\BassiScopeFoundryMicroscopes\ScopeFoundryHW\joystick_hardware\joystick_device.py", line 65, in get_hat_values
    return hats[index][0]
IndexError: list index out of range

2019-12-06T18:31:43|CRITICAL|root|Unhandled exception:Traceback (most recent call last):
  File "C:\Users\Andrea Bassi\Documents\PythonProjects\BassiScopeFoundryMicroscopes\ScopeFoundry\hardware.py", line 182, in read_from_hardware
    lq.read_from_hardware()
  File "C:\Users\Andrea Bassi\Documents\PythonProjects\BassiScopeFoundryMicroscopes\ScopeFoundry\logged_quantity.py", line 163, in read_from_hardware
    val = self.hardware_read_func()
  File "C:\Users\Andrea Bassi\Documents\PythonProjects\BassiScopeFoundryMicroscopes\ScopeFoundryHW\joystick_hardware\joystick_device.py", line 65, in get_hat_values
    return hats[index][0]
IndexError: list index out of range

2019-12-06T18:31:44|CRITICAL|root|Unhandled exception:Traceback (most recent call last):
  File "C:\Users\Andrea Bassi\Documents\PythonProjects\BassiScopeFoundryMicroscopes\ScopeFoundry\hardware.py", line 182, in read_from_hardware
    lq.read_from_hardware()
  File "C:\Users\Andrea Bassi\Documents\PythonProjects\BassiScopeFoundryMicroscopes\ScopeFoundry\logged_quantity.py", line 163, in read_from_hardware
    val = self.hardware_read_func()
  File "C:\Users\Andrea Bassi\Documents\PythonProjects\BassiScopeFoundryMicroscopes\ScopeFoundryHW\joystick_hardware\joystick_device.py", line 65, in get_hat_values
    return hats[index][0]
IndexError: list index out of range

2019-12-06T18:31:44|CRITICAL|root|Unhandled exception:Traceback (most recent call last):
  File "C:\Users\Andrea Bassi\Documents\PythonProjects\BassiScopeFoundryMicroscopes\ScopeFoundry\hardware.py", line 182, in read_from_hardware
    lq.read_from_hardware()
  File "C:\Users\Andrea Bassi\Documents\PythonProjects\BassiScopeFoundryMicroscopes\ScopeFoundry\logged_quantity.py", line 163, in read_from_hardware
    val = self.hardware_read_func()
  File "C:\Users\Andrea Bassi\Documents\PythonProjects\BassiScopeFoundryMicroscopes\ScopeFoundryHW\joystick_hardware\joystick_device.py", line 65, in get_hat_values
    return hats[index][0]
IndexError: list index out of range

2019-12-06T18:36:38|CRITICAL|root|Unhandled exception:Traceback (most recent call last):
  File "C:\Users\Andrea Bassi\Documents\PythonProjects\BassiScopeFoundryMicroscopes\ScopeFoundry\hardware.py", line 182, in read_from_hardware
    lq.read_from_hardware()
  File "C:\Users\Andrea Bassi\Documents\PythonProjects\BassiScopeFoundryMicroscopes\ScopeFoundry\logged_quantity.py", line 163, in read_from_hardware
    val = self.hardware_read_func()
  File "C:\Users\Andrea Bassi\Documents\PythonProjects\BassiScopeFoundryMicroscopes\ScopeFoundryHW\joystick_hardware\joystick_device.py", line 65, in get_hat_values
    return hats[index][0]
IndexError: list index out of range

2019-12-06T18:36:39|CRITICAL|root|Unhandled exception:Traceback (most recent call last):
  File "C:\Users\Andrea Bassi\Documents\PythonProjects\BassiScopeFoundryMicroscopes\ScopeFoundry\hardware.py", line 182, in read_from_hardware
    lq.read_from_hardware()
  File "C:\Users\Andrea Bassi\Documents\PythonProjects\BassiScopeFoundryMicroscopes\ScopeFoundry\logged_quantity.py", line 163, in read_from_hardware
    val = self.hardware_read_func()
  File "C:\Users\Andrea Bassi\Documents\PythonProjects\BassiScopeFoundryMicroscopes\ScopeFoundryHW\joystick_hardware\joystick_device.py", line 65, in get_hat_values
    return hats[index][0]
IndexError: list index out of range

2019-12-06T18:36:40|CRITICAL|root|Unhandled exception:Traceback (most recent call last):
  File "C:\Users\Andrea Bassi\Documents\PythonProjects\BassiScopeFoundryMicroscopes\ScopeFoundry\hardware.py", line 182, in read_from_hardware
    lq.read_from_hardware()
  File "C:\Users\Andrea Bassi\Documents\PythonProjects\BassiScopeFoundryMicroscopes\ScopeFoundry\logged_quantity.py", line 163, in read_from_hardware
    val = self.hardware_read_func()
  File "C:\Users\Andrea Bassi\Documents\PythonProjects\BassiScopeFoundryMicroscopes\ScopeFoundryHW\joystick_hardware\joystick_device.py", line 65, in get_hat_values
    return hats[index][0]
IndexError: list index out of range

2019-12-06T18:36:41|CRITICAL|root|Unhandled exception:Traceback (most recent call last):
  File "C:\Users\Andrea Bassi\Documents\PythonProjects\BassiScopeFoundryMicroscopes\ScopeFoundry\hardware.py", line 182, in read_from_hardware
    lq.read_from_hardware()
  File "C:\Users\Andrea Bassi\Documents\PythonProjects\BassiScopeFoundryMicroscopes\ScopeFoundry\logged_quantity.py", line 163, in read_from_hardware
    val = self.hardware_read_func()
  File "C:\Users\Andrea Bassi\Documents\PythonProjects\BassiScopeFoundryMicroscopes\ScopeFoundryHW\joystick_hardware\joystick_device.py", line 65, in get_hat_values
    return hats[index][0]
IndexError: list index out of range

2019-12-06T18:36:45|CRITICAL|root|Unhandled exception:Traceback (most recent call last):
  File "C:\Users\Andrea Bassi\Documents\PythonProjects\BassiScopeFoundryMicroscopes\ScopeFoundry\hardware.py", line 182, in read_from_hardware
    lq.read_from_hardware()
  File "C:\Users\Andrea Bassi\Documents\PythonProjects\BassiScopeFoundryMicroscopes\ScopeFoundry\logged_quantity.py", line 163, in read_from_hardware
    val = self.hardware_read_func()
  File "C:\Users\Andrea Bassi\Documents\PythonProjects\BassiScopeFoundryMicroscopes\ScopeFoundryHW\joystick_hardware\joystick_device.py", line 65, in get_hat_values
    return hats[index][0]
IndexError: list index out of range

2019-12-06T18:36:46|CRITICAL|root|Unhandled exception:Traceback (most recent call last):
  File "C:\Users\Andrea Bassi\Documents\PythonProjects\BassiScopeFoundryMicroscopes\ScopeFoundry\hardware.py", line 182, in read_from_hardware
    lq.read_from_hardware()
  File "C:\Users\Andrea Bassi\Documents\PythonProjects\BassiScopeFoundryMicroscopes\ScopeFoundry\logged_quantity.py", line 163, in read_from_hardware
    val = self.hardware_read_func()
  File "C:\Users\Andrea Bassi\Documents\PythonProjects\BassiScopeFoundryMicroscopes\ScopeFoundryHW\joystick_hardware\joystick_device.py", line 65, in get_hat_values
    return hats[index][0]
IndexError: list index out of range

2019-12-06T18:36:48|CRITICAL|root|Unhandled exception:Traceback (most recent call last):
  File "C:\Users\Andrea Bassi\Documents\PythonProjects\BassiScopeFoundryMicroscopes\ScopeFoundry\hardware.py", line 182, in read_from_hardware
    lq.read_from_hardware()
  File "C:\Users\Andrea Bassi\Documents\PythonProjects\BassiScopeFoundryMicroscopes\ScopeFoundry\logged_quantity.py", line 163, in read_from_hardware
    val = self.hardware_read_func()
  File "C:\Users\Andrea Bassi\Documents\PythonProjects\BassiScopeFoundryMicroscopes\ScopeFoundryHW\joystick_hardware\joystick_device.py", line 65, in get_hat_values
    return hats[index][0]
IndexError: list index out of range

2019-12-06T18:36:49|CRITICAL|root|Unhandled exception:Traceback (most recent call last):
  File "C:\Users\Andrea Bassi\Documents\PythonProjects\BassiScopeFoundryMicroscopes\ScopeFoundry\hardware.py", line 182, in read_from_hardware
    lq.read_from_hardware()
  File "C:\Users\Andrea Bassi\Documents\PythonProjects\BassiScopeFoundryMicroscopes\ScopeFoundry\logged_quantity.py", line 163, in read_from_hardware
    val = self.hardware_read_func()
  File "C:\Users\Andrea Bassi\Documents\PythonProjects\BassiScopeFoundryMicroscopes\ScopeFoundryHW\joystick_hardware\joystick_device.py", line 65, in get_hat_values
    return hats[index][0]
IndexError: list index out of range

2019-12-06T18:36:50|CRITICAL|root|Unhandled exception:Traceback (most recent call last):
  File "C:\Users\Andrea Bassi\Documents\PythonProjects\BassiScopeFoundryMicroscopes\ScopeFoundry\hardware.py", line 182, in read_from_hardware
    lq.read_from_hardware()
  File "C:\Users\Andrea Bassi\Documents\PythonProjects\BassiScopeFoundryMicroscopes\ScopeFoundry\logged_quantity.py", line 163, in read_from_hardware
    val = self.hardware_read_func()
  File "C:\Users\Andrea Bassi\Documents\PythonProjects\BassiScopeFoundryMicroscopes\ScopeFoundryHW\joystick_hardware\joystick_device.py", line 65, in get_hat_values
    return hats[index][0]
IndexError: list index out of range

2019-12-06T18:36:51|CRITICAL|root|Unhandled exception:Traceback (most recent call last):
  File "C:\Users\Andrea Bassi\Documents\PythonProjects\BassiScopeFoundryMicroscopes\ScopeFoundry\hardware.py", line 182, in read_from_hardware
    lq.read_from_hardware()
  File "C:\Users\Andrea Bassi\Documents\PythonProjects\BassiScopeFoundryMicroscopes\ScopeFoundry\logged_quantity.py", line 163, in read_from_hardware
    val = self.hardware_read_func()
  File "C:\Users\Andrea Bassi\Documents\PythonProjects\BassiScopeFoundryMicroscopes\ScopeFoundryHW\joystick_hardware\joystick_device.py", line 65, in get_hat_values
    return hats[index][0]
IndexError: list index out of range

2019-12-06T18:36:52|CRITICAL|root|Unhandled exception:Traceback (most recent call last):
  File "C:\Users\Andrea Bassi\Documents\PythonProjects\BassiScopeFoundryMicroscopes\ScopeFoundry\hardware.py", line 182, in read_from_hardware
    lq.read_from_hardware()
  File "C:\Users\Andrea Bassi\Documents\PythonProjects\BassiScopeFoundryMicroscopes\ScopeFoundry\logged_quantity.py", line 163, in read_from_hardware
    val = self.hardware_read_func()
  File "C:\Users\Andrea Bassi\Documents\PythonProjects\BassiScopeFoundryMicroscopes\ScopeFoundryHW\joystick_hardware\joystick_device.py", line 65, in get_hat_values
    return hats[index][0]
IndexError: list index out of range

2019-12-06T18:36:53|CRITICAL|root|Unhandled exception:Traceback (most recent call last):
  File "C:\Users\Andrea Bassi\Documents\PythonProjects\BassiScopeFoundryMicroscopes\ScopeFoundry\hardware.py", line 182, in read_from_hardware
    lq.read_from_hardware()
  File "C:\Users\Andrea Bassi\Documents\PythonProjects\BassiScopeFoundryMicroscopes\ScopeFoundry\logged_quantity.py", line 163, in read_from_hardware
    val = self.hardware_read_func()
  File "C:\Users\Andrea Bassi\Documents\PythonProjects\BassiScopeFoundryMicroscopes\ScopeFoundryHW\joystick_hardware\joystick_device.py", line 65, in get_hat_values
    return hats[index][0]
IndexError: list index out of range

2019-12-06T18:36:59|CRITICAL|root|Unhandled exception:Traceback (most recent call last):
  File "C:\Users\Andrea Bassi\Documents\PythonProjects\BassiScopeFoundryMicroscopes\ScopeFoundry\hardware.py", line 182, in read_from_hardware
    lq.read_from_hardware()
  File "C:\Users\Andrea Bassi\Documents\PythonProjects\BassiScopeFoundryMicroscopes\ScopeFoundry\logged_quantity.py", line 163, in read_from_hardware
    val = self.hardware_read_func()
  File "C:\Users\Andrea Bassi\Documents\PythonProjects\BassiScopeFoundryMicroscopes\ScopeFoundryHW\joystick_hardware\joystick_device.py", line 65, in get_hat_values
    return hats[index][0]
IndexError: list index out of range

2019-12-06T18:37:00|CRITICAL|root|Unhandled exception:Traceback (most recent call last):
  File "C:\Users\Andrea Bassi\Documents\PythonProjects\BassiScopeFoundryMicroscopes\ScopeFoundry\hardware.py", line 182, in read_from_hardware
    lq.read_from_hardware()
  File "C:\Users\Andrea Bassi\Documents\PythonProjects\BassiScopeFoundryMicroscopes\ScopeFoundry\logged_quantity.py", line 163, in read_from_hardware
    val = self.hardware_read_func()
  File "C:\Users\Andrea Bassi\Documents\PythonProjects\BassiScopeFoundryMicroscopes\ScopeFoundryHW\joystick_hardware\joystick_device.py", line 65, in get_hat_values
    return hats[index][0]
IndexError: list index out of range

2019-12-06T18:37:01|CRITICAL|root|Unhandled exception:Traceback (most recent call last):
  File "C:\Users\Andrea Bassi\Documents\PythonProjects\BassiScopeFoundryMicroscopes\ScopeFoundry\hardware.py", line 182, in read_from_hardware
    lq.read_from_hardware()
  File "C:\Users\Andrea Bassi\Documents\PythonProjects\BassiScopeFoundryMicroscopes\ScopeFoundry\logged_quantity.py", line 163, in read_from_hardware
    val = self.hardware_read_func()
  File "C:\Users\Andrea Bassi\Documents\PythonProjects\BassiScopeFoundryMicroscopes\ScopeFoundryHW\joystick_hardware\joystick_device.py", line 65, in get_hat_values
    return hats[index][0]
IndexError: list index out of range

2019-12-06T18:37:02|CRITICAL|root|Unhandled exception:Traceback (most recent call last):
  File "C:\Users\Andrea Bassi\Documents\PythonProjects\BassiScopeFoundryMicroscopes\ScopeFoundry\hardware.py", line 182, in read_from_hardware
    lq.read_from_hardware()
  File "C:\Users\Andrea Bassi\Documents\PythonProjects\BassiScopeFoundryMicroscopes\ScopeFoundry\logged_quantity.py", line 163, in read_from_hardware
    val = self.hardware_read_func()
  File "C:\Users\Andrea Bassi\Documents\PythonProjects\BassiScopeFoundryMicroscopes\ScopeFoundryHW\joystick_hardware\joystick_device.py", line 65, in get_hat_values
    return hats[index][0]
IndexError: list index out of range

2019-12-06T18:37:03|CRITICAL|root|Unhandled exception:Traceback (most recent call last):
  File "C:\Users\Andrea Bassi\Documents\PythonProjects\BassiScopeFoundryMicroscopes\ScopeFoundry\hardware.py", line 182, in read_from_hardware
    lq.read_from_hardware()
  File "C:\Users\Andrea Bassi\Documents\PythonProjects\BassiScopeFoundryMicroscopes\ScopeFoundry\logged_quantity.py", line 163, in read_from_hardware
    val = self.hardware_read_func()
  File "C:\Users\Andrea Bassi\Documents\PythonProjects\BassiScopeFoundryMicroscopes\ScopeFoundryHW\joystick_hardware\joystick_device.py", line 65, in get_hat_values
    return hats[index][0]
IndexError: list index out of range

2019-12-06T18:37:49|ERROR|SineWaveJoyStickMeasure|sine_wave_joystick Failed to update figure1: 'JoyStick_HW' object has no attribute 'joystick_dev'. ['Traceback (most recent call last):\n', '  File "C:\\Users\\Andrea Bassi\\Documents\\PythonProjects\\BassiScopeFoundryMicroscopes\\ScopeFoundry\\measurement.py", line 279, in _on_display_update_timer\n    self.update_display()\n', '  File "C:\\Users\\Andrea Bassi\\Documents\\PythonProjects\\BassiScopeFoundryMicroscopes\\Microscopes\\VirtualMicroscopeJoyStick\\SineGenJoyStick_measure.py", line 82, in update_display\n    THIS READS THE JOYSTICK AXIS VALUE AND SET THE AMPLITUDE OF THE FUNCTION GENERATOR\n', "AttributeError: 'JoyStick_HW' object has no attribute 'joystick_dev'\n"]
2019-12-06T18:37:49|ERROR|SineWaveJoyStickMeasure|sine_wave_joystick Failed to update figure1: 'JoyStick_HW' object has no attribute 'joystick_dev'. ['Traceback (most recent call last):\n', '  File "C:\\Users\\Andrea Bassi\\Documents\\PythonProjects\\BassiScopeFoundryMicroscopes\\ScopeFoundry\\measurement.py", line 279, in _on_display_update_timer\n    self.update_display()\n', '  File "C:\\Users\\Andrea Bassi\\Documents\\PythonProjects\\BassiScopeFoundryMicroscopes\\Microscopes\\VirtualMicroscopeJoyStick\\SineGenJoyStick_measure.py", line 82, in update_display\n    THIS READS THE JOYSTICK AXIS VALUE AND SET THE AMPLITUDE OF THE FUNCTION GENERATOR\n', "AttributeError: 'JoyStick_HW' object has no attribute 'joystick_dev'\n"]
2019-12-06T18:37:50|ERROR|SineWaveJoyStickMeasure|sine_wave_joystick Failed to update figure1: 'JoyStick_HW' object has no attribute 'joystick_dev'. ['Traceback (most recent call last):\n', '  File "C:\\Users\\Andrea Bassi\\Documents\\PythonProjects\\BassiScopeFoundryMicroscopes\\ScopeFoundry\\measurement.py", line 279, in _on_display_update_timer\n    self.update_display()\n', '  File "C:\\Users\\Andrea Bassi\\Documents\\PythonProjects\\BassiScopeFoundryMicroscopes\\Microscopes\\VirtualMicroscopeJoyStick\\SineGenJoyStick_measure.py", line 82, in update_display\n    THIS READS THE JOYSTICK AXIS VALUE AND SET THE AMPLITUDE OF THE FUNCTION GENERATOR\n', "AttributeError: 'JoyStick_HW' object has no attribute 'joystick_dev'\n"]
2019-12-06T18:37:50|ERROR|SineWaveJoyStickMeasure|sine_wave_joystick Failed to update figure1: 'JoyStick_HW' object has no attribute 'joystick_dev'. ['Traceback (most recent call last):\n', '  File "C:\\Users\\Andrea Bassi\\Documents\\PythonProjects\\BassiScopeFoundryMicroscopes\\ScopeFoundry\\measurement.py", line 279, in _on_display_update_timer\n    self.update_display()\n', '  File "C:\\Users\\Andrea Bassi\\Documents\\PythonProjects\\BassiScopeFoundryMicroscopes\\Microscopes\\VirtualMicroscopeJoyStick\\SineGenJoyStick_measure.py", line 82, in update_display\n    THIS READS THE JOYSTICK AXIS VALUE AND SET THE AMPLITUDE OF THE FUNCTION GENERATOR\n', "AttributeError: 'JoyStick_HW' object has no attribute 'joystick_dev'\n"]
2019-12-06T18:37:50|ERROR|SineWaveJoyStickMeasure|sine_wave_joystick Failed to update figure1: 'JoyStick_HW' object has no attribute 'joystick_dev'. ['Traceback (most recent call last):\n', '  File "C:\\Users\\Andrea Bassi\\Documents\\PythonProjects\\BassiScopeFoundryMicroscopes\\ScopeFoundry\\measurement.py", line 279, in _on_display_update_timer\n    self.update_display()\n', '  File "C:\\Users\\Andrea Bassi\\Documents\\PythonProjects\\BassiScopeFoundryMicroscopes\\Microscopes\\VirtualMicroscopeJoyStick\\SineGenJoyStick_measure.py", line 82, in update_display\n    THIS READS THE JOYSTICK AXIS VALUE AND SET THE AMPLITUDE OF THE FUNCTION GENERATOR\n', "AttributeError: 'JoyStick_HW' object has no attribute 'joystick_dev'\n"]
2019-12-06T18:37:50|ERROR|SineWaveJoyStickMeasure|sine_wave_joystick Failed to update figure1: 'JoyStick_HW' object has no attribute 'joystick_dev'. ['Traceback (most recent call last):\n', '  File "C:\\Users\\Andrea Bassi\\Documents\\PythonProjects\\BassiScopeFoundryMicroscopes\\ScopeFoundry\\measurement.py", line 279, in _on_display_update_timer\n    self.update_display()\n', '  File "C:\\Users\\Andrea Bassi\\Documents\\PythonProjects\\BassiScopeFoundryMicroscopes\\Microscopes\\VirtualMicroscopeJoyStick\\SineGenJoyStick_measure.py", line 82, in update_display\n    THIS READS THE JOYSTICK AXIS VALUE AND SET THE AMPLITUDE OF THE FUNCTION GENERATOR\n', "AttributeError: 'JoyStick_HW' object has no attribute 'joystick_dev'\n"]
2019-12-06T18:37:51|ERROR|SineWaveJoyStickMeasure|sine_wave_joystick Failed to update figure1: 'JoyStick_HW' object has no attribute 'joystick_dev'. ['Traceback (most recent call last):\n', '  File "C:\\Users\\Andrea Bassi\\Documents\\PythonProjects\\BassiScopeFoundryMicroscopes\\ScopeFoundry\\measurement.py", line 279, in _on_display_update_timer\n    self.update_display()\n', '  File "C:\\Users\\Andrea Bassi\\Documents\\PythonProjects\\BassiScopeFoundryMicroscopes\\Microscopes\\VirtualMicroscopeJoyStick\\SineGenJoyStick_measure.py", line 82, in update_display\n    THIS READS THE JOYSTICK AXIS VALUE AND SET THE AMPLITUDE OF THE FUNCTION GENERATOR\n', "AttributeError: 'JoyStick_HW' object has no attribute 'joystick_dev'\n"]
2019-12-06T18:37:51|ERROR|SineWaveJoyStickMeasure|sine_wave_joystick Failed to update figure1: 'JoyStick_HW' object has no attribute 'joystick_dev'. ['Traceback (most recent call last):\n', '  File "C:\\Users\\Andrea Bassi\\Documents\\PythonProjects\\BassiScopeFoundryMicroscopes\\ScopeFoundry\\measurement.py", line 279, in _on_display_update_timer\n    self.update_display()\n', '  File "C:\\Users\\Andrea Bassi\\Documents\\PythonProjects\\BassiScopeFoundryMicroscopes\\Microscopes\\VirtualMicroscopeJoyStick\\SineGenJoyStick_measure.py", line 82, in update_display\n    THIS READS THE JOYSTICK AXIS VALUE AND SET THE AMPLITUDE OF THE FUNCTION GENERATOR\n', "AttributeError: 'JoyStick_HW' object has no attribute 'joystick_dev'\n"]
2019-12-06T18:37:51|ERROR|SineWaveJoyStickMeasure|sine_wave_joystick Failed to update figure1: 'JoyStick_HW' object has no attribute 'joystick_dev'. ['Traceback (most recent call last):\n', '  File "C:\\Users\\Andrea Bassi\\Documents\\PythonProjects\\BassiScopeFoundryMicroscopes\\ScopeFoundry\\measurement.py", line 279, in _on_display_update_timer\n    self.update_display()\n', '  File "C:\\Users\\Andrea Bassi\\Documents\\PythonProjects\\BassiScopeFoundryMicroscopes\\Microscopes\\VirtualMicroscopeJoyStick\\SineGenJoyStick_measure.py", line 82, in update_display\n    THIS READS THE JOYSTICK AXIS VALUE AND SET THE AMPLITUDE OF THE FUNCTION GENERATOR\n', "AttributeError: 'JoyStick_HW' object has no attribute 'joystick_dev'\n"]
2019-12-06T18:37:51|ERROR|SineWaveJoyStickMeasure|sine_wave_joystick Failed to update figure1: 'JoyStick_HW' object has no attribute 'joystick_dev'. ['Traceback (most recent call last):\n', '  File "C:\\Users\\Andrea Bassi\\Documents\\PythonProjects\\BassiScopeFoundryMicroscopes\\ScopeFoundry\\measurement.py", line 279, in _on_display_update_timer\n    self.update_display()\n', '  File "C:\\Users\\Andrea Bassi\\Documents\\PythonProjects\\BassiScopeFoundryMicroscopes\\Microscopes\\VirtualMicroscopeJoyStick\\SineGenJoyStick_measure.py", line 82, in update_display\n    THIS READS THE JOYSTICK AXIS VALUE AND SET THE AMPLITUDE OF THE FUNCTION GENERATOR\n', "AttributeError: 'JoyStick_HW' object has no attribute 'joystick_dev'\n"]
2019-12-06T18:37:51|ERROR|SineWaveJoyStickMeasure|sine_wave_joystick Failed to update figure1: 'JoyStick_HW' object has no attribute 'joystick_dev'. ['Traceback (most recent call last):\n', '  File "C:\\Users\\Andrea Bassi\\Documents\\PythonProjects\\BassiScopeFoundryMicroscopes\\ScopeFoundry\\measurement.py", line 279, in _on_display_update_timer\n    self.update_display()\n', '  File "C:\\Users\\Andrea Bassi\\Documents\\PythonProjects\\BassiScopeFoundryMicroscopes\\Microscopes\\VirtualMicroscopeJoyStick\\SineGenJoyStick_measure.py", line 82, in update_display\n    THIS READS THE JOYSTICK AXIS VALUE AND SET THE AMPLITUDE OF THE FUNCTION GENERATOR\n', "AttributeError: 'JoyStick_HW' object has no attribute 'joystick_dev'\n"]
2019-12-06T18:37:52|ERROR|SineWaveJoyStickMeasure|sine_wave_joystick Failed to update figure1: 'JoyStick_HW' object has no attribute 'joystick_dev'. ['Traceback (most recent call last):\n', '  File "C:\\Users\\Andrea Bassi\\Documents\\PythonProjects\\BassiScopeFoundryMicroscopes\\ScopeFoundry\\measurement.py", line 279, in _on_display_update_timer\n    self.update_display()\n', '  File "C:\\Users\\Andrea Bassi\\Documents\\PythonProjects\\BassiScopeFoundryMicroscopes\\Microscopes\\VirtualMicroscopeJoyStick\\SineGenJoyStick_measure.py", line 82, in update_display\n    THIS READS THE JOYSTICK AXIS VALUE AND SET THE AMPLITUDE OF THE FUNCTION GENERATOR\n', "AttributeError: 'JoyStick_HW' object has no attribute 'joystick_dev'\n"]
2019-12-06T18:37:52|ERROR|SineWaveJoyStickMeasure|sine_wave_joystick Failed to update figure1: 'JoyStick_HW' object has no attribute 'joystick_dev'. ['Traceback (most recent call last):\n', '  File "C:\\Users\\Andrea Bassi\\Documents\\PythonProjects\\BassiScopeFoundryMicroscopes\\ScopeFoundry\\measurement.py", line 279, in _on_display_update_timer\n    self.update_display()\n', '  File "C:\\Users\\Andrea Bassi\\Documents\\PythonProjects\\BassiScopeFoundryMicroscopes\\Microscopes\\VirtualMicroscopeJoyStick\\SineGenJoyStick_measure.py", line 82, in update_display\n    THIS READS THE JOYSTICK AXIS VALUE AND SET THE AMPLITUDE OF THE FUNCTION GENERATOR\n', "AttributeError: 'JoyStick_HW' object has no attribute 'joystick_dev'\n"]
2019-12-06T18:37:52|ERROR|SineWaveJoyStickMeasure|sine_wave_joystick Failed to update figure1: 'JoyStick_HW' object has no attribute 'joystick_dev'. ['Traceback (most recent call last):\n', '  File "C:\\Users\\Andrea Bassi\\Documents\\PythonProjects\\BassiScopeFoundryMicroscopes\\ScopeFoundry\\measurement.py", line 279, in _on_display_update_timer\n    self.update_display()\n', '  File "C:\\Users\\Andrea Bassi\\Documents\\PythonProjects\\BassiScopeFoundryMicroscopes\\Microscopes\\VirtualMicroscopeJoyStick\\SineGenJoyStick_measure.py", line 82, in update_display\n    THIS READS THE JOYSTICK AXIS VALUE AND SET THE AMPLITUDE OF THE FUNCTION GENERATOR\n', "AttributeError: 'JoyStick_HW' object has no attribute 'joystick_dev'\n"]
2019-12-06T18:37:53|ERROR|SineWaveJoyStickMeasure|sine_wave_joystick Failed to update figure1: 'JoyStick_HW' object has no attribute 'joystick_dev'. ['Traceback (most recent call last):\n', '  File "C:\\Users\\Andrea Bassi\\Documents\\PythonProjects\\BassiScopeFoundryMicroscopes\\ScopeFoundry\\measurement.py", line 279, in _on_display_update_timer\n    self.update_display()\n', '  File "C:\\Users\\Andrea Bassi\\Documents\\PythonProjects\\BassiScopeFoundryMicroscopes\\Microscopes\\VirtualMicroscopeJoyStick\\SineGenJoyStick_measure.py", line 82, in update_display\n    THIS READS THE JOYSTICK AXIS VALUE AND SET THE AMPLITUDE OF THE FUNCTION GENERATOR\n', "AttributeError: 'JoyStick_HW' object has no attribute 'joystick_dev'\n"]
2019-12-06T18:37:53|ERROR|SineWaveJoyStickMeasure|sine_wave_joystick Failed to update figure1: 'JoyStick_HW' object has no attribute 'joystick_dev'. ['Traceback (most recent call last):\n', '  File "C:\\Users\\Andrea Bassi\\Documents\\PythonProjects\\BassiScopeFoundryMicroscopes\\ScopeFoundry\\measurement.py", line 279, in _on_display_update_timer\n    self.update_display()\n', '  File "C:\\Users\\Andrea Bassi\\Documents\\PythonProjects\\BassiScopeFoundryMicroscopes\\Microscopes\\VirtualMicroscopeJoyStick\\SineGenJoyStick_measure.py", line 82, in update_display\n    THIS READS THE JOYSTICK AXIS VALUE AND SET THE AMPLITUDE OF THE FUNCTION GENERATOR\n', "AttributeError: 'JoyStick_HW' object has no attribute 'joystick_dev'\n"]
2019-12-06T18:37:53|ERROR|SineWaveJoyStickMeasure|sine_wave_joystick Failed to update figure1: 'JoyStick_HW' object has no attribute 'joystick_dev'. ['Traceback (most recent call last):\n', '  File "C:\\Users\\Andrea Bassi\\Documents\\PythonProjects\\BassiScopeFoundryMicroscopes\\ScopeFoundry\\measurement.py", line 279, in _on_display_update_timer\n    self.update_display()\n', '  File "C:\\Users\\Andrea Bassi\\Documents\\PythonProjects\\BassiScopeFoundryMicroscopes\\Microscopes\\VirtualMicroscopeJoyStick\\SineGenJoyStick_measure.py", line 82, in update_display\n    THIS READS THE JOYSTICK AXIS VALUE AND SET THE AMPLITUDE OF THE FUNCTION GENERATOR\n', "AttributeError: 'JoyStick_HW' object has no attribute 'joystick_dev'\n"]
2019-12-06T18:37:54|ERROR|SineWaveJoyStickMeasure|sine_wave_joystick Failed to update figure1: 'JoyStick_HW' object has no attribute 'joystick_dev'. ['Traceback (most recent call last):\n', '  File "C:\\Users\\Andrea Bassi\\Documents\\PythonProjects\\BassiScopeFoundryMicroscopes\\ScopeFoundry\\measurement.py", line 279, in _on_display_update_timer\n    self.update_display()\n', '  File "C:\\Users\\Andrea Bassi\\Documents\\PythonProjects\\BassiScopeFoundryMicroscopes\\Microscopes\\VirtualMicroscopeJoyStick\\SineGenJoyStick_measure.py", line 82, in update_display\n    THIS READS THE JOYSTICK AXIS VALUE AND SET THE AMPLITUDE OF THE FUNCTION GENERATOR\n', "AttributeError: 'JoyStick_HW' object has no attribute 'joystick_dev'\n"]
2019-12-06T18:37:54|ERROR|SineWaveJoyStickMeasure|sine_wave_joystick Failed to update figure1: 'JoyStick_HW' object has no attribute 'joystick_dev'. ['Traceback (most recent call last):\n', '  File "C:\\Users\\Andrea Bassi\\Documents\\PythonProjects\\BassiScopeFoundryMicroscopes\\ScopeFoundry\\measurement.py", line 279, in _on_display_update_timer\n    self.update_display()\n', '  File "C:\\Users\\Andrea Bassi\\Documents\\PythonProjects\\BassiScopeFoundryMicroscopes\\Microscopes\\VirtualMicroscopeJoyStick\\SineGenJoyStick_measure.py", line 82, in update_display\n    THIS READS THE JOYSTICK AXIS VALUE AND SET THE AMPLITUDE OF THE FUNCTION GENERATOR\n', "AttributeError: 'JoyStick_HW' object has no attribute 'joystick_dev'\n"]
2019-12-06T18:37:54|ERROR|SineWaveJoyStickMeasure|sine_wave_joystick Failed to update figure1: 'JoyStick_HW' object has no attribute 'joystick_dev'. ['Traceback (most recent call last):\n', '  File "C:\\Users\\Andrea Bassi\\Documents\\PythonProjects\\BassiScopeFoundryMicroscopes\\ScopeFoundry\\measurement.py", line 279, in _on_display_update_timer\n    self.update_display()\n', '  File "C:\\Users\\Andrea Bassi\\Documents\\PythonProjects\\BassiScopeFoundryMicroscopes\\Microscopes\\VirtualMicroscopeJoyStick\\SineGenJoyStick_measure.py", line 82, in update_display\n    THIS READS THE JOYSTICK AXIS VALUE AND SET THE AMPLITUDE OF THE FUNCTION GENERATOR\n', "AttributeError: 'JoyStick_HW' object has no attribute 'joystick_dev'\n"]
2019-12-06T18:37:54|ERROR|SineWaveJoyStickMeasure|sine_wave_joystick Failed to update figure1: 'JoyStick_HW' object has no attribute 'joystick_dev'. ['Traceback (most recent call last):\n', '  File "C:\\Users\\Andrea Bassi\\Documents\\PythonProjects\\BassiScopeFoundryMicroscopes\\ScopeFoundry\\measurement.py", line 279, in _on_display_update_timer\n    self.update_display()\n', '  File "C:\\Users\\Andrea Bassi\\Documents\\PythonProjects\\BassiScopeFoundryMicroscopes\\Microscopes\\VirtualMicroscopeJoyStick\\SineGenJoyStick_measure.py", line 82, in update_display\n    THIS READS THE JOYSTICK AXIS VALUE AND SET THE AMPLITUDE OF THE FUNCTION GENERATOR\n', "AttributeError: 'JoyStick_HW' object has no attribute 'joystick_dev'\n"]
2019-12-06T18:37:55|ERROR|SineWaveJoyStickMeasure|sine_wave_joystick Failed to update figure1: 'JoyStick_HW' object has no attribute 'joystick_dev'. ['Traceback (most recent call last):\n', '  File "C:\\Users\\Andrea Bassi\\Documents\\PythonProjects\\BassiScopeFoundryMicroscopes\\ScopeFoundry\\measurement.py", line 279, in _on_display_update_timer\n    self.update_display()\n', '  File "C:\\Users\\Andrea Bassi\\Documents\\PythonProjects\\BassiScopeFoundryMicroscopes\\Microscopes\\VirtualMicroscopeJoyStick\\SineGenJoyStick_measure.py", line 82, in update_display\n    THIS READS THE JOYSTICK AXIS VALUE AND SET THE AMPLITUDE OF THE FUNCTION GENERATOR\n', "AttributeError: 'JoyStick_HW' object has no attribute 'joystick_dev'\n"]
2019-12-06T18:37:55|ERROR|SineWaveJoyStickMeasure|sine_wave_joystick Failed to update figure1: 'JoyStick_HW' object has no attribute 'joystick_dev'. ['Traceback (most recent call last):\n', '  File "C:\\Users\\Andrea Bassi\\Documents\\PythonProjects\\BassiScopeFoundryMicroscopes\\ScopeFoundry\\measurement.py", line 279, in _on_display_update_timer\n    self.update_display()\n', '  File "C:\\Users\\Andrea Bassi\\Documents\\PythonProjects\\BassiScopeFoundryMicroscopes\\Microscopes\\VirtualMicroscopeJoyStick\\SineGenJoyStick_measure.py", line 82, in update_display\n    THIS READS THE JOYSTICK AXIS VALUE AND SET THE AMPLITUDE OF THE FUNCTION GENERATOR\n', "AttributeError: 'JoyStick_HW' object has no attribute 'joystick_dev'\n"]
2019-12-06T18:37:55|ERROR|SineWaveJoyStickMeasure|sine_wave_joystick Failed to update figure1: 'JoyStick_HW' object has no attribute 'joystick_dev'. ['Traceback (most recent call last):\n', '  File "C:\\Users\\Andrea Bassi\\Documents\\PythonProjects\\BassiScopeFoundryMicroscopes\\ScopeFoundry\\measurement.py", line 279, in _on_display_update_timer\n    self.update_display()\n', '  File "C:\\Users\\Andrea Bassi\\Documents\\PythonProjects\\BassiScopeFoundryMicroscopes\\Microscopes\\VirtualMicroscopeJoyStick\\SineGenJoyStick_measure.py", line 82, in update_display\n    THIS READS THE JOYSTICK AXIS VALUE AND SET THE AMPLITUDE OF THE FUNCTION GENERATOR\n', "AttributeError: 'JoyStick_HW' object has no attribute 'joystick_dev'\n"]
2019-12-06T18:37:56|ERROR|SineWaveJoyStickMeasure|sine_wave_joystick Failed to update figure1: 'JoyStick_HW' object has no attribute 'joystick_dev'. ['Traceback (most recent call last):\n', '  File "C:\\Users\\Andrea Bassi\\Documents\\PythonProjects\\BassiScopeFoundryMicroscopes\\ScopeFoundry\\measurement.py", line 279, in _on_display_update_timer\n    self.update_display()\n', '  File "C:\\Users\\Andrea Bassi\\Documents\\PythonProjects\\BassiScopeFoundryMicroscopes\\Microscopes\\VirtualMicroscopeJoyStick\\SineGenJoyStick_measure.py", line 82, in update_display\n    THIS READS THE JOYSTICK AXIS VALUE AND SET THE AMPLITUDE OF THE FUNCTION GENERATOR\n', "AttributeError: 'JoyStick_HW' object has no attribute 'joystick_dev'\n"]
2019-12-06T18:37:56|ERROR|SineWaveJoyStickMeasure|sine_wave_joystick Failed to update figure1: 'JoyStick_HW' object has no attribute 'joystick_dev'. ['Traceback (most recent call last):\n', '  File "C:\\Users\\Andrea Bassi\\Documents\\PythonProjects\\BassiScopeFoundryMicroscopes\\ScopeFoundry\\measurement.py", line 279, in _on_display_update_timer\n    self.update_display()\n', '  File "C:\\Users\\Andrea Bassi\\Documents\\PythonProjects\\BassiScopeFoundryMicroscopes\\Microscopes\\VirtualMicroscopeJoyStick\\SineGenJoyStick_measure.py", line 82, in update_display\n    THIS READS THE JOYSTICK AXIS VALUE AND SET THE AMPLITUDE OF THE FUNCTION GENERATOR\n', "AttributeError: 'JoyStick_HW' object has no attribute 'joystick_dev'\n"]
2019-12-06T18:37:56|ERROR|SineWaveJoyStickMeasure|sine_wave_joystick Failed to update figure1: 'JoyStick_HW' object has no attribute 'joystick_dev'. ['Traceback (most recent call last):\n', '  File "C:\\Users\\Andrea Bassi\\Documents\\PythonProjects\\BassiScopeFoundryMicroscopes\\ScopeFoundry\\measurement.py", line 279, in _on_display_update_timer\n    self.update_display()\n', '  File "C:\\Users\\Andrea Bassi\\Documents\\PythonProjects\\BassiScopeFoundryMicroscopes\\Microscopes\\VirtualMicroscopeJoyStick\\SineGenJoyStick_measure.py", line 82, in update_display\n    THIS READS THE JOYSTICK AXIS VALUE AND SET THE AMPLITUDE OF THE FUNCTION GENERATOR\n', "AttributeError: 'JoyStick_HW' object has no attribute 'joystick_dev'\n"]
2019-12-06T18:37:57|ERROR|SineWaveJoyStickMeasure|sine_wave_joystick Failed to update figure1: 'JoyStick_HW' object has no attribute 'joystick_dev'. ['Traceback (most recent call last):\n', '  File "C:\\Users\\Andrea Bassi\\Documents\\PythonProjects\\BassiScopeFoundryMicroscopes\\ScopeFoundry\\measurement.py", line 279, in _on_display_update_timer\n    self.update_display()\n', '  File "C:\\Users\\Andrea Bassi\\Documents\\PythonProjects\\BassiScopeFoundryMicroscopes\\Microscopes\\VirtualMicroscopeJoyStick\\SineGenJoyStick_measure.py", line 82, in update_display\n    THIS READS THE JOYSTICK AXIS VALUE AND SET THE AMPLITUDE OF THE FUNCTION GENERATOR\n', "AttributeError: 'JoyStick_HW' object has no attribute 'joystick_dev'\n"]
2019-12-06T18:37:57|ERROR|SineWaveJoyStickMeasure|sine_wave_joystick Failed to update figure1: 'JoyStick_HW' object has no attribute 'joystick_dev'. ['Traceback (most recent call last):\n', '  File "C:\\Users\\Andrea Bassi\\Documents\\PythonProjects\\BassiScopeFoundryMicroscopes\\ScopeFoundry\\measurement.py", line 279, in _on_display_update_timer\n    self.update_display()\n', '  File "C:\\Users\\Andrea Bassi\\Documents\\PythonProjects\\BassiScopeFoundryMicroscopes\\Microscopes\\VirtualMicroscopeJoyStick\\SineGenJoyStick_measure.py", line 82, in update_display\n    THIS READS THE JOYSTICK AXIS VALUE AND SET THE AMPLITUDE OF THE FUNCTION GENERATOR\n', "AttributeError: 'JoyStick_HW' object has no attribute 'joystick_dev'\n"]
2019-12-06T18:37:57|ERROR|SineWaveJoyStickMeasure|sine_wave_joystick Failed to update figure1: 'JoyStick_HW' object has no attribute 'joystick_dev'. ['Traceback (most recent call last):\n', '  File "C:\\Users\\Andrea Bassi\\Documents\\PythonProjects\\BassiScopeFoundryMicroscopes\\ScopeFoundry\\measurement.py", line 279, in _on_display_update_timer\n    self.update_display()\n', '  File "C:\\Users\\Andrea Bassi\\Documents\\PythonProjects\\BassiScopeFoundryMicroscopes\\Microscopes\\VirtualMicroscopeJoyStick\\SineGenJoyStick_measure.py", line 82, in update_display\n    THIS READS THE JOYSTICK AXIS VALUE AND SET THE AMPLITUDE OF THE FUNCTION GENERATOR\n', "AttributeError: 'JoyStick_HW' object has no attribute 'joystick_dev'\n"]
2019-12-06T18:39:38|ERROR|SineWaveJoyStickMeasure|sine_wave_joystick Failed to update figure1: 'JoyStick_HW' object has no attribute 'joystick_dev'. ['Traceback (most recent call last):\n', '  File "C:\\Users\\Andrea Bassi\\Documents\\PythonProjects\\BassiScopeFoundryMicroscopes\\ScopeFoundry\\measurement.py", line 279, in _on_display_update_timer\n    self.update_display()\n', '  File "C:\\Users\\Andrea Bassi\\Documents\\PythonProjects\\BassiScopeFoundryMicroscopes\\Microscopes\\VirtualMicroscopeJoyStick\\SineGenJoyStick_measure.py", line 85, in update_display\n    self.func_gen.settings[\'amplitude\'] = self.joystick.joystick_dev.get_axis_values(AXIS_L2)\n', "AttributeError: 'JoyStick_HW' object has no attribute 'joystick_dev'\n"]
2019-12-06T18:39:39|ERROR|SineWaveJoyStickMeasure|sine_wave_joystick Failed to update figure1: 'JoyStick_HW' object has no attribute 'joystick_dev'. ['Traceback (most recent call last):\n', '  File "C:\\Users\\Andrea Bassi\\Documents\\PythonProjects\\BassiScopeFoundryMicroscopes\\ScopeFoundry\\measurement.py", line 279, in _on_display_update_timer\n    self.update_display()\n', '  File "C:\\Users\\Andrea Bassi\\Documents\\PythonProjects\\BassiScopeFoundryMicroscopes\\Microscopes\\VirtualMicroscopeJoyStick\\SineGenJoyStick_measure.py", line 85, in update_display\n    self.func_gen.settings[\'amplitude\'] = self.joystick.joystick_dev.get_axis_values(AXIS_L2)\n', "AttributeError: 'JoyStick_HW' object has no attribute 'joystick_dev'\n"]
2019-12-06T18:39:39|ERROR|SineWaveJoyStickMeasure|sine_wave_joystick Failed to update figure1: 'JoyStick_HW' object has no attribute 'joystick_dev'. ['Traceback (most recent call last):\n', '  File "C:\\Users\\Andrea Bassi\\Documents\\PythonProjects\\BassiScopeFoundryMicroscopes\\ScopeFoundry\\measurement.py", line 279, in _on_display_update_timer\n    self.update_display()\n', '  File "C:\\Users\\Andrea Bassi\\Documents\\PythonProjects\\BassiScopeFoundryMicroscopes\\Microscopes\\VirtualMicroscopeJoyStick\\SineGenJoyStick_measure.py", line 85, in update_display\n    self.func_gen.settings[\'amplitude\'] = self.joystick.joystick_dev.get_axis_values(AXIS_L2)\n', "AttributeError: 'JoyStick_HW' object has no attribute 'joystick_dev'\n"]
2019-12-06T18:39:39|ERROR|SineWaveJoyStickMeasure|sine_wave_joystick Failed to update figure1: 'JoyStick_HW' object has no attribute 'joystick_dev'. ['Traceback (most recent call last):\n', '  File "C:\\Users\\Andrea Bassi\\Documents\\PythonProjects\\BassiScopeFoundryMicroscopes\\ScopeFoundry\\measurement.py", line 279, in _on_display_update_timer\n    self.update_display()\n', '  File "C:\\Users\\Andrea Bassi\\Documents\\PythonProjects\\BassiScopeFoundryMicroscopes\\Microscopes\\VirtualMicroscopeJoyStick\\SineGenJoyStick_measure.py", line 85, in update_display\n    self.func_gen.settings[\'amplitude\'] = self.joystick.joystick_dev.get_axis_values(AXIS_L2)\n', "AttributeError: 'JoyStick_HW' object has no attribute 'joystick_dev'\n"]
2019-12-06T18:39:40|ERROR|SineWaveJoyStickMeasure|sine_wave_joystick Failed to update figure1: 'JoyStick_HW' object has no attribute 'joystick_dev'. ['Traceback (most recent call last):\n', '  File "C:\\Users\\Andrea Bassi\\Documents\\PythonProjects\\BassiScopeFoundryMicroscopes\\ScopeFoundry\\measurement.py", line 279, in _on_display_update_timer\n    self.update_display()\n', '  File "C:\\Users\\Andrea Bassi\\Documents\\PythonProjects\\BassiScopeFoundryMicroscopes\\Microscopes\\VirtualMicroscopeJoyStick\\SineGenJoyStick_measure.py", line 85, in update_display\n    self.func_gen.settings[\'amplitude\'] = self.joystick.joystick_dev.get_axis_values(AXIS_L2)\n', "AttributeError: 'JoyStick_HW' object has no attribute 'joystick_dev'\n"]
2019-12-06T18:39:40|ERROR|SineWaveJoyStickMeasure|sine_wave_joystick Failed to update figure1: 'JoyStick_HW' object has no attribute 'joystick_dev'. ['Traceback (most recent call last):\n', '  File "C:\\Users\\Andrea Bassi\\Documents\\PythonProjects\\BassiScopeFoundryMicroscopes\\ScopeFoundry\\measurement.py", line 279, in _on_display_update_timer\n    self.update_display()\n', '  File "C:\\Users\\Andrea Bassi\\Documents\\PythonProjects\\BassiScopeFoundryMicroscopes\\Microscopes\\VirtualMicroscopeJoyStick\\SineGenJoyStick_measure.py", line 85, in update_display\n    self.func_gen.settings[\'amplitude\'] = self.joystick.joystick_dev.get_axis_values(AXIS_L2)\n', "AttributeError: 'JoyStick_HW' object has no attribute 'joystick_dev'\n"]
2019-12-06T18:39:40|ERROR|SineWaveJoyStickMeasure|sine_wave_joystick Failed to update figure1: 'JoyStick_HW' object has no attribute 'joystick_dev'. ['Traceback (most recent call last):\n', '  File "C:\\Users\\Andrea Bassi\\Documents\\PythonProjects\\BassiScopeFoundryMicroscopes\\ScopeFoundry\\measurement.py", line 279, in _on_display_update_timer\n    self.update_display()\n', '  File "C:\\Users\\Andrea Bassi\\Documents\\PythonProjects\\BassiScopeFoundryMicroscopes\\Microscopes\\VirtualMicroscopeJoyStick\\SineGenJoyStick_measure.py", line 85, in update_display\n    self.func_gen.settings[\'amplitude\'] = self.joystick.joystick_dev.get_axis_values(AXIS_L2)\n', "AttributeError: 'JoyStick_HW' object has no attribute 'joystick_dev'\n"]
2019-12-06T18:39:41|ERROR|SineWaveJoyStickMeasure|sine_wave_joystick Failed to update figure1: 'JoyStick_HW' object has no attribute 'joystick_dev'. ['Traceback (most recent call last):\n', '  File "C:\\Users\\Andrea Bassi\\Documents\\PythonProjects\\BassiScopeFoundryMicroscopes\\ScopeFoundry\\measurement.py", line 279, in _on_display_update_timer\n    self.update_display()\n', '  File "C:\\Users\\Andrea Bassi\\Documents\\PythonProjects\\BassiScopeFoundryMicroscopes\\Microscopes\\VirtualMicroscopeJoyStick\\SineGenJoyStick_measure.py", line 85, in update_display\n    self.func_gen.settings[\'amplitude\'] = self.joystick.joystick_dev.get_axis_values(AXIS_L2)\n', "AttributeError: 'JoyStick_HW' object has no attribute 'joystick_dev'\n"]
2019-12-06T18:39:41|ERROR|SineWaveJoyStickMeasure|sine_wave_joystick Failed to update figure1: 'JoyStick_HW' object has no attribute 'joystick_dev'. ['Traceback (most recent call last):\n', '  File "C:\\Users\\Andrea Bassi\\Documents\\PythonProjects\\BassiScopeFoundryMicroscopes\\ScopeFoundry\\measurement.py", line 279, in _on_display_update_timer\n    self.update_display()\n', '  File "C:\\Users\\Andrea Bassi\\Documents\\PythonProjects\\BassiScopeFoundryMicroscopes\\Microscopes\\VirtualMicroscopeJoyStick\\SineGenJoyStick_measure.py", line 85, in update_display\n    self.func_gen.settings[\'amplitude\'] = self.joystick.joystick_dev.get_axis_values(AXIS_L2)\n', "AttributeError: 'JoyStick_HW' object has no attribute 'joystick_dev'\n"]
2019-12-06T18:39:41|ERROR|SineWaveJoyStickMeasure|sine_wave_joystick Failed to update figure1: 'JoyStick_HW' object has no attribute 'joystick_dev'. ['Traceback (most recent call last):\n', '  File "C:\\Users\\Andrea Bassi\\Documents\\PythonProjects\\BassiScopeFoundryMicroscopes\\ScopeFoundry\\measurement.py", line 279, in _on_display_update_timer\n    self.update_display()\n', '  File "C:\\Users\\Andrea Bassi\\Documents\\PythonProjects\\BassiScopeFoundryMicroscopes\\Microscopes\\VirtualMicroscopeJoyStick\\SineGenJoyStick_measure.py", line 85, in update_display\n    self.func_gen.settings[\'amplitude\'] = self.joystick.joystick_dev.get_axis_values(AXIS_L2)\n', "AttributeError: 'JoyStick_HW' object has no attribute 'joystick_dev'\n"]
2019-12-06T18:39:42|ERROR|SineWaveJoyStickMeasure|sine_wave_joystick Failed to update figure1: 'JoyStick_HW' object has no attribute 'joystick_dev'. ['Traceback (most recent call last):\n', '  File "C:\\Users\\Andrea Bassi\\Documents\\PythonProjects\\BassiScopeFoundryMicroscopes\\ScopeFoundry\\measurement.py", line 279, in _on_display_update_timer\n    self.update_display()\n', '  File "C:\\Users\\Andrea Bassi\\Documents\\PythonProjects\\BassiScopeFoundryMicroscopes\\Microscopes\\VirtualMicroscopeJoyStick\\SineGenJoyStick_measure.py", line 85, in update_display\n    self.func_gen.settings[\'amplitude\'] = self.joystick.joystick_dev.get_axis_values(AXIS_L2)\n', "AttributeError: 'JoyStick_HW' object has no attribute 'joystick_dev'\n"]
2019-12-06T18:39:42|ERROR|SineWaveJoyStickMeasure|sine_wave_joystick Failed to update figure1: 'JoyStick_HW' object has no attribute 'joystick_dev'. ['Traceback (most recent call last):\n', '  File "C:\\Users\\Andrea Bassi\\Documents\\PythonProjects\\BassiScopeFoundryMicroscopes\\ScopeFoundry\\measurement.py", line 279, in _on_display_update_timer\n    self.update_display()\n', '  File "C:\\Users\\Andrea Bassi\\Documents\\PythonProjects\\BassiScopeFoundryMicroscopes\\Microscopes\\VirtualMicroscopeJoyStick\\SineGenJoyStick_measure.py", line 85, in update_display\n    self.func_gen.settings[\'amplitude\'] = self.joystick.joystick_dev.get_axis_values(AXIS_L2)\n', "AttributeError: 'JoyStick_HW' object has no attribute 'joystick_dev'\n"]
2019-12-06T18:39:42|ERROR|SineWaveJoyStickMeasure|sine_wave_joystick Failed to update figure1: 'JoyStick_HW' object has no attribute 'joystick_dev'. ['Traceback (most recent call last):\n', '  File "C:\\Users\\Andrea Bassi\\Documents\\PythonProjects\\BassiScopeFoundryMicroscopes\\ScopeFoundry\\measurement.py", line 279, in _on_display_update_timer\n    self.update_display()\n', '  File "C:\\Users\\Andrea Bassi\\Documents\\PythonProjects\\BassiScopeFoundryMicroscopes\\Microscopes\\VirtualMicroscopeJoyStick\\SineGenJoyStick_measure.py", line 85, in update_display\n    self.func_gen.settings[\'amplitude\'] = self.joystick.joystick_dev.get_axis_values(AXIS_L2)\n', "AttributeError: 'JoyStick_HW' object has no attribute 'joystick_dev'\n"]
2019-12-06T18:39:43|ERROR|SineWaveJoyStickMeasure|sine_wave_joystick Failed to update figure1: 'JoyStick_HW' object has no attribute 'joystick_dev'. ['Traceback (most recent call last):\n', '  File "C:\\Users\\Andrea Bassi\\Documents\\PythonProjects\\BassiScopeFoundryMicroscopes\\ScopeFoundry\\measurement.py", line 279, in _on_display_update_timer\n    self.update_display()\n', '  File "C:\\Users\\Andrea Bassi\\Documents\\PythonProjects\\BassiScopeFoundryMicroscopes\\Microscopes\\VirtualMicroscopeJoyStick\\SineGenJoyStick_measure.py", line 85, in update_display\n    self.func_gen.settings[\'amplitude\'] = self.joystick.joystick_dev.get_axis_values(AXIS_L2)\n', "AttributeError: 'JoyStick_HW' object has no attribute 'joystick_dev'\n"]
2019-12-06T18:39:43|ERROR|SineWaveJoyStickMeasure|sine_wave_joystick Failed to update figure1: 'JoyStick_HW' object has no attribute 'joystick_dev'. ['Traceback (most recent call last):\n', '  File "C:\\Users\\Andrea Bassi\\Documents\\PythonProjects\\BassiScopeFoundryMicroscopes\\ScopeFoundry\\measurement.py", line 279, in _on_display_update_timer\n    self.update_display()\n', '  File "C:\\Users\\Andrea Bassi\\Documents\\PythonProjects\\BassiScopeFoundryMicroscopes\\Microscopes\\VirtualMicroscopeJoyStick\\SineGenJoyStick_measure.py", line 85, in update_display\n    self.func_gen.settings[\'amplitude\'] = self.joystick.joystick_dev.get_axis_values(AXIS_L2)\n', "AttributeError: 'JoyStick_HW' object has no attribute 'joystick_dev'\n"]
2019-12-06T18:39:43|ERROR|SineWaveJoyStickMeasure|sine_wave_joystick Failed to update figure1: 'JoyStick_HW' object has no attribute 'joystick_dev'. ['Traceback (most recent call last):\n', '  File "C:\\Users\\Andrea Bassi\\Documents\\PythonProjects\\BassiScopeFoundryMicroscopes\\ScopeFoundry\\measurement.py", line 279, in _on_display_update_timer\n    self.update_display()\n', '  File "C:\\Users\\Andrea Bassi\\Documents\\PythonProjects\\BassiScopeFoundryMicroscopes\\Microscopes\\VirtualMicroscopeJoyStick\\SineGenJoyStick_measure.py", line 85, in update_display\n    self.func_gen.settings[\'amplitude\'] = self.joystick.joystick_dev.get_axis_values(AXIS_L2)\n', "AttributeError: 'JoyStick_HW' object has no attribute 'joystick_dev'\n"]
2019-12-06T18:39:44|ERROR|SineWaveJoyStickMeasure|sine_wave_joystick Failed to update figure1: 'JoyStick_HW' object has no attribute 'joystick_dev'. ['Traceback (most recent call last):\n', '  File "C:\\Users\\Andrea Bassi\\Documents\\PythonProjects\\BassiScopeFoundryMicroscopes\\ScopeFoundry\\measurement.py", line 279, in _on_display_update_timer\n    self.update_display()\n', '  File "C:\\Users\\Andrea Bassi\\Documents\\PythonProjects\\BassiScopeFoundryMicroscopes\\Microscopes\\VirtualMicroscopeJoyStick\\SineGenJoyStick_measure.py", line 85, in update_display\n    self.func_gen.settings[\'amplitude\'] = self.joystick.joystick_dev.get_axis_values(AXIS_L2)\n', "AttributeError: 'JoyStick_HW' object has no attribute 'joystick_dev'\n"]
2019-12-06T18:39:44|ERROR|SineWaveJoyStickMeasure|sine_wave_joystick Failed to update figure1: 'JoyStick_HW' object has no attribute 'joystick_dev'. ['Traceback (most recent call last):\n', '  File "C:\\Users\\Andrea Bassi\\Documents\\PythonProjects\\BassiScopeFoundryMicroscopes\\ScopeFoundry\\measurement.py", line 279, in _on_display_update_timer\n    self.update_display()\n', '  File "C:\\Users\\Andrea Bassi\\Documents\\PythonProjects\\BassiScopeFoundryMicroscopes\\Microscopes\\VirtualMicroscopeJoyStick\\SineGenJoyStick_measure.py", line 85, in update_display\n    self.func_gen.settings[\'amplitude\'] = self.joystick.joystick_dev.get_axis_values(AXIS_L2)\n', "AttributeError: 'JoyStick_HW' object has no attribute 'joystick_dev'\n"]
2019-12-06T18:39:44|ERROR|SineWaveJoyStickMeasure|sine_wave_joystick Failed to update figure1: 'JoyStick_HW' object has no attribute 'joystick_dev'. ['Traceback (most recent call last):\n', '  File "C:\\Users\\Andrea Bassi\\Documents\\PythonProjects\\BassiScopeFoundryMicroscopes\\ScopeFoundry\\measurement.py", line 279, in _on_display_update_timer\n    self.update_display()\n', '  File "C:\\Users\\Andrea Bassi\\Documents\\PythonProjects\\BassiScopeFoundryMicroscopes\\Microscopes\\VirtualMicroscopeJoyStick\\SineGenJoyStick_measure.py", line 85, in update_display\n    self.func_gen.settings[\'amplitude\'] = self.joystick.joystick_dev.get_axis_values(AXIS_L2)\n', "AttributeError: 'JoyStick_HW' object has no attribute 'joystick_dev'\n"]
2019-12-06T18:39:45|ERROR|SineWaveJoyStickMeasure|sine_wave_joystick Failed to update figure1: 'JoyStick_HW' object has no attribute 'joystick_dev'. ['Traceback (most recent call last):\n', '  File "C:\\Users\\Andrea Bassi\\Documents\\PythonProjects\\BassiScopeFoundryMicroscopes\\ScopeFoundry\\measurement.py", line 279, in _on_display_update_timer\n    self.update_display()\n', '  File "C:\\Users\\Andrea Bassi\\Documents\\PythonProjects\\BassiScopeFoundryMicroscopes\\Microscopes\\VirtualMicroscopeJoyStick\\SineGenJoyStick_measure.py", line 85, in update_display\n    self.func_gen.settings[\'amplitude\'] = self.joystick.joystick_dev.get_axis_values(AXIS_L2)\n', "AttributeError: 'JoyStick_HW' object has no attribute 'joystick_dev'\n"]
2019-12-06T18:39:45|ERROR|SineWaveJoyStickMeasure|sine_wave_joystick Failed to update figure1: 'JoyStick_HW' object has no attribute 'joystick_dev'. ['Traceback (most recent call last):\n', '  File "C:\\Users\\Andrea Bassi\\Documents\\PythonProjects\\BassiScopeFoundryMicroscopes\\ScopeFoundry\\measurement.py", line 279, in _on_display_update_timer\n    self.update_display()\n', '  File "C:\\Users\\Andrea Bassi\\Documents\\PythonProjects\\BassiScopeFoundryMicroscopes\\Microscopes\\VirtualMicroscopeJoyStick\\SineGenJoyStick_measure.py", line 85, in update_display\n    self.func_gen.settings[\'amplitude\'] = self.joystick.joystick_dev.get_axis_values(AXIS_L2)\n', "AttributeError: 'JoyStick_HW' object has no attribute 'joystick_dev'\n"]
2019-12-06T18:39:45|ERROR|SineWaveJoyStickMeasure|sine_wave_joystick Failed to update figure1: 'JoyStick_HW' object has no attribute 'joystick_dev'. ['Traceback (most recent call last):\n', '  File "C:\\Users\\Andrea Bassi\\Documents\\PythonProjects\\BassiScopeFoundryMicroscopes\\ScopeFoundry\\measurement.py", line 279, in _on_display_update_timer\n    self.update_display()\n', '  File "C:\\Users\\Andrea Bassi\\Documents\\PythonProjects\\BassiScopeFoundryMicroscopes\\Microscopes\\VirtualMicroscopeJoyStick\\SineGenJoyStick_measure.py", line 85, in update_display\n    self.func_gen.settings[\'amplitude\'] = self.joystick.joystick_dev.get_axis_values(AXIS_L2)\n', "AttributeError: 'JoyStick_HW' object has no attribute 'joystick_dev'\n"]
2019-12-06T18:39:46|ERROR|SineWaveJoyStickMeasure|sine_wave_joystick Failed to update figure1: 'JoyStick_HW' object has no attribute 'joystick_dev'. ['Traceback (most recent call last):\n', '  File "C:\\Users\\Andrea Bassi\\Documents\\PythonProjects\\BassiScopeFoundryMicroscopes\\ScopeFoundry\\measurement.py", line 279, in _on_display_update_timer\n    self.update_display()\n', '  File "C:\\Users\\Andrea Bassi\\Documents\\PythonProjects\\BassiScopeFoundryMicroscopes\\Microscopes\\VirtualMicroscopeJoyStick\\SineGenJoyStick_measure.py", line 85, in update_display\n    self.func_gen.settings[\'amplitude\'] = self.joystick.joystick_dev.get_axis_values(AXIS_L2)\n', "AttributeError: 'JoyStick_HW' object has no attribute 'joystick_dev'\n"]
2019-12-06T18:39:46|ERROR|SineWaveJoyStickMeasure|sine_wave_joystick Failed to update figure1: 'JoyStick_HW' object has no attribute 'joystick_dev'. ['Traceback (most recent call last):\n', '  File "C:\\Users\\Andrea Bassi\\Documents\\PythonProjects\\BassiScopeFoundryMicroscopes\\ScopeFoundry\\measurement.py", line 279, in _on_display_update_timer\n    self.update_display()\n', '  File "C:\\Users\\Andrea Bassi\\Documents\\PythonProjects\\BassiScopeFoundryMicroscopes\\Microscopes\\VirtualMicroscopeJoyStick\\SineGenJoyStick_measure.py", line 85, in update_display\n    self.func_gen.settings[\'amplitude\'] = self.joystick.joystick_dev.get_axis_values(AXIS_L2)\n', "AttributeError: 'JoyStick_HW' object has no attribute 'joystick_dev'\n"]
2019-12-06T18:39:46|ERROR|SineWaveJoyStickMeasure|sine_wave_joystick Failed to update figure1: 'JoyStick_HW' object has no attribute 'joystick_dev'. ['Traceback (most recent call last):\n', '  File "C:\\Users\\Andrea Bassi\\Documents\\PythonProjects\\BassiScopeFoundryMicroscopes\\ScopeFoundry\\measurement.py", line 279, in _on_display_update_timer\n    self.update_display()\n', '  File "C:\\Users\\Andrea Bassi\\Documents\\PythonProjects\\BassiScopeFoundryMicroscopes\\Microscopes\\VirtualMicroscopeJoyStick\\SineGenJoyStick_measure.py", line 85, in update_display\n    self.func_gen.settings[\'amplitude\'] = self.joystick.joystick_dev.get_axis_values(AXIS_L2)\n', "AttributeError: 'JoyStick_HW' object has no attribute 'joystick_dev'\n"]
2019-12-06T18:39:47|ERROR|SineWaveJoyStickMeasure|sine_wave_joystick Failed to update figure1: 'JoyStick_HW' object has no attribute 'joystick_dev'. ['Traceback (most recent call last):\n', '  File "C:\\Users\\Andrea Bassi\\Documents\\PythonProjects\\BassiScopeFoundryMicroscopes\\ScopeFoundry\\measurement.py", line 279, in _on_display_update_timer\n    self.update_display()\n', '  File "C:\\Users\\Andrea Bassi\\Documents\\PythonProjects\\BassiScopeFoundryMicroscopes\\Microscopes\\VirtualMicroscopeJoyStick\\SineGenJoyStick_measure.py", line 85, in update_display\n    self.func_gen.settings[\'amplitude\'] = self.joystick.joystick_dev.get_axis_values(AXIS_L2)\n', "AttributeError: 'JoyStick_HW' object has no attribute 'joystick_dev'\n"]
2019-12-06T18:39:47|ERROR|SineWaveJoyStickMeasure|sine_wave_joystick Failed to update figure1: 'JoyStick_HW' object has no attribute 'joystick_dev'. ['Traceback (most recent call last):\n', '  File "C:\\Users\\Andrea Bassi\\Documents\\PythonProjects\\BassiScopeFoundryMicroscopes\\ScopeFoundry\\measurement.py", line 279, in _on_display_update_timer\n    self.update_display()\n', '  File "C:\\Users\\Andrea Bassi\\Documents\\PythonProjects\\BassiScopeFoundryMicroscopes\\Microscopes\\VirtualMicroscopeJoyStick\\SineGenJoyStick_measure.py", line 85, in update_display\n    self.func_gen.settings[\'amplitude\'] = self.joystick.joystick_dev.get_axis_values(AXIS_L2)\n', "AttributeError: 'JoyStick_HW' object has no attribute 'joystick_dev'\n"]
2019-12-06T18:39:47|ERROR|SineWaveJoyStickMeasure|sine_wave_joystick Failed to update figure1: 'JoyStick_HW' object has no attribute 'joystick_dev'. ['Traceback (most recent call last):\n', '  File "C:\\Users\\Andrea Bassi\\Documents\\PythonProjects\\BassiScopeFoundryMicroscopes\\ScopeFoundry\\measurement.py", line 279, in _on_display_update_timer\n    self.update_display()\n', '  File "C:\\Users\\Andrea Bassi\\Documents\\PythonProjects\\BassiScopeFoundryMicroscopes\\Microscopes\\VirtualMicroscopeJoyStick\\SineGenJoyStick_measure.py", line 85, in update_display\n    self.func_gen.settings[\'amplitude\'] = self.joystick.joystick_dev.get_axis_values(AXIS_L2)\n', "AttributeError: 'JoyStick_HW' object has no attribute 'joystick_dev'\n"]
2019-12-06T18:39:48|ERROR|SineWaveJoyStickMeasure|sine_wave_joystick Failed to update figure1: 'JoyStick_HW' object has no attribute 'joystick_dev'. ['Traceback (most recent call last):\n', '  File "C:\\Users\\Andrea Bassi\\Documents\\PythonProjects\\BassiScopeFoundryMicroscopes\\ScopeFoundry\\measurement.py", line 279, in _on_display_update_timer\n    self.update_display()\n', '  File "C:\\Users\\Andrea Bassi\\Documents\\PythonProjects\\BassiScopeFoundryMicroscopes\\Microscopes\\VirtualMicroscopeJoyStick\\SineGenJoyStick_measure.py", line 85, in update_display\n    self.func_gen.settings[\'amplitude\'] = self.joystick.joystick_dev.get_axis_values(AXIS_L2)\n', "AttributeError: 'JoyStick_HW' object has no attribute 'joystick_dev'\n"]
2019-12-06T18:39:48|ERROR|SineWaveJoyStickMeasure|sine_wave_joystick Failed to update figure1: 'JoyStick_HW' object has no attribute 'joystick_dev'. ['Traceback (most recent call last):\n', '  File "C:\\Users\\Andrea Bassi\\Documents\\PythonProjects\\BassiScopeFoundryMicroscopes\\ScopeFoundry\\measurement.py", line 279, in _on_display_update_timer\n    self.update_display()\n', '  File "C:\\Users\\Andrea Bassi\\Documents\\PythonProjects\\BassiScopeFoundryMicroscopes\\Microscopes\\VirtualMicroscopeJoyStick\\SineGenJoyStick_measure.py", line 85, in update_display\n    self.func_gen.settings[\'amplitude\'] = self.joystick.joystick_dev.get_axis_values(AXIS_L2)\n', "AttributeError: 'JoyStick_HW' object has no attribute 'joystick_dev'\n"]
