2020-08-09T19:08:27|CRITICAL|root|Unhandled exception:Traceback (most recent call last):
  File "C:\Users\Andrea Bassi\anaconda3\envs\scopefoundry\lib\site-packages\ScopeFoundry\measurement.py", line 25, in run
    self.measurement._thread_run()
  File "C:\Users\Andrea Bassi\anaconda3\envs\scopefoundry\lib\site-packages\ScopeFoundry\measurement.py", line 179, in _thread_run
    self.run()
  File "C:\Users\Andrea Bassi\OneDrive - Politecnico di Milano\Documenti\PythonProjects\BassiScopeFoundryMicroscopes\Microscopes\CellRecongnitionMicroscope\FakeCameraMeasurement.py", line 139, in run
    self.image = self.camera.fakecamera.get_image()
AttributeError: 'FakeCameraHardware' object has no attribute 'fakecamera'

