2020-08-03T11:38:42|CRITICAL|root|Unhandled exception:Traceback (most recent call last):
  File "C:\Users\Andrea Bassi\anaconda3\envs\scopefoundry\lib\site-packages\ScopeFoundry\measurement.py", line 25, in run
    self.measurement._thread_run()
  File "C:\Users\Andrea Bassi\anaconda3\envs\scopefoundry\lib\site-packages\ScopeFoundry\measurement.py", line 179, in _thread_run
    self.run()
  File "C:\Users\Andrea Bassi\OneDrive - Politecnico di Milano\Documenti\PythonProjects\BassiScopeFoundryMicroscopes\Microscopes\CellRecongnitionMicroscope\FakeCameraMeasurement.py", line 141, in run
    self.image = self.camera.fakecamera.get_image()
  File "C:\Users\Andrea Bassi\OneDrive - Politecnico di Milano\Documenti\PythonProjects\BassiScopeFoundryMicroscopes\Microscopes\CellRecongnitionMicroscope\FakeCameraMeasurement.py", line 141, in run
    self.image = self.camera.fakecamera.get_image()
  File "C:\Users\Andrea Bassi\anaconda3\envs\scopefoundry\lib\bdb.py", line 51, in trace_dispatch
    return self.dispatch_line(frame)
  File "C:\Users\Andrea Bassi\anaconda3\envs\scopefoundry\lib\bdb.py", line 70, in dispatch_line
    if self.quitting: raise BdbQuit
bdb.BdbQuit

