2020-07-23T13:21:18|CRITICAL|root|Unhandled exception:Traceback (most recent call last):
  File "C:\Users\Andrea Bassi\anaconda3\envs\scopefoundry\lib\site-packages\pyqtgraph\graphicsItems\HistogramLUTItem.py", line 195, in imageChanged
    h = self.imageItem().getHistogram()
  File "C:\Users\Andrea Bassi\anaconda3\envs\scopefoundry\lib\site-packages\pyqtgraph\graphicsItems\ImageItem.py", line 464, in getHistogram
    bins = np.arange(mn, mx+1.01*step, step, dtype=np.int)
ValueError: arange: cannot compute length

2020-07-23T13:21:24|CRITICAL|root|Unhandled exception:Traceback (most recent call last):
  File "C:\Users\Andrea Bassi\anaconda3\envs\scopefoundry\lib\site-packages\pyqtgraph\graphicsItems\HistogramLUTItem.py", line 195, in imageChanged
    h = self.imageItem().getHistogram()
  File "C:\Users\Andrea Bassi\anaconda3\envs\scopefoundry\lib\site-packages\pyqtgraph\graphicsItems\ImageItem.py", line 464, in getHistogram
    bins = np.arange(mn, mx+1.01*step, step, dtype=np.int)
ValueError: arange: cannot compute length

2020-07-23T13:21:26|CRITICAL|root|Unhandled exception:Traceback (most recent call last):
  File "C:\Users\Andrea Bassi\anaconda3\envs\scopefoundry\lib\site-packages\pyqtgraph\graphicsItems\HistogramLUTItem.py", line 195, in imageChanged
    h = self.imageItem().getHistogram()
  File "C:\Users\Andrea Bassi\anaconda3\envs\scopefoundry\lib\site-packages\pyqtgraph\graphicsItems\ImageItem.py", line 464, in getHistogram
    bins = np.arange(mn, mx+1.01*step, step, dtype=np.int)
ValueError: arange: cannot compute length

2020-07-23T13:21:36|ERROR|FakeCameraMeasurement|fake_camera_image Failed to update figure1: <built-in method emit of PyQt5.QtCore.pyqtBoundSignal object at 0x000001C119A3BDF0> returned a result with an error set. ['Traceback (most recent call last):\n', '  File "C:\\Users\\Andrea Bassi\\anaconda3\\envs\\scopefoundry\\lib\\site-packages\\pyqtgraph\\graphicsItems\\HistogramLUTItem.py", line 195, in imageChanged\n    h = self.imageItem().getHistogram()\n', '  File "C:\\Users\\Andrea Bassi\\anaconda3\\envs\\scopefoundry\\lib\\site-packages\\pyqtgraph\\graphicsItems\\ImageItem.py", line 464, in getHistogram\n    bins = np.arange(mn, mx+1.01*step, step, dtype=np.int)\n', 'ValueError: arange: cannot compute length\n', '\nThe above exception was the direct cause of the following exception:\n\n', 'Traceback (most recent call last):\n', '  File "C:\\Users\\Andrea Bassi\\anaconda3\\envs\\scopefoundry\\lib\\site-packages\\ScopeFoundry\\measurement.py", line 273, in _on_display_update_timer\n    self.update_display()\n', '  File "C:\\Users\\Andrea Bassi\\OneDrive - Politecnico di Milano\\Documenti\\PythonProjects\\BassiScopeFoundryMicroscopes\\Microscopes\\CellRecongnitionMicroscope\\FakeCameraMeasurement.py", line 87, in update_display\n    self.imv.setImage((self.displayed_image), autoLevels=self.settings.autoLevels.val, autoRange=self.settings.autoRange.val)\n', '  File "C:\\Users\\Andrea Bassi\\anaconda3\\envs\\scopefoundry\\lib\\site-packages\\pyqtgraph\\imageview\\ImageView.py", line 301, in setImage\n    self.updateImage(autoHistogramRange=autoHistogramRange)\n', '  File "C:\\Users\\Andrea Bassi\\anaconda3\\envs\\scopefoundry\\lib\\site-packages\\pyqtgraph\\imageview\\ImageView.py", line 676, in updateImage\n    self.imageItem.updateImage(image)\n', '  File "C:\\Users\\Andrea Bassi\\anaconda3\\envs\\scopefoundry\\lib\\site-packages\\pyqtgraph\\graphicsItems\\ImageItem.py", line 342, in updateImage\n    return self.setImage(*args, **defaults)\n', '  File "C:\\Users\\Andrea Bassi\\anaconda3\\envs\\scopefoundry\\lib\\site-packages\\pyqtgraph\\graphicsItems\\ImageItem.py", line 283, in setImage\n    self.sigImageChanged.emit()\n', 'SystemError: <built-in method emit of PyQt5.QtCore.pyqtBoundSignal object at 0x000001C119A3BDF0> returned a result with an error set\n']
2020-07-23T13:21:36|ERROR|FakeCameraMeasurement|fake_camera_image Failed to update figure1: <built-in method emit of PyQt5.QtCore.pyqtBoundSignal object at 0x000001C119A3BE90> returned a result with an error set. ['Traceback (most recent call last):\n', '  File "C:\\Users\\Andrea Bassi\\anaconda3\\envs\\scopefoundry\\lib\\site-packages\\pyqtgraph\\graphicsItems\\HistogramLUTItem.py", line 195, in imageChanged\n    h = self.imageItem().getHistogram()\n', '  File "C:\\Users\\Andrea Bassi\\anaconda3\\envs\\scopefoundry\\lib\\site-packages\\pyqtgraph\\graphicsItems\\ImageItem.py", line 464, in getHistogram\n    bins = np.arange(mn, mx+1.01*step, step, dtype=np.int)\n', 'ValueError: arange: cannot compute length\n', '\nThe above exception was the direct cause of the following exception:\n\n', 'Traceback (most recent call last):\n', '  File "C:\\Users\\Andrea Bassi\\anaconda3\\envs\\scopefoundry\\lib\\site-packages\\ScopeFoundry\\measurement.py", line 273, in _on_display_update_timer\n    self.update_display()\n', '  File "C:\\Users\\Andrea Bassi\\OneDrive - Politecnico di Milano\\Documenti\\PythonProjects\\BassiScopeFoundryMicroscopes\\Microscopes\\CellRecongnitionMicroscope\\FakeCameraMeasurement.py", line 87, in update_display\n    self.imv.setImage((self.displayed_image), autoLevels=self.settings.autoLevels.val, autoRange=self.settings.autoRange.val)\n', '  File "C:\\Users\\Andrea Bassi\\anaconda3\\envs\\scopefoundry\\lib\\site-packages\\pyqtgraph\\imageview\\ImageView.py", line 301, in setImage\n    self.updateImage(autoHistogramRange=autoHistogramRange)\n', '  File "C:\\Users\\Andrea Bassi\\anaconda3\\envs\\scopefoundry\\lib\\site-packages\\pyqtgraph\\imageview\\ImageView.py", line 676, in updateImage\n    self.imageItem.updateImage(image)\n', '  File "C:\\Users\\Andrea Bassi\\anaconda3\\envs\\scopefoundry\\lib\\site-packages\\pyqtgraph\\graphicsItems\\ImageItem.py", line 342, in updateImage\n    return self.setImage(*args, **defaults)\n', '  File "C:\\Users\\Andrea Bassi\\anaconda3\\envs\\scopefoundry\\lib\\site-packages\\pyqtgraph\\graphicsItems\\ImageItem.py", line 283, in setImage\n    self.sigImageChanged.emit()\n', 'SystemError: <built-in method emit of PyQt5.QtCore.pyqtBoundSignal object at 0x000001C119A3BE90> returned a result with an error set\n']
2020-07-23T13:21:36|ERROR|FakeCameraMeasurement|fake_camera_image Failed to update figure1: <built-in method emit of PyQt5.QtCore.pyqtBoundSignal object at 0x000001C119A3BAD0> returned a result with an error set. ['Traceback (most recent call last):\n', '  File "C:\\Users\\Andrea Bassi\\anaconda3\\envs\\scopefoundry\\lib\\site-packages\\pyqtgraph\\graphicsItems\\HistogramLUTItem.py", line 195, in imageChanged\n    h = self.imageItem().getHistogram()\n', '  File "C:\\Users\\Andrea Bassi\\anaconda3\\envs\\scopefoundry\\lib\\site-packages\\pyqtgraph\\graphicsItems\\ImageItem.py", line 464, in getHistogram\n    bins = np.arange(mn, mx+1.01*step, step, dtype=np.int)\n', 'ValueError: arange: cannot compute length\n', '\nThe above exception was the direct cause of the following exception:\n\n', 'Traceback (most recent call last):\n', '  File "C:\\Users\\Andrea Bassi\\anaconda3\\envs\\scopefoundry\\lib\\site-packages\\ScopeFoundry\\measurement.py", line 273, in _on_display_update_timer\n    self.update_display()\n', '  File "C:\\Users\\Andrea Bassi\\OneDrive - Politecnico di Milano\\Documenti\\PythonProjects\\BassiScopeFoundryMicroscopes\\Microscopes\\CellRecongnitionMicroscope\\FakeCameraMeasurement.py", line 87, in update_display\n    self.imv.setImage((self.displayed_image), autoLevels=self.settings.autoLevels.val, autoRange=self.settings.autoRange.val)\n', '  File "C:\\Users\\Andrea Bassi\\anaconda3\\envs\\scopefoundry\\lib\\site-packages\\pyqtgraph\\imageview\\ImageView.py", line 301, in setImage\n    self.updateImage(autoHistogramRange=autoHistogramRange)\n', '  File "C:\\Users\\Andrea Bassi\\anaconda3\\envs\\scopefoundry\\lib\\site-packages\\pyqtgraph\\imageview\\ImageView.py", line 676, in updateImage\n    self.imageItem.updateImage(image)\n', '  File "C:\\Users\\Andrea Bassi\\anaconda3\\envs\\scopefoundry\\lib\\site-packages\\pyqtgraph\\graphicsItems\\ImageItem.py", line 342, in updateImage\n    return self.setImage(*args, **defaults)\n', '  File "C:\\Users\\Andrea Bassi\\anaconda3\\envs\\scopefoundry\\lib\\site-packages\\pyqtgraph\\graphicsItems\\ImageItem.py", line 283, in setImage\n    self.sigImageChanged.emit()\n', 'SystemError: <built-in method emit of PyQt5.QtCore.pyqtBoundSignal object at 0x000001C119A3BAD0> returned a result with an error set\n']
2020-07-23T13:21:36|ERROR|FakeCameraMeasurement|fake_camera_image Failed to update figure1: <built-in method emit of PyQt5.QtCore.pyqtBoundSignal object at 0x000001C1099EC490> returned a result with an error set. ['Traceback (most recent call last):\n', '  File "C:\\Users\\Andrea Bassi\\anaconda3\\envs\\scopefoundry\\lib\\site-packages\\pyqtgraph\\graphicsItems\\HistogramLUTItem.py", line 195, in imageChanged\n    h = self.imageItem().getHistogram()\n', '  File "C:\\Users\\Andrea Bassi\\anaconda3\\envs\\scopefoundry\\lib\\site-packages\\pyqtgraph\\graphicsItems\\ImageItem.py", line 464, in getHistogram\n    bins = np.arange(mn, mx+1.01*step, step, dtype=np.int)\n', 'ValueError: arange: cannot compute length\n', '\nThe above exception was the direct cause of the following exception:\n\n', 'Traceback (most recent call last):\n', '  File "C:\\Users\\Andrea Bassi\\anaconda3\\envs\\scopefoundry\\lib\\site-packages\\ScopeFoundry\\measurement.py", line 273, in _on_display_update_timer\n    self.update_display()\n', '  File "C:\\Users\\Andrea Bassi\\OneDrive - Politecnico di Milano\\Documenti\\PythonProjects\\BassiScopeFoundryMicroscopes\\Microscopes\\CellRecongnitionMicroscope\\FakeCameraMeasurement.py", line 87, in update_display\n    self.imv.setImage((self.displayed_image), autoLevels=self.settings.autoLevels.val, autoRange=self.settings.autoRange.val)\n', '  File "C:\\Users\\Andrea Bassi\\anaconda3\\envs\\scopefoundry\\lib\\site-packages\\pyqtgraph\\imageview\\ImageView.py", line 301, in setImage\n    self.updateImage(autoHistogramRange=autoHistogramRange)\n', '  File "C:\\Users\\Andrea Bassi\\anaconda3\\envs\\scopefoundry\\lib\\site-packages\\pyqtgraph\\imageview\\ImageView.py", line 676, in updateImage\n    self.imageItem.updateImage(image)\n', '  File "C:\\Users\\Andrea Bassi\\anaconda3\\envs\\scopefoundry\\lib\\site-packages\\pyqtgraph\\graphicsItems\\ImageItem.py", line 342, in updateImage\n    return self.setImage(*args, **defaults)\n', '  File "C:\\Users\\Andrea Bassi\\anaconda3\\envs\\scopefoundry\\lib\\site-packages\\pyqtgraph\\graphicsItems\\ImageItem.py", line 283, in setImage\n    self.sigImageChanged.emit()\n', 'SystemError: <built-in method emit of PyQt5.QtCore.pyqtBoundSignal object at 0x000001C1099EC490> returned a result with an error set\n']
2020-07-23T13:21:36|ERROR|FakeCameraMeasurement|fake_camera_image Failed to update figure1: <built-in method emit of PyQt5.QtCore.pyqtBoundSignal object at 0x000001C1177B4EE0> returned a result with an error set. ['Traceback (most recent call last):\n', '  File "C:\\Users\\Andrea Bassi\\anaconda3\\envs\\scopefoundry\\lib\\site-packages\\pyqtgraph\\graphicsItems\\HistogramLUTItem.py", line 195, in imageChanged\n    h = self.imageItem().getHistogram()\n', '  File "C:\\Users\\Andrea Bassi\\anaconda3\\envs\\scopefoundry\\lib\\site-packages\\pyqtgraph\\graphicsItems\\ImageItem.py", line 464, in getHistogram\n    bins = np.arange(mn, mx+1.01*step, step, dtype=np.int)\n', 'ValueError: arange: cannot compute length\n', '\nThe above exception was the direct cause of the following exception:\n\n', 'Traceback (most recent call last):\n', '  File "C:\\Users\\Andrea Bassi\\anaconda3\\envs\\scopefoundry\\lib\\site-packages\\ScopeFoundry\\measurement.py", line 273, in _on_display_update_timer\n    self.update_display()\n', '  File "C:\\Users\\Andrea Bassi\\OneDrive - Politecnico di Milano\\Documenti\\PythonProjects\\BassiScopeFoundryMicroscopes\\Microscopes\\CellRecongnitionMicroscope\\FakeCameraMeasurement.py", line 87, in update_display\n    self.imv.setImage((self.displayed_image), autoLevels=self.settings.autoLevels.val, autoRange=self.settings.autoRange.val)\n', '  File "C:\\Users\\Andrea Bassi\\anaconda3\\envs\\scopefoundry\\lib\\site-packages\\pyqtgraph\\imageview\\ImageView.py", line 301, in setImage\n    self.updateImage(autoHistogramRange=autoHistogramRange)\n', '  File "C:\\Users\\Andrea Bassi\\anaconda3\\envs\\scopefoundry\\lib\\site-packages\\pyqtgraph\\imageview\\ImageView.py", line 676, in updateImage\n    self.imageItem.updateImage(image)\n', '  File "C:\\Users\\Andrea Bassi\\anaconda3\\envs\\scopefoundry\\lib\\site-packages\\pyqtgraph\\graphicsItems\\ImageItem.py", line 342, in updateImage\n    return self.setImage(*args, **defaults)\n', '  File "C:\\Users\\Andrea Bassi\\anaconda3\\envs\\scopefoundry\\lib\\site-packages\\pyqtgraph\\graphicsItems\\ImageItem.py", line 283, in setImage\n    self.sigImageChanged.emit()\n', 'SystemError: <built-in method emit of PyQt5.QtCore.pyqtBoundSignal object at 0x000001C1177B4EE0> returned a result with an error set\n']
2020-07-23T13:21:36|ERROR|FakeCameraMeasurement|fake_camera_image Failed to update figure1: <built-in method emit of PyQt5.QtCore.pyqtBoundSignal object at 0x000001C1177B4EE0> returned a result with an error set. ['Traceback (most recent call last):\n', '  File "C:\\Users\\Andrea Bassi\\anaconda3\\envs\\scopefoundry\\lib\\site-packages\\pyqtgraph\\graphicsItems\\HistogramLUTItem.py", line 195, in imageChanged\n    h = self.imageItem().getHistogram()\n', '  File "C:\\Users\\Andrea Bassi\\anaconda3\\envs\\scopefoundry\\lib\\site-packages\\pyqtgraph\\graphicsItems\\ImageItem.py", line 464, in getHistogram\n    bins = np.arange(mn, mx+1.01*step, step, dtype=np.int)\n', 'ValueError: arange: cannot compute length\n', '\nThe above exception was the direct cause of the following exception:\n\n', 'Traceback (most recent call last):\n', '  File "C:\\Users\\Andrea Bassi\\anaconda3\\envs\\scopefoundry\\lib\\site-packages\\ScopeFoundry\\measurement.py", line 273, in _on_display_update_timer\n    self.update_display()\n', '  File "C:\\Users\\Andrea Bassi\\OneDrive - Politecnico di Milano\\Documenti\\PythonProjects\\BassiScopeFoundryMicroscopes\\Microscopes\\CellRecongnitionMicroscope\\FakeCameraMeasurement.py", line 87, in update_display\n    self.imv.setImage((self.displayed_image), autoLevels=self.settings.autoLevels.val, autoRange=self.settings.autoRange.val)\n', '  File "C:\\Users\\Andrea Bassi\\anaconda3\\envs\\scopefoundry\\lib\\site-packages\\pyqtgraph\\imageview\\ImageView.py", line 301, in setImage\n    self.updateImage(autoHistogramRange=autoHistogramRange)\n', '  File "C:\\Users\\Andrea Bassi\\anaconda3\\envs\\scopefoundry\\lib\\site-packages\\pyqtgraph\\imageview\\ImageView.py", line 676, in updateImage\n    self.imageItem.updateImage(image)\n', '  File "C:\\Users\\Andrea Bassi\\anaconda3\\envs\\scopefoundry\\lib\\site-packages\\pyqtgraph\\graphicsItems\\ImageItem.py", line 342, in updateImage\n    return self.setImage(*args, **defaults)\n', '  File "C:\\Users\\Andrea Bassi\\anaconda3\\envs\\scopefoundry\\lib\\site-packages\\pyqtgraph\\graphicsItems\\ImageItem.py", line 283, in setImage\n    self.sigImageChanged.emit()\n', 'SystemError: <built-in method emit of PyQt5.QtCore.pyqtBoundSignal object at 0x000001C1177B4EE0> returned a result with an error set\n']
2020-07-23T13:21:36|ERROR|FakeCameraMeasurement|fake_camera_image Failed to update figure1: <built-in method emit of PyQt5.QtCore.pyqtBoundSignal object at 0x000001C1099EC490> returned a result with an error set. ['Traceback (most recent call last):\n', '  File "C:\\Users\\Andrea Bassi\\anaconda3\\envs\\scopefoundry\\lib\\site-packages\\pyqtgraph\\graphicsItems\\HistogramLUTItem.py", line 195, in imageChanged\n    h = self.imageItem().getHistogram()\n', '  File "C:\\Users\\Andrea Bassi\\anaconda3\\envs\\scopefoundry\\lib\\site-packages\\pyqtgraph\\graphicsItems\\ImageItem.py", line 464, in getHistogram\n    bins = np.arange(mn, mx+1.01*step, step, dtype=np.int)\n', 'ValueError: arange: cannot compute length\n', '\nThe above exception was the direct cause of the following exception:\n\n', 'Traceback (most recent call last):\n', '  File "C:\\Users\\Andrea Bassi\\anaconda3\\envs\\scopefoundry\\lib\\site-packages\\ScopeFoundry\\measurement.py", line 273, in _on_display_update_timer\n    self.update_display()\n', '  File "C:\\Users\\Andrea Bassi\\OneDrive - Politecnico di Milano\\Documenti\\PythonProjects\\BassiScopeFoundryMicroscopes\\Microscopes\\CellRecongnitionMicroscope\\FakeCameraMeasurement.py", line 87, in update_display\n    self.imv.setImage((self.displayed_image), autoLevels=self.settings.autoLevels.val, autoRange=self.settings.autoRange.val)\n', '  File "C:\\Users\\Andrea Bassi\\anaconda3\\envs\\scopefoundry\\lib\\site-packages\\pyqtgraph\\imageview\\ImageView.py", line 301, in setImage\n    self.updateImage(autoHistogramRange=autoHistogramRange)\n', '  File "C:\\Users\\Andrea Bassi\\anaconda3\\envs\\scopefoundry\\lib\\site-packages\\pyqtgraph\\imageview\\ImageView.py", line 676, in updateImage\n    self.imageItem.updateImage(image)\n', '  File "C:\\Users\\Andrea Bassi\\anaconda3\\envs\\scopefoundry\\lib\\site-packages\\pyqtgraph\\graphicsItems\\ImageItem.py", line 342, in updateImage\n    return self.setImage(*args, **defaults)\n', '  File "C:\\Users\\Andrea Bassi\\anaconda3\\envs\\scopefoundry\\lib\\site-packages\\pyqtgraph\\graphicsItems\\ImageItem.py", line 283, in setImage\n    self.sigImageChanged.emit()\n', 'SystemError: <built-in method emit of PyQt5.QtCore.pyqtBoundSignal object at 0x000001C1099EC490> returned a result with an error set\n']
2020-07-23T13:21:36|ERROR|FakeCameraMeasurement|fake_camera_image Failed to update figure1: <built-in method emit of PyQt5.QtCore.pyqtBoundSignal object at 0x000001C1099EC490> returned a result with an error set. ['Traceback (most recent call last):\n', '  File "C:\\Users\\Andrea Bassi\\anaconda3\\envs\\scopefoundry\\lib\\site-packages\\pyqtgraph\\graphicsItems\\HistogramLUTItem.py", line 195, in imageChanged\n    h = self.imageItem().getHistogram()\n', '  File "C:\\Users\\Andrea Bassi\\anaconda3\\envs\\scopefoundry\\lib\\site-packages\\pyqtgraph\\graphicsItems\\ImageItem.py", line 464, in getHistogram\n    bins = np.arange(mn, mx+1.01*step, step, dtype=np.int)\n', 'ValueError: arange: cannot compute length\n', '\nThe above exception was the direct cause of the following exception:\n\n', 'Traceback (most recent call last):\n', '  File "C:\\Users\\Andrea Bassi\\anaconda3\\envs\\scopefoundry\\lib\\site-packages\\ScopeFoundry\\measurement.py", line 273, in _on_display_update_timer\n    self.update_display()\n', '  File "C:\\Users\\Andrea Bassi\\OneDrive - Politecnico di Milano\\Documenti\\PythonProjects\\BassiScopeFoundryMicroscopes\\Microscopes\\CellRecongnitionMicroscope\\FakeCameraMeasurement.py", line 87, in update_display\n    self.imv.setImage((self.displayed_image), autoLevels=self.settings.autoLevels.val, autoRange=self.settings.autoRange.val)\n', '  File "C:\\Users\\Andrea Bassi\\anaconda3\\envs\\scopefoundry\\lib\\site-packages\\pyqtgraph\\imageview\\ImageView.py", line 301, in setImage\n    self.updateImage(autoHistogramRange=autoHistogramRange)\n', '  File "C:\\Users\\Andrea Bassi\\anaconda3\\envs\\scopefoundry\\lib\\site-packages\\pyqtgraph\\imageview\\ImageView.py", line 676, in updateImage\n    self.imageItem.updateImage(image)\n', '  File "C:\\Users\\Andrea Bassi\\anaconda3\\envs\\scopefoundry\\lib\\site-packages\\pyqtgraph\\graphicsItems\\ImageItem.py", line 342, in updateImage\n    return self.setImage(*args, **defaults)\n', '  File "C:\\Users\\Andrea Bassi\\anaconda3\\envs\\scopefoundry\\lib\\site-packages\\pyqtgraph\\graphicsItems\\ImageItem.py", line 283, in setImage\n    self.sigImageChanged.emit()\n', 'SystemError: <built-in method emit of PyQt5.QtCore.pyqtBoundSignal object at 0x000001C1099EC490> returned a result with an error set\n']
2020-07-23T13:21:36|ERROR|FakeCameraMeasurement|fake_camera_image Failed to update figure1: <built-in method emit of PyQt5.QtCore.pyqtBoundSignal object at 0x000001C1099EC490> returned a result with an error set. ['Traceback (most recent call last):\n', '  File "C:\\Users\\Andrea Bassi\\anaconda3\\envs\\scopefoundry\\lib\\site-packages\\pyqtgraph\\graphicsItems\\HistogramLUTItem.py", line 195, in imageChanged\n    h = self.imageItem().getHistogram()\n', '  File "C:\\Users\\Andrea Bassi\\anaconda3\\envs\\scopefoundry\\lib\\site-packages\\pyqtgraph\\graphicsItems\\ImageItem.py", line 464, in getHistogram\n    bins = np.arange(mn, mx+1.01*step, step, dtype=np.int)\n', 'ValueError: arange: cannot compute length\n', '\nThe above exception was the direct cause of the following exception:\n\n', 'Traceback (most recent call last):\n', '  File "C:\\Users\\Andrea Bassi\\anaconda3\\envs\\scopefoundry\\lib\\site-packages\\ScopeFoundry\\measurement.py", line 273, in _on_display_update_timer\n    self.update_display()\n', '  File "C:\\Users\\Andrea Bassi\\OneDrive - Politecnico di Milano\\Documenti\\PythonProjects\\BassiScopeFoundryMicroscopes\\Microscopes\\CellRecongnitionMicroscope\\FakeCameraMeasurement.py", line 87, in update_display\n    self.imv.setImage((self.displayed_image), autoLevels=self.settings.autoLevels.val, autoRange=self.settings.autoRange.val)\n', '  File "C:\\Users\\Andrea Bassi\\anaconda3\\envs\\scopefoundry\\lib\\site-packages\\pyqtgraph\\imageview\\ImageView.py", line 301, in setImage\n    self.updateImage(autoHistogramRange=autoHistogramRange)\n', '  File "C:\\Users\\Andrea Bassi\\anaconda3\\envs\\scopefoundry\\lib\\site-packages\\pyqtgraph\\imageview\\ImageView.py", line 676, in updateImage\n    self.imageItem.updateImage(image)\n', '  File "C:\\Users\\Andrea Bassi\\anaconda3\\envs\\scopefoundry\\lib\\site-packages\\pyqtgraph\\graphicsItems\\ImageItem.py", line 342, in updateImage\n    return self.setImage(*args, **defaults)\n', '  File "C:\\Users\\Andrea Bassi\\anaconda3\\envs\\scopefoundry\\lib\\site-packages\\pyqtgraph\\graphicsItems\\ImageItem.py", line 283, in setImage\n    self.sigImageChanged.emit()\n', 'SystemError: <built-in method emit of PyQt5.QtCore.pyqtBoundSignal object at 0x000001C1099EC490> returned a result with an error set\n']
2020-07-23T13:21:36|ERROR|FakeCameraMeasurement|fake_camera_image Failed to update figure1: <built-in method emit of PyQt5.QtCore.pyqtBoundSignal object at 0x000001C1099EC490> returned a result with an error set. ['Traceback (most recent call last):\n', '  File "C:\\Users\\Andrea Bassi\\anaconda3\\envs\\scopefoundry\\lib\\site-packages\\pyqtgraph\\graphicsItems\\HistogramLUTItem.py", line 195, in imageChanged\n    h = self.imageItem().getHistogram()\n', '  File "C:\\Users\\Andrea Bassi\\anaconda3\\envs\\scopefoundry\\lib\\site-packages\\pyqtgraph\\graphicsItems\\ImageItem.py", line 464, in getHistogram\n    bins = np.arange(mn, mx+1.01*step, step, dtype=np.int)\n', 'ValueError: arange: cannot compute length\n', '\nThe above exception was the direct cause of the following exception:\n\n', 'Traceback (most recent call last):\n', '  File "C:\\Users\\Andrea Bassi\\anaconda3\\envs\\scopefoundry\\lib\\site-packages\\ScopeFoundry\\measurement.py", line 273, in _on_display_update_timer\n    self.update_display()\n', '  File "C:\\Users\\Andrea Bassi\\OneDrive - Politecnico di Milano\\Documenti\\PythonProjects\\BassiScopeFoundryMicroscopes\\Microscopes\\CellRecongnitionMicroscope\\FakeCameraMeasurement.py", line 87, in update_display\n    self.imv.setImage((self.displayed_image), autoLevels=self.settings.autoLevels.val, autoRange=self.settings.autoRange.val)\n', '  File "C:\\Users\\Andrea Bassi\\anaconda3\\envs\\scopefoundry\\lib\\site-packages\\pyqtgraph\\imageview\\ImageView.py", line 301, in setImage\n    self.updateImage(autoHistogramRange=autoHistogramRange)\n', '  File "C:\\Users\\Andrea Bassi\\anaconda3\\envs\\scopefoundry\\lib\\site-packages\\pyqtgraph\\imageview\\ImageView.py", line 676, in updateImage\n    self.imageItem.updateImage(image)\n', '  File "C:\\Users\\Andrea Bassi\\anaconda3\\envs\\scopefoundry\\lib\\site-packages\\pyqtgraph\\graphicsItems\\ImageItem.py", line 342, in updateImage\n    return self.setImage(*args, **defaults)\n', '  File "C:\\Users\\Andrea Bassi\\anaconda3\\envs\\scopefoundry\\lib\\site-packages\\pyqtgraph\\graphicsItems\\ImageItem.py", line 283, in setImage\n    self.sigImageChanged.emit()\n', 'SystemError: <built-in method emit of PyQt5.QtCore.pyqtBoundSignal object at 0x000001C1099EC490> returned a result with an error set\n']
2020-07-23T13:21:36|ERROR|FakeCameraMeasurement|fake_camera_image Failed to update figure1: <built-in method emit of PyQt5.QtCore.pyqtBoundSignal object at 0x000001C1177B4EE0> returned a result with an error set. ['Traceback (most recent call last):\n', '  File "C:\\Users\\Andrea Bassi\\anaconda3\\envs\\scopefoundry\\lib\\site-packages\\pyqtgraph\\graphicsItems\\HistogramLUTItem.py", line 195, in imageChanged\n    h = self.imageItem().getHistogram()\n', '  File "C:\\Users\\Andrea Bassi\\anaconda3\\envs\\scopefoundry\\lib\\site-packages\\pyqtgraph\\graphicsItems\\ImageItem.py", line 464, in getHistogram\n    bins = np.arange(mn, mx+1.01*step, step, dtype=np.int)\n', 'ValueError: arange: cannot compute length\n', '\nThe above exception was the direct cause of the following exception:\n\n', 'Traceback (most recent call last):\n', '  File "C:\\Users\\Andrea Bassi\\anaconda3\\envs\\scopefoundry\\lib\\site-packages\\ScopeFoundry\\measurement.py", line 273, in _on_display_update_timer\n    self.update_display()\n', '  File "C:\\Users\\Andrea Bassi\\OneDrive - Politecnico di Milano\\Documenti\\PythonProjects\\BassiScopeFoundryMicroscopes\\Microscopes\\CellRecongnitionMicroscope\\FakeCameraMeasurement.py", line 87, in update_display\n    self.imv.setImage((self.displayed_image), autoLevels=self.settings.autoLevels.val, autoRange=self.settings.autoRange.val)\n', '  File "C:\\Users\\Andrea Bassi\\anaconda3\\envs\\scopefoundry\\lib\\site-packages\\pyqtgraph\\imageview\\ImageView.py", line 301, in setImage\n    self.updateImage(autoHistogramRange=autoHistogramRange)\n', '  File "C:\\Users\\Andrea Bassi\\anaconda3\\envs\\scopefoundry\\lib\\site-packages\\pyqtgraph\\imageview\\ImageView.py", line 676, in updateImage\n    self.imageItem.updateImage(image)\n', '  File "C:\\Users\\Andrea Bassi\\anaconda3\\envs\\scopefoundry\\lib\\site-packages\\pyqtgraph\\graphicsItems\\ImageItem.py", line 342, in updateImage\n    return self.setImage(*args, **defaults)\n', '  File "C:\\Users\\Andrea Bassi\\anaconda3\\envs\\scopefoundry\\lib\\site-packages\\pyqtgraph\\graphicsItems\\ImageItem.py", line 283, in setImage\n    self.sigImageChanged.emit()\n', 'SystemError: <built-in method emit of PyQt5.QtCore.pyqtBoundSignal object at 0x000001C1177B4EE0> returned a result with an error set\n']
2020-07-23T13:21:36|ERROR|FakeCameraMeasurement|fake_camera_image Failed to update figure1: <built-in method emit of PyQt5.QtCore.pyqtBoundSignal object at 0x000001C1177B4EE0> returned a result with an error set. ['Traceback (most recent call last):\n', '  File "C:\\Users\\Andrea Bassi\\anaconda3\\envs\\scopefoundry\\lib\\site-packages\\pyqtgraph\\graphicsItems\\HistogramLUTItem.py", line 195, in imageChanged\n    h = self.imageItem().getHistogram()\n', '  File "C:\\Users\\Andrea Bassi\\anaconda3\\envs\\scopefoundry\\lib\\site-packages\\pyqtgraph\\graphicsItems\\ImageItem.py", line 464, in getHistogram\n    bins = np.arange(mn, mx+1.01*step, step, dtype=np.int)\n', 'ValueError: arange: cannot compute length\n', '\nThe above exception was the direct cause of the following exception:\n\n', 'Traceback (most recent call last):\n', '  File "C:\\Users\\Andrea Bassi\\anaconda3\\envs\\scopefoundry\\lib\\site-packages\\ScopeFoundry\\measurement.py", line 273, in _on_display_update_timer\n    self.update_display()\n', '  File "C:\\Users\\Andrea Bassi\\OneDrive - Politecnico di Milano\\Documenti\\PythonProjects\\BassiScopeFoundryMicroscopes\\Microscopes\\CellRecongnitionMicroscope\\FakeCameraMeasurement.py", line 87, in update_display\n    self.imv.setImage((self.displayed_image), autoLevels=self.settings.autoLevels.val, autoRange=self.settings.autoRange.val)\n', '  File "C:\\Users\\Andrea Bassi\\anaconda3\\envs\\scopefoundry\\lib\\site-packages\\pyqtgraph\\imageview\\ImageView.py", line 301, in setImage\n    self.updateImage(autoHistogramRange=autoHistogramRange)\n', '  File "C:\\Users\\Andrea Bassi\\anaconda3\\envs\\scopefoundry\\lib\\site-packages\\pyqtgraph\\imageview\\ImageView.py", line 676, in updateImage\n    self.imageItem.updateImage(image)\n', '  File "C:\\Users\\Andrea Bassi\\anaconda3\\envs\\scopefoundry\\lib\\site-packages\\pyqtgraph\\graphicsItems\\ImageItem.py", line 342, in updateImage\n    return self.setImage(*args, **defaults)\n', '  File "C:\\Users\\Andrea Bassi\\anaconda3\\envs\\scopefoundry\\lib\\site-packages\\pyqtgraph\\graphicsItems\\ImageItem.py", line 283, in setImage\n    self.sigImageChanged.emit()\n', 'SystemError: <built-in method emit of PyQt5.QtCore.pyqtBoundSignal object at 0x000001C1177B4EE0> returned a result with an error set\n']
2020-07-23T13:21:36|ERROR|FakeCameraMeasurement|fake_camera_image Failed to update figure1: <built-in method emit of PyQt5.QtCore.pyqtBoundSignal object at 0x000001C1177B4EE0> returned a result with an error set. ['Traceback (most recent call last):\n', '  File "C:\\Users\\Andrea Bassi\\anaconda3\\envs\\scopefoundry\\lib\\site-packages\\pyqtgraph\\graphicsItems\\HistogramLUTItem.py", line 195, in imageChanged\n    h = self.imageItem().getHistogram()\n', '  File "C:\\Users\\Andrea Bassi\\anaconda3\\envs\\scopefoundry\\lib\\site-packages\\pyqtgraph\\graphicsItems\\ImageItem.py", line 464, in getHistogram\n    bins = np.arange(mn, mx+1.01*step, step, dtype=np.int)\n', 'ValueError: arange: cannot compute length\n', '\nThe above exception was the direct cause of the following exception:\n\n', 'Traceback (most recent call last):\n', '  File "C:\\Users\\Andrea Bassi\\anaconda3\\envs\\scopefoundry\\lib\\site-packages\\ScopeFoundry\\measurement.py", line 273, in _on_display_update_timer\n    self.update_display()\n', '  File "C:\\Users\\Andrea Bassi\\OneDrive - Politecnico di Milano\\Documenti\\PythonProjects\\BassiScopeFoundryMicroscopes\\Microscopes\\CellRecongnitionMicroscope\\FakeCameraMeasurement.py", line 87, in update_display\n    self.imv.setImage((self.displayed_image), autoLevels=self.settings.autoLevels.val, autoRange=self.settings.autoRange.val)\n', '  File "C:\\Users\\Andrea Bassi\\anaconda3\\envs\\scopefoundry\\lib\\site-packages\\pyqtgraph\\imageview\\ImageView.py", line 301, in setImage\n    self.updateImage(autoHistogramRange=autoHistogramRange)\n', '  File "C:\\Users\\Andrea Bassi\\anaconda3\\envs\\scopefoundry\\lib\\site-packages\\pyqtgraph\\imageview\\ImageView.py", line 676, in updateImage\n    self.imageItem.updateImage(image)\n', '  File "C:\\Users\\Andrea Bassi\\anaconda3\\envs\\scopefoundry\\lib\\site-packages\\pyqtgraph\\graphicsItems\\ImageItem.py", line 342, in updateImage\n    return self.setImage(*args, **defaults)\n', '  File "C:\\Users\\Andrea Bassi\\anaconda3\\envs\\scopefoundry\\lib\\site-packages\\pyqtgraph\\graphicsItems\\ImageItem.py", line 283, in setImage\n    self.sigImageChanged.emit()\n', 'SystemError: <built-in method emit of PyQt5.QtCore.pyqtBoundSignal object at 0x000001C1177B4EE0> returned a result with an error set\n']
2020-07-23T13:21:38|ERROR|FakeCameraMeasurement|fake_camera_image Failed to update figure1: <built-in method emit of PyQt5.QtCore.pyqtBoundSignal object at 0x000001C1099EC490> returned a result with an error set. ['Traceback (most recent call last):\n', '  File "C:\\Users\\Andrea Bassi\\anaconda3\\envs\\scopefoundry\\lib\\site-packages\\pyqtgraph\\graphicsItems\\HistogramLUTItem.py", line 195, in imageChanged\n    h = self.imageItem().getHistogram()\n', '  File "C:\\Users\\Andrea Bassi\\anaconda3\\envs\\scopefoundry\\lib\\site-packages\\pyqtgraph\\graphicsItems\\ImageItem.py", line 464, in getHistogram\n    bins = np.arange(mn, mx+1.01*step, step, dtype=np.int)\n', 'ValueError: arange: cannot compute length\n', '\nThe above exception was the direct cause of the following exception:\n\n', 'Traceback (most recent call last):\n', '  File "C:\\Users\\Andrea Bassi\\anaconda3\\envs\\scopefoundry\\lib\\site-packages\\ScopeFoundry\\measurement.py", line 273, in _on_display_update_timer\n    self.update_display()\n', '  File "C:\\Users\\Andrea Bassi\\OneDrive - Politecnico di Milano\\Documenti\\PythonProjects\\BassiScopeFoundryMicroscopes\\Microscopes\\CellRecongnitionMicroscope\\FakeCameraMeasurement.py", line 87, in update_display\n    self.imv.setImage((self.displayed_image), autoLevels=self.settings.autoLevels.val, autoRange=self.settings.autoRange.val)\n', '  File "C:\\Users\\Andrea Bassi\\anaconda3\\envs\\scopefoundry\\lib\\site-packages\\pyqtgraph\\imageview\\ImageView.py", line 301, in setImage\n    self.updateImage(autoHistogramRange=autoHistogramRange)\n', '  File "C:\\Users\\Andrea Bassi\\anaconda3\\envs\\scopefoundry\\lib\\site-packages\\pyqtgraph\\imageview\\ImageView.py", line 676, in updateImage\n    self.imageItem.updateImage(image)\n', '  File "C:\\Users\\Andrea Bassi\\anaconda3\\envs\\scopefoundry\\lib\\site-packages\\pyqtgraph\\graphicsItems\\ImageItem.py", line 342, in updateImage\n    return self.setImage(*args, **defaults)\n', '  File "C:\\Users\\Andrea Bassi\\anaconda3\\envs\\scopefoundry\\lib\\site-packages\\pyqtgraph\\graphicsItems\\ImageItem.py", line 283, in setImage\n    self.sigImageChanged.emit()\n', 'SystemError: <built-in method emit of PyQt5.QtCore.pyqtBoundSignal object at 0x000001C1099EC490> returned a result with an error set\n']
2020-07-23T13:21:38|ERROR|FakeCameraMeasurement|fake_camera_image Failed to update figure1: <built-in method emit of PyQt5.QtCore.pyqtBoundSignal object at 0x000001C1099EC490> returned a result with an error set. ['Traceback (most recent call last):\n', '  File "C:\\Users\\Andrea Bassi\\anaconda3\\envs\\scopefoundry\\lib\\site-packages\\pyqtgraph\\graphicsItems\\HistogramLUTItem.py", line 195, in imageChanged\n    h = self.imageItem().getHistogram()\n', '  File "C:\\Users\\Andrea Bassi\\anaconda3\\envs\\scopefoundry\\lib\\site-packages\\pyqtgraph\\graphicsItems\\ImageItem.py", line 464, in getHistogram\n    bins = np.arange(mn, mx+1.01*step, step, dtype=np.int)\n', 'ValueError: arange: cannot compute length\n', '\nThe above exception was the direct cause of the following exception:\n\n', 'Traceback (most recent call last):\n', '  File "C:\\Users\\Andrea Bassi\\anaconda3\\envs\\scopefoundry\\lib\\site-packages\\ScopeFoundry\\measurement.py", line 273, in _on_display_update_timer\n    self.update_display()\n', '  File "C:\\Users\\Andrea Bassi\\OneDrive - Politecnico di Milano\\Documenti\\PythonProjects\\BassiScopeFoundryMicroscopes\\Microscopes\\CellRecongnitionMicroscope\\FakeCameraMeasurement.py", line 87, in update_display\n    self.imv.setImage((self.displayed_image), autoLevels=self.settings.autoLevels.val, autoRange=self.settings.autoRange.val)\n', '  File "C:\\Users\\Andrea Bassi\\anaconda3\\envs\\scopefoundry\\lib\\site-packages\\pyqtgraph\\imageview\\ImageView.py", line 301, in setImage\n    self.updateImage(autoHistogramRange=autoHistogramRange)\n', '  File "C:\\Users\\Andrea Bassi\\anaconda3\\envs\\scopefoundry\\lib\\site-packages\\pyqtgraph\\imageview\\ImageView.py", line 676, in updateImage\n    self.imageItem.updateImage(image)\n', '  File "C:\\Users\\Andrea Bassi\\anaconda3\\envs\\scopefoundry\\lib\\site-packages\\pyqtgraph\\graphicsItems\\ImageItem.py", line 342, in updateImage\n    return self.setImage(*args, **defaults)\n', '  File "C:\\Users\\Andrea Bassi\\anaconda3\\envs\\scopefoundry\\lib\\site-packages\\pyqtgraph\\graphicsItems\\ImageItem.py", line 283, in setImage\n    self.sigImageChanged.emit()\n', 'SystemError: <built-in method emit of PyQt5.QtCore.pyqtBoundSignal object at 0x000001C1099EC490> returned a result with an error set\n']
2020-07-23T13:21:38|ERROR|FakeCameraMeasurement|fake_camera_image Failed to update figure1: <built-in method emit of PyQt5.QtCore.pyqtBoundSignal object at 0x000001C1099EC490> returned a result with an error set. ['Traceback (most recent call last):\n', '  File "C:\\Users\\Andrea Bassi\\anaconda3\\envs\\scopefoundry\\lib\\site-packages\\pyqtgraph\\graphicsItems\\HistogramLUTItem.py", line 195, in imageChanged\n    h = self.imageItem().getHistogram()\n', '  File "C:\\Users\\Andrea Bassi\\anaconda3\\envs\\scopefoundry\\lib\\site-packages\\pyqtgraph\\graphicsItems\\ImageItem.py", line 464, in getHistogram\n    bins = np.arange(mn, mx+1.01*step, step, dtype=np.int)\n', 'ValueError: arange: cannot compute length\n', '\nThe above exception was the direct cause of the following exception:\n\n', 'Traceback (most recent call last):\n', '  File "C:\\Users\\Andrea Bassi\\anaconda3\\envs\\scopefoundry\\lib\\site-packages\\ScopeFoundry\\measurement.py", line 273, in _on_display_update_timer\n    self.update_display()\n', '  File "C:\\Users\\Andrea Bassi\\OneDrive - Politecnico di Milano\\Documenti\\PythonProjects\\BassiScopeFoundryMicroscopes\\Microscopes\\CellRecongnitionMicroscope\\FakeCameraMeasurement.py", line 87, in update_display\n    self.imv.setImage((self.displayed_image), autoLevels=self.settings.autoLevels.val, autoRange=self.settings.autoRange.val)\n', '  File "C:\\Users\\Andrea Bassi\\anaconda3\\envs\\scopefoundry\\lib\\site-packages\\pyqtgraph\\imageview\\ImageView.py", line 301, in setImage\n    self.updateImage(autoHistogramRange=autoHistogramRange)\n', '  File "C:\\Users\\Andrea Bassi\\anaconda3\\envs\\scopefoundry\\lib\\site-packages\\pyqtgraph\\imageview\\ImageView.py", line 676, in updateImage\n    self.imageItem.updateImage(image)\n', '  File "C:\\Users\\Andrea Bassi\\anaconda3\\envs\\scopefoundry\\lib\\site-packages\\pyqtgraph\\graphicsItems\\ImageItem.py", line 342, in updateImage\n    return self.setImage(*args, **defaults)\n', '  File "C:\\Users\\Andrea Bassi\\anaconda3\\envs\\scopefoundry\\lib\\site-packages\\pyqtgraph\\graphicsItems\\ImageItem.py", line 283, in setImage\n    self.sigImageChanged.emit()\n', 'SystemError: <built-in method emit of PyQt5.QtCore.pyqtBoundSignal object at 0x000001C1099EC490> returned a result with an error set\n']
2020-07-23T13:21:38|ERROR|FakeCameraMeasurement|fake_camera_image Failed to update figure1: <built-in method emit of PyQt5.QtCore.pyqtBoundSignal object at 0x000001C1099EC490> returned a result with an error set. ['Traceback (most recent call last):\n', '  File "C:\\Users\\Andrea Bassi\\anaconda3\\envs\\scopefoundry\\lib\\site-packages\\pyqtgraph\\graphicsItems\\HistogramLUTItem.py", line 195, in imageChanged\n    h = self.imageItem().getHistogram()\n', '  File "C:\\Users\\Andrea Bassi\\anaconda3\\envs\\scopefoundry\\lib\\site-packages\\pyqtgraph\\graphicsItems\\ImageItem.py", line 464, in getHistogram\n    bins = np.arange(mn, mx+1.01*step, step, dtype=np.int)\n', 'ValueError: arange: cannot compute length\n', '\nThe above exception was the direct cause of the following exception:\n\n', 'Traceback (most recent call last):\n', '  File "C:\\Users\\Andrea Bassi\\anaconda3\\envs\\scopefoundry\\lib\\site-packages\\ScopeFoundry\\measurement.py", line 273, in _on_display_update_timer\n    self.update_display()\n', '  File "C:\\Users\\Andrea Bassi\\OneDrive - Politecnico di Milano\\Documenti\\PythonProjects\\BassiScopeFoundryMicroscopes\\Microscopes\\CellRecongnitionMicroscope\\FakeCameraMeasurement.py", line 87, in update_display\n    self.imv.setImage((self.displayed_image), autoLevels=self.settings.autoLevels.val, autoRange=self.settings.autoRange.val)\n', '  File "C:\\Users\\Andrea Bassi\\anaconda3\\envs\\scopefoundry\\lib\\site-packages\\pyqtgraph\\imageview\\ImageView.py", line 301, in setImage\n    self.updateImage(autoHistogramRange=autoHistogramRange)\n', '  File "C:\\Users\\Andrea Bassi\\anaconda3\\envs\\scopefoundry\\lib\\site-packages\\pyqtgraph\\imageview\\ImageView.py", line 676, in updateImage\n    self.imageItem.updateImage(image)\n', '  File "C:\\Users\\Andrea Bassi\\anaconda3\\envs\\scopefoundry\\lib\\site-packages\\pyqtgraph\\graphicsItems\\ImageItem.py", line 342, in updateImage\n    return self.setImage(*args, **defaults)\n', '  File "C:\\Users\\Andrea Bassi\\anaconda3\\envs\\scopefoundry\\lib\\site-packages\\pyqtgraph\\graphicsItems\\ImageItem.py", line 283, in setImage\n    self.sigImageChanged.emit()\n', 'SystemError: <built-in method emit of PyQt5.QtCore.pyqtBoundSignal object at 0x000001C1099EC490> returned a result with an error set\n']
2020-07-23T13:21:38|ERROR|FakeCameraMeasurement|fake_camera_image Failed to update figure1: <built-in method emit of PyQt5.QtCore.pyqtBoundSignal object at 0x000001C1099EC490> returned a result with an error set. ['Traceback (most recent call last):\n', '  File "C:\\Users\\Andrea Bassi\\anaconda3\\envs\\scopefoundry\\lib\\site-packages\\pyqtgraph\\graphicsItems\\HistogramLUTItem.py", line 195, in imageChanged\n    h = self.imageItem().getHistogram()\n', '  File "C:\\Users\\Andrea Bassi\\anaconda3\\envs\\scopefoundry\\lib\\site-packages\\pyqtgraph\\graphicsItems\\ImageItem.py", line 464, in getHistogram\n    bins = np.arange(mn, mx+1.01*step, step, dtype=np.int)\n', 'ValueError: arange: cannot compute length\n', '\nThe above exception was the direct cause of the following exception:\n\n', 'Traceback (most recent call last):\n', '  File "C:\\Users\\Andrea Bassi\\anaconda3\\envs\\scopefoundry\\lib\\site-packages\\ScopeFoundry\\measurement.py", line 273, in _on_display_update_timer\n    self.update_display()\n', '  File "C:\\Users\\Andrea Bassi\\OneDrive - Politecnico di Milano\\Documenti\\PythonProjects\\BassiScopeFoundryMicroscopes\\Microscopes\\CellRecongnitionMicroscope\\FakeCameraMeasurement.py", line 87, in update_display\n    self.imv.setImage((self.displayed_image), autoLevels=self.settings.autoLevels.val, autoRange=self.settings.autoRange.val)\n', '  File "C:\\Users\\Andrea Bassi\\anaconda3\\envs\\scopefoundry\\lib\\site-packages\\pyqtgraph\\imageview\\ImageView.py", line 301, in setImage\n    self.updateImage(autoHistogramRange=autoHistogramRange)\n', '  File "C:\\Users\\Andrea Bassi\\anaconda3\\envs\\scopefoundry\\lib\\site-packages\\pyqtgraph\\imageview\\ImageView.py", line 676, in updateImage\n    self.imageItem.updateImage(image)\n', '  File "C:\\Users\\Andrea Bassi\\anaconda3\\envs\\scopefoundry\\lib\\site-packages\\pyqtgraph\\graphicsItems\\ImageItem.py", line 342, in updateImage\n    return self.setImage(*args, **defaults)\n', '  File "C:\\Users\\Andrea Bassi\\anaconda3\\envs\\scopefoundry\\lib\\site-packages\\pyqtgraph\\graphicsItems\\ImageItem.py", line 283, in setImage\n    self.sigImageChanged.emit()\n', 'SystemError: <built-in method emit of PyQt5.QtCore.pyqtBoundSignal object at 0x000001C1099EC490> returned a result with an error set\n']
2020-07-23T13:21:38|ERROR|FakeCameraMeasurement|fake_camera_image Failed to update figure1: <built-in method emit of PyQt5.QtCore.pyqtBoundSignal object at 0x000001C1099EC490> returned a result with an error set. ['Traceback (most recent call last):\n', '  File "C:\\Users\\Andrea Bassi\\anaconda3\\envs\\scopefoundry\\lib\\site-packages\\pyqtgraph\\graphicsItems\\HistogramLUTItem.py", line 195, in imageChanged\n    h = self.imageItem().getHistogram()\n', '  File "C:\\Users\\Andrea Bassi\\anaconda3\\envs\\scopefoundry\\lib\\site-packages\\pyqtgraph\\graphicsItems\\ImageItem.py", line 464, in getHistogram\n    bins = np.arange(mn, mx+1.01*step, step, dtype=np.int)\n', 'ValueError: arange: cannot compute length\n', '\nThe above exception was the direct cause of the following exception:\n\n', 'Traceback (most recent call last):\n', '  File "C:\\Users\\Andrea Bassi\\anaconda3\\envs\\scopefoundry\\lib\\site-packages\\ScopeFoundry\\measurement.py", line 273, in _on_display_update_timer\n    self.update_display()\n', '  File "C:\\Users\\Andrea Bassi\\OneDrive - Politecnico di Milano\\Documenti\\PythonProjects\\BassiScopeFoundryMicroscopes\\Microscopes\\CellRecongnitionMicroscope\\FakeCameraMeasurement.py", line 87, in update_display\n    self.imv.setImage((self.displayed_image), autoLevels=self.settings.autoLevels.val, autoRange=self.settings.autoRange.val)\n', '  File "C:\\Users\\Andrea Bassi\\anaconda3\\envs\\scopefoundry\\lib\\site-packages\\pyqtgraph\\imageview\\ImageView.py", line 301, in setImage\n    self.updateImage(autoHistogramRange=autoHistogramRange)\n', '  File "C:\\Users\\Andrea Bassi\\anaconda3\\envs\\scopefoundry\\lib\\site-packages\\pyqtgraph\\imageview\\ImageView.py", line 676, in updateImage\n    self.imageItem.updateImage(image)\n', '  File "C:\\Users\\Andrea Bassi\\anaconda3\\envs\\scopefoundry\\lib\\site-packages\\pyqtgraph\\graphicsItems\\ImageItem.py", line 342, in updateImage\n    return self.setImage(*args, **defaults)\n', '  File "C:\\Users\\Andrea Bassi\\anaconda3\\envs\\scopefoundry\\lib\\site-packages\\pyqtgraph\\graphicsItems\\ImageItem.py", line 283, in setImage\n    self.sigImageChanged.emit()\n', 'SystemError: <built-in method emit of PyQt5.QtCore.pyqtBoundSignal object at 0x000001C1099EC490> returned a result with an error set\n']
2020-07-23T13:21:38|ERROR|FakeCameraMeasurement|fake_camera_image Failed to update figure1: <built-in method emit of PyQt5.QtCore.pyqtBoundSignal object at 0x000001C1099EC490> returned a result with an error set. ['Traceback (most recent call last):\n', '  File "C:\\Users\\Andrea Bassi\\anaconda3\\envs\\scopefoundry\\lib\\site-packages\\pyqtgraph\\graphicsItems\\HistogramLUTItem.py", line 195, in imageChanged\n    h = self.imageItem().getHistogram()\n', '  File "C:\\Users\\Andrea Bassi\\anaconda3\\envs\\scopefoundry\\lib\\site-packages\\pyqtgraph\\graphicsItems\\ImageItem.py", line 464, in getHistogram\n    bins = np.arange(mn, mx+1.01*step, step, dtype=np.int)\n', 'ValueError: arange: cannot compute length\n', '\nThe above exception was the direct cause of the following exception:\n\n', 'Traceback (most recent call last):\n', '  File "C:\\Users\\Andrea Bassi\\anaconda3\\envs\\scopefoundry\\lib\\site-packages\\ScopeFoundry\\measurement.py", line 273, in _on_display_update_timer\n    self.update_display()\n', '  File "C:\\Users\\Andrea Bassi\\OneDrive - Politecnico di Milano\\Documenti\\PythonProjects\\BassiScopeFoundryMicroscopes\\Microscopes\\CellRecongnitionMicroscope\\FakeCameraMeasurement.py", line 87, in update_display\n    self.imv.setImage((self.displayed_image), autoLevels=self.settings.autoLevels.val, autoRange=self.settings.autoRange.val)\n', '  File "C:\\Users\\Andrea Bassi\\anaconda3\\envs\\scopefoundry\\lib\\site-packages\\pyqtgraph\\imageview\\ImageView.py", line 301, in setImage\n    self.updateImage(autoHistogramRange=autoHistogramRange)\n', '  File "C:\\Users\\Andrea Bassi\\anaconda3\\envs\\scopefoundry\\lib\\site-packages\\pyqtgraph\\imageview\\ImageView.py", line 676, in updateImage\n    self.imageItem.updateImage(image)\n', '  File "C:\\Users\\Andrea Bassi\\anaconda3\\envs\\scopefoundry\\lib\\site-packages\\pyqtgraph\\graphicsItems\\ImageItem.py", line 342, in updateImage\n    return self.setImage(*args, **defaults)\n', '  File "C:\\Users\\Andrea Bassi\\anaconda3\\envs\\scopefoundry\\lib\\site-packages\\pyqtgraph\\graphicsItems\\ImageItem.py", line 283, in setImage\n    self.sigImageChanged.emit()\n', 'SystemError: <built-in method emit of PyQt5.QtCore.pyqtBoundSignal object at 0x000001C1099EC490> returned a result with an error set\n']
2020-07-23T13:21:39|ERROR|FakeCameraMeasurement|fake_camera_image Failed to update figure1: <built-in method emit of PyQt5.QtCore.pyqtBoundSignal object at 0x000001C1099EC490> returned a result with an error set. ['Traceback (most recent call last):\n', '  File "C:\\Users\\Andrea Bassi\\anaconda3\\envs\\scopefoundry\\lib\\site-packages\\pyqtgraph\\graphicsItems\\HistogramLUTItem.py", line 195, in imageChanged\n    h = self.imageItem().getHistogram()\n', '  File "C:\\Users\\Andrea Bassi\\anaconda3\\envs\\scopefoundry\\lib\\site-packages\\pyqtgraph\\graphicsItems\\ImageItem.py", line 464, in getHistogram\n    bins = np.arange(mn, mx+1.01*step, step, dtype=np.int)\n', 'ValueError: arange: cannot compute length\n', '\nThe above exception was the direct cause of the following exception:\n\n', 'Traceback (most recent call last):\n', '  File "C:\\Users\\Andrea Bassi\\anaconda3\\envs\\scopefoundry\\lib\\site-packages\\ScopeFoundry\\measurement.py", line 273, in _on_display_update_timer\n    self.update_display()\n', '  File "C:\\Users\\Andrea Bassi\\OneDrive - Politecnico di Milano\\Documenti\\PythonProjects\\BassiScopeFoundryMicroscopes\\Microscopes\\CellRecongnitionMicroscope\\FakeCameraMeasurement.py", line 87, in update_display\n    self.imv.setImage((self.displayed_image), autoLevels=self.settings.autoLevels.val, autoRange=self.settings.autoRange.val)\n', '  File "C:\\Users\\Andrea Bassi\\anaconda3\\envs\\scopefoundry\\lib\\site-packages\\pyqtgraph\\imageview\\ImageView.py", line 301, in setImage\n    self.updateImage(autoHistogramRange=autoHistogramRange)\n', '  File "C:\\Users\\Andrea Bassi\\anaconda3\\envs\\scopefoundry\\lib\\site-packages\\pyqtgraph\\imageview\\ImageView.py", line 676, in updateImage\n    self.imageItem.updateImage(image)\n', '  File "C:\\Users\\Andrea Bassi\\anaconda3\\envs\\scopefoundry\\lib\\site-packages\\pyqtgraph\\graphicsItems\\ImageItem.py", line 342, in updateImage\n    return self.setImage(*args, **defaults)\n', '  File "C:\\Users\\Andrea Bassi\\anaconda3\\envs\\scopefoundry\\lib\\site-packages\\pyqtgraph\\graphicsItems\\ImageItem.py", line 283, in setImage\n    self.sigImageChanged.emit()\n', 'SystemError: <built-in method emit of PyQt5.QtCore.pyqtBoundSignal object at 0x000001C1099EC490> returned a result with an error set\n']
2020-07-23T13:21:39|ERROR|FakeCameraMeasurement|fake_camera_image Failed to update figure1: <built-in method emit of PyQt5.QtCore.pyqtBoundSignal object at 0x000001C1099EC490> returned a result with an error set. ['Traceback (most recent call last):\n', '  File "C:\\Users\\Andrea Bassi\\anaconda3\\envs\\scopefoundry\\lib\\site-packages\\pyqtgraph\\graphicsItems\\HistogramLUTItem.py", line 195, in imageChanged\n    h = self.imageItem().getHistogram()\n', '  File "C:\\Users\\Andrea Bassi\\anaconda3\\envs\\scopefoundry\\lib\\site-packages\\pyqtgraph\\graphicsItems\\ImageItem.py", line 464, in getHistogram\n    bins = np.arange(mn, mx+1.01*step, step, dtype=np.int)\n', 'ValueError: arange: cannot compute length\n', '\nThe above exception was the direct cause of the following exception:\n\n', 'Traceback (most recent call last):\n', '  File "C:\\Users\\Andrea Bassi\\anaconda3\\envs\\scopefoundry\\lib\\site-packages\\ScopeFoundry\\measurement.py", line 273, in _on_display_update_timer\n    self.update_display()\n', '  File "C:\\Users\\Andrea Bassi\\OneDrive - Politecnico di Milano\\Documenti\\PythonProjects\\BassiScopeFoundryMicroscopes\\Microscopes\\CellRecongnitionMicroscope\\FakeCameraMeasurement.py", line 87, in update_display\n    self.imv.setImage((self.displayed_image), autoLevels=self.settings.autoLevels.val, autoRange=self.settings.autoRange.val)\n', '  File "C:\\Users\\Andrea Bassi\\anaconda3\\envs\\scopefoundry\\lib\\site-packages\\pyqtgraph\\imageview\\ImageView.py", line 301, in setImage\n    self.updateImage(autoHistogramRange=autoHistogramRange)\n', '  File "C:\\Users\\Andrea Bassi\\anaconda3\\envs\\scopefoundry\\lib\\site-packages\\pyqtgraph\\imageview\\ImageView.py", line 676, in updateImage\n    self.imageItem.updateImage(image)\n', '  File "C:\\Users\\Andrea Bassi\\anaconda3\\envs\\scopefoundry\\lib\\site-packages\\pyqtgraph\\graphicsItems\\ImageItem.py", line 342, in updateImage\n    return self.setImage(*args, **defaults)\n', '  File "C:\\Users\\Andrea Bassi\\anaconda3\\envs\\scopefoundry\\lib\\site-packages\\pyqtgraph\\graphicsItems\\ImageItem.py", line 283, in setImage\n    self.sigImageChanged.emit()\n', 'SystemError: <built-in method emit of PyQt5.QtCore.pyqtBoundSignal object at 0x000001C1099EC490> returned a result with an error set\n']
2020-07-23T13:21:39|ERROR|FakeCameraMeasurement|fake_camera_image Failed to update figure1: <built-in method emit of PyQt5.QtCore.pyqtBoundSignal object at 0x000001C1099EC490> returned a result with an error set. ['Traceback (most recent call last):\n', '  File "C:\\Users\\Andrea Bassi\\anaconda3\\envs\\scopefoundry\\lib\\site-packages\\pyqtgraph\\graphicsItems\\HistogramLUTItem.py", line 195, in imageChanged\n    h = self.imageItem().getHistogram()\n', '  File "C:\\Users\\Andrea Bassi\\anaconda3\\envs\\scopefoundry\\lib\\site-packages\\pyqtgraph\\graphicsItems\\ImageItem.py", line 464, in getHistogram\n    bins = np.arange(mn, mx+1.01*step, step, dtype=np.int)\n', 'ValueError: arange: cannot compute length\n', '\nThe above exception was the direct cause of the following exception:\n\n', 'Traceback (most recent call last):\n', '  File "C:\\Users\\Andrea Bassi\\anaconda3\\envs\\scopefoundry\\lib\\site-packages\\ScopeFoundry\\measurement.py", line 273, in _on_display_update_timer\n    self.update_display()\n', '  File "C:\\Users\\Andrea Bassi\\OneDrive - Politecnico di Milano\\Documenti\\PythonProjects\\BassiScopeFoundryMicroscopes\\Microscopes\\CellRecongnitionMicroscope\\FakeCameraMeasurement.py", line 87, in update_display\n    self.imv.setImage((self.displayed_image), autoLevels=self.settings.autoLevels.val, autoRange=self.settings.autoRange.val)\n', '  File "C:\\Users\\Andrea Bassi\\anaconda3\\envs\\scopefoundry\\lib\\site-packages\\pyqtgraph\\imageview\\ImageView.py", line 301, in setImage\n    self.updateImage(autoHistogramRange=autoHistogramRange)\n', '  File "C:\\Users\\Andrea Bassi\\anaconda3\\envs\\scopefoundry\\lib\\site-packages\\pyqtgraph\\imageview\\ImageView.py", line 676, in updateImage\n    self.imageItem.updateImage(image)\n', '  File "C:\\Users\\Andrea Bassi\\anaconda3\\envs\\scopefoundry\\lib\\site-packages\\pyqtgraph\\graphicsItems\\ImageItem.py", line 342, in updateImage\n    return self.setImage(*args, **defaults)\n', '  File "C:\\Users\\Andrea Bassi\\anaconda3\\envs\\scopefoundry\\lib\\site-packages\\pyqtgraph\\graphicsItems\\ImageItem.py", line 283, in setImage\n    self.sigImageChanged.emit()\n', 'SystemError: <built-in method emit of PyQt5.QtCore.pyqtBoundSignal object at 0x000001C1099EC490> returned a result with an error set\n']
2020-07-23T13:21:39|ERROR|FakeCameraMeasurement|fake_camera_image Failed to update figure1: <built-in method emit of PyQt5.QtCore.pyqtBoundSignal object at 0x000001C119A3BF80> returned a result with an error set. ['Traceback (most recent call last):\n', '  File "C:\\Users\\Andrea Bassi\\anaconda3\\envs\\scopefoundry\\lib\\site-packages\\pyqtgraph\\graphicsItems\\HistogramLUTItem.py", line 195, in imageChanged\n    h = self.imageItem().getHistogram()\n', '  File "C:\\Users\\Andrea Bassi\\anaconda3\\envs\\scopefoundry\\lib\\site-packages\\pyqtgraph\\graphicsItems\\ImageItem.py", line 464, in getHistogram\n    bins = np.arange(mn, mx+1.01*step, step, dtype=np.int)\n', 'ValueError: arange: cannot compute length\n', '\nThe above exception was the direct cause of the following exception:\n\n', 'Traceback (most recent call last):\n', '  File "C:\\Users\\Andrea Bassi\\anaconda3\\envs\\scopefoundry\\lib\\site-packages\\ScopeFoundry\\measurement.py", line 273, in _on_display_update_timer\n    self.update_display()\n', '  File "C:\\Users\\Andrea Bassi\\OneDrive - Politecnico di Milano\\Documenti\\PythonProjects\\BassiScopeFoundryMicroscopes\\Microscopes\\CellRecongnitionMicroscope\\FakeCameraMeasurement.py", line 87, in update_display\n    self.imv.setImage((self.displayed_image), autoLevels=self.settings.autoLevels.val, autoRange=self.settings.autoRange.val)\n', '  File "C:\\Users\\Andrea Bassi\\anaconda3\\envs\\scopefoundry\\lib\\site-packages\\pyqtgraph\\imageview\\ImageView.py", line 301, in setImage\n    self.updateImage(autoHistogramRange=autoHistogramRange)\n', '  File "C:\\Users\\Andrea Bassi\\anaconda3\\envs\\scopefoundry\\lib\\site-packages\\pyqtgraph\\imageview\\ImageView.py", line 676, in updateImage\n    self.imageItem.updateImage(image)\n', '  File "C:\\Users\\Andrea Bassi\\anaconda3\\envs\\scopefoundry\\lib\\site-packages\\pyqtgraph\\graphicsItems\\ImageItem.py", line 342, in updateImage\n    return self.setImage(*args, **defaults)\n', '  File "C:\\Users\\Andrea Bassi\\anaconda3\\envs\\scopefoundry\\lib\\site-packages\\pyqtgraph\\graphicsItems\\ImageItem.py", line 283, in setImage\n    self.sigImageChanged.emit()\n', 'SystemError: <built-in method emit of PyQt5.QtCore.pyqtBoundSignal object at 0x000001C119A3BF80> returned a result with an error set\n']
2020-07-23T13:21:39|ERROR|FakeCameraMeasurement|fake_camera_image Failed to update figure1: <built-in method emit of PyQt5.QtCore.pyqtBoundSignal object at 0x000001C119A3BF80> returned a result with an error set. ['Traceback (most recent call last):\n', '  File "C:\\Users\\Andrea Bassi\\anaconda3\\envs\\scopefoundry\\lib\\site-packages\\pyqtgraph\\graphicsItems\\HistogramLUTItem.py", line 195, in imageChanged\n    h = self.imageItem().getHistogram()\n', '  File "C:\\Users\\Andrea Bassi\\anaconda3\\envs\\scopefoundry\\lib\\site-packages\\pyqtgraph\\graphicsItems\\ImageItem.py", line 464, in getHistogram\n    bins = np.arange(mn, mx+1.01*step, step, dtype=np.int)\n', 'ValueError: arange: cannot compute length\n', '\nThe above exception was the direct cause of the following exception:\n\n', 'Traceback (most recent call last):\n', '  File "C:\\Users\\Andrea Bassi\\anaconda3\\envs\\scopefoundry\\lib\\site-packages\\ScopeFoundry\\measurement.py", line 273, in _on_display_update_timer\n    self.update_display()\n', '  File "C:\\Users\\Andrea Bassi\\OneDrive - Politecnico di Milano\\Documenti\\PythonProjects\\BassiScopeFoundryMicroscopes\\Microscopes\\CellRecongnitionMicroscope\\FakeCameraMeasurement.py", line 87, in update_display\n    self.imv.setImage((self.displayed_image), autoLevels=self.settings.autoLevels.val, autoRange=self.settings.autoRange.val)\n', '  File "C:\\Users\\Andrea Bassi\\anaconda3\\envs\\scopefoundry\\lib\\site-packages\\pyqtgraph\\imageview\\ImageView.py", line 301, in setImage\n    self.updateImage(autoHistogramRange=autoHistogramRange)\n', '  File "C:\\Users\\Andrea Bassi\\anaconda3\\envs\\scopefoundry\\lib\\site-packages\\pyqtgraph\\imageview\\ImageView.py", line 676, in updateImage\n    self.imageItem.updateImage(image)\n', '  File "C:\\Users\\Andrea Bassi\\anaconda3\\envs\\scopefoundry\\lib\\site-packages\\pyqtgraph\\graphicsItems\\ImageItem.py", line 342, in updateImage\n    return self.setImage(*args, **defaults)\n', '  File "C:\\Users\\Andrea Bassi\\anaconda3\\envs\\scopefoundry\\lib\\site-packages\\pyqtgraph\\graphicsItems\\ImageItem.py", line 283, in setImage\n    self.sigImageChanged.emit()\n', 'SystemError: <built-in method emit of PyQt5.QtCore.pyqtBoundSignal object at 0x000001C119A3BF80> returned a result with an error set\n']
2020-07-23T13:21:39|ERROR|FakeCameraMeasurement|fake_camera_image Failed to update figure1: <built-in method emit of PyQt5.QtCore.pyqtBoundSignal object at 0x000001C119A3BA80> returned a result with an error set. ['Traceback (most recent call last):\n', '  File "C:\\Users\\Andrea Bassi\\anaconda3\\envs\\scopefoundry\\lib\\site-packages\\pyqtgraph\\graphicsItems\\HistogramLUTItem.py", line 195, in imageChanged\n    h = self.imageItem().getHistogram()\n', '  File "C:\\Users\\Andrea Bassi\\anaconda3\\envs\\scopefoundry\\lib\\site-packages\\pyqtgraph\\graphicsItems\\ImageItem.py", line 464, in getHistogram\n    bins = np.arange(mn, mx+1.01*step, step, dtype=np.int)\n', 'ValueError: arange: cannot compute length\n', '\nThe above exception was the direct cause of the following exception:\n\n', 'Traceback (most recent call last):\n', '  File "C:\\Users\\Andrea Bassi\\anaconda3\\envs\\scopefoundry\\lib\\site-packages\\ScopeFoundry\\measurement.py", line 273, in _on_display_update_timer\n    self.update_display()\n', '  File "C:\\Users\\Andrea Bassi\\OneDrive - Politecnico di Milano\\Documenti\\PythonProjects\\BassiScopeFoundryMicroscopes\\Microscopes\\CellRecongnitionMicroscope\\FakeCameraMeasurement.py", line 87, in update_display\n    self.imv.setImage((self.displayed_image), autoLevels=self.settings.autoLevels.val, autoRange=self.settings.autoRange.val)\n', '  File "C:\\Users\\Andrea Bassi\\anaconda3\\envs\\scopefoundry\\lib\\site-packages\\pyqtgraph\\imageview\\ImageView.py", line 301, in setImage\n    self.updateImage(autoHistogramRange=autoHistogramRange)\n', '  File "C:\\Users\\Andrea Bassi\\anaconda3\\envs\\scopefoundry\\lib\\site-packages\\pyqtgraph\\imageview\\ImageView.py", line 676, in updateImage\n    self.imageItem.updateImage(image)\n', '  File "C:\\Users\\Andrea Bassi\\anaconda3\\envs\\scopefoundry\\lib\\site-packages\\pyqtgraph\\graphicsItems\\ImageItem.py", line 342, in updateImage\n    return self.setImage(*args, **defaults)\n', '  File "C:\\Users\\Andrea Bassi\\anaconda3\\envs\\scopefoundry\\lib\\site-packages\\pyqtgraph\\graphicsItems\\ImageItem.py", line 283, in setImage\n    self.sigImageChanged.emit()\n', 'SystemError: <built-in method emit of PyQt5.QtCore.pyqtBoundSignal object at 0x000001C119A3BA80> returned a result with an error set\n']
2020-07-23T13:21:39|ERROR|FakeCameraMeasurement|fake_camera_image Failed to update figure1: <built-in method emit of PyQt5.QtCore.pyqtBoundSignal object at 0x000001C1099EC490> returned a result with an error set. ['Traceback (most recent call last):\n', '  File "C:\\Users\\Andrea Bassi\\anaconda3\\envs\\scopefoundry\\lib\\site-packages\\pyqtgraph\\graphicsItems\\HistogramLUTItem.py", line 195, in imageChanged\n    h = self.imageItem().getHistogram()\n', '  File "C:\\Users\\Andrea Bassi\\anaconda3\\envs\\scopefoundry\\lib\\site-packages\\pyqtgraph\\graphicsItems\\ImageItem.py", line 464, in getHistogram\n    bins = np.arange(mn, mx+1.01*step, step, dtype=np.int)\n', 'ValueError: arange: cannot compute length\n', '\nThe above exception was the direct cause of the following exception:\n\n', 'Traceback (most recent call last):\n', '  File "C:\\Users\\Andrea Bassi\\anaconda3\\envs\\scopefoundry\\lib\\site-packages\\ScopeFoundry\\measurement.py", line 273, in _on_display_update_timer\n    self.update_display()\n', '  File "C:\\Users\\Andrea Bassi\\OneDrive - Politecnico di Milano\\Documenti\\PythonProjects\\BassiScopeFoundryMicroscopes\\Microscopes\\CellRecongnitionMicroscope\\FakeCameraMeasurement.py", line 87, in update_display\n    self.imv.setImage((self.displayed_image), autoLevels=self.settings.autoLevels.val, autoRange=self.settings.autoRange.val)\n', '  File "C:\\Users\\Andrea Bassi\\anaconda3\\envs\\scopefoundry\\lib\\site-packages\\pyqtgraph\\imageview\\ImageView.py", line 301, in setImage\n    self.updateImage(autoHistogramRange=autoHistogramRange)\n', '  File "C:\\Users\\Andrea Bassi\\anaconda3\\envs\\scopefoundry\\lib\\site-packages\\pyqtgraph\\imageview\\ImageView.py", line 676, in updateImage\n    self.imageItem.updateImage(image)\n', '  File "C:\\Users\\Andrea Bassi\\anaconda3\\envs\\scopefoundry\\lib\\site-packages\\pyqtgraph\\graphicsItems\\ImageItem.py", line 342, in updateImage\n    return self.setImage(*args, **defaults)\n', '  File "C:\\Users\\Andrea Bassi\\anaconda3\\envs\\scopefoundry\\lib\\site-packages\\pyqtgraph\\graphicsItems\\ImageItem.py", line 283, in setImage\n    self.sigImageChanged.emit()\n', 'SystemError: <built-in method emit of PyQt5.QtCore.pyqtBoundSignal object at 0x000001C1099EC490> returned a result with an error set\n']
2020-07-23T13:21:39|ERROR|FakeCameraMeasurement|fake_camera_image Failed to update figure1: <built-in method emit of PyQt5.QtCore.pyqtBoundSignal object at 0x000001C1099EC490> returned a result with an error set. ['Traceback (most recent call last):\n', '  File "C:\\Users\\Andrea Bassi\\anaconda3\\envs\\scopefoundry\\lib\\site-packages\\pyqtgraph\\graphicsItems\\HistogramLUTItem.py", line 195, in imageChanged\n    h = self.imageItem().getHistogram()\n', '  File "C:\\Users\\Andrea Bassi\\anaconda3\\envs\\scopefoundry\\lib\\site-packages\\pyqtgraph\\graphicsItems\\ImageItem.py", line 464, in getHistogram\n    bins = np.arange(mn, mx+1.01*step, step, dtype=np.int)\n', 'ValueError: arange: cannot compute length\n', '\nThe above exception was the direct cause of the following exception:\n\n', 'Traceback (most recent call last):\n', '  File "C:\\Users\\Andrea Bassi\\anaconda3\\envs\\scopefoundry\\lib\\site-packages\\ScopeFoundry\\measurement.py", line 273, in _on_display_update_timer\n    self.update_display()\n', '  File "C:\\Users\\Andrea Bassi\\OneDrive - Politecnico di Milano\\Documenti\\PythonProjects\\BassiScopeFoundryMicroscopes\\Microscopes\\CellRecongnitionMicroscope\\FakeCameraMeasurement.py", line 87, in update_display\n    self.imv.setImage((self.displayed_image), autoLevels=self.settings.autoLevels.val, autoRange=self.settings.autoRange.val)\n', '  File "C:\\Users\\Andrea Bassi\\anaconda3\\envs\\scopefoundry\\lib\\site-packages\\pyqtgraph\\imageview\\ImageView.py", line 301, in setImage\n    self.updateImage(autoHistogramRange=autoHistogramRange)\n', '  File "C:\\Users\\Andrea Bassi\\anaconda3\\envs\\scopefoundry\\lib\\site-packages\\pyqtgraph\\imageview\\ImageView.py", line 676, in updateImage\n    self.imageItem.updateImage(image)\n', '  File "C:\\Users\\Andrea Bassi\\anaconda3\\envs\\scopefoundry\\lib\\site-packages\\pyqtgraph\\graphicsItems\\ImageItem.py", line 342, in updateImage\n    return self.setImage(*args, **defaults)\n', '  File "C:\\Users\\Andrea Bassi\\anaconda3\\envs\\scopefoundry\\lib\\site-packages\\pyqtgraph\\graphicsItems\\ImageItem.py", line 283, in setImage\n    self.sigImageChanged.emit()\n', 'SystemError: <built-in method emit of PyQt5.QtCore.pyqtBoundSignal object at 0x000001C1099EC490> returned a result with an error set\n']
2020-07-23T13:21:39|ERROR|FakeCameraMeasurement|fake_camera_image Failed to update figure1: <built-in method emit of PyQt5.QtCore.pyqtBoundSignal object at 0x000001C1099EC490> returned a result with an error set. ['Traceback (most recent call last):\n', '  File "C:\\Users\\Andrea Bassi\\anaconda3\\envs\\scopefoundry\\lib\\site-packages\\pyqtgraph\\graphicsItems\\HistogramLUTItem.py", line 195, in imageChanged\n    h = self.imageItem().getHistogram()\n', '  File "C:\\Users\\Andrea Bassi\\anaconda3\\envs\\scopefoundry\\lib\\site-packages\\pyqtgraph\\graphicsItems\\ImageItem.py", line 464, in getHistogram\n    bins = np.arange(mn, mx+1.01*step, step, dtype=np.int)\n', 'ValueError: arange: cannot compute length\n', '\nThe above exception was the direct cause of the following exception:\n\n', 'Traceback (most recent call last):\n', '  File "C:\\Users\\Andrea Bassi\\anaconda3\\envs\\scopefoundry\\lib\\site-packages\\ScopeFoundry\\measurement.py", line 273, in _on_display_update_timer\n    self.update_display()\n', '  File "C:\\Users\\Andrea Bassi\\OneDrive - Politecnico di Milano\\Documenti\\PythonProjects\\BassiScopeFoundryMicroscopes\\Microscopes\\CellRecongnitionMicroscope\\FakeCameraMeasurement.py", line 87, in update_display\n    self.imv.setImage((self.displayed_image), autoLevels=self.settings.autoLevels.val, autoRange=self.settings.autoRange.val)\n', '  File "C:\\Users\\Andrea Bassi\\anaconda3\\envs\\scopefoundry\\lib\\site-packages\\pyqtgraph\\imageview\\ImageView.py", line 301, in setImage\n    self.updateImage(autoHistogramRange=autoHistogramRange)\n', '  File "C:\\Users\\Andrea Bassi\\anaconda3\\envs\\scopefoundry\\lib\\site-packages\\pyqtgraph\\imageview\\ImageView.py", line 676, in updateImage\n    self.imageItem.updateImage(image)\n', '  File "C:\\Users\\Andrea Bassi\\anaconda3\\envs\\scopefoundry\\lib\\site-packages\\pyqtgraph\\graphicsItems\\ImageItem.py", line 342, in updateImage\n    return self.setImage(*args, **defaults)\n', '  File "C:\\Users\\Andrea Bassi\\anaconda3\\envs\\scopefoundry\\lib\\site-packages\\pyqtgraph\\graphicsItems\\ImageItem.py", line 283, in setImage\n    self.sigImageChanged.emit()\n', 'SystemError: <built-in method emit of PyQt5.QtCore.pyqtBoundSignal object at 0x000001C1099EC490> returned a result with an error set\n']
2020-07-23T13:21:39|ERROR|FakeCameraMeasurement|fake_camera_image Failed to update figure1: <built-in method emit of PyQt5.QtCore.pyqtBoundSignal object at 0x000001C1099EC490> returned a result with an error set. ['Traceback (most recent call last):\n', '  File "C:\\Users\\Andrea Bassi\\anaconda3\\envs\\scopefoundry\\lib\\site-packages\\pyqtgraph\\graphicsItems\\HistogramLUTItem.py", line 195, in imageChanged\n    h = self.imageItem().getHistogram()\n', '  File "C:\\Users\\Andrea Bassi\\anaconda3\\envs\\scopefoundry\\lib\\site-packages\\pyqtgraph\\graphicsItems\\ImageItem.py", line 464, in getHistogram\n    bins = np.arange(mn, mx+1.01*step, step, dtype=np.int)\n', 'ValueError: arange: cannot compute length\n', '\nThe above exception was the direct cause of the following exception:\n\n', 'Traceback (most recent call last):\n', '  File "C:\\Users\\Andrea Bassi\\anaconda3\\envs\\scopefoundry\\lib\\site-packages\\ScopeFoundry\\measurement.py", line 273, in _on_display_update_timer\n    self.update_display()\n', '  File "C:\\Users\\Andrea Bassi\\OneDrive - Politecnico di Milano\\Documenti\\PythonProjects\\BassiScopeFoundryMicroscopes\\Microscopes\\CellRecongnitionMicroscope\\FakeCameraMeasurement.py", line 87, in update_display\n    self.imv.setImage((self.displayed_image), autoLevels=self.settings.autoLevels.val, autoRange=self.settings.autoRange.val)\n', '  File "C:\\Users\\Andrea Bassi\\anaconda3\\envs\\scopefoundry\\lib\\site-packages\\pyqtgraph\\imageview\\ImageView.py", line 301, in setImage\n    self.updateImage(autoHistogramRange=autoHistogramRange)\n', '  File "C:\\Users\\Andrea Bassi\\anaconda3\\envs\\scopefoundry\\lib\\site-packages\\pyqtgraph\\imageview\\ImageView.py", line 676, in updateImage\n    self.imageItem.updateImage(image)\n', '  File "C:\\Users\\Andrea Bassi\\anaconda3\\envs\\scopefoundry\\lib\\site-packages\\pyqtgraph\\graphicsItems\\ImageItem.py", line 342, in updateImage\n    return self.setImage(*args, **defaults)\n', '  File "C:\\Users\\Andrea Bassi\\anaconda3\\envs\\scopefoundry\\lib\\site-packages\\pyqtgraph\\graphicsItems\\ImageItem.py", line 283, in setImage\n    self.sigImageChanged.emit()\n', 'SystemError: <built-in method emit of PyQt5.QtCore.pyqtBoundSignal object at 0x000001C1099EC490> returned a result with an error set\n']
2020-07-23T13:21:39|ERROR|FakeCameraMeasurement|fake_camera_image Failed to update figure1: <built-in method emit of PyQt5.QtCore.pyqtBoundSignal object at 0x000001C1099EC490> returned a result with an error set. ['Traceback (most recent call last):\n', '  File "C:\\Users\\Andrea Bassi\\anaconda3\\envs\\scopefoundry\\lib\\site-packages\\pyqtgraph\\graphicsItems\\HistogramLUTItem.py", line 195, in imageChanged\n    h = self.imageItem().getHistogram()\n', '  File "C:\\Users\\Andrea Bassi\\anaconda3\\envs\\scopefoundry\\lib\\site-packages\\pyqtgraph\\graphicsItems\\ImageItem.py", line 464, in getHistogram\n    bins = np.arange(mn, mx+1.01*step, step, dtype=np.int)\n', 'ValueError: arange: cannot compute length\n', '\nThe above exception was the direct cause of the following exception:\n\n', 'Traceback (most recent call last):\n', '  File "C:\\Users\\Andrea Bassi\\anaconda3\\envs\\scopefoundry\\lib\\site-packages\\ScopeFoundry\\measurement.py", line 273, in _on_display_update_timer\n    self.update_display()\n', '  File "C:\\Users\\Andrea Bassi\\OneDrive - Politecnico di Milano\\Documenti\\PythonProjects\\BassiScopeFoundryMicroscopes\\Microscopes\\CellRecongnitionMicroscope\\FakeCameraMeasurement.py", line 87, in update_display\n    self.imv.setImage((self.displayed_image), autoLevels=self.settings.autoLevels.val, autoRange=self.settings.autoRange.val)\n', '  File "C:\\Users\\Andrea Bassi\\anaconda3\\envs\\scopefoundry\\lib\\site-packages\\pyqtgraph\\imageview\\ImageView.py", line 301, in setImage\n    self.updateImage(autoHistogramRange=autoHistogramRange)\n', '  File "C:\\Users\\Andrea Bassi\\anaconda3\\envs\\scopefoundry\\lib\\site-packages\\pyqtgraph\\imageview\\ImageView.py", line 676, in updateImage\n    self.imageItem.updateImage(image)\n', '  File "C:\\Users\\Andrea Bassi\\anaconda3\\envs\\scopefoundry\\lib\\site-packages\\pyqtgraph\\graphicsItems\\ImageItem.py", line 342, in updateImage\n    return self.setImage(*args, **defaults)\n', '  File "C:\\Users\\Andrea Bassi\\anaconda3\\envs\\scopefoundry\\lib\\site-packages\\pyqtgraph\\graphicsItems\\ImageItem.py", line 283, in setImage\n    self.sigImageChanged.emit()\n', 'SystemError: <built-in method emit of PyQt5.QtCore.pyqtBoundSignal object at 0x000001C1099EC490> returned a result with an error set\n']
2020-07-23T13:21:39|ERROR|FakeCameraMeasurement|fake_camera_image Failed to update figure1: <built-in method emit of PyQt5.QtCore.pyqtBoundSignal object at 0x000001C1099EC490> returned a result with an error set. ['Traceback (most recent call last):\n', '  File "C:\\Users\\Andrea Bassi\\anaconda3\\envs\\scopefoundry\\lib\\site-packages\\pyqtgraph\\graphicsItems\\HistogramLUTItem.py", line 195, in imageChanged\n    h = self.imageItem().getHistogram()\n', '  File "C:\\Users\\Andrea Bassi\\anaconda3\\envs\\scopefoundry\\lib\\site-packages\\pyqtgraph\\graphicsItems\\ImageItem.py", line 464, in getHistogram\n    bins = np.arange(mn, mx+1.01*step, step, dtype=np.int)\n', 'ValueError: arange: cannot compute length\n', '\nThe above exception was the direct cause of the following exception:\n\n', 'Traceback (most recent call last):\n', '  File "C:\\Users\\Andrea Bassi\\anaconda3\\envs\\scopefoundry\\lib\\site-packages\\ScopeFoundry\\measurement.py", line 273, in _on_display_update_timer\n    self.update_display()\n', '  File "C:\\Users\\Andrea Bassi\\OneDrive - Politecnico di Milano\\Documenti\\PythonProjects\\BassiScopeFoundryMicroscopes\\Microscopes\\CellRecongnitionMicroscope\\FakeCameraMeasurement.py", line 87, in update_display\n    self.imv.setImage((self.displayed_image), autoLevels=self.settings.autoLevels.val, autoRange=self.settings.autoRange.val)\n', '  File "C:\\Users\\Andrea Bassi\\anaconda3\\envs\\scopefoundry\\lib\\site-packages\\pyqtgraph\\imageview\\ImageView.py", line 301, in setImage\n    self.updateImage(autoHistogramRange=autoHistogramRange)\n', '  File "C:\\Users\\Andrea Bassi\\anaconda3\\envs\\scopefoundry\\lib\\site-packages\\pyqtgraph\\imageview\\ImageView.py", line 676, in updateImage\n    self.imageItem.updateImage(image)\n', '  File "C:\\Users\\Andrea Bassi\\anaconda3\\envs\\scopefoundry\\lib\\site-packages\\pyqtgraph\\graphicsItems\\ImageItem.py", line 342, in updateImage\n    return self.setImage(*args, **defaults)\n', '  File "C:\\Users\\Andrea Bassi\\anaconda3\\envs\\scopefoundry\\lib\\site-packages\\pyqtgraph\\graphicsItems\\ImageItem.py", line 283, in setImage\n    self.sigImageChanged.emit()\n', 'SystemError: <built-in method emit of PyQt5.QtCore.pyqtBoundSignal object at 0x000001C1099EC490> returned a result with an error set\n']
2020-07-23T13:21:39|ERROR|FakeCameraMeasurement|fake_camera_image Failed to update figure1: <built-in method emit of PyQt5.QtCore.pyqtBoundSignal object at 0x000001C1099EC490> returned a result with an error set. ['Traceback (most recent call last):\n', '  File "C:\\Users\\Andrea Bassi\\anaconda3\\envs\\scopefoundry\\lib\\site-packages\\pyqtgraph\\graphicsItems\\HistogramLUTItem.py", line 195, in imageChanged\n    h = self.imageItem().getHistogram()\n', '  File "C:\\Users\\Andrea Bassi\\anaconda3\\envs\\scopefoundry\\lib\\site-packages\\pyqtgraph\\graphicsItems\\ImageItem.py", line 464, in getHistogram\n    bins = np.arange(mn, mx+1.01*step, step, dtype=np.int)\n', 'ValueError: arange: cannot compute length\n', '\nThe above exception was the direct cause of the following exception:\n\n', 'Traceback (most recent call last):\n', '  File "C:\\Users\\Andrea Bassi\\anaconda3\\envs\\scopefoundry\\lib\\site-packages\\ScopeFoundry\\measurement.py", line 273, in _on_display_update_timer\n    self.update_display()\n', '  File "C:\\Users\\Andrea Bassi\\OneDrive - Politecnico di Milano\\Documenti\\PythonProjects\\BassiScopeFoundryMicroscopes\\Microscopes\\CellRecongnitionMicroscope\\FakeCameraMeasurement.py", line 87, in update_display\n    self.imv.setImage((self.displayed_image), autoLevels=self.settings.autoLevels.val, autoRange=self.settings.autoRange.val)\n', '  File "C:\\Users\\Andrea Bassi\\anaconda3\\envs\\scopefoundry\\lib\\site-packages\\pyqtgraph\\imageview\\ImageView.py", line 301, in setImage\n    self.updateImage(autoHistogramRange=autoHistogramRange)\n', '  File "C:\\Users\\Andrea Bassi\\anaconda3\\envs\\scopefoundry\\lib\\site-packages\\pyqtgraph\\imageview\\ImageView.py", line 676, in updateImage\n    self.imageItem.updateImage(image)\n', '  File "C:\\Users\\Andrea Bassi\\anaconda3\\envs\\scopefoundry\\lib\\site-packages\\pyqtgraph\\graphicsItems\\ImageItem.py", line 342, in updateImage\n    return self.setImage(*args, **defaults)\n', '  File "C:\\Users\\Andrea Bassi\\anaconda3\\envs\\scopefoundry\\lib\\site-packages\\pyqtgraph\\graphicsItems\\ImageItem.py", line 283, in setImage\n    self.sigImageChanged.emit()\n', 'SystemError: <built-in method emit of PyQt5.QtCore.pyqtBoundSignal object at 0x000001C1099EC490> returned a result with an error set\n']
2020-07-23T13:21:39|ERROR|FakeCameraMeasurement|fake_camera_image Failed to update figure1: <built-in method emit of PyQt5.QtCore.pyqtBoundSignal object at 0x000001C1099EC490> returned a result with an error set. ['Traceback (most recent call last):\n', '  File "C:\\Users\\Andrea Bassi\\anaconda3\\envs\\scopefoundry\\lib\\site-packages\\pyqtgraph\\graphicsItems\\HistogramLUTItem.py", line 195, in imageChanged\n    h = self.imageItem().getHistogram()\n', '  File "C:\\Users\\Andrea Bassi\\anaconda3\\envs\\scopefoundry\\lib\\site-packages\\pyqtgraph\\graphicsItems\\ImageItem.py", line 464, in getHistogram\n    bins = np.arange(mn, mx+1.01*step, step, dtype=np.int)\n', 'ValueError: arange: cannot compute length\n', '\nThe above exception was the direct cause of the following exception:\n\n', 'Traceback (most recent call last):\n', '  File "C:\\Users\\Andrea Bassi\\anaconda3\\envs\\scopefoundry\\lib\\site-packages\\ScopeFoundry\\measurement.py", line 273, in _on_display_update_timer\n    self.update_display()\n', '  File "C:\\Users\\Andrea Bassi\\OneDrive - Politecnico di Milano\\Documenti\\PythonProjects\\BassiScopeFoundryMicroscopes\\Microscopes\\CellRecongnitionMicroscope\\FakeCameraMeasurement.py", line 87, in update_display\n    self.imv.setImage((self.displayed_image), autoLevels=self.settings.autoLevels.val, autoRange=self.settings.autoRange.val)\n', '  File "C:\\Users\\Andrea Bassi\\anaconda3\\envs\\scopefoundry\\lib\\site-packages\\pyqtgraph\\imageview\\ImageView.py", line 301, in setImage\n    self.updateImage(autoHistogramRange=autoHistogramRange)\n', '  File "C:\\Users\\Andrea Bassi\\anaconda3\\envs\\scopefoundry\\lib\\site-packages\\pyqtgraph\\imageview\\ImageView.py", line 676, in updateImage\n    self.imageItem.updateImage(image)\n', '  File "C:\\Users\\Andrea Bassi\\anaconda3\\envs\\scopefoundry\\lib\\site-packages\\pyqtgraph\\graphicsItems\\ImageItem.py", line 342, in updateImage\n    return self.setImage(*args, **defaults)\n', '  File "C:\\Users\\Andrea Bassi\\anaconda3\\envs\\scopefoundry\\lib\\site-packages\\pyqtgraph\\graphicsItems\\ImageItem.py", line 283, in setImage\n    self.sigImageChanged.emit()\n', 'SystemError: <built-in method emit of PyQt5.QtCore.pyqtBoundSignal object at 0x000001C1099EC490> returned a result with an error set\n']
2020-07-23T13:21:39|ERROR|FakeCameraMeasurement|fake_camera_image Failed to update figure1: <built-in method emit of PyQt5.QtCore.pyqtBoundSignal object at 0x000001C119A3BA58> returned a result with an error set. ['Traceback (most recent call last):\n', '  File "C:\\Users\\Andrea Bassi\\anaconda3\\envs\\scopefoundry\\lib\\site-packages\\pyqtgraph\\graphicsItems\\HistogramLUTItem.py", line 195, in imageChanged\n    h = self.imageItem().getHistogram()\n', '  File "C:\\Users\\Andrea Bassi\\anaconda3\\envs\\scopefoundry\\lib\\site-packages\\pyqtgraph\\graphicsItems\\ImageItem.py", line 464, in getHistogram\n    bins = np.arange(mn, mx+1.01*step, step, dtype=np.int)\n', 'ValueError: arange: cannot compute length\n', '\nThe above exception was the direct cause of the following exception:\n\n', 'Traceback (most recent call last):\n', '  File "C:\\Users\\Andrea Bassi\\anaconda3\\envs\\scopefoundry\\lib\\site-packages\\ScopeFoundry\\measurement.py", line 273, in _on_display_update_timer\n    self.update_display()\n', '  File "C:\\Users\\Andrea Bassi\\OneDrive - Politecnico di Milano\\Documenti\\PythonProjects\\BassiScopeFoundryMicroscopes\\Microscopes\\CellRecongnitionMicroscope\\FakeCameraMeasurement.py", line 87, in update_display\n    self.imv.setImage((self.displayed_image), autoLevels=self.settings.autoLevels.val, autoRange=self.settings.autoRange.val)\n', '  File "C:\\Users\\Andrea Bassi\\anaconda3\\envs\\scopefoundry\\lib\\site-packages\\pyqtgraph\\imageview\\ImageView.py", line 301, in setImage\n    self.updateImage(autoHistogramRange=autoHistogramRange)\n', '  File "C:\\Users\\Andrea Bassi\\anaconda3\\envs\\scopefoundry\\lib\\site-packages\\pyqtgraph\\imageview\\ImageView.py", line 676, in updateImage\n    self.imageItem.updateImage(image)\n', '  File "C:\\Users\\Andrea Bassi\\anaconda3\\envs\\scopefoundry\\lib\\site-packages\\pyqtgraph\\graphicsItems\\ImageItem.py", line 342, in updateImage\n    return self.setImage(*args, **defaults)\n', '  File "C:\\Users\\Andrea Bassi\\anaconda3\\envs\\scopefoundry\\lib\\site-packages\\pyqtgraph\\graphicsItems\\ImageItem.py", line 283, in setImage\n    self.sigImageChanged.emit()\n', 'SystemError: <built-in method emit of PyQt5.QtCore.pyqtBoundSignal object at 0x000001C119A3BA58> returned a result with an error set\n']
2020-07-23T13:21:39|ERROR|FakeCameraMeasurement|fake_camera_image Failed to update figure1: <built-in method emit of PyQt5.QtCore.pyqtBoundSignal object at 0x000001C119A3BE90> returned a result with an error set. ['Traceback (most recent call last):\n', '  File "C:\\Users\\Andrea Bassi\\anaconda3\\envs\\scopefoundry\\lib\\site-packages\\pyqtgraph\\graphicsItems\\HistogramLUTItem.py", line 195, in imageChanged\n    h = self.imageItem().getHistogram()\n', '  File "C:\\Users\\Andrea Bassi\\anaconda3\\envs\\scopefoundry\\lib\\site-packages\\pyqtgraph\\graphicsItems\\ImageItem.py", line 464, in getHistogram\n    bins = np.arange(mn, mx+1.01*step, step, dtype=np.int)\n', 'ValueError: arange: cannot compute length\n', '\nThe above exception was the direct cause of the following exception:\n\n', 'Traceback (most recent call last):\n', '  File "C:\\Users\\Andrea Bassi\\anaconda3\\envs\\scopefoundry\\lib\\site-packages\\ScopeFoundry\\measurement.py", line 273, in _on_display_update_timer\n    self.update_display()\n', '  File "C:\\Users\\Andrea Bassi\\OneDrive - Politecnico di Milano\\Documenti\\PythonProjects\\BassiScopeFoundryMicroscopes\\Microscopes\\CellRecongnitionMicroscope\\FakeCameraMeasurement.py", line 87, in update_display\n    self.imv.setImage((self.displayed_image), autoLevels=self.settings.autoLevels.val, autoRange=self.settings.autoRange.val)\n', '  File "C:\\Users\\Andrea Bassi\\anaconda3\\envs\\scopefoundry\\lib\\site-packages\\pyqtgraph\\imageview\\ImageView.py", line 301, in setImage\n    self.updateImage(autoHistogramRange=autoHistogramRange)\n', '  File "C:\\Users\\Andrea Bassi\\anaconda3\\envs\\scopefoundry\\lib\\site-packages\\pyqtgraph\\imageview\\ImageView.py", line 676, in updateImage\n    self.imageItem.updateImage(image)\n', '  File "C:\\Users\\Andrea Bassi\\anaconda3\\envs\\scopefoundry\\lib\\site-packages\\pyqtgraph\\graphicsItems\\ImageItem.py", line 342, in updateImage\n    return self.setImage(*args, **defaults)\n', '  File "C:\\Users\\Andrea Bassi\\anaconda3\\envs\\scopefoundry\\lib\\site-packages\\pyqtgraph\\graphicsItems\\ImageItem.py", line 283, in setImage\n    self.sigImageChanged.emit()\n', 'SystemError: <built-in method emit of PyQt5.QtCore.pyqtBoundSignal object at 0x000001C119A3BE90> returned a result with an error set\n']
2020-07-23T13:21:39|ERROR|FakeCameraMeasurement|fake_camera_image Failed to update figure1: <built-in method emit of PyQt5.QtCore.pyqtBoundSignal object at 0x000001C119A3BF08> returned a result with an error set. ['Traceback (most recent call last):\n', '  File "C:\\Users\\Andrea Bassi\\anaconda3\\envs\\scopefoundry\\lib\\site-packages\\pyqtgraph\\graphicsItems\\HistogramLUTItem.py", line 195, in imageChanged\n    h = self.imageItem().getHistogram()\n', '  File "C:\\Users\\Andrea Bassi\\anaconda3\\envs\\scopefoundry\\lib\\site-packages\\pyqtgraph\\graphicsItems\\ImageItem.py", line 464, in getHistogram\n    bins = np.arange(mn, mx+1.01*step, step, dtype=np.int)\n', 'ValueError: arange: cannot compute length\n', '\nThe above exception was the direct cause of the following exception:\n\n', 'Traceback (most recent call last):\n', '  File "C:\\Users\\Andrea Bassi\\anaconda3\\envs\\scopefoundry\\lib\\site-packages\\ScopeFoundry\\measurement.py", line 273, in _on_display_update_timer\n    self.update_display()\n', '  File "C:\\Users\\Andrea Bassi\\OneDrive - Politecnico di Milano\\Documenti\\PythonProjects\\BassiScopeFoundryMicroscopes\\Microscopes\\CellRecongnitionMicroscope\\FakeCameraMeasurement.py", line 87, in update_display\n    self.imv.setImage((self.displayed_image), autoLevels=self.settings.autoLevels.val, autoRange=self.settings.autoRange.val)\n', '  File "C:\\Users\\Andrea Bassi\\anaconda3\\envs\\scopefoundry\\lib\\site-packages\\pyqtgraph\\imageview\\ImageView.py", line 301, in setImage\n    self.updateImage(autoHistogramRange=autoHistogramRange)\n', '  File "C:\\Users\\Andrea Bassi\\anaconda3\\envs\\scopefoundry\\lib\\site-packages\\pyqtgraph\\imageview\\ImageView.py", line 676, in updateImage\n    self.imageItem.updateImage(image)\n', '  File "C:\\Users\\Andrea Bassi\\anaconda3\\envs\\scopefoundry\\lib\\site-packages\\pyqtgraph\\graphicsItems\\ImageItem.py", line 342, in updateImage\n    return self.setImage(*args, **defaults)\n', '  File "C:\\Users\\Andrea Bassi\\anaconda3\\envs\\scopefoundry\\lib\\site-packages\\pyqtgraph\\graphicsItems\\ImageItem.py", line 283, in setImage\n    self.sigImageChanged.emit()\n', 'SystemError: <built-in method emit of PyQt5.QtCore.pyqtBoundSignal object at 0x000001C119A3BF08> returned a result with an error set\n']
2020-07-23T13:21:39|ERROR|FakeCameraMeasurement|fake_camera_image Failed to update figure1: <built-in method emit of PyQt5.QtCore.pyqtBoundSignal object at 0x000001C1099EC490> returned a result with an error set. ['Traceback (most recent call last):\n', '  File "C:\\Users\\Andrea Bassi\\anaconda3\\envs\\scopefoundry\\lib\\site-packages\\pyqtgraph\\graphicsItems\\HistogramLUTItem.py", line 195, in imageChanged\n    h = self.imageItem().getHistogram()\n', '  File "C:\\Users\\Andrea Bassi\\anaconda3\\envs\\scopefoundry\\lib\\site-packages\\pyqtgraph\\graphicsItems\\ImageItem.py", line 464, in getHistogram\n    bins = np.arange(mn, mx+1.01*step, step, dtype=np.int)\n', 'ValueError: arange: cannot compute length\n', '\nThe above exception was the direct cause of the following exception:\n\n', 'Traceback (most recent call last):\n', '  File "C:\\Users\\Andrea Bassi\\anaconda3\\envs\\scopefoundry\\lib\\site-packages\\ScopeFoundry\\measurement.py", line 273, in _on_display_update_timer\n    self.update_display()\n', '  File "C:\\Users\\Andrea Bassi\\OneDrive - Politecnico di Milano\\Documenti\\PythonProjects\\BassiScopeFoundryMicroscopes\\Microscopes\\CellRecongnitionMicroscope\\FakeCameraMeasurement.py", line 87, in update_display\n    self.imv.setImage((self.displayed_image), autoLevels=self.settings.autoLevels.val, autoRange=self.settings.autoRange.val)\n', '  File "C:\\Users\\Andrea Bassi\\anaconda3\\envs\\scopefoundry\\lib\\site-packages\\pyqtgraph\\imageview\\ImageView.py", line 301, in setImage\n    self.updateImage(autoHistogramRange=autoHistogramRange)\n', '  File "C:\\Users\\Andrea Bassi\\anaconda3\\envs\\scopefoundry\\lib\\site-packages\\pyqtgraph\\imageview\\ImageView.py", line 676, in updateImage\n    self.imageItem.updateImage(image)\n', '  File "C:\\Users\\Andrea Bassi\\anaconda3\\envs\\scopefoundry\\lib\\site-packages\\pyqtgraph\\graphicsItems\\ImageItem.py", line 342, in updateImage\n    return self.setImage(*args, **defaults)\n', '  File "C:\\Users\\Andrea Bassi\\anaconda3\\envs\\scopefoundry\\lib\\site-packages\\pyqtgraph\\graphicsItems\\ImageItem.py", line 283, in setImage\n    self.sigImageChanged.emit()\n', 'SystemError: <built-in method emit of PyQt5.QtCore.pyqtBoundSignal object at 0x000001C1099EC490> returned a result with an error set\n']
2020-07-23T13:21:39|ERROR|FakeCameraMeasurement|fake_camera_image Failed to update figure1: <built-in method emit of PyQt5.QtCore.pyqtBoundSignal object at 0x000001C1099EC490> returned a result with an error set. ['Traceback (most recent call last):\n', '  File "C:\\Users\\Andrea Bassi\\anaconda3\\envs\\scopefoundry\\lib\\site-packages\\pyqtgraph\\graphicsItems\\HistogramLUTItem.py", line 195, in imageChanged\n    h = self.imageItem().getHistogram()\n', '  File "C:\\Users\\Andrea Bassi\\anaconda3\\envs\\scopefoundry\\lib\\site-packages\\pyqtgraph\\graphicsItems\\ImageItem.py", line 464, in getHistogram\n    bins = np.arange(mn, mx+1.01*step, step, dtype=np.int)\n', 'ValueError: arange: cannot compute length\n', '\nThe above exception was the direct cause of the following exception:\n\n', 'Traceback (most recent call last):\n', '  File "C:\\Users\\Andrea Bassi\\anaconda3\\envs\\scopefoundry\\lib\\site-packages\\ScopeFoundry\\measurement.py", line 273, in _on_display_update_timer\n    self.update_display()\n', '  File "C:\\Users\\Andrea Bassi\\OneDrive - Politecnico di Milano\\Documenti\\PythonProjects\\BassiScopeFoundryMicroscopes\\Microscopes\\CellRecongnitionMicroscope\\FakeCameraMeasurement.py", line 87, in update_display\n    self.imv.setImage((self.displayed_image), autoLevels=self.settings.autoLevels.val, autoRange=self.settings.autoRange.val)\n', '  File "C:\\Users\\Andrea Bassi\\anaconda3\\envs\\scopefoundry\\lib\\site-packages\\pyqtgraph\\imageview\\ImageView.py", line 301, in setImage\n    self.updateImage(autoHistogramRange=autoHistogramRange)\n', '  File "C:\\Users\\Andrea Bassi\\anaconda3\\envs\\scopefoundry\\lib\\site-packages\\pyqtgraph\\imageview\\ImageView.py", line 676, in updateImage\n    self.imageItem.updateImage(image)\n', '  File "C:\\Users\\Andrea Bassi\\anaconda3\\envs\\scopefoundry\\lib\\site-packages\\pyqtgraph\\graphicsItems\\ImageItem.py", line 342, in updateImage\n    return self.setImage(*args, **defaults)\n', '  File "C:\\Users\\Andrea Bassi\\anaconda3\\envs\\scopefoundry\\lib\\site-packages\\pyqtgraph\\graphicsItems\\ImageItem.py", line 283, in setImage\n    self.sigImageChanged.emit()\n', 'SystemError: <built-in method emit of PyQt5.QtCore.pyqtBoundSignal object at 0x000001C1099EC490> returned a result with an error set\n']
2020-07-23T13:21:39|ERROR|FakeCameraMeasurement|fake_camera_image Failed to update figure1: <built-in method emit of PyQt5.QtCore.pyqtBoundSignal object at 0x000001C1099EC490> returned a result with an error set. ['Traceback (most recent call last):\n', '  File "C:\\Users\\Andrea Bassi\\anaconda3\\envs\\scopefoundry\\lib\\site-packages\\pyqtgraph\\graphicsItems\\HistogramLUTItem.py", line 195, in imageChanged\n    h = self.imageItem().getHistogram()\n', '  File "C:\\Users\\Andrea Bassi\\anaconda3\\envs\\scopefoundry\\lib\\site-packages\\pyqtgraph\\graphicsItems\\ImageItem.py", line 464, in getHistogram\n    bins = np.arange(mn, mx+1.01*step, step, dtype=np.int)\n', 'ValueError: arange: cannot compute length\n', '\nThe above exception was the direct cause of the following exception:\n\n', 'Traceback (most recent call last):\n', '  File "C:\\Users\\Andrea Bassi\\anaconda3\\envs\\scopefoundry\\lib\\site-packages\\ScopeFoundry\\measurement.py", line 273, in _on_display_update_timer\n    self.update_display()\n', '  File "C:\\Users\\Andrea Bassi\\OneDrive - Politecnico di Milano\\Documenti\\PythonProjects\\BassiScopeFoundryMicroscopes\\Microscopes\\CellRecongnitionMicroscope\\FakeCameraMeasurement.py", line 87, in update_display\n    self.imv.setImage((self.displayed_image), autoLevels=self.settings.autoLevels.val, autoRange=self.settings.autoRange.val)\n', '  File "C:\\Users\\Andrea Bassi\\anaconda3\\envs\\scopefoundry\\lib\\site-packages\\pyqtgraph\\imageview\\ImageView.py", line 301, in setImage\n    self.updateImage(autoHistogramRange=autoHistogramRange)\n', '  File "C:\\Users\\Andrea Bassi\\anaconda3\\envs\\scopefoundry\\lib\\site-packages\\pyqtgraph\\imageview\\ImageView.py", line 676, in updateImage\n    self.imageItem.updateImage(image)\n', '  File "C:\\Users\\Andrea Bassi\\anaconda3\\envs\\scopefoundry\\lib\\site-packages\\pyqtgraph\\graphicsItems\\ImageItem.py", line 342, in updateImage\n    return self.setImage(*args, **defaults)\n', '  File "C:\\Users\\Andrea Bassi\\anaconda3\\envs\\scopefoundry\\lib\\site-packages\\pyqtgraph\\graphicsItems\\ImageItem.py", line 283, in setImage\n    self.sigImageChanged.emit()\n', 'SystemError: <built-in method emit of PyQt5.QtCore.pyqtBoundSignal object at 0x000001C1099EC490> returned a result with an error set\n']
2020-07-23T13:21:39|ERROR|FakeCameraMeasurement|fake_camera_image Failed to update figure1: <built-in method emit of PyQt5.QtCore.pyqtBoundSignal object at 0x000001C1099EC490> returned a result with an error set. ['Traceback (most recent call last):\n', '  File "C:\\Users\\Andrea Bassi\\anaconda3\\envs\\scopefoundry\\lib\\site-packages\\pyqtgraph\\graphicsItems\\HistogramLUTItem.py", line 195, in imageChanged\n    h = self.imageItem().getHistogram()\n', '  File "C:\\Users\\Andrea Bassi\\anaconda3\\envs\\scopefoundry\\lib\\site-packages\\pyqtgraph\\graphicsItems\\ImageItem.py", line 464, in getHistogram\n    bins = np.arange(mn, mx+1.01*step, step, dtype=np.int)\n', 'ValueError: arange: cannot compute length\n', '\nThe above exception was the direct cause of the following exception:\n\n', 'Traceback (most recent call last):\n', '  File "C:\\Users\\Andrea Bassi\\anaconda3\\envs\\scopefoundry\\lib\\site-packages\\ScopeFoundry\\measurement.py", line 273, in _on_display_update_timer\n    self.update_display()\n', '  File "C:\\Users\\Andrea Bassi\\OneDrive - Politecnico di Milano\\Documenti\\PythonProjects\\BassiScopeFoundryMicroscopes\\Microscopes\\CellRecongnitionMicroscope\\FakeCameraMeasurement.py", line 87, in update_display\n    self.imv.setImage((self.displayed_image), autoLevels=self.settings.autoLevels.val, autoRange=self.settings.autoRange.val)\n', '  File "C:\\Users\\Andrea Bassi\\anaconda3\\envs\\scopefoundry\\lib\\site-packages\\pyqtgraph\\imageview\\ImageView.py", line 301, in setImage\n    self.updateImage(autoHistogramRange=autoHistogramRange)\n', '  File "C:\\Users\\Andrea Bassi\\anaconda3\\envs\\scopefoundry\\lib\\site-packages\\pyqtgraph\\imageview\\ImageView.py", line 676, in updateImage\n    self.imageItem.updateImage(image)\n', '  File "C:\\Users\\Andrea Bassi\\anaconda3\\envs\\scopefoundry\\lib\\site-packages\\pyqtgraph\\graphicsItems\\ImageItem.py", line 342, in updateImage\n    return self.setImage(*args, **defaults)\n', '  File "C:\\Users\\Andrea Bassi\\anaconda3\\envs\\scopefoundry\\lib\\site-packages\\pyqtgraph\\graphicsItems\\ImageItem.py", line 283, in setImage\n    self.sigImageChanged.emit()\n', 'SystemError: <built-in method emit of PyQt5.QtCore.pyqtBoundSignal object at 0x000001C1099EC490> returned a result with an error set\n']
2020-07-23T13:21:39|ERROR|FakeCameraMeasurement|fake_camera_image Failed to update figure1: <built-in method emit of PyQt5.QtCore.pyqtBoundSignal object at 0x000001C1099EC490> returned a result with an error set. ['Traceback (most recent call last):\n', '  File "C:\\Users\\Andrea Bassi\\anaconda3\\envs\\scopefoundry\\lib\\site-packages\\pyqtgraph\\graphicsItems\\HistogramLUTItem.py", line 195, in imageChanged\n    h = self.imageItem().getHistogram()\n', '  File "C:\\Users\\Andrea Bassi\\anaconda3\\envs\\scopefoundry\\lib\\site-packages\\pyqtgraph\\graphicsItems\\ImageItem.py", line 464, in getHistogram\n    bins = np.arange(mn, mx+1.01*step, step, dtype=np.int)\n', 'ValueError: arange: cannot compute length\n', '\nThe above exception was the direct cause of the following exception:\n\n', 'Traceback (most recent call last):\n', '  File "C:\\Users\\Andrea Bassi\\anaconda3\\envs\\scopefoundry\\lib\\site-packages\\ScopeFoundry\\measurement.py", line 273, in _on_display_update_timer\n    self.update_display()\n', '  File "C:\\Users\\Andrea Bassi\\OneDrive - Politecnico di Milano\\Documenti\\PythonProjects\\BassiScopeFoundryMicroscopes\\Microscopes\\CellRecongnitionMicroscope\\FakeCameraMeasurement.py", line 87, in update_display\n    self.imv.setImage((self.displayed_image), autoLevels=self.settings.autoLevels.val, autoRange=self.settings.autoRange.val)\n', '  File "C:\\Users\\Andrea Bassi\\anaconda3\\envs\\scopefoundry\\lib\\site-packages\\pyqtgraph\\imageview\\ImageView.py", line 301, in setImage\n    self.updateImage(autoHistogramRange=autoHistogramRange)\n', '  File "C:\\Users\\Andrea Bassi\\anaconda3\\envs\\scopefoundry\\lib\\site-packages\\pyqtgraph\\imageview\\ImageView.py", line 676, in updateImage\n    self.imageItem.updateImage(image)\n', '  File "C:\\Users\\Andrea Bassi\\anaconda3\\envs\\scopefoundry\\lib\\site-packages\\pyqtgraph\\graphicsItems\\ImageItem.py", line 342, in updateImage\n    return self.setImage(*args, **defaults)\n', '  File "C:\\Users\\Andrea Bassi\\anaconda3\\envs\\scopefoundry\\lib\\site-packages\\pyqtgraph\\graphicsItems\\ImageItem.py", line 283, in setImage\n    self.sigImageChanged.emit()\n', 'SystemError: <built-in method emit of PyQt5.QtCore.pyqtBoundSignal object at 0x000001C1099EC490> returned a result with an error set\n']
2020-07-23T13:21:39|ERROR|FakeCameraMeasurement|fake_camera_image Failed to update figure1: <built-in method emit of PyQt5.QtCore.pyqtBoundSignal object at 0x000001C1099EC490> returned a result with an error set. ['Traceback (most recent call last):\n', '  File "C:\\Users\\Andrea Bassi\\anaconda3\\envs\\scopefoundry\\lib\\site-packages\\pyqtgraph\\graphicsItems\\HistogramLUTItem.py", line 195, in imageChanged\n    h = self.imageItem().getHistogram()\n', '  File "C:\\Users\\Andrea Bassi\\anaconda3\\envs\\scopefoundry\\lib\\site-packages\\pyqtgraph\\graphicsItems\\ImageItem.py", line 464, in getHistogram\n    bins = np.arange(mn, mx+1.01*step, step, dtype=np.int)\n', 'ValueError: arange: cannot compute length\n', '\nThe above exception was the direct cause of the following exception:\n\n', 'Traceback (most recent call last):\n', '  File "C:\\Users\\Andrea Bassi\\anaconda3\\envs\\scopefoundry\\lib\\site-packages\\ScopeFoundry\\measurement.py", line 273, in _on_display_update_timer\n    self.update_display()\n', '  File "C:\\Users\\Andrea Bassi\\OneDrive - Politecnico di Milano\\Documenti\\PythonProjects\\BassiScopeFoundryMicroscopes\\Microscopes\\CellRecongnitionMicroscope\\FakeCameraMeasurement.py", line 87, in update_display\n    self.imv.setImage((self.displayed_image), autoLevels=self.settings.autoLevels.val, autoRange=self.settings.autoRange.val)\n', '  File "C:\\Users\\Andrea Bassi\\anaconda3\\envs\\scopefoundry\\lib\\site-packages\\pyqtgraph\\imageview\\ImageView.py", line 301, in setImage\n    self.updateImage(autoHistogramRange=autoHistogramRange)\n', '  File "C:\\Users\\Andrea Bassi\\anaconda3\\envs\\scopefoundry\\lib\\site-packages\\pyqtgraph\\imageview\\ImageView.py", line 676, in updateImage\n    self.imageItem.updateImage(image)\n', '  File "C:\\Users\\Andrea Bassi\\anaconda3\\envs\\scopefoundry\\lib\\site-packages\\pyqtgraph\\graphicsItems\\ImageItem.py", line 342, in updateImage\n    return self.setImage(*args, **defaults)\n', '  File "C:\\Users\\Andrea Bassi\\anaconda3\\envs\\scopefoundry\\lib\\site-packages\\pyqtgraph\\graphicsItems\\ImageItem.py", line 283, in setImage\n    self.sigImageChanged.emit()\n', 'SystemError: <built-in method emit of PyQt5.QtCore.pyqtBoundSignal object at 0x000001C1099EC490> returned a result with an error set\n']
2020-07-23T13:21:39|ERROR|FakeCameraMeasurement|fake_camera_image Failed to update figure1: <built-in method emit of PyQt5.QtCore.pyqtBoundSignal object at 0x000001C1099EC490> returned a result with an error set. ['Traceback (most recent call last):\n', '  File "C:\\Users\\Andrea Bassi\\anaconda3\\envs\\scopefoundry\\lib\\site-packages\\pyqtgraph\\graphicsItems\\HistogramLUTItem.py", line 195, in imageChanged\n    h = self.imageItem().getHistogram()\n', '  File "C:\\Users\\Andrea Bassi\\anaconda3\\envs\\scopefoundry\\lib\\site-packages\\pyqtgraph\\graphicsItems\\ImageItem.py", line 464, in getHistogram\n    bins = np.arange(mn, mx+1.01*step, step, dtype=np.int)\n', 'ValueError: arange: cannot compute length\n', '\nThe above exception was the direct cause of the following exception:\n\n', 'Traceback (most recent call last):\n', '  File "C:\\Users\\Andrea Bassi\\anaconda3\\envs\\scopefoundry\\lib\\site-packages\\ScopeFoundry\\measurement.py", line 273, in _on_display_update_timer\n    self.update_display()\n', '  File "C:\\Users\\Andrea Bassi\\OneDrive - Politecnico di Milano\\Documenti\\PythonProjects\\BassiScopeFoundryMicroscopes\\Microscopes\\CellRecongnitionMicroscope\\FakeCameraMeasurement.py", line 87, in update_display\n    self.imv.setImage((self.displayed_image), autoLevels=self.settings.autoLevels.val, autoRange=self.settings.autoRange.val)\n', '  File "C:\\Users\\Andrea Bassi\\anaconda3\\envs\\scopefoundry\\lib\\site-packages\\pyqtgraph\\imageview\\ImageView.py", line 301, in setImage\n    self.updateImage(autoHistogramRange=autoHistogramRange)\n', '  File "C:\\Users\\Andrea Bassi\\anaconda3\\envs\\scopefoundry\\lib\\site-packages\\pyqtgraph\\imageview\\ImageView.py", line 676, in updateImage\n    self.imageItem.updateImage(image)\n', '  File "C:\\Users\\Andrea Bassi\\anaconda3\\envs\\scopefoundry\\lib\\site-packages\\pyqtgraph\\graphicsItems\\ImageItem.py", line 342, in updateImage\n    return self.setImage(*args, **defaults)\n', '  File "C:\\Users\\Andrea Bassi\\anaconda3\\envs\\scopefoundry\\lib\\site-packages\\pyqtgraph\\graphicsItems\\ImageItem.py", line 283, in setImage\n    self.sigImageChanged.emit()\n', 'SystemError: <built-in method emit of PyQt5.QtCore.pyqtBoundSignal object at 0x000001C1099EC490> returned a result with an error set\n']
2020-07-23T13:21:39|ERROR|FakeCameraMeasurement|fake_camera_image Failed to update figure1: <built-in method emit of PyQt5.QtCore.pyqtBoundSignal object at 0x000001C119A3BEB8> returned a result with an error set. ['Traceback (most recent call last):\n', '  File "C:\\Users\\Andrea Bassi\\anaconda3\\envs\\scopefoundry\\lib\\site-packages\\pyqtgraph\\graphicsItems\\HistogramLUTItem.py", line 195, in imageChanged\n    h = self.imageItem().getHistogram()\n', '  File "C:\\Users\\Andrea Bassi\\anaconda3\\envs\\scopefoundry\\lib\\site-packages\\pyqtgraph\\graphicsItems\\ImageItem.py", line 464, in getHistogram\n    bins = np.arange(mn, mx+1.01*step, step, dtype=np.int)\n', 'ValueError: arange: cannot compute length\n', '\nThe above exception was the direct cause of the following exception:\n\n', 'Traceback (most recent call last):\n', '  File "C:\\Users\\Andrea Bassi\\anaconda3\\envs\\scopefoundry\\lib\\site-packages\\ScopeFoundry\\measurement.py", line 273, in _on_display_update_timer\n    self.update_display()\n', '  File "C:\\Users\\Andrea Bassi\\OneDrive - Politecnico di Milano\\Documenti\\PythonProjects\\BassiScopeFoundryMicroscopes\\Microscopes\\CellRecongnitionMicroscope\\FakeCameraMeasurement.py", line 87, in update_display\n    self.imv.setImage((self.displayed_image), autoLevels=self.settings.autoLevels.val, autoRange=self.settings.autoRange.val)\n', '  File "C:\\Users\\Andrea Bassi\\anaconda3\\envs\\scopefoundry\\lib\\site-packages\\pyqtgraph\\imageview\\ImageView.py", line 301, in setImage\n    self.updateImage(autoHistogramRange=autoHistogramRange)\n', '  File "C:\\Users\\Andrea Bassi\\anaconda3\\envs\\scopefoundry\\lib\\site-packages\\pyqtgraph\\imageview\\ImageView.py", line 676, in updateImage\n    self.imageItem.updateImage(image)\n', '  File "C:\\Users\\Andrea Bassi\\anaconda3\\envs\\scopefoundry\\lib\\site-packages\\pyqtgraph\\graphicsItems\\ImageItem.py", line 342, in updateImage\n    return self.setImage(*args, **defaults)\n', '  File "C:\\Users\\Andrea Bassi\\anaconda3\\envs\\scopefoundry\\lib\\site-packages\\pyqtgraph\\graphicsItems\\ImageItem.py", line 283, in setImage\n    self.sigImageChanged.emit()\n', 'SystemError: <built-in method emit of PyQt5.QtCore.pyqtBoundSignal object at 0x000001C119A3BEB8> returned a result with an error set\n']
2020-07-23T13:21:39|ERROR|FakeCameraMeasurement|fake_camera_image Failed to update figure1: <built-in method emit of PyQt5.QtCore.pyqtBoundSignal object at 0x000001C119A3BF58> returned a result with an error set. ['Traceback (most recent call last):\n', '  File "C:\\Users\\Andrea Bassi\\anaconda3\\envs\\scopefoundry\\lib\\site-packages\\pyqtgraph\\graphicsItems\\HistogramLUTItem.py", line 195, in imageChanged\n    h = self.imageItem().getHistogram()\n', '  File "C:\\Users\\Andrea Bassi\\anaconda3\\envs\\scopefoundry\\lib\\site-packages\\pyqtgraph\\graphicsItems\\ImageItem.py", line 464, in getHistogram\n    bins = np.arange(mn, mx+1.01*step, step, dtype=np.int)\n', 'ValueError: arange: cannot compute length\n', '\nThe above exception was the direct cause of the following exception:\n\n', 'Traceback (most recent call last):\n', '  File "C:\\Users\\Andrea Bassi\\anaconda3\\envs\\scopefoundry\\lib\\site-packages\\ScopeFoundry\\measurement.py", line 273, in _on_display_update_timer\n    self.update_display()\n', '  File "C:\\Users\\Andrea Bassi\\OneDrive - Politecnico di Milano\\Documenti\\PythonProjects\\BassiScopeFoundryMicroscopes\\Microscopes\\CellRecongnitionMicroscope\\FakeCameraMeasurement.py", line 87, in update_display\n    self.imv.setImage((self.displayed_image), autoLevels=self.settings.autoLevels.val, autoRange=self.settings.autoRange.val)\n', '  File "C:\\Users\\Andrea Bassi\\anaconda3\\envs\\scopefoundry\\lib\\site-packages\\pyqtgraph\\imageview\\ImageView.py", line 301, in setImage\n    self.updateImage(autoHistogramRange=autoHistogramRange)\n', '  File "C:\\Users\\Andrea Bassi\\anaconda3\\envs\\scopefoundry\\lib\\site-packages\\pyqtgraph\\imageview\\ImageView.py", line 676, in updateImage\n    self.imageItem.updateImage(image)\n', '  File "C:\\Users\\Andrea Bassi\\anaconda3\\envs\\scopefoundry\\lib\\site-packages\\pyqtgraph\\graphicsItems\\ImageItem.py", line 342, in updateImage\n    return self.setImage(*args, **defaults)\n', '  File "C:\\Users\\Andrea Bassi\\anaconda3\\envs\\scopefoundry\\lib\\site-packages\\pyqtgraph\\graphicsItems\\ImageItem.py", line 283, in setImage\n    self.sigImageChanged.emit()\n', 'SystemError: <built-in method emit of PyQt5.QtCore.pyqtBoundSignal object at 0x000001C119A3BF58> returned a result with an error set\n']
2020-07-23T13:21:39|ERROR|FakeCameraMeasurement|fake_camera_image Failed to update figure1: <built-in method emit of PyQt5.QtCore.pyqtBoundSignal object at 0x000001C119A3BB98> returned a result with an error set. ['Traceback (most recent call last):\n', '  File "C:\\Users\\Andrea Bassi\\anaconda3\\envs\\scopefoundry\\lib\\site-packages\\pyqtgraph\\graphicsItems\\HistogramLUTItem.py", line 195, in imageChanged\n    h = self.imageItem().getHistogram()\n', '  File "C:\\Users\\Andrea Bassi\\anaconda3\\envs\\scopefoundry\\lib\\site-packages\\pyqtgraph\\graphicsItems\\ImageItem.py", line 464, in getHistogram\n    bins = np.arange(mn, mx+1.01*step, step, dtype=np.int)\n', 'ValueError: arange: cannot compute length\n', '\nThe above exception was the direct cause of the following exception:\n\n', 'Traceback (most recent call last):\n', '  File "C:\\Users\\Andrea Bassi\\anaconda3\\envs\\scopefoundry\\lib\\site-packages\\ScopeFoundry\\measurement.py", line 273, in _on_display_update_timer\n    self.update_display()\n', '  File "C:\\Users\\Andrea Bassi\\OneDrive - Politecnico di Milano\\Documenti\\PythonProjects\\BassiScopeFoundryMicroscopes\\Microscopes\\CellRecongnitionMicroscope\\FakeCameraMeasurement.py", line 87, in update_display\n    self.imv.setImage((self.displayed_image), autoLevels=self.settings.autoLevels.val, autoRange=self.settings.autoRange.val)\n', '  File "C:\\Users\\Andrea Bassi\\anaconda3\\envs\\scopefoundry\\lib\\site-packages\\pyqtgraph\\imageview\\ImageView.py", line 301, in setImage\n    self.updateImage(autoHistogramRange=autoHistogramRange)\n', '  File "C:\\Users\\Andrea Bassi\\anaconda3\\envs\\scopefoundry\\lib\\site-packages\\pyqtgraph\\imageview\\ImageView.py", line 676, in updateImage\n    self.imageItem.updateImage(image)\n', '  File "C:\\Users\\Andrea Bassi\\anaconda3\\envs\\scopefoundry\\lib\\site-packages\\pyqtgraph\\graphicsItems\\ImageItem.py", line 342, in updateImage\n    return self.setImage(*args, **defaults)\n', '  File "C:\\Users\\Andrea Bassi\\anaconda3\\envs\\scopefoundry\\lib\\site-packages\\pyqtgraph\\graphicsItems\\ImageItem.py", line 283, in setImage\n    self.sigImageChanged.emit()\n', 'SystemError: <built-in method emit of PyQt5.QtCore.pyqtBoundSignal object at 0x000001C119A3BB98> returned a result with an error set\n']
2020-07-23T13:21:39|ERROR|FakeCameraMeasurement|fake_camera_image Failed to update figure1: <built-in method emit of PyQt5.QtCore.pyqtBoundSignal object at 0x000001C119A3B580> returned a result with an error set. ['Traceback (most recent call last):\n', '  File "C:\\Users\\Andrea Bassi\\anaconda3\\envs\\scopefoundry\\lib\\site-packages\\pyqtgraph\\graphicsItems\\HistogramLUTItem.py", line 195, in imageChanged\n    h = self.imageItem().getHistogram()\n', '  File "C:\\Users\\Andrea Bassi\\anaconda3\\envs\\scopefoundry\\lib\\site-packages\\pyqtgraph\\graphicsItems\\ImageItem.py", line 464, in getHistogram\n    bins = np.arange(mn, mx+1.01*step, step, dtype=np.int)\n', 'ValueError: arange: cannot compute length\n', '\nThe above exception was the direct cause of the following exception:\n\n', 'Traceback (most recent call last):\n', '  File "C:\\Users\\Andrea Bassi\\anaconda3\\envs\\scopefoundry\\lib\\site-packages\\ScopeFoundry\\measurement.py", line 273, in _on_display_update_timer\n    self.update_display()\n', '  File "C:\\Users\\Andrea Bassi\\OneDrive - Politecnico di Milano\\Documenti\\PythonProjects\\BassiScopeFoundryMicroscopes\\Microscopes\\CellRecongnitionMicroscope\\FakeCameraMeasurement.py", line 87, in update_display\n    self.imv.setImage((self.displayed_image), autoLevels=self.settings.autoLevels.val, autoRange=self.settings.autoRange.val)\n', '  File "C:\\Users\\Andrea Bassi\\anaconda3\\envs\\scopefoundry\\lib\\site-packages\\pyqtgraph\\imageview\\ImageView.py", line 301, in setImage\n    self.updateImage(autoHistogramRange=autoHistogramRange)\n', '  File "C:\\Users\\Andrea Bassi\\anaconda3\\envs\\scopefoundry\\lib\\site-packages\\pyqtgraph\\imageview\\ImageView.py", line 676, in updateImage\n    self.imageItem.updateImage(image)\n', '  File "C:\\Users\\Andrea Bassi\\anaconda3\\envs\\scopefoundry\\lib\\site-packages\\pyqtgraph\\graphicsItems\\ImageItem.py", line 342, in updateImage\n    return self.setImage(*args, **defaults)\n', '  File "C:\\Users\\Andrea Bassi\\anaconda3\\envs\\scopefoundry\\lib\\site-packages\\pyqtgraph\\graphicsItems\\ImageItem.py", line 283, in setImage\n    self.sigImageChanged.emit()\n', 'SystemError: <built-in method emit of PyQt5.QtCore.pyqtBoundSignal object at 0x000001C119A3B580> returned a result with an error set\n']
2020-07-23T13:21:39|ERROR|FakeCameraMeasurement|fake_camera_image Failed to update figure1: <built-in method emit of PyQt5.QtCore.pyqtBoundSignal object at 0x000001C1099EC490> returned a result with an error set. ['Traceback (most recent call last):\n', '  File "C:\\Users\\Andrea Bassi\\anaconda3\\envs\\scopefoundry\\lib\\site-packages\\pyqtgraph\\graphicsItems\\HistogramLUTItem.py", line 195, in imageChanged\n    h = self.imageItem().getHistogram()\n', '  File "C:\\Users\\Andrea Bassi\\anaconda3\\envs\\scopefoundry\\lib\\site-packages\\pyqtgraph\\graphicsItems\\ImageItem.py", line 464, in getHistogram\n    bins = np.arange(mn, mx+1.01*step, step, dtype=np.int)\n', 'ValueError: arange: cannot compute length\n', '\nThe above exception was the direct cause of the following exception:\n\n', 'Traceback (most recent call last):\n', '  File "C:\\Users\\Andrea Bassi\\anaconda3\\envs\\scopefoundry\\lib\\site-packages\\ScopeFoundry\\measurement.py", line 273, in _on_display_update_timer\n    self.update_display()\n', '  File "C:\\Users\\Andrea Bassi\\OneDrive - Politecnico di Milano\\Documenti\\PythonProjects\\BassiScopeFoundryMicroscopes\\Microscopes\\CellRecongnitionMicroscope\\FakeCameraMeasurement.py", line 87, in update_display\n    self.imv.setImage((self.displayed_image), autoLevels=self.settings.autoLevels.val, autoRange=self.settings.autoRange.val)\n', '  File "C:\\Users\\Andrea Bassi\\anaconda3\\envs\\scopefoundry\\lib\\site-packages\\pyqtgraph\\imageview\\ImageView.py", line 301, in setImage\n    self.updateImage(autoHistogramRange=autoHistogramRange)\n', '  File "C:\\Users\\Andrea Bassi\\anaconda3\\envs\\scopefoundry\\lib\\site-packages\\pyqtgraph\\imageview\\ImageView.py", line 676, in updateImage\n    self.imageItem.updateImage(image)\n', '  File "C:\\Users\\Andrea Bassi\\anaconda3\\envs\\scopefoundry\\lib\\site-packages\\pyqtgraph\\graphicsItems\\ImageItem.py", line 342, in updateImage\n    return self.setImage(*args, **defaults)\n', '  File "C:\\Users\\Andrea Bassi\\anaconda3\\envs\\scopefoundry\\lib\\site-packages\\pyqtgraph\\graphicsItems\\ImageItem.py", line 283, in setImage\n    self.sigImageChanged.emit()\n', 'SystemError: <built-in method emit of PyQt5.QtCore.pyqtBoundSignal object at 0x000001C1099EC490> returned a result with an error set\n']
2020-07-23T13:21:39|ERROR|FakeCameraMeasurement|fake_camera_image Failed to update figure1: <built-in method emit of PyQt5.QtCore.pyqtBoundSignal object at 0x000001C1099EC490> returned a result with an error set. ['Traceback (most recent call last):\n', '  File "C:\\Users\\Andrea Bassi\\anaconda3\\envs\\scopefoundry\\lib\\site-packages\\pyqtgraph\\graphicsItems\\HistogramLUTItem.py", line 195, in imageChanged\n    h = self.imageItem().getHistogram()\n', '  File "C:\\Users\\Andrea Bassi\\anaconda3\\envs\\scopefoundry\\lib\\site-packages\\pyqtgraph\\graphicsItems\\ImageItem.py", line 464, in getHistogram\n    bins = np.arange(mn, mx+1.01*step, step, dtype=np.int)\n', 'ValueError: arange: cannot compute length\n', '\nThe above exception was the direct cause of the following exception:\n\n', 'Traceback (most recent call last):\n', '  File "C:\\Users\\Andrea Bassi\\anaconda3\\envs\\scopefoundry\\lib\\site-packages\\ScopeFoundry\\measurement.py", line 273, in _on_display_update_timer\n    self.update_display()\n', '  File "C:\\Users\\Andrea Bassi\\OneDrive - Politecnico di Milano\\Documenti\\PythonProjects\\BassiScopeFoundryMicroscopes\\Microscopes\\CellRecongnitionMicroscope\\FakeCameraMeasurement.py", line 87, in update_display\n    self.imv.setImage((self.displayed_image), autoLevels=self.settings.autoLevels.val, autoRange=self.settings.autoRange.val)\n', '  File "C:\\Users\\Andrea Bassi\\anaconda3\\envs\\scopefoundry\\lib\\site-packages\\pyqtgraph\\imageview\\ImageView.py", line 301, in setImage\n    self.updateImage(autoHistogramRange=autoHistogramRange)\n', '  File "C:\\Users\\Andrea Bassi\\anaconda3\\envs\\scopefoundry\\lib\\site-packages\\pyqtgraph\\imageview\\ImageView.py", line 676, in updateImage\n    self.imageItem.updateImage(image)\n', '  File "C:\\Users\\Andrea Bassi\\anaconda3\\envs\\scopefoundry\\lib\\site-packages\\pyqtgraph\\graphicsItems\\ImageItem.py", line 342, in updateImage\n    return self.setImage(*args, **defaults)\n', '  File "C:\\Users\\Andrea Bassi\\anaconda3\\envs\\scopefoundry\\lib\\site-packages\\pyqtgraph\\graphicsItems\\ImageItem.py", line 283, in setImage\n    self.sigImageChanged.emit()\n', 'SystemError: <built-in method emit of PyQt5.QtCore.pyqtBoundSignal object at 0x000001C1099EC490> returned a result with an error set\n']
2020-07-23T13:21:39|ERROR|FakeCameraMeasurement|fake_camera_image Failed to update figure1: <built-in method emit of PyQt5.QtCore.pyqtBoundSignal object at 0x000001C1099EC490> returned a result with an error set. ['Traceback (most recent call last):\n', '  File "C:\\Users\\Andrea Bassi\\anaconda3\\envs\\scopefoundry\\lib\\site-packages\\pyqtgraph\\graphicsItems\\HistogramLUTItem.py", line 195, in imageChanged\n    h = self.imageItem().getHistogram()\n', '  File "C:\\Users\\Andrea Bassi\\anaconda3\\envs\\scopefoundry\\lib\\site-packages\\pyqtgraph\\graphicsItems\\ImageItem.py", line 464, in getHistogram\n    bins = np.arange(mn, mx+1.01*step, step, dtype=np.int)\n', 'ValueError: arange: cannot compute length\n', '\nThe above exception was the direct cause of the following exception:\n\n', 'Traceback (most recent call last):\n', '  File "C:\\Users\\Andrea Bassi\\anaconda3\\envs\\scopefoundry\\lib\\site-packages\\ScopeFoundry\\measurement.py", line 273, in _on_display_update_timer\n    self.update_display()\n', '  File "C:\\Users\\Andrea Bassi\\OneDrive - Politecnico di Milano\\Documenti\\PythonProjects\\BassiScopeFoundryMicroscopes\\Microscopes\\CellRecongnitionMicroscope\\FakeCameraMeasurement.py", line 87, in update_display\n    self.imv.setImage((self.displayed_image), autoLevels=self.settings.autoLevels.val, autoRange=self.settings.autoRange.val)\n', '  File "C:\\Users\\Andrea Bassi\\anaconda3\\envs\\scopefoundry\\lib\\site-packages\\pyqtgraph\\imageview\\ImageView.py", line 301, in setImage\n    self.updateImage(autoHistogramRange=autoHistogramRange)\n', '  File "C:\\Users\\Andrea Bassi\\anaconda3\\envs\\scopefoundry\\lib\\site-packages\\pyqtgraph\\imageview\\ImageView.py", line 676, in updateImage\n    self.imageItem.updateImage(image)\n', '  File "C:\\Users\\Andrea Bassi\\anaconda3\\envs\\scopefoundry\\lib\\site-packages\\pyqtgraph\\graphicsItems\\ImageItem.py", line 342, in updateImage\n    return self.setImage(*args, **defaults)\n', '  File "C:\\Users\\Andrea Bassi\\anaconda3\\envs\\scopefoundry\\lib\\site-packages\\pyqtgraph\\graphicsItems\\ImageItem.py", line 283, in setImage\n    self.sigImageChanged.emit()\n', 'SystemError: <built-in method emit of PyQt5.QtCore.pyqtBoundSignal object at 0x000001C1099EC490> returned a result with an error set\n']
2020-07-23T13:21:39|ERROR|FakeCameraMeasurement|fake_camera_image Failed to update figure1: <built-in method emit of PyQt5.QtCore.pyqtBoundSignal object at 0x000001C119A3BB48> returned a result with an error set. ['Traceback (most recent call last):\n', '  File "C:\\Users\\Andrea Bassi\\anaconda3\\envs\\scopefoundry\\lib\\site-packages\\pyqtgraph\\graphicsItems\\HistogramLUTItem.py", line 195, in imageChanged\n    h = self.imageItem().getHistogram()\n', '  File "C:\\Users\\Andrea Bassi\\anaconda3\\envs\\scopefoundry\\lib\\site-packages\\pyqtgraph\\graphicsItems\\ImageItem.py", line 464, in getHistogram\n    bins = np.arange(mn, mx+1.01*step, step, dtype=np.int)\n', 'ValueError: arange: cannot compute length\n', '\nThe above exception was the direct cause of the following exception:\n\n', 'Traceback (most recent call last):\n', '  File "C:\\Users\\Andrea Bassi\\anaconda3\\envs\\scopefoundry\\lib\\site-packages\\ScopeFoundry\\measurement.py", line 273, in _on_display_update_timer\n    self.update_display()\n', '  File "C:\\Users\\Andrea Bassi\\OneDrive - Politecnico di Milano\\Documenti\\PythonProjects\\BassiScopeFoundryMicroscopes\\Microscopes\\CellRecongnitionMicroscope\\FakeCameraMeasurement.py", line 87, in update_display\n    self.imv.setImage((self.displayed_image), autoLevels=self.settings.autoLevels.val, autoRange=self.settings.autoRange.val)\n', '  File "C:\\Users\\Andrea Bassi\\anaconda3\\envs\\scopefoundry\\lib\\site-packages\\pyqtgraph\\imageview\\ImageView.py", line 301, in setImage\n    self.updateImage(autoHistogramRange=autoHistogramRange)\n', '  File "C:\\Users\\Andrea Bassi\\anaconda3\\envs\\scopefoundry\\lib\\site-packages\\pyqtgraph\\imageview\\ImageView.py", line 676, in updateImage\n    self.imageItem.updateImage(image)\n', '  File "C:\\Users\\Andrea Bassi\\anaconda3\\envs\\scopefoundry\\lib\\site-packages\\pyqtgraph\\graphicsItems\\ImageItem.py", line 342, in updateImage\n    return self.setImage(*args, **defaults)\n', '  File "C:\\Users\\Andrea Bassi\\anaconda3\\envs\\scopefoundry\\lib\\site-packages\\pyqtgraph\\graphicsItems\\ImageItem.py", line 283, in setImage\n    self.sigImageChanged.emit()\n', 'SystemError: <built-in method emit of PyQt5.QtCore.pyqtBoundSignal object at 0x000001C119A3BB48> returned a result with an error set\n']
2020-07-23T13:21:40|ERROR|FakeCameraMeasurement|fake_camera_image Failed to update figure1: <built-in method emit of PyQt5.QtCore.pyqtBoundSignal object at 0x000001C119A3B580> returned a result with an error set. ['Traceback (most recent call last):\n', '  File "C:\\Users\\Andrea Bassi\\anaconda3\\envs\\scopefoundry\\lib\\site-packages\\pyqtgraph\\graphicsItems\\HistogramLUTItem.py", line 195, in imageChanged\n    h = self.imageItem().getHistogram()\n', '  File "C:\\Users\\Andrea Bassi\\anaconda3\\envs\\scopefoundry\\lib\\site-packages\\pyqtgraph\\graphicsItems\\ImageItem.py", line 464, in getHistogram\n    bins = np.arange(mn, mx+1.01*step, step, dtype=np.int)\n', 'ValueError: arange: cannot compute length\n', '\nThe above exception was the direct cause of the following exception:\n\n', 'Traceback (most recent call last):\n', '  File "C:\\Users\\Andrea Bassi\\anaconda3\\envs\\scopefoundry\\lib\\site-packages\\ScopeFoundry\\measurement.py", line 273, in _on_display_update_timer\n    self.update_display()\n', '  File "C:\\Users\\Andrea Bassi\\OneDrive - Politecnico di Milano\\Documenti\\PythonProjects\\BassiScopeFoundryMicroscopes\\Microscopes\\CellRecongnitionMicroscope\\FakeCameraMeasurement.py", line 87, in update_display\n    self.imv.setImage((self.displayed_image), autoLevels=self.settings.autoLevels.val, autoRange=self.settings.autoRange.val)\n', '  File "C:\\Users\\Andrea Bassi\\anaconda3\\envs\\scopefoundry\\lib\\site-packages\\pyqtgraph\\imageview\\ImageView.py", line 301, in setImage\n    self.updateImage(autoHistogramRange=autoHistogramRange)\n', '  File "C:\\Users\\Andrea Bassi\\anaconda3\\envs\\scopefoundry\\lib\\site-packages\\pyqtgraph\\imageview\\ImageView.py", line 676, in updateImage\n    self.imageItem.updateImage(image)\n', '  File "C:\\Users\\Andrea Bassi\\anaconda3\\envs\\scopefoundry\\lib\\site-packages\\pyqtgraph\\graphicsItems\\ImageItem.py", line 342, in updateImage\n    return self.setImage(*args, **defaults)\n', '  File "C:\\Users\\Andrea Bassi\\anaconda3\\envs\\scopefoundry\\lib\\site-packages\\pyqtgraph\\graphicsItems\\ImageItem.py", line 283, in setImage\n    self.sigImageChanged.emit()\n', 'SystemError: <built-in method emit of PyQt5.QtCore.pyqtBoundSignal object at 0x000001C119A3B580> returned a result with an error set\n']
2020-07-23T13:21:40|ERROR|FakeCameraMeasurement|fake_camera_image Failed to update figure1: <built-in method emit of PyQt5.QtCore.pyqtBoundSignal object at 0x000001C119A3B580> returned a result with an error set. ['Traceback (most recent call last):\n', '  File "C:\\Users\\Andrea Bassi\\anaconda3\\envs\\scopefoundry\\lib\\site-packages\\pyqtgraph\\graphicsItems\\HistogramLUTItem.py", line 195, in imageChanged\n    h = self.imageItem().getHistogram()\n', '  File "C:\\Users\\Andrea Bassi\\anaconda3\\envs\\scopefoundry\\lib\\site-packages\\pyqtgraph\\graphicsItems\\ImageItem.py", line 464, in getHistogram\n    bins = np.arange(mn, mx+1.01*step, step, dtype=np.int)\n', 'ValueError: arange: cannot compute length\n', '\nThe above exception was the direct cause of the following exception:\n\n', 'Traceback (most recent call last):\n', '  File "C:\\Users\\Andrea Bassi\\anaconda3\\envs\\scopefoundry\\lib\\site-packages\\ScopeFoundry\\measurement.py", line 273, in _on_display_update_timer\n    self.update_display()\n', '  File "C:\\Users\\Andrea Bassi\\OneDrive - Politecnico di Milano\\Documenti\\PythonProjects\\BassiScopeFoundryMicroscopes\\Microscopes\\CellRecongnitionMicroscope\\FakeCameraMeasurement.py", line 87, in update_display\n    self.imv.setImage((self.displayed_image), autoLevels=self.settings.autoLevels.val, autoRange=self.settings.autoRange.val)\n', '  File "C:\\Users\\Andrea Bassi\\anaconda3\\envs\\scopefoundry\\lib\\site-packages\\pyqtgraph\\imageview\\ImageView.py", line 301, in setImage\n    self.updateImage(autoHistogramRange=autoHistogramRange)\n', '  File "C:\\Users\\Andrea Bassi\\anaconda3\\envs\\scopefoundry\\lib\\site-packages\\pyqtgraph\\imageview\\ImageView.py", line 676, in updateImage\n    self.imageItem.updateImage(image)\n', '  File "C:\\Users\\Andrea Bassi\\anaconda3\\envs\\scopefoundry\\lib\\site-packages\\pyqtgraph\\graphicsItems\\ImageItem.py", line 342, in updateImage\n    return self.setImage(*args, **defaults)\n', '  File "C:\\Users\\Andrea Bassi\\anaconda3\\envs\\scopefoundry\\lib\\site-packages\\pyqtgraph\\graphicsItems\\ImageItem.py", line 283, in setImage\n    self.sigImageChanged.emit()\n', 'SystemError: <built-in method emit of PyQt5.QtCore.pyqtBoundSignal object at 0x000001C119A3B580> returned a result with an error set\n']
2020-07-23T13:21:40|ERROR|FakeCameraMeasurement|fake_camera_image Failed to update figure1: <built-in method emit of PyQt5.QtCore.pyqtBoundSignal object at 0x000001C119A3BEB8> returned a result with an error set. ['Traceback (most recent call last):\n', '  File "C:\\Users\\Andrea Bassi\\anaconda3\\envs\\scopefoundry\\lib\\site-packages\\pyqtgraph\\graphicsItems\\HistogramLUTItem.py", line 195, in imageChanged\n    h = self.imageItem().getHistogram()\n', '  File "C:\\Users\\Andrea Bassi\\anaconda3\\envs\\scopefoundry\\lib\\site-packages\\pyqtgraph\\graphicsItems\\ImageItem.py", line 464, in getHistogram\n    bins = np.arange(mn, mx+1.01*step, step, dtype=np.int)\n', 'ValueError: arange: cannot compute length\n', '\nThe above exception was the direct cause of the following exception:\n\n', 'Traceback (most recent call last):\n', '  File "C:\\Users\\Andrea Bassi\\anaconda3\\envs\\scopefoundry\\lib\\site-packages\\ScopeFoundry\\measurement.py", line 273, in _on_display_update_timer\n    self.update_display()\n', '  File "C:\\Users\\Andrea Bassi\\OneDrive - Politecnico di Milano\\Documenti\\PythonProjects\\BassiScopeFoundryMicroscopes\\Microscopes\\CellRecongnitionMicroscope\\FakeCameraMeasurement.py", line 87, in update_display\n    self.imv.setImage((self.displayed_image), autoLevels=self.settings.autoLevels.val, autoRange=self.settings.autoRange.val)\n', '  File "C:\\Users\\Andrea Bassi\\anaconda3\\envs\\scopefoundry\\lib\\site-packages\\pyqtgraph\\imageview\\ImageView.py", line 301, in setImage\n    self.updateImage(autoHistogramRange=autoHistogramRange)\n', '  File "C:\\Users\\Andrea Bassi\\anaconda3\\envs\\scopefoundry\\lib\\site-packages\\pyqtgraph\\imageview\\ImageView.py", line 676, in updateImage\n    self.imageItem.updateImage(image)\n', '  File "C:\\Users\\Andrea Bassi\\anaconda3\\envs\\scopefoundry\\lib\\site-packages\\pyqtgraph\\graphicsItems\\ImageItem.py", line 342, in updateImage\n    return self.setImage(*args, **defaults)\n', '  File "C:\\Users\\Andrea Bassi\\anaconda3\\envs\\scopefoundry\\lib\\site-packages\\pyqtgraph\\graphicsItems\\ImageItem.py", line 283, in setImage\n    self.sigImageChanged.emit()\n', 'SystemError: <built-in method emit of PyQt5.QtCore.pyqtBoundSignal object at 0x000001C119A3BEB8> returned a result with an error set\n']
2020-07-23T13:21:40|ERROR|FakeCameraMeasurement|fake_camera_image Failed to update figure1: <built-in method emit of PyQt5.QtCore.pyqtBoundSignal object at 0x000001C1099EC490> returned a result with an error set. ['Traceback (most recent call last):\n', '  File "C:\\Users\\Andrea Bassi\\anaconda3\\envs\\scopefoundry\\lib\\site-packages\\pyqtgraph\\graphicsItems\\HistogramLUTItem.py", line 195, in imageChanged\n    h = self.imageItem().getHistogram()\n', '  File "C:\\Users\\Andrea Bassi\\anaconda3\\envs\\scopefoundry\\lib\\site-packages\\pyqtgraph\\graphicsItems\\ImageItem.py", line 464, in getHistogram\n    bins = np.arange(mn, mx+1.01*step, step, dtype=np.int)\n', 'ValueError: arange: cannot compute length\n', '\nThe above exception was the direct cause of the following exception:\n\n', 'Traceback (most recent call last):\n', '  File "C:\\Users\\Andrea Bassi\\anaconda3\\envs\\scopefoundry\\lib\\site-packages\\ScopeFoundry\\measurement.py", line 273, in _on_display_update_timer\n    self.update_display()\n', '  File "C:\\Users\\Andrea Bassi\\OneDrive - Politecnico di Milano\\Documenti\\PythonProjects\\BassiScopeFoundryMicroscopes\\Microscopes\\CellRecongnitionMicroscope\\FakeCameraMeasurement.py", line 87, in update_display\n    self.imv.setImage((self.displayed_image), autoLevels=self.settings.autoLevels.val, autoRange=self.settings.autoRange.val)\n', '  File "C:\\Users\\Andrea Bassi\\anaconda3\\envs\\scopefoundry\\lib\\site-packages\\pyqtgraph\\imageview\\ImageView.py", line 301, in setImage\n    self.updateImage(autoHistogramRange=autoHistogramRange)\n', '  File "C:\\Users\\Andrea Bassi\\anaconda3\\envs\\scopefoundry\\lib\\site-packages\\pyqtgraph\\imageview\\ImageView.py", line 676, in updateImage\n    self.imageItem.updateImage(image)\n', '  File "C:\\Users\\Andrea Bassi\\anaconda3\\envs\\scopefoundry\\lib\\site-packages\\pyqtgraph\\graphicsItems\\ImageItem.py", line 342, in updateImage\n    return self.setImage(*args, **defaults)\n', '  File "C:\\Users\\Andrea Bassi\\anaconda3\\envs\\scopefoundry\\lib\\site-packages\\pyqtgraph\\graphicsItems\\ImageItem.py", line 283, in setImage\n    self.sigImageChanged.emit()\n', 'SystemError: <built-in method emit of PyQt5.QtCore.pyqtBoundSignal object at 0x000001C1099EC490> returned a result with an error set\n']
2020-07-23T13:21:40|ERROR|FakeCameraMeasurement|fake_camera_image Failed to update figure1: <built-in method emit of PyQt5.QtCore.pyqtBoundSignal object at 0x000001C1099EC490> returned a result with an error set. ['Traceback (most recent call last):\n', '  File "C:\\Users\\Andrea Bassi\\anaconda3\\envs\\scopefoundry\\lib\\site-packages\\pyqtgraph\\graphicsItems\\HistogramLUTItem.py", line 195, in imageChanged\n    h = self.imageItem().getHistogram()\n', '  File "C:\\Users\\Andrea Bassi\\anaconda3\\envs\\scopefoundry\\lib\\site-packages\\pyqtgraph\\graphicsItems\\ImageItem.py", line 464, in getHistogram\n    bins = np.arange(mn, mx+1.01*step, step, dtype=np.int)\n', 'ValueError: arange: cannot compute length\n', '\nThe above exception was the direct cause of the following exception:\n\n', 'Traceback (most recent call last):\n', '  File "C:\\Users\\Andrea Bassi\\anaconda3\\envs\\scopefoundry\\lib\\site-packages\\ScopeFoundry\\measurement.py", line 273, in _on_display_update_timer\n    self.update_display()\n', '  File "C:\\Users\\Andrea Bassi\\OneDrive - Politecnico di Milano\\Documenti\\PythonProjects\\BassiScopeFoundryMicroscopes\\Microscopes\\CellRecongnitionMicroscope\\FakeCameraMeasurement.py", line 87, in update_display\n    self.imv.setImage((self.displayed_image), autoLevels=self.settings.autoLevels.val, autoRange=self.settings.autoRange.val)\n', '  File "C:\\Users\\Andrea Bassi\\anaconda3\\envs\\scopefoundry\\lib\\site-packages\\pyqtgraph\\imageview\\ImageView.py", line 301, in setImage\n    self.updateImage(autoHistogramRange=autoHistogramRange)\n', '  File "C:\\Users\\Andrea Bassi\\anaconda3\\envs\\scopefoundry\\lib\\site-packages\\pyqtgraph\\imageview\\ImageView.py", line 676, in updateImage\n    self.imageItem.updateImage(image)\n', '  File "C:\\Users\\Andrea Bassi\\anaconda3\\envs\\scopefoundry\\lib\\site-packages\\pyqtgraph\\graphicsItems\\ImageItem.py", line 342, in updateImage\n    return self.setImage(*args, **defaults)\n', '  File "C:\\Users\\Andrea Bassi\\anaconda3\\envs\\scopefoundry\\lib\\site-packages\\pyqtgraph\\graphicsItems\\ImageItem.py", line 283, in setImage\n    self.sigImageChanged.emit()\n', 'SystemError: <built-in method emit of PyQt5.QtCore.pyqtBoundSignal object at 0x000001C1099EC490> returned a result with an error set\n']
2020-07-23T13:21:40|ERROR|FakeCameraMeasurement|fake_camera_image Failed to update figure1: <built-in method emit of PyQt5.QtCore.pyqtBoundSignal object at 0x000001C1099EC490> returned a result with an error set. ['Traceback (most recent call last):\n', '  File "C:\\Users\\Andrea Bassi\\anaconda3\\envs\\scopefoundry\\lib\\site-packages\\pyqtgraph\\graphicsItems\\HistogramLUTItem.py", line 195, in imageChanged\n    h = self.imageItem().getHistogram()\n', '  File "C:\\Users\\Andrea Bassi\\anaconda3\\envs\\scopefoundry\\lib\\site-packages\\pyqtgraph\\graphicsItems\\ImageItem.py", line 464, in getHistogram\n    bins = np.arange(mn, mx+1.01*step, step, dtype=np.int)\n', 'ValueError: arange: cannot compute length\n', '\nThe above exception was the direct cause of the following exception:\n\n', 'Traceback (most recent call last):\n', '  File "C:\\Users\\Andrea Bassi\\anaconda3\\envs\\scopefoundry\\lib\\site-packages\\ScopeFoundry\\measurement.py", line 273, in _on_display_update_timer\n    self.update_display()\n', '  File "C:\\Users\\Andrea Bassi\\OneDrive - Politecnico di Milano\\Documenti\\PythonProjects\\BassiScopeFoundryMicroscopes\\Microscopes\\CellRecongnitionMicroscope\\FakeCameraMeasurement.py", line 87, in update_display\n    self.imv.setImage((self.displayed_image), autoLevels=self.settings.autoLevels.val, autoRange=self.settings.autoRange.val)\n', '  File "C:\\Users\\Andrea Bassi\\anaconda3\\envs\\scopefoundry\\lib\\site-packages\\pyqtgraph\\imageview\\ImageView.py", line 301, in setImage\n    self.updateImage(autoHistogramRange=autoHistogramRange)\n', '  File "C:\\Users\\Andrea Bassi\\anaconda3\\envs\\scopefoundry\\lib\\site-packages\\pyqtgraph\\imageview\\ImageView.py", line 676, in updateImage\n    self.imageItem.updateImage(image)\n', '  File "C:\\Users\\Andrea Bassi\\anaconda3\\envs\\scopefoundry\\lib\\site-packages\\pyqtgraph\\graphicsItems\\ImageItem.py", line 342, in updateImage\n    return self.setImage(*args, **defaults)\n', '  File "C:\\Users\\Andrea Bassi\\anaconda3\\envs\\scopefoundry\\lib\\site-packages\\pyqtgraph\\graphicsItems\\ImageItem.py", line 283, in setImage\n    self.sigImageChanged.emit()\n', 'SystemError: <built-in method emit of PyQt5.QtCore.pyqtBoundSignal object at 0x000001C1099EC490> returned a result with an error set\n']
2020-07-23T13:21:40|ERROR|FakeCameraMeasurement|fake_camera_image Failed to update figure1: <built-in method emit of PyQt5.QtCore.pyqtBoundSignal object at 0x000001C1099EC490> returned a result with an error set. ['Traceback (most recent call last):\n', '  File "C:\\Users\\Andrea Bassi\\anaconda3\\envs\\scopefoundry\\lib\\site-packages\\pyqtgraph\\graphicsItems\\HistogramLUTItem.py", line 195, in imageChanged\n    h = self.imageItem().getHistogram()\n', '  File "C:\\Users\\Andrea Bassi\\anaconda3\\envs\\scopefoundry\\lib\\site-packages\\pyqtgraph\\graphicsItems\\ImageItem.py", line 464, in getHistogram\n    bins = np.arange(mn, mx+1.01*step, step, dtype=np.int)\n', 'ValueError: arange: cannot compute length\n', '\nThe above exception was the direct cause of the following exception:\n\n', 'Traceback (most recent call last):\n', '  File "C:\\Users\\Andrea Bassi\\anaconda3\\envs\\scopefoundry\\lib\\site-packages\\ScopeFoundry\\measurement.py", line 273, in _on_display_update_timer\n    self.update_display()\n', '  File "C:\\Users\\Andrea Bassi\\OneDrive - Politecnico di Milano\\Documenti\\PythonProjects\\BassiScopeFoundryMicroscopes\\Microscopes\\CellRecongnitionMicroscope\\FakeCameraMeasurement.py", line 87, in update_display\n    self.imv.setImage((self.displayed_image), autoLevels=self.settings.autoLevels.val, autoRange=self.settings.autoRange.val)\n', '  File "C:\\Users\\Andrea Bassi\\anaconda3\\envs\\scopefoundry\\lib\\site-packages\\pyqtgraph\\imageview\\ImageView.py", line 301, in setImage\n    self.updateImage(autoHistogramRange=autoHistogramRange)\n', '  File "C:\\Users\\Andrea Bassi\\anaconda3\\envs\\scopefoundry\\lib\\site-packages\\pyqtgraph\\imageview\\ImageView.py", line 676, in updateImage\n    self.imageItem.updateImage(image)\n', '  File "C:\\Users\\Andrea Bassi\\anaconda3\\envs\\scopefoundry\\lib\\site-packages\\pyqtgraph\\graphicsItems\\ImageItem.py", line 342, in updateImage\n    return self.setImage(*args, **defaults)\n', '  File "C:\\Users\\Andrea Bassi\\anaconda3\\envs\\scopefoundry\\lib\\site-packages\\pyqtgraph\\graphicsItems\\ImageItem.py", line 283, in setImage\n    self.sigImageChanged.emit()\n', 'SystemError: <built-in method emit of PyQt5.QtCore.pyqtBoundSignal object at 0x000001C1099EC490> returned a result with an error set\n']
2020-07-23T13:21:40|ERROR|FakeCameraMeasurement|fake_camera_image Failed to update figure1: <built-in method emit of PyQt5.QtCore.pyqtBoundSignal object at 0x000001C1099EC490> returned a result with an error set. ['Traceback (most recent call last):\n', '  File "C:\\Users\\Andrea Bassi\\anaconda3\\envs\\scopefoundry\\lib\\site-packages\\pyqtgraph\\graphicsItems\\HistogramLUTItem.py", line 195, in imageChanged\n    h = self.imageItem().getHistogram()\n', '  File "C:\\Users\\Andrea Bassi\\anaconda3\\envs\\scopefoundry\\lib\\site-packages\\pyqtgraph\\graphicsItems\\ImageItem.py", line 464, in getHistogram\n    bins = np.arange(mn, mx+1.01*step, step, dtype=np.int)\n', 'ValueError: arange: cannot compute length\n', '\nThe above exception was the direct cause of the following exception:\n\n', 'Traceback (most recent call last):\n', '  File "C:\\Users\\Andrea Bassi\\anaconda3\\envs\\scopefoundry\\lib\\site-packages\\ScopeFoundry\\measurement.py", line 273, in _on_display_update_timer\n    self.update_display()\n', '  File "C:\\Users\\Andrea Bassi\\OneDrive - Politecnico di Milano\\Documenti\\PythonProjects\\BassiScopeFoundryMicroscopes\\Microscopes\\CellRecongnitionMicroscope\\FakeCameraMeasurement.py", line 87, in update_display\n    self.imv.setImage((self.displayed_image), autoLevels=self.settings.autoLevels.val, autoRange=self.settings.autoRange.val)\n', '  File "C:\\Users\\Andrea Bassi\\anaconda3\\envs\\scopefoundry\\lib\\site-packages\\pyqtgraph\\imageview\\ImageView.py", line 301, in setImage\n    self.updateImage(autoHistogramRange=autoHistogramRange)\n', '  File "C:\\Users\\Andrea Bassi\\anaconda3\\envs\\scopefoundry\\lib\\site-packages\\pyqtgraph\\imageview\\ImageView.py", line 676, in updateImage\n    self.imageItem.updateImage(image)\n', '  File "C:\\Users\\Andrea Bassi\\anaconda3\\envs\\scopefoundry\\lib\\site-packages\\pyqtgraph\\graphicsItems\\ImageItem.py", line 342, in updateImage\n    return self.setImage(*args, **defaults)\n', '  File "C:\\Users\\Andrea Bassi\\anaconda3\\envs\\scopefoundry\\lib\\site-packages\\pyqtgraph\\graphicsItems\\ImageItem.py", line 283, in setImage\n    self.sigImageChanged.emit()\n', 'SystemError: <built-in method emit of PyQt5.QtCore.pyqtBoundSignal object at 0x000001C1099EC490> returned a result with an error set\n']
2020-07-23T13:21:40|ERROR|FakeCameraMeasurement|fake_camera_image Failed to update figure1: <built-in method emit of PyQt5.QtCore.pyqtBoundSignal object at 0x000001C1099EC490> returned a result with an error set. ['Traceback (most recent call last):\n', '  File "C:\\Users\\Andrea Bassi\\anaconda3\\envs\\scopefoundry\\lib\\site-packages\\pyqtgraph\\graphicsItems\\HistogramLUTItem.py", line 195, in imageChanged\n    h = self.imageItem().getHistogram()\n', '  File "C:\\Users\\Andrea Bassi\\anaconda3\\envs\\scopefoundry\\lib\\site-packages\\pyqtgraph\\graphicsItems\\ImageItem.py", line 464, in getHistogram\n    bins = np.arange(mn, mx+1.01*step, step, dtype=np.int)\n', 'ValueError: arange: cannot compute length\n', '\nThe above exception was the direct cause of the following exception:\n\n', 'Traceback (most recent call last):\n', '  File "C:\\Users\\Andrea Bassi\\anaconda3\\envs\\scopefoundry\\lib\\site-packages\\ScopeFoundry\\measurement.py", line 273, in _on_display_update_timer\n    self.update_display()\n', '  File "C:\\Users\\Andrea Bassi\\OneDrive - Politecnico di Milano\\Documenti\\PythonProjects\\BassiScopeFoundryMicroscopes\\Microscopes\\CellRecongnitionMicroscope\\FakeCameraMeasurement.py", line 87, in update_display\n    self.imv.setImage((self.displayed_image), autoLevels=self.settings.autoLevels.val, autoRange=self.settings.autoRange.val)\n', '  File "C:\\Users\\Andrea Bassi\\anaconda3\\envs\\scopefoundry\\lib\\site-packages\\pyqtgraph\\imageview\\ImageView.py", line 301, in setImage\n    self.updateImage(autoHistogramRange=autoHistogramRange)\n', '  File "C:\\Users\\Andrea Bassi\\anaconda3\\envs\\scopefoundry\\lib\\site-packages\\pyqtgraph\\imageview\\ImageView.py", line 676, in updateImage\n    self.imageItem.updateImage(image)\n', '  File "C:\\Users\\Andrea Bassi\\anaconda3\\envs\\scopefoundry\\lib\\site-packages\\pyqtgraph\\graphicsItems\\ImageItem.py", line 342, in updateImage\n    return self.setImage(*args, **defaults)\n', '  File "C:\\Users\\Andrea Bassi\\anaconda3\\envs\\scopefoundry\\lib\\site-packages\\pyqtgraph\\graphicsItems\\ImageItem.py", line 283, in setImage\n    self.sigImageChanged.emit()\n', 'SystemError: <built-in method emit of PyQt5.QtCore.pyqtBoundSignal object at 0x000001C1099EC490> returned a result with an error set\n']
2020-07-23T13:21:40|ERROR|FakeCameraMeasurement|fake_camera_image Failed to update figure1: <built-in method emit of PyQt5.QtCore.pyqtBoundSignal object at 0x000001C1099EC490> returned a result with an error set. ['Traceback (most recent call last):\n', '  File "C:\\Users\\Andrea Bassi\\anaconda3\\envs\\scopefoundry\\lib\\site-packages\\pyqtgraph\\graphicsItems\\HistogramLUTItem.py", line 195, in imageChanged\n    h = self.imageItem().getHistogram()\n', '  File "C:\\Users\\Andrea Bassi\\anaconda3\\envs\\scopefoundry\\lib\\site-packages\\pyqtgraph\\graphicsItems\\ImageItem.py", line 464, in getHistogram\n    bins = np.arange(mn, mx+1.01*step, step, dtype=np.int)\n', 'ValueError: arange: cannot compute length\n', '\nThe above exception was the direct cause of the following exception:\n\n', 'Traceback (most recent call last):\n', '  File "C:\\Users\\Andrea Bassi\\anaconda3\\envs\\scopefoundry\\lib\\site-packages\\ScopeFoundry\\measurement.py", line 273, in _on_display_update_timer\n    self.update_display()\n', '  File "C:\\Users\\Andrea Bassi\\OneDrive - Politecnico di Milano\\Documenti\\PythonProjects\\BassiScopeFoundryMicroscopes\\Microscopes\\CellRecongnitionMicroscope\\FakeCameraMeasurement.py", line 87, in update_display\n    self.imv.setImage((self.displayed_image), autoLevels=self.settings.autoLevels.val, autoRange=self.settings.autoRange.val)\n', '  File "C:\\Users\\Andrea Bassi\\anaconda3\\envs\\scopefoundry\\lib\\site-packages\\pyqtgraph\\imageview\\ImageView.py", line 301, in setImage\n    self.updateImage(autoHistogramRange=autoHistogramRange)\n', '  File "C:\\Users\\Andrea Bassi\\anaconda3\\envs\\scopefoundry\\lib\\site-packages\\pyqtgraph\\imageview\\ImageView.py", line 676, in updateImage\n    self.imageItem.updateImage(image)\n', '  File "C:\\Users\\Andrea Bassi\\anaconda3\\envs\\scopefoundry\\lib\\site-packages\\pyqtgraph\\graphicsItems\\ImageItem.py", line 342, in updateImage\n    return self.setImage(*args, **defaults)\n', '  File "C:\\Users\\Andrea Bassi\\anaconda3\\envs\\scopefoundry\\lib\\site-packages\\pyqtgraph\\graphicsItems\\ImageItem.py", line 283, in setImage\n    self.sigImageChanged.emit()\n', 'SystemError: <built-in method emit of PyQt5.QtCore.pyqtBoundSignal object at 0x000001C1099EC490> returned a result with an error set\n']
2020-07-23T13:21:40|ERROR|FakeCameraMeasurement|fake_camera_image Failed to update figure1: <built-in method emit of PyQt5.QtCore.pyqtBoundSignal object at 0x000001C119A3BB98> returned a result with an error set. ['Traceback (most recent call last):\n', '  File "C:\\Users\\Andrea Bassi\\anaconda3\\envs\\scopefoundry\\lib\\site-packages\\pyqtgraph\\graphicsItems\\HistogramLUTItem.py", line 195, in imageChanged\n    h = self.imageItem().getHistogram()\n', '  File "C:\\Users\\Andrea Bassi\\anaconda3\\envs\\scopefoundry\\lib\\site-packages\\pyqtgraph\\graphicsItems\\ImageItem.py", line 464, in getHistogram\n    bins = np.arange(mn, mx+1.01*step, step, dtype=np.int)\n', 'ValueError: arange: cannot compute length\n', '\nThe above exception was the direct cause of the following exception:\n\n', 'Traceback (most recent call last):\n', '  File "C:\\Users\\Andrea Bassi\\anaconda3\\envs\\scopefoundry\\lib\\site-packages\\ScopeFoundry\\measurement.py", line 273, in _on_display_update_timer\n    self.update_display()\n', '  File "C:\\Users\\Andrea Bassi\\OneDrive - Politecnico di Milano\\Documenti\\PythonProjects\\BassiScopeFoundryMicroscopes\\Microscopes\\CellRecongnitionMicroscope\\FakeCameraMeasurement.py", line 87, in update_display\n    self.imv.setImage((self.displayed_image), autoLevels=self.settings.autoLevels.val, autoRange=self.settings.autoRange.val)\n', '  File "C:\\Users\\Andrea Bassi\\anaconda3\\envs\\scopefoundry\\lib\\site-packages\\pyqtgraph\\imageview\\ImageView.py", line 301, in setImage\n    self.updateImage(autoHistogramRange=autoHistogramRange)\n', '  File "C:\\Users\\Andrea Bassi\\anaconda3\\envs\\scopefoundry\\lib\\site-packages\\pyqtgraph\\imageview\\ImageView.py", line 676, in updateImage\n    self.imageItem.updateImage(image)\n', '  File "C:\\Users\\Andrea Bassi\\anaconda3\\envs\\scopefoundry\\lib\\site-packages\\pyqtgraph\\graphicsItems\\ImageItem.py", line 342, in updateImage\n    return self.setImage(*args, **defaults)\n', '  File "C:\\Users\\Andrea Bassi\\anaconda3\\envs\\scopefoundry\\lib\\site-packages\\pyqtgraph\\graphicsItems\\ImageItem.py", line 283, in setImage\n    self.sigImageChanged.emit()\n', 'SystemError: <built-in method emit of PyQt5.QtCore.pyqtBoundSignal object at 0x000001C119A3BB98> returned a result with an error set\n']
2020-07-23T13:21:40|ERROR|FakeCameraMeasurement|fake_camera_image Failed to update figure1: <built-in method emit of PyQt5.QtCore.pyqtBoundSignal object at 0x000001C119A3BE40> returned a result with an error set. ['Traceback (most recent call last):\n', '  File "C:\\Users\\Andrea Bassi\\anaconda3\\envs\\scopefoundry\\lib\\site-packages\\pyqtgraph\\graphicsItems\\HistogramLUTItem.py", line 195, in imageChanged\n    h = self.imageItem().getHistogram()\n', '  File "C:\\Users\\Andrea Bassi\\anaconda3\\envs\\scopefoundry\\lib\\site-packages\\pyqtgraph\\graphicsItems\\ImageItem.py", line 464, in getHistogram\n    bins = np.arange(mn, mx+1.01*step, step, dtype=np.int)\n', 'ValueError: arange: cannot compute length\n', '\nThe above exception was the direct cause of the following exception:\n\n', 'Traceback (most recent call last):\n', '  File "C:\\Users\\Andrea Bassi\\anaconda3\\envs\\scopefoundry\\lib\\site-packages\\ScopeFoundry\\measurement.py", line 273, in _on_display_update_timer\n    self.update_display()\n', '  File "C:\\Users\\Andrea Bassi\\OneDrive - Politecnico di Milano\\Documenti\\PythonProjects\\BassiScopeFoundryMicroscopes\\Microscopes\\CellRecongnitionMicroscope\\FakeCameraMeasurement.py", line 87, in update_display\n    self.imv.setImage((self.displayed_image), autoLevels=self.settings.autoLevels.val, autoRange=self.settings.autoRange.val)\n', '  File "C:\\Users\\Andrea Bassi\\anaconda3\\envs\\scopefoundry\\lib\\site-packages\\pyqtgraph\\imageview\\ImageView.py", line 301, in setImage\n    self.updateImage(autoHistogramRange=autoHistogramRange)\n', '  File "C:\\Users\\Andrea Bassi\\anaconda3\\envs\\scopefoundry\\lib\\site-packages\\pyqtgraph\\imageview\\ImageView.py", line 676, in updateImage\n    self.imageItem.updateImage(image)\n', '  File "C:\\Users\\Andrea Bassi\\anaconda3\\envs\\scopefoundry\\lib\\site-packages\\pyqtgraph\\graphicsItems\\ImageItem.py", line 342, in updateImage\n    return self.setImage(*args, **defaults)\n', '  File "C:\\Users\\Andrea Bassi\\anaconda3\\envs\\scopefoundry\\lib\\site-packages\\pyqtgraph\\graphicsItems\\ImageItem.py", line 283, in setImage\n    self.sigImageChanged.emit()\n', 'SystemError: <built-in method emit of PyQt5.QtCore.pyqtBoundSignal object at 0x000001C119A3BE40> returned a result with an error set\n']
2020-07-23T13:21:40|ERROR|FakeCameraMeasurement|fake_camera_image Failed to update figure1: <built-in method emit of PyQt5.QtCore.pyqtBoundSignal object at 0x000001C119A3BE90> returned a result with an error set. ['Traceback (most recent call last):\n', '  File "C:\\Users\\Andrea Bassi\\anaconda3\\envs\\scopefoundry\\lib\\site-packages\\pyqtgraph\\graphicsItems\\HistogramLUTItem.py", line 195, in imageChanged\n    h = self.imageItem().getHistogram()\n', '  File "C:\\Users\\Andrea Bassi\\anaconda3\\envs\\scopefoundry\\lib\\site-packages\\pyqtgraph\\graphicsItems\\ImageItem.py", line 464, in getHistogram\n    bins = np.arange(mn, mx+1.01*step, step, dtype=np.int)\n', 'ValueError: arange: cannot compute length\n', '\nThe above exception was the direct cause of the following exception:\n\n', 'Traceback (most recent call last):\n', '  File "C:\\Users\\Andrea Bassi\\anaconda3\\envs\\scopefoundry\\lib\\site-packages\\ScopeFoundry\\measurement.py", line 273, in _on_display_update_timer\n    self.update_display()\n', '  File "C:\\Users\\Andrea Bassi\\OneDrive - Politecnico di Milano\\Documenti\\PythonProjects\\BassiScopeFoundryMicroscopes\\Microscopes\\CellRecongnitionMicroscope\\FakeCameraMeasurement.py", line 87, in update_display\n    self.imv.setImage((self.displayed_image), autoLevels=self.settings.autoLevels.val, autoRange=self.settings.autoRange.val)\n', '  File "C:\\Users\\Andrea Bassi\\anaconda3\\envs\\scopefoundry\\lib\\site-packages\\pyqtgraph\\imageview\\ImageView.py", line 301, in setImage\n    self.updateImage(autoHistogramRange=autoHistogramRange)\n', '  File "C:\\Users\\Andrea Bassi\\anaconda3\\envs\\scopefoundry\\lib\\site-packages\\pyqtgraph\\imageview\\ImageView.py", line 676, in updateImage\n    self.imageItem.updateImage(image)\n', '  File "C:\\Users\\Andrea Bassi\\anaconda3\\envs\\scopefoundry\\lib\\site-packages\\pyqtgraph\\graphicsItems\\ImageItem.py", line 342, in updateImage\n    return self.setImage(*args, **defaults)\n', '  File "C:\\Users\\Andrea Bassi\\anaconda3\\envs\\scopefoundry\\lib\\site-packages\\pyqtgraph\\graphicsItems\\ImageItem.py", line 283, in setImage\n    self.sigImageChanged.emit()\n', 'SystemError: <built-in method emit of PyQt5.QtCore.pyqtBoundSignal object at 0x000001C119A3BE90> returned a result with an error set\n']
2020-07-23T13:21:40|ERROR|FakeCameraMeasurement|fake_camera_image Failed to update figure1: <built-in method emit of PyQt5.QtCore.pyqtBoundSignal object at 0x000001C119A3BE40> returned a result with an error set. ['Traceback (most recent call last):\n', '  File "C:\\Users\\Andrea Bassi\\anaconda3\\envs\\scopefoundry\\lib\\site-packages\\pyqtgraph\\graphicsItems\\HistogramLUTItem.py", line 195, in imageChanged\n    h = self.imageItem().getHistogram()\n', '  File "C:\\Users\\Andrea Bassi\\anaconda3\\envs\\scopefoundry\\lib\\site-packages\\pyqtgraph\\graphicsItems\\ImageItem.py", line 464, in getHistogram\n    bins = np.arange(mn, mx+1.01*step, step, dtype=np.int)\n', 'ValueError: arange: cannot compute length\n', '\nThe above exception was the direct cause of the following exception:\n\n', 'Traceback (most recent call last):\n', '  File "C:\\Users\\Andrea Bassi\\anaconda3\\envs\\scopefoundry\\lib\\site-packages\\ScopeFoundry\\measurement.py", line 273, in _on_display_update_timer\n    self.update_display()\n', '  File "C:\\Users\\Andrea Bassi\\OneDrive - Politecnico di Milano\\Documenti\\PythonProjects\\BassiScopeFoundryMicroscopes\\Microscopes\\CellRecongnitionMicroscope\\FakeCameraMeasurement.py", line 87, in update_display\n    self.imv.setImage((self.displayed_image), autoLevels=self.settings.autoLevels.val, autoRange=self.settings.autoRange.val)\n', '  File "C:\\Users\\Andrea Bassi\\anaconda3\\envs\\scopefoundry\\lib\\site-packages\\pyqtgraph\\imageview\\ImageView.py", line 301, in setImage\n    self.updateImage(autoHistogramRange=autoHistogramRange)\n', '  File "C:\\Users\\Andrea Bassi\\anaconda3\\envs\\scopefoundry\\lib\\site-packages\\pyqtgraph\\imageview\\ImageView.py", line 676, in updateImage\n    self.imageItem.updateImage(image)\n', '  File "C:\\Users\\Andrea Bassi\\anaconda3\\envs\\scopefoundry\\lib\\site-packages\\pyqtgraph\\graphicsItems\\ImageItem.py", line 342, in updateImage\n    return self.setImage(*args, **defaults)\n', '  File "C:\\Users\\Andrea Bassi\\anaconda3\\envs\\scopefoundry\\lib\\site-packages\\pyqtgraph\\graphicsItems\\ImageItem.py", line 283, in setImage\n    self.sigImageChanged.emit()\n', 'SystemError: <built-in method emit of PyQt5.QtCore.pyqtBoundSignal object at 0x000001C119A3BE40> returned a result with an error set\n']
2020-07-23T13:21:40|ERROR|FakeCameraMeasurement|fake_camera_image Failed to update figure1: <built-in method emit of PyQt5.QtCore.pyqtBoundSignal object at 0x000001C1099EC490> returned a result with an error set. ['Traceback (most recent call last):\n', '  File "C:\\Users\\Andrea Bassi\\anaconda3\\envs\\scopefoundry\\lib\\site-packages\\pyqtgraph\\graphicsItems\\HistogramLUTItem.py", line 195, in imageChanged\n    h = self.imageItem().getHistogram()\n', '  File "C:\\Users\\Andrea Bassi\\anaconda3\\envs\\scopefoundry\\lib\\site-packages\\pyqtgraph\\graphicsItems\\ImageItem.py", line 464, in getHistogram\n    bins = np.arange(mn, mx+1.01*step, step, dtype=np.int)\n', 'ValueError: arange: cannot compute length\n', '\nThe above exception was the direct cause of the following exception:\n\n', 'Traceback (most recent call last):\n', '  File "C:\\Users\\Andrea Bassi\\anaconda3\\envs\\scopefoundry\\lib\\site-packages\\ScopeFoundry\\measurement.py", line 273, in _on_display_update_timer\n    self.update_display()\n', '  File "C:\\Users\\Andrea Bassi\\OneDrive - Politecnico di Milano\\Documenti\\PythonProjects\\BassiScopeFoundryMicroscopes\\Microscopes\\CellRecongnitionMicroscope\\FakeCameraMeasurement.py", line 87, in update_display\n    self.imv.setImage((self.displayed_image), autoLevels=self.settings.autoLevels.val, autoRange=self.settings.autoRange.val)\n', '  File "C:\\Users\\Andrea Bassi\\anaconda3\\envs\\scopefoundry\\lib\\site-packages\\pyqtgraph\\imageview\\ImageView.py", line 301, in setImage\n    self.updateImage(autoHistogramRange=autoHistogramRange)\n', '  File "C:\\Users\\Andrea Bassi\\anaconda3\\envs\\scopefoundry\\lib\\site-packages\\pyqtgraph\\imageview\\ImageView.py", line 676, in updateImage\n    self.imageItem.updateImage(image)\n', '  File "C:\\Users\\Andrea Bassi\\anaconda3\\envs\\scopefoundry\\lib\\site-packages\\pyqtgraph\\graphicsItems\\ImageItem.py", line 342, in updateImage\n    return self.setImage(*args, **defaults)\n', '  File "C:\\Users\\Andrea Bassi\\anaconda3\\envs\\scopefoundry\\lib\\site-packages\\pyqtgraph\\graphicsItems\\ImageItem.py", line 283, in setImage\n    self.sigImageChanged.emit()\n', 'SystemError: <built-in method emit of PyQt5.QtCore.pyqtBoundSignal object at 0x000001C1099EC490> returned a result with an error set\n']
2020-07-23T13:21:40|ERROR|FakeCameraMeasurement|fake_camera_image Failed to update figure1: <built-in method emit of PyQt5.QtCore.pyqtBoundSignal object at 0x000001C1099EC490> returned a result with an error set. ['Traceback (most recent call last):\n', '  File "C:\\Users\\Andrea Bassi\\anaconda3\\envs\\scopefoundry\\lib\\site-packages\\pyqtgraph\\graphicsItems\\HistogramLUTItem.py", line 195, in imageChanged\n    h = self.imageItem().getHistogram()\n', '  File "C:\\Users\\Andrea Bassi\\anaconda3\\envs\\scopefoundry\\lib\\site-packages\\pyqtgraph\\graphicsItems\\ImageItem.py", line 464, in getHistogram\n    bins = np.arange(mn, mx+1.01*step, step, dtype=np.int)\n', 'ValueError: arange: cannot compute length\n', '\nThe above exception was the direct cause of the following exception:\n\n', 'Traceback (most recent call last):\n', '  File "C:\\Users\\Andrea Bassi\\anaconda3\\envs\\scopefoundry\\lib\\site-packages\\ScopeFoundry\\measurement.py", line 273, in _on_display_update_timer\n    self.update_display()\n', '  File "C:\\Users\\Andrea Bassi\\OneDrive - Politecnico di Milano\\Documenti\\PythonProjects\\BassiScopeFoundryMicroscopes\\Microscopes\\CellRecongnitionMicroscope\\FakeCameraMeasurement.py", line 87, in update_display\n    self.imv.setImage((self.displayed_image), autoLevels=self.settings.autoLevels.val, autoRange=self.settings.autoRange.val)\n', '  File "C:\\Users\\Andrea Bassi\\anaconda3\\envs\\scopefoundry\\lib\\site-packages\\pyqtgraph\\imageview\\ImageView.py", line 301, in setImage\n    self.updateImage(autoHistogramRange=autoHistogramRange)\n', '  File "C:\\Users\\Andrea Bassi\\anaconda3\\envs\\scopefoundry\\lib\\site-packages\\pyqtgraph\\imageview\\ImageView.py", line 676, in updateImage\n    self.imageItem.updateImage(image)\n', '  File "C:\\Users\\Andrea Bassi\\anaconda3\\envs\\scopefoundry\\lib\\site-packages\\pyqtgraph\\graphicsItems\\ImageItem.py", line 342, in updateImage\n    return self.setImage(*args, **defaults)\n', '  File "C:\\Users\\Andrea Bassi\\anaconda3\\envs\\scopefoundry\\lib\\site-packages\\pyqtgraph\\graphicsItems\\ImageItem.py", line 283, in setImage\n    self.sigImageChanged.emit()\n', 'SystemError: <built-in method emit of PyQt5.QtCore.pyqtBoundSignal object at 0x000001C1099EC490> returned a result with an error set\n']
2020-07-23T13:21:40|ERROR|FakeCameraMeasurement|fake_camera_image Failed to update figure1: <built-in method emit of PyQt5.QtCore.pyqtBoundSignal object at 0x000001C1099EC490> returned a result with an error set. ['Traceback (most recent call last):\n', '  File "C:\\Users\\Andrea Bassi\\anaconda3\\envs\\scopefoundry\\lib\\site-packages\\pyqtgraph\\graphicsItems\\HistogramLUTItem.py", line 195, in imageChanged\n    h = self.imageItem().getHistogram()\n', '  File "C:\\Users\\Andrea Bassi\\anaconda3\\envs\\scopefoundry\\lib\\site-packages\\pyqtgraph\\graphicsItems\\ImageItem.py", line 464, in getHistogram\n    bins = np.arange(mn, mx+1.01*step, step, dtype=np.int)\n', 'ValueError: arange: cannot compute length\n', '\nThe above exception was the direct cause of the following exception:\n\n', 'Traceback (most recent call last):\n', '  File "C:\\Users\\Andrea Bassi\\anaconda3\\envs\\scopefoundry\\lib\\site-packages\\ScopeFoundry\\measurement.py", line 273, in _on_display_update_timer\n    self.update_display()\n', '  File "C:\\Users\\Andrea Bassi\\OneDrive - Politecnico di Milano\\Documenti\\PythonProjects\\BassiScopeFoundryMicroscopes\\Microscopes\\CellRecongnitionMicroscope\\FakeCameraMeasurement.py", line 87, in update_display\n    self.imv.setImage((self.displayed_image), autoLevels=self.settings.autoLevels.val, autoRange=self.settings.autoRange.val)\n', '  File "C:\\Users\\Andrea Bassi\\anaconda3\\envs\\scopefoundry\\lib\\site-packages\\pyqtgraph\\imageview\\ImageView.py", line 301, in setImage\n    self.updateImage(autoHistogramRange=autoHistogramRange)\n', '  File "C:\\Users\\Andrea Bassi\\anaconda3\\envs\\scopefoundry\\lib\\site-packages\\pyqtgraph\\imageview\\ImageView.py", line 676, in updateImage\n    self.imageItem.updateImage(image)\n', '  File "C:\\Users\\Andrea Bassi\\anaconda3\\envs\\scopefoundry\\lib\\site-packages\\pyqtgraph\\graphicsItems\\ImageItem.py", line 342, in updateImage\n    return self.setImage(*args, **defaults)\n', '  File "C:\\Users\\Andrea Bassi\\anaconda3\\envs\\scopefoundry\\lib\\site-packages\\pyqtgraph\\graphicsItems\\ImageItem.py", line 283, in setImage\n    self.sigImageChanged.emit()\n', 'SystemError: <built-in method emit of PyQt5.QtCore.pyqtBoundSignal object at 0x000001C1099EC490> returned a result with an error set\n']
2020-07-23T13:21:40|ERROR|FakeCameraMeasurement|fake_camera_image Failed to update figure1: <built-in method emit of PyQt5.QtCore.pyqtBoundSignal object at 0x000001C1099EC490> returned a result with an error set. ['Traceback (most recent call last):\n', '  File "C:\\Users\\Andrea Bassi\\anaconda3\\envs\\scopefoundry\\lib\\site-packages\\pyqtgraph\\graphicsItems\\HistogramLUTItem.py", line 195, in imageChanged\n    h = self.imageItem().getHistogram()\n', '  File "C:\\Users\\Andrea Bassi\\anaconda3\\envs\\scopefoundry\\lib\\site-packages\\pyqtgraph\\graphicsItems\\ImageItem.py", line 464, in getHistogram\n    bins = np.arange(mn, mx+1.01*step, step, dtype=np.int)\n', 'ValueError: arange: cannot compute length\n', '\nThe above exception was the direct cause of the following exception:\n\n', 'Traceback (most recent call last):\n', '  File "C:\\Users\\Andrea Bassi\\anaconda3\\envs\\scopefoundry\\lib\\site-packages\\ScopeFoundry\\measurement.py", line 273, in _on_display_update_timer\n    self.update_display()\n', '  File "C:\\Users\\Andrea Bassi\\OneDrive - Politecnico di Milano\\Documenti\\PythonProjects\\BassiScopeFoundryMicroscopes\\Microscopes\\CellRecongnitionMicroscope\\FakeCameraMeasurement.py", line 87, in update_display\n    self.imv.setImage((self.displayed_image), autoLevels=self.settings.autoLevels.val, autoRange=self.settings.autoRange.val)\n', '  File "C:\\Users\\Andrea Bassi\\anaconda3\\envs\\scopefoundry\\lib\\site-packages\\pyqtgraph\\imageview\\ImageView.py", line 301, in setImage\n    self.updateImage(autoHistogramRange=autoHistogramRange)\n', '  File "C:\\Users\\Andrea Bassi\\anaconda3\\envs\\scopefoundry\\lib\\site-packages\\pyqtgraph\\imageview\\ImageView.py", line 676, in updateImage\n    self.imageItem.updateImage(image)\n', '  File "C:\\Users\\Andrea Bassi\\anaconda3\\envs\\scopefoundry\\lib\\site-packages\\pyqtgraph\\graphicsItems\\ImageItem.py", line 342, in updateImage\n    return self.setImage(*args, **defaults)\n', '  File "C:\\Users\\Andrea Bassi\\anaconda3\\envs\\scopefoundry\\lib\\site-packages\\pyqtgraph\\graphicsItems\\ImageItem.py", line 283, in setImage\n    self.sigImageChanged.emit()\n', 'SystemError: <built-in method emit of PyQt5.QtCore.pyqtBoundSignal object at 0x000001C1099EC490> returned a result with an error set\n']
2020-07-23T13:21:40|ERROR|FakeCameraMeasurement|fake_camera_image Failed to update figure1: <built-in method emit of PyQt5.QtCore.pyqtBoundSignal object at 0x000001C119A3BF08> returned a result with an error set. ['Traceback (most recent call last):\n', '  File "C:\\Users\\Andrea Bassi\\anaconda3\\envs\\scopefoundry\\lib\\site-packages\\pyqtgraph\\graphicsItems\\HistogramLUTItem.py", line 195, in imageChanged\n    h = self.imageItem().getHistogram()\n', '  File "C:\\Users\\Andrea Bassi\\anaconda3\\envs\\scopefoundry\\lib\\site-packages\\pyqtgraph\\graphicsItems\\ImageItem.py", line 464, in getHistogram\n    bins = np.arange(mn, mx+1.01*step, step, dtype=np.int)\n', 'ValueError: arange: cannot compute length\n', '\nThe above exception was the direct cause of the following exception:\n\n', 'Traceback (most recent call last):\n', '  File "C:\\Users\\Andrea Bassi\\anaconda3\\envs\\scopefoundry\\lib\\site-packages\\ScopeFoundry\\measurement.py", line 273, in _on_display_update_timer\n    self.update_display()\n', '  File "C:\\Users\\Andrea Bassi\\OneDrive - Politecnico di Milano\\Documenti\\PythonProjects\\BassiScopeFoundryMicroscopes\\Microscopes\\CellRecongnitionMicroscope\\FakeCameraMeasurement.py", line 87, in update_display\n    self.imv.setImage((self.displayed_image), autoLevels=self.settings.autoLevels.val, autoRange=self.settings.autoRange.val)\n', '  File "C:\\Users\\Andrea Bassi\\anaconda3\\envs\\scopefoundry\\lib\\site-packages\\pyqtgraph\\imageview\\ImageView.py", line 301, in setImage\n    self.updateImage(autoHistogramRange=autoHistogramRange)\n', '  File "C:\\Users\\Andrea Bassi\\anaconda3\\envs\\scopefoundry\\lib\\site-packages\\pyqtgraph\\imageview\\ImageView.py", line 676, in updateImage\n    self.imageItem.updateImage(image)\n', '  File "C:\\Users\\Andrea Bassi\\anaconda3\\envs\\scopefoundry\\lib\\site-packages\\pyqtgraph\\graphicsItems\\ImageItem.py", line 342, in updateImage\n    return self.setImage(*args, **defaults)\n', '  File "C:\\Users\\Andrea Bassi\\anaconda3\\envs\\scopefoundry\\lib\\site-packages\\pyqtgraph\\graphicsItems\\ImageItem.py", line 283, in setImage\n    self.sigImageChanged.emit()\n', 'SystemError: <built-in method emit of PyQt5.QtCore.pyqtBoundSignal object at 0x000001C119A3BF08> returned a result with an error set\n']
2020-07-23T13:21:40|ERROR|FakeCameraMeasurement|fake_camera_image Failed to update figure1: <built-in method emit of PyQt5.QtCore.pyqtBoundSignal object at 0x000001C119A3BF30> returned a result with an error set. ['Traceback (most recent call last):\n', '  File "C:\\Users\\Andrea Bassi\\anaconda3\\envs\\scopefoundry\\lib\\site-packages\\pyqtgraph\\graphicsItems\\HistogramLUTItem.py", line 195, in imageChanged\n    h = self.imageItem().getHistogram()\n', '  File "C:\\Users\\Andrea Bassi\\anaconda3\\envs\\scopefoundry\\lib\\site-packages\\pyqtgraph\\graphicsItems\\ImageItem.py", line 464, in getHistogram\n    bins = np.arange(mn, mx+1.01*step, step, dtype=np.int)\n', 'ValueError: arange: cannot compute length\n', '\nThe above exception was the direct cause of the following exception:\n\n', 'Traceback (most recent call last):\n', '  File "C:\\Users\\Andrea Bassi\\anaconda3\\envs\\scopefoundry\\lib\\site-packages\\ScopeFoundry\\measurement.py", line 273, in _on_display_update_timer\n    self.update_display()\n', '  File "C:\\Users\\Andrea Bassi\\OneDrive - Politecnico di Milano\\Documenti\\PythonProjects\\BassiScopeFoundryMicroscopes\\Microscopes\\CellRecongnitionMicroscope\\FakeCameraMeasurement.py", line 87, in update_display\n    self.imv.setImage((self.displayed_image), autoLevels=self.settings.autoLevels.val, autoRange=self.settings.autoRange.val)\n', '  File "C:\\Users\\Andrea Bassi\\anaconda3\\envs\\scopefoundry\\lib\\site-packages\\pyqtgraph\\imageview\\ImageView.py", line 301, in setImage\n    self.updateImage(autoHistogramRange=autoHistogramRange)\n', '  File "C:\\Users\\Andrea Bassi\\anaconda3\\envs\\scopefoundry\\lib\\site-packages\\pyqtgraph\\imageview\\ImageView.py", line 676, in updateImage\n    self.imageItem.updateImage(image)\n', '  File "C:\\Users\\Andrea Bassi\\anaconda3\\envs\\scopefoundry\\lib\\site-packages\\pyqtgraph\\graphicsItems\\ImageItem.py", line 342, in updateImage\n    return self.setImage(*args, **defaults)\n', '  File "C:\\Users\\Andrea Bassi\\anaconda3\\envs\\scopefoundry\\lib\\site-packages\\pyqtgraph\\graphicsItems\\ImageItem.py", line 283, in setImage\n    self.sigImageChanged.emit()\n', 'SystemError: <built-in method emit of PyQt5.QtCore.pyqtBoundSignal object at 0x000001C119A3BF30> returned a result with an error set\n']
2020-07-23T13:21:40|ERROR|FakeCameraMeasurement|fake_camera_image Failed to update figure1: <built-in method emit of PyQt5.QtCore.pyqtBoundSignal object at 0x000001C119A3BF80> returned a result with an error set. ['Traceback (most recent call last):\n', '  File "C:\\Users\\Andrea Bassi\\anaconda3\\envs\\scopefoundry\\lib\\site-packages\\pyqtgraph\\graphicsItems\\HistogramLUTItem.py", line 195, in imageChanged\n    h = self.imageItem().getHistogram()\n', '  File "C:\\Users\\Andrea Bassi\\anaconda3\\envs\\scopefoundry\\lib\\site-packages\\pyqtgraph\\graphicsItems\\ImageItem.py", line 464, in getHistogram\n    bins = np.arange(mn, mx+1.01*step, step, dtype=np.int)\n', 'ValueError: arange: cannot compute length\n', '\nThe above exception was the direct cause of the following exception:\n\n', 'Traceback (most recent call last):\n', '  File "C:\\Users\\Andrea Bassi\\anaconda3\\envs\\scopefoundry\\lib\\site-packages\\ScopeFoundry\\measurement.py", line 273, in _on_display_update_timer\n    self.update_display()\n', '  File "C:\\Users\\Andrea Bassi\\OneDrive - Politecnico di Milano\\Documenti\\PythonProjects\\BassiScopeFoundryMicroscopes\\Microscopes\\CellRecongnitionMicroscope\\FakeCameraMeasurement.py", line 87, in update_display\n    self.imv.setImage((self.displayed_image), autoLevels=self.settings.autoLevels.val, autoRange=self.settings.autoRange.val)\n', '  File "C:\\Users\\Andrea Bassi\\anaconda3\\envs\\scopefoundry\\lib\\site-packages\\pyqtgraph\\imageview\\ImageView.py", line 301, in setImage\n    self.updateImage(autoHistogramRange=autoHistogramRange)\n', '  File "C:\\Users\\Andrea Bassi\\anaconda3\\envs\\scopefoundry\\lib\\site-packages\\pyqtgraph\\imageview\\ImageView.py", line 676, in updateImage\n    self.imageItem.updateImage(image)\n', '  File "C:\\Users\\Andrea Bassi\\anaconda3\\envs\\scopefoundry\\lib\\site-packages\\pyqtgraph\\graphicsItems\\ImageItem.py", line 342, in updateImage\n    return self.setImage(*args, **defaults)\n', '  File "C:\\Users\\Andrea Bassi\\anaconda3\\envs\\scopefoundry\\lib\\site-packages\\pyqtgraph\\graphicsItems\\ImageItem.py", line 283, in setImage\n    self.sigImageChanged.emit()\n', 'SystemError: <built-in method emit of PyQt5.QtCore.pyqtBoundSignal object at 0x000001C119A3BF80> returned a result with an error set\n']
2020-07-23T13:21:40|ERROR|FakeCameraMeasurement|fake_camera_image Failed to update figure1: <built-in method emit of PyQt5.QtCore.pyqtBoundSignal object at 0x000001C119A3BEE0> returned a result with an error set. ['Traceback (most recent call last):\n', '  File "C:\\Users\\Andrea Bassi\\anaconda3\\envs\\scopefoundry\\lib\\site-packages\\pyqtgraph\\graphicsItems\\HistogramLUTItem.py", line 195, in imageChanged\n    h = self.imageItem().getHistogram()\n', '  File "C:\\Users\\Andrea Bassi\\anaconda3\\envs\\scopefoundry\\lib\\site-packages\\pyqtgraph\\graphicsItems\\ImageItem.py", line 464, in getHistogram\n    bins = np.arange(mn, mx+1.01*step, step, dtype=np.int)\n', 'ValueError: arange: cannot compute length\n', '\nThe above exception was the direct cause of the following exception:\n\n', 'Traceback (most recent call last):\n', '  File "C:\\Users\\Andrea Bassi\\anaconda3\\envs\\scopefoundry\\lib\\site-packages\\ScopeFoundry\\measurement.py", line 273, in _on_display_update_timer\n    self.update_display()\n', '  File "C:\\Users\\Andrea Bassi\\OneDrive - Politecnico di Milano\\Documenti\\PythonProjects\\BassiScopeFoundryMicroscopes\\Microscopes\\CellRecongnitionMicroscope\\FakeCameraMeasurement.py", line 87, in update_display\n    self.imv.setImage((self.displayed_image), autoLevels=self.settings.autoLevels.val, autoRange=self.settings.autoRange.val)\n', '  File "C:\\Users\\Andrea Bassi\\anaconda3\\envs\\scopefoundry\\lib\\site-packages\\pyqtgraph\\imageview\\ImageView.py", line 301, in setImage\n    self.updateImage(autoHistogramRange=autoHistogramRange)\n', '  File "C:\\Users\\Andrea Bassi\\anaconda3\\envs\\scopefoundry\\lib\\site-packages\\pyqtgraph\\imageview\\ImageView.py", line 676, in updateImage\n    self.imageItem.updateImage(image)\n', '  File "C:\\Users\\Andrea Bassi\\anaconda3\\envs\\scopefoundry\\lib\\site-packages\\pyqtgraph\\graphicsItems\\ImageItem.py", line 342, in updateImage\n    return self.setImage(*args, **defaults)\n', '  File "C:\\Users\\Andrea Bassi\\anaconda3\\envs\\scopefoundry\\lib\\site-packages\\pyqtgraph\\graphicsItems\\ImageItem.py", line 283, in setImage\n    self.sigImageChanged.emit()\n', 'SystemError: <built-in method emit of PyQt5.QtCore.pyqtBoundSignal object at 0x000001C119A3BEE0> returned a result with an error set\n']
2020-07-23T14:44:30|CRITICAL|root|Unhandled exception:Traceback (most recent call last):
  File "C:\Users\Andrea Bassi\anaconda3\envs\scopefoundry\lib\site-packages\pyqtgraph\graphicsItems\HistogramLUTItem.py", line 195, in imageChanged
    h = self.imageItem().getHistogram()
  File "C:\Users\Andrea Bassi\anaconda3\envs\scopefoundry\lib\site-packages\pyqtgraph\graphicsItems\ImageItem.py", line 464, in getHistogram
    bins = np.arange(mn, mx+1.01*step, step, dtype=np.int)
ValueError: arange: cannot compute length

