2020-07-26T10:56:37|ERROR|FakeCameraMeasurement|fake_camera_image Failed to update figure1: <built-in method emit of PyQt5.QtCore.pyqtBoundSignal object at 0x000001A1BA2B5E90> returned a result with an error set. ['Traceback (most recent call last):\n', '  File "C:\\Users\\Andrea Bassi\\anaconda3\\envs\\scopefoundry\\lib\\site-packages\\pyqtgraph\\graphicsItems\\HistogramLUTItem.py", line 195, in imageChanged\n    h = self.imageItem().getHistogram()\n', '  File "C:\\Users\\Andrea Bassi\\anaconda3\\envs\\scopefoundry\\lib\\site-packages\\pyqtgraph\\graphicsItems\\ImageItem.py", line 464, in getHistogram\n    bins = np.arange(mn, mx+1.01*step, step, dtype=np.int)\n', 'ValueError: arange: cannot compute length\n', '\nThe above exception was the direct cause of the following exception:\n\n', 'Traceback (most recent call last):\n', '  File "C:\\Users\\Andrea Bassi\\anaconda3\\envs\\scopefoundry\\lib\\site-packages\\ScopeFoundry\\measurement.py", line 273, in _on_display_update_timer\n    self.update_display()\n', '  File "C:\\Users\\Andrea Bassi\\OneDrive - Politecnico di Milano\\Documenti\\PythonProjects\\BassiScopeFoundryMicroscopes\\Microscopes\\CellRecongnitionMicroscope\\FakeCameraMeasurement.py", line 80, in update_display\n    self.imv.setImage((self.displayed_image), autoLevels=True, autoRange=self.settings.autoRange.val)\n', '  File "C:\\Users\\Andrea Bassi\\anaconda3\\envs\\scopefoundry\\lib\\site-packages\\pyqtgraph\\imageview\\ImageView.py", line 301, in setImage\n    self.updateImage(autoHistogramRange=autoHistogramRange)\n', '  File "C:\\Users\\Andrea Bassi\\anaconda3\\envs\\scopefoundry\\lib\\site-packages\\pyqtgraph\\imageview\\ImageView.py", line 676, in updateImage\n    self.imageItem.updateImage(image)\n', '  File "C:\\Users\\Andrea Bassi\\anaconda3\\envs\\scopefoundry\\lib\\site-packages\\pyqtgraph\\graphicsItems\\ImageItem.py", line 342, in updateImage\n    return self.setImage(*args, **defaults)\n', '  File "C:\\Users\\Andrea Bassi\\anaconda3\\envs\\scopefoundry\\lib\\site-packages\\pyqtgraph\\graphicsItems\\ImageItem.py", line 283, in setImage\n    self.sigImageChanged.emit()\n', 'SystemError: <built-in method emit of PyQt5.QtCore.pyqtBoundSignal object at 0x000001A1BA2B5E90> returned a result with an error set\n']
2020-07-26T10:56:37|ERROR|FakeCameraMeasurement|fake_camera_image Failed to update figure1: <built-in method emit of PyQt5.QtCore.pyqtBoundSignal object at 0x000001A1AC4FC468> returned a result with an error set. ['Traceback (most recent call last):\n', '  File "C:\\Users\\Andrea Bassi\\anaconda3\\envs\\scopefoundry\\lib\\site-packages\\pyqtgraph\\graphicsItems\\HistogramLUTItem.py", line 195, in imageChanged\n    h = self.imageItem().getHistogram()\n', '  File "C:\\Users\\Andrea Bassi\\anaconda3\\envs\\scopefoundry\\lib\\site-packages\\pyqtgraph\\graphicsItems\\ImageItem.py", line 464, in getHistogram\n    bins = np.arange(mn, mx+1.01*step, step, dtype=np.int)\n', 'ValueError: arange: cannot compute length\n', '\nThe above exception was the direct cause of the following exception:\n\n', 'Traceback (most recent call last):\n', '  File "C:\\Users\\Andrea Bassi\\anaconda3\\envs\\scopefoundry\\lib\\site-packages\\ScopeFoundry\\measurement.py", line 273, in _on_display_update_timer\n    self.update_display()\n', '  File "C:\\Users\\Andrea Bassi\\OneDrive - Politecnico di Milano\\Documenti\\PythonProjects\\BassiScopeFoundryMicroscopes\\Microscopes\\CellRecongnitionMicroscope\\FakeCameraMeasurement.py", line 80, in update_display\n    self.imv.setImage((self.displayed_image), autoLevels=True, autoRange=self.settings.autoRange.val)\n', '  File "C:\\Users\\Andrea Bassi\\anaconda3\\envs\\scopefoundry\\lib\\site-packages\\pyqtgraph\\imageview\\ImageView.py", line 301, in setImage\n    self.updateImage(autoHistogramRange=autoHistogramRange)\n', '  File "C:\\Users\\Andrea Bassi\\anaconda3\\envs\\scopefoundry\\lib\\site-packages\\pyqtgraph\\imageview\\ImageView.py", line 676, in updateImage\n    self.imageItem.updateImage(image)\n', '  File "C:\\Users\\Andrea Bassi\\anaconda3\\envs\\scopefoundry\\lib\\site-packages\\pyqtgraph\\graphicsItems\\ImageItem.py", line 342, in updateImage\n    return self.setImage(*args, **defaults)\n', '  File "C:\\Users\\Andrea Bassi\\anaconda3\\envs\\scopefoundry\\lib\\site-packages\\pyqtgraph\\graphicsItems\\ImageItem.py", line 283, in setImage\n    self.sigImageChanged.emit()\n', 'SystemError: <built-in method emit of PyQt5.QtCore.pyqtBoundSignal object at 0x000001A1AC4FC468> returned a result with an error set\n']
2020-07-26T10:56:37|ERROR|FakeCameraMeasurement|fake_camera_image Failed to update figure1: <built-in method emit of PyQt5.QtCore.pyqtBoundSignal object at 0x000001A1AC4FC468> returned a result with an error set. ['Traceback (most recent call last):\n', '  File "C:\\Users\\Andrea Bassi\\anaconda3\\envs\\scopefoundry\\lib\\site-packages\\pyqtgraph\\graphicsItems\\HistogramLUTItem.py", line 195, in imageChanged\n    h = self.imageItem().getHistogram()\n', '  File "C:\\Users\\Andrea Bassi\\anaconda3\\envs\\scopefoundry\\lib\\site-packages\\pyqtgraph\\graphicsItems\\ImageItem.py", line 464, in getHistogram\n    bins = np.arange(mn, mx+1.01*step, step, dtype=np.int)\n', 'ValueError: arange: cannot compute length\n', '\nThe above exception was the direct cause of the following exception:\n\n', 'Traceback (most recent call last):\n', '  File "C:\\Users\\Andrea Bassi\\anaconda3\\envs\\scopefoundry\\lib\\site-packages\\ScopeFoundry\\measurement.py", line 273, in _on_display_update_timer\n    self.update_display()\n', '  File "C:\\Users\\Andrea Bassi\\OneDrive - Politecnico di Milano\\Documenti\\PythonProjects\\BassiScopeFoundryMicroscopes\\Microscopes\\CellRecongnitionMicroscope\\FakeCameraMeasurement.py", line 80, in update_display\n    self.imv.setImage((self.displayed_image), autoLevels=True, autoRange=self.settings.autoRange.val)\n', '  File "C:\\Users\\Andrea Bassi\\anaconda3\\envs\\scopefoundry\\lib\\site-packages\\pyqtgraph\\imageview\\ImageView.py", line 301, in setImage\n    self.updateImage(autoHistogramRange=autoHistogramRange)\n', '  File "C:\\Users\\Andrea Bassi\\anaconda3\\envs\\scopefoundry\\lib\\site-packages\\pyqtgraph\\imageview\\ImageView.py", line 676, in updateImage\n    self.imageItem.updateImage(image)\n', '  File "C:\\Users\\Andrea Bassi\\anaconda3\\envs\\scopefoundry\\lib\\site-packages\\pyqtgraph\\graphicsItems\\ImageItem.py", line 342, in updateImage\n    return self.setImage(*args, **defaults)\n', '  File "C:\\Users\\Andrea Bassi\\anaconda3\\envs\\scopefoundry\\lib\\site-packages\\pyqtgraph\\graphicsItems\\ImageItem.py", line 283, in setImage\n    self.sigImageChanged.emit()\n', 'SystemError: <built-in method emit of PyQt5.QtCore.pyqtBoundSignal object at 0x000001A1AC4FC468> returned a result with an error set\n']
2020-07-26T10:56:37|ERROR|FakeCameraMeasurement|fake_camera_image Failed to update figure1: <built-in method emit of PyQt5.QtCore.pyqtBoundSignal object at 0x000001A1AC4FC468> returned a result with an error set. ['Traceback (most recent call last):\n', '  File "C:\\Users\\Andrea Bassi\\anaconda3\\envs\\scopefoundry\\lib\\site-packages\\pyqtgraph\\graphicsItems\\HistogramLUTItem.py", line 195, in imageChanged\n    h = self.imageItem().getHistogram()\n', '  File "C:\\Users\\Andrea Bassi\\anaconda3\\envs\\scopefoundry\\lib\\site-packages\\pyqtgraph\\graphicsItems\\ImageItem.py", line 464, in getHistogram\n    bins = np.arange(mn, mx+1.01*step, step, dtype=np.int)\n', 'ValueError: arange: cannot compute length\n', '\nThe above exception was the direct cause of the following exception:\n\n', 'Traceback (most recent call last):\n', '  File "C:\\Users\\Andrea Bassi\\anaconda3\\envs\\scopefoundry\\lib\\site-packages\\ScopeFoundry\\measurement.py", line 273, in _on_display_update_timer\n    self.update_display()\n', '  File "C:\\Users\\Andrea Bassi\\OneDrive - Politecnico di Milano\\Documenti\\PythonProjects\\BassiScopeFoundryMicroscopes\\Microscopes\\CellRecongnitionMicroscope\\FakeCameraMeasurement.py", line 80, in update_display\n    self.imv.setImage((self.displayed_image), autoLevels=True, autoRange=self.settings.autoRange.val)\n', '  File "C:\\Users\\Andrea Bassi\\anaconda3\\envs\\scopefoundry\\lib\\site-packages\\pyqtgraph\\imageview\\ImageView.py", line 301, in setImage\n    self.updateImage(autoHistogramRange=autoHistogramRange)\n', '  File "C:\\Users\\Andrea Bassi\\anaconda3\\envs\\scopefoundry\\lib\\site-packages\\pyqtgraph\\imageview\\ImageView.py", line 676, in updateImage\n    self.imageItem.updateImage(image)\n', '  File "C:\\Users\\Andrea Bassi\\anaconda3\\envs\\scopefoundry\\lib\\site-packages\\pyqtgraph\\graphicsItems\\ImageItem.py", line 342, in updateImage\n    return self.setImage(*args, **defaults)\n', '  File "C:\\Users\\Andrea Bassi\\anaconda3\\envs\\scopefoundry\\lib\\site-packages\\pyqtgraph\\graphicsItems\\ImageItem.py", line 283, in setImage\n    self.sigImageChanged.emit()\n', 'SystemError: <built-in method emit of PyQt5.QtCore.pyqtBoundSignal object at 0x000001A1AC4FC468> returned a result with an error set\n']
2020-07-26T10:56:37|ERROR|FakeCameraMeasurement|fake_camera_image Failed to update figure1: <built-in method emit of PyQt5.QtCore.pyqtBoundSignal object at 0x000001A1AC4FC468> returned a result with an error set. ['Traceback (most recent call last):\n', '  File "C:\\Users\\Andrea Bassi\\anaconda3\\envs\\scopefoundry\\lib\\site-packages\\pyqtgraph\\graphicsItems\\HistogramLUTItem.py", line 195, in imageChanged\n    h = self.imageItem().getHistogram()\n', '  File "C:\\Users\\Andrea Bassi\\anaconda3\\envs\\scopefoundry\\lib\\site-packages\\pyqtgraph\\graphicsItems\\ImageItem.py", line 464, in getHistogram\n    bins = np.arange(mn, mx+1.01*step, step, dtype=np.int)\n', 'ValueError: arange: cannot compute length\n', '\nThe above exception was the direct cause of the following exception:\n\n', 'Traceback (most recent call last):\n', '  File "C:\\Users\\Andrea Bassi\\anaconda3\\envs\\scopefoundry\\lib\\site-packages\\ScopeFoundry\\measurement.py", line 273, in _on_display_update_timer\n    self.update_display()\n', '  File "C:\\Users\\Andrea Bassi\\OneDrive - Politecnico di Milano\\Documenti\\PythonProjects\\BassiScopeFoundryMicroscopes\\Microscopes\\CellRecongnitionMicroscope\\FakeCameraMeasurement.py", line 80, in update_display\n    self.imv.setImage((self.displayed_image), autoLevels=True, autoRange=self.settings.autoRange.val)\n', '  File "C:\\Users\\Andrea Bassi\\anaconda3\\envs\\scopefoundry\\lib\\site-packages\\pyqtgraph\\imageview\\ImageView.py", line 301, in setImage\n    self.updateImage(autoHistogramRange=autoHistogramRange)\n', '  File "C:\\Users\\Andrea Bassi\\anaconda3\\envs\\scopefoundry\\lib\\site-packages\\pyqtgraph\\imageview\\ImageView.py", line 676, in updateImage\n    self.imageItem.updateImage(image)\n', '  File "C:\\Users\\Andrea Bassi\\anaconda3\\envs\\scopefoundry\\lib\\site-packages\\pyqtgraph\\graphicsItems\\ImageItem.py", line 342, in updateImage\n    return self.setImage(*args, **defaults)\n', '  File "C:\\Users\\Andrea Bassi\\anaconda3\\envs\\scopefoundry\\lib\\site-packages\\pyqtgraph\\graphicsItems\\ImageItem.py", line 283, in setImage\n    self.sigImageChanged.emit()\n', 'SystemError: <built-in method emit of PyQt5.QtCore.pyqtBoundSignal object at 0x000001A1AC4FC468> returned a result with an error set\n']
2020-07-26T10:56:37|ERROR|FakeCameraMeasurement|fake_camera_image Failed to update figure1: <built-in method emit of PyQt5.QtCore.pyqtBoundSignal object at 0x000001A1AC4FC468> returned a result with an error set. ['Traceback (most recent call last):\n', '  File "C:\\Users\\Andrea Bassi\\anaconda3\\envs\\scopefoundry\\lib\\site-packages\\pyqtgraph\\graphicsItems\\HistogramLUTItem.py", line 195, in imageChanged\n    h = self.imageItem().getHistogram()\n', '  File "C:\\Users\\Andrea Bassi\\anaconda3\\envs\\scopefoundry\\lib\\site-packages\\pyqtgraph\\graphicsItems\\ImageItem.py", line 464, in getHistogram\n    bins = np.arange(mn, mx+1.01*step, step, dtype=np.int)\n', 'ValueError: arange: cannot compute length\n', '\nThe above exception was the direct cause of the following exception:\n\n', 'Traceback (most recent call last):\n', '  File "C:\\Users\\Andrea Bassi\\anaconda3\\envs\\scopefoundry\\lib\\site-packages\\ScopeFoundry\\measurement.py", line 273, in _on_display_update_timer\n    self.update_display()\n', '  File "C:\\Users\\Andrea Bassi\\OneDrive - Politecnico di Milano\\Documenti\\PythonProjects\\BassiScopeFoundryMicroscopes\\Microscopes\\CellRecongnitionMicroscope\\FakeCameraMeasurement.py", line 80, in update_display\n    self.imv.setImage((self.displayed_image), autoLevels=True, autoRange=self.settings.autoRange.val)\n', '  File "C:\\Users\\Andrea Bassi\\anaconda3\\envs\\scopefoundry\\lib\\site-packages\\pyqtgraph\\imageview\\ImageView.py", line 301, in setImage\n    self.updateImage(autoHistogramRange=autoHistogramRange)\n', '  File "C:\\Users\\Andrea Bassi\\anaconda3\\envs\\scopefoundry\\lib\\site-packages\\pyqtgraph\\imageview\\ImageView.py", line 676, in updateImage\n    self.imageItem.updateImage(image)\n', '  File "C:\\Users\\Andrea Bassi\\anaconda3\\envs\\scopefoundry\\lib\\site-packages\\pyqtgraph\\graphicsItems\\ImageItem.py", line 342, in updateImage\n    return self.setImage(*args, **defaults)\n', '  File "C:\\Users\\Andrea Bassi\\anaconda3\\envs\\scopefoundry\\lib\\site-packages\\pyqtgraph\\graphicsItems\\ImageItem.py", line 283, in setImage\n    self.sigImageChanged.emit()\n', 'SystemError: <built-in method emit of PyQt5.QtCore.pyqtBoundSignal object at 0x000001A1AC4FC468> returned a result with an error set\n']
2020-07-26T10:56:37|ERROR|FakeCameraMeasurement|fake_camera_image Failed to update figure1: <built-in method emit of PyQt5.QtCore.pyqtBoundSignal object at 0x000001A1AC4FC468> returned a result with an error set. ['Traceback (most recent call last):\n', '  File "C:\\Users\\Andrea Bassi\\anaconda3\\envs\\scopefoundry\\lib\\site-packages\\pyqtgraph\\graphicsItems\\HistogramLUTItem.py", line 195, in imageChanged\n    h = self.imageItem().getHistogram()\n', '  File "C:\\Users\\Andrea Bassi\\anaconda3\\envs\\scopefoundry\\lib\\site-packages\\pyqtgraph\\graphicsItems\\ImageItem.py", line 464, in getHistogram\n    bins = np.arange(mn, mx+1.01*step, step, dtype=np.int)\n', 'ValueError: arange: cannot compute length\n', '\nThe above exception was the direct cause of the following exception:\n\n', 'Traceback (most recent call last):\n', '  File "C:\\Users\\Andrea Bassi\\anaconda3\\envs\\scopefoundry\\lib\\site-packages\\ScopeFoundry\\measurement.py", line 273, in _on_display_update_timer\n    self.update_display()\n', '  File "C:\\Users\\Andrea Bassi\\OneDrive - Politecnico di Milano\\Documenti\\PythonProjects\\BassiScopeFoundryMicroscopes\\Microscopes\\CellRecongnitionMicroscope\\FakeCameraMeasurement.py", line 80, in update_display\n    self.imv.setImage((self.displayed_image), autoLevels=True, autoRange=self.settings.autoRange.val)\n', '  File "C:\\Users\\Andrea Bassi\\anaconda3\\envs\\scopefoundry\\lib\\site-packages\\pyqtgraph\\imageview\\ImageView.py", line 301, in setImage\n    self.updateImage(autoHistogramRange=autoHistogramRange)\n', '  File "C:\\Users\\Andrea Bassi\\anaconda3\\envs\\scopefoundry\\lib\\site-packages\\pyqtgraph\\imageview\\ImageView.py", line 676, in updateImage\n    self.imageItem.updateImage(image)\n', '  File "C:\\Users\\Andrea Bassi\\anaconda3\\envs\\scopefoundry\\lib\\site-packages\\pyqtgraph\\graphicsItems\\ImageItem.py", line 342, in updateImage\n    return self.setImage(*args, **defaults)\n', '  File "C:\\Users\\Andrea Bassi\\anaconda3\\envs\\scopefoundry\\lib\\site-packages\\pyqtgraph\\graphicsItems\\ImageItem.py", line 283, in setImage\n    self.sigImageChanged.emit()\n', 'SystemError: <built-in method emit of PyQt5.QtCore.pyqtBoundSignal object at 0x000001A1AC4FC468> returned a result with an error set\n']
2020-07-26T10:56:37|ERROR|FakeCameraMeasurement|fake_camera_image Failed to update figure1: <built-in method emit of PyQt5.QtCore.pyqtBoundSignal object at 0x000001A1AC4FC468> returned a result with an error set. ['Traceback (most recent call last):\n', '  File "C:\\Users\\Andrea Bassi\\anaconda3\\envs\\scopefoundry\\lib\\site-packages\\pyqtgraph\\graphicsItems\\HistogramLUTItem.py", line 195, in imageChanged\n    h = self.imageItem().getHistogram()\n', '  File "C:\\Users\\Andrea Bassi\\anaconda3\\envs\\scopefoundry\\lib\\site-packages\\pyqtgraph\\graphicsItems\\ImageItem.py", line 464, in getHistogram\n    bins = np.arange(mn, mx+1.01*step, step, dtype=np.int)\n', 'ValueError: arange: cannot compute length\n', '\nThe above exception was the direct cause of the following exception:\n\n', 'Traceback (most recent call last):\n', '  File "C:\\Users\\Andrea Bassi\\anaconda3\\envs\\scopefoundry\\lib\\site-packages\\ScopeFoundry\\measurement.py", line 273, in _on_display_update_timer\n    self.update_display()\n', '  File "C:\\Users\\Andrea Bassi\\OneDrive - Politecnico di Milano\\Documenti\\PythonProjects\\BassiScopeFoundryMicroscopes\\Microscopes\\CellRecongnitionMicroscope\\FakeCameraMeasurement.py", line 80, in update_display\n    self.imv.setImage((self.displayed_image), autoLevels=True, autoRange=self.settings.autoRange.val)\n', '  File "C:\\Users\\Andrea Bassi\\anaconda3\\envs\\scopefoundry\\lib\\site-packages\\pyqtgraph\\imageview\\ImageView.py", line 301, in setImage\n    self.updateImage(autoHistogramRange=autoHistogramRange)\n', '  File "C:\\Users\\Andrea Bassi\\anaconda3\\envs\\scopefoundry\\lib\\site-packages\\pyqtgraph\\imageview\\ImageView.py", line 676, in updateImage\n    self.imageItem.updateImage(image)\n', '  File "C:\\Users\\Andrea Bassi\\anaconda3\\envs\\scopefoundry\\lib\\site-packages\\pyqtgraph\\graphicsItems\\ImageItem.py", line 342, in updateImage\n    return self.setImage(*args, **defaults)\n', '  File "C:\\Users\\Andrea Bassi\\anaconda3\\envs\\scopefoundry\\lib\\site-packages\\pyqtgraph\\graphicsItems\\ImageItem.py", line 283, in setImage\n    self.sigImageChanged.emit()\n', 'SystemError: <built-in method emit of PyQt5.QtCore.pyqtBoundSignal object at 0x000001A1AC4FC468> returned a result with an error set\n']
2020-07-26T10:56:37|ERROR|FakeCameraMeasurement|fake_camera_image Failed to update figure1: <built-in method emit of PyQt5.QtCore.pyqtBoundSignal object at 0x000001A1AC4FC468> returned a result with an error set. ['Traceback (most recent call last):\n', '  File "C:\\Users\\Andrea Bassi\\anaconda3\\envs\\scopefoundry\\lib\\site-packages\\pyqtgraph\\graphicsItems\\HistogramLUTItem.py", line 195, in imageChanged\n    h = self.imageItem().getHistogram()\n', '  File "C:\\Users\\Andrea Bassi\\anaconda3\\envs\\scopefoundry\\lib\\site-packages\\pyqtgraph\\graphicsItems\\ImageItem.py", line 464, in getHistogram\n    bins = np.arange(mn, mx+1.01*step, step, dtype=np.int)\n', 'ValueError: arange: cannot compute length\n', '\nThe above exception was the direct cause of the following exception:\n\n', 'Traceback (most recent call last):\n', '  File "C:\\Users\\Andrea Bassi\\anaconda3\\envs\\scopefoundry\\lib\\site-packages\\ScopeFoundry\\measurement.py", line 273, in _on_display_update_timer\n    self.update_display()\n', '  File "C:\\Users\\Andrea Bassi\\OneDrive - Politecnico di Milano\\Documenti\\PythonProjects\\BassiScopeFoundryMicroscopes\\Microscopes\\CellRecongnitionMicroscope\\FakeCameraMeasurement.py", line 80, in update_display\n    self.imv.setImage((self.displayed_image), autoLevels=True, autoRange=self.settings.autoRange.val)\n', '  File "C:\\Users\\Andrea Bassi\\anaconda3\\envs\\scopefoundry\\lib\\site-packages\\pyqtgraph\\imageview\\ImageView.py", line 301, in setImage\n    self.updateImage(autoHistogramRange=autoHistogramRange)\n', '  File "C:\\Users\\Andrea Bassi\\anaconda3\\envs\\scopefoundry\\lib\\site-packages\\pyqtgraph\\imageview\\ImageView.py", line 676, in updateImage\n    self.imageItem.updateImage(image)\n', '  File "C:\\Users\\Andrea Bassi\\anaconda3\\envs\\scopefoundry\\lib\\site-packages\\pyqtgraph\\graphicsItems\\ImageItem.py", line 342, in updateImage\n    return self.setImage(*args, **defaults)\n', '  File "C:\\Users\\Andrea Bassi\\anaconda3\\envs\\scopefoundry\\lib\\site-packages\\pyqtgraph\\graphicsItems\\ImageItem.py", line 283, in setImage\n    self.sigImageChanged.emit()\n', 'SystemError: <built-in method emit of PyQt5.QtCore.pyqtBoundSignal object at 0x000001A1AC4FC468> returned a result with an error set\n']
2020-07-26T10:56:37|ERROR|FakeCameraMeasurement|fake_camera_image Failed to update figure1: <built-in method emit of PyQt5.QtCore.pyqtBoundSignal object at 0x000001A1AC4FC468> returned a result with an error set. ['Traceback (most recent call last):\n', '  File "C:\\Users\\Andrea Bassi\\anaconda3\\envs\\scopefoundry\\lib\\site-packages\\pyqtgraph\\graphicsItems\\HistogramLUTItem.py", line 195, in imageChanged\n    h = self.imageItem().getHistogram()\n', '  File "C:\\Users\\Andrea Bassi\\anaconda3\\envs\\scopefoundry\\lib\\site-packages\\pyqtgraph\\graphicsItems\\ImageItem.py", line 464, in getHistogram\n    bins = np.arange(mn, mx+1.01*step, step, dtype=np.int)\n', 'ValueError: arange: cannot compute length\n', '\nThe above exception was the direct cause of the following exception:\n\n', 'Traceback (most recent call last):\n', '  File "C:\\Users\\Andrea Bassi\\anaconda3\\envs\\scopefoundry\\lib\\site-packages\\ScopeFoundry\\measurement.py", line 273, in _on_display_update_timer\n    self.update_display()\n', '  File "C:\\Users\\Andrea Bassi\\OneDrive - Politecnico di Milano\\Documenti\\PythonProjects\\BassiScopeFoundryMicroscopes\\Microscopes\\CellRecongnitionMicroscope\\FakeCameraMeasurement.py", line 80, in update_display\n    self.imv.setImage((self.displayed_image), autoLevels=True, autoRange=self.settings.autoRange.val)\n', '  File "C:\\Users\\Andrea Bassi\\anaconda3\\envs\\scopefoundry\\lib\\site-packages\\pyqtgraph\\imageview\\ImageView.py", line 301, in setImage\n    self.updateImage(autoHistogramRange=autoHistogramRange)\n', '  File "C:\\Users\\Andrea Bassi\\anaconda3\\envs\\scopefoundry\\lib\\site-packages\\pyqtgraph\\imageview\\ImageView.py", line 676, in updateImage\n    self.imageItem.updateImage(image)\n', '  File "C:\\Users\\Andrea Bassi\\anaconda3\\envs\\scopefoundry\\lib\\site-packages\\pyqtgraph\\graphicsItems\\ImageItem.py", line 342, in updateImage\n    return self.setImage(*args, **defaults)\n', '  File "C:\\Users\\Andrea Bassi\\anaconda3\\envs\\scopefoundry\\lib\\site-packages\\pyqtgraph\\graphicsItems\\ImageItem.py", line 283, in setImage\n    self.sigImageChanged.emit()\n', 'SystemError: <built-in method emit of PyQt5.QtCore.pyqtBoundSignal object at 0x000001A1AC4FC468> returned a result with an error set\n']
2020-07-26T10:56:37|ERROR|FakeCameraMeasurement|fake_camera_image Failed to update figure1: <built-in method emit of PyQt5.QtCore.pyqtBoundSignal object at 0x000001A1AC4FC468> returned a result with an error set. ['Traceback (most recent call last):\n', '  File "C:\\Users\\Andrea Bassi\\anaconda3\\envs\\scopefoundry\\lib\\site-packages\\pyqtgraph\\graphicsItems\\HistogramLUTItem.py", line 195, in imageChanged\n    h = self.imageItem().getHistogram()\n', '  File "C:\\Users\\Andrea Bassi\\anaconda3\\envs\\scopefoundry\\lib\\site-packages\\pyqtgraph\\graphicsItems\\ImageItem.py", line 464, in getHistogram\n    bins = np.arange(mn, mx+1.01*step, step, dtype=np.int)\n', 'ValueError: arange: cannot compute length\n', '\nThe above exception was the direct cause of the following exception:\n\n', 'Traceback (most recent call last):\n', '  File "C:\\Users\\Andrea Bassi\\anaconda3\\envs\\scopefoundry\\lib\\site-packages\\ScopeFoundry\\measurement.py", line 273, in _on_display_update_timer\n    self.update_display()\n', '  File "C:\\Users\\Andrea Bassi\\OneDrive - Politecnico di Milano\\Documenti\\PythonProjects\\BassiScopeFoundryMicroscopes\\Microscopes\\CellRecongnitionMicroscope\\FakeCameraMeasurement.py", line 80, in update_display\n    self.imv.setImage((self.displayed_image), autoLevels=True, autoRange=self.settings.autoRange.val)\n', '  File "C:\\Users\\Andrea Bassi\\anaconda3\\envs\\scopefoundry\\lib\\site-packages\\pyqtgraph\\imageview\\ImageView.py", line 301, in setImage\n    self.updateImage(autoHistogramRange=autoHistogramRange)\n', '  File "C:\\Users\\Andrea Bassi\\anaconda3\\envs\\scopefoundry\\lib\\site-packages\\pyqtgraph\\imageview\\ImageView.py", line 676, in updateImage\n    self.imageItem.updateImage(image)\n', '  File "C:\\Users\\Andrea Bassi\\anaconda3\\envs\\scopefoundry\\lib\\site-packages\\pyqtgraph\\graphicsItems\\ImageItem.py", line 342, in updateImage\n    return self.setImage(*args, **defaults)\n', '  File "C:\\Users\\Andrea Bassi\\anaconda3\\envs\\scopefoundry\\lib\\site-packages\\pyqtgraph\\graphicsItems\\ImageItem.py", line 283, in setImage\n    self.sigImageChanged.emit()\n', 'SystemError: <built-in method emit of PyQt5.QtCore.pyqtBoundSignal object at 0x000001A1AC4FC468> returned a result with an error set\n']
2020-07-26T10:56:37|ERROR|FakeCameraMeasurement|fake_camera_image Failed to update figure1: <built-in method emit of PyQt5.QtCore.pyqtBoundSignal object at 0x000001A1AC4FC468> returned a result with an error set. ['Traceback (most recent call last):\n', '  File "C:\\Users\\Andrea Bassi\\anaconda3\\envs\\scopefoundry\\lib\\site-packages\\pyqtgraph\\graphicsItems\\HistogramLUTItem.py", line 195, in imageChanged\n    h = self.imageItem().getHistogram()\n', '  File "C:\\Users\\Andrea Bassi\\anaconda3\\envs\\scopefoundry\\lib\\site-packages\\pyqtgraph\\graphicsItems\\ImageItem.py", line 464, in getHistogram\n    bins = np.arange(mn, mx+1.01*step, step, dtype=np.int)\n', 'ValueError: arange: cannot compute length\n', '\nThe above exception was the direct cause of the following exception:\n\n', 'Traceback (most recent call last):\n', '  File "C:\\Users\\Andrea Bassi\\anaconda3\\envs\\scopefoundry\\lib\\site-packages\\ScopeFoundry\\measurement.py", line 273, in _on_display_update_timer\n    self.update_display()\n', '  File "C:\\Users\\Andrea Bassi\\OneDrive - Politecnico di Milano\\Documenti\\PythonProjects\\BassiScopeFoundryMicroscopes\\Microscopes\\CellRecongnitionMicroscope\\FakeCameraMeasurement.py", line 80, in update_display\n    self.imv.setImage((self.displayed_image), autoLevels=True, autoRange=self.settings.autoRange.val)\n', '  File "C:\\Users\\Andrea Bassi\\anaconda3\\envs\\scopefoundry\\lib\\site-packages\\pyqtgraph\\imageview\\ImageView.py", line 301, in setImage\n    self.updateImage(autoHistogramRange=autoHistogramRange)\n', '  File "C:\\Users\\Andrea Bassi\\anaconda3\\envs\\scopefoundry\\lib\\site-packages\\pyqtgraph\\imageview\\ImageView.py", line 676, in updateImage\n    self.imageItem.updateImage(image)\n', '  File "C:\\Users\\Andrea Bassi\\anaconda3\\envs\\scopefoundry\\lib\\site-packages\\pyqtgraph\\graphicsItems\\ImageItem.py", line 342, in updateImage\n    return self.setImage(*args, **defaults)\n', '  File "C:\\Users\\Andrea Bassi\\anaconda3\\envs\\scopefoundry\\lib\\site-packages\\pyqtgraph\\graphicsItems\\ImageItem.py", line 283, in setImage\n    self.sigImageChanged.emit()\n', 'SystemError: <built-in method emit of PyQt5.QtCore.pyqtBoundSignal object at 0x000001A1AC4FC468> returned a result with an error set\n']
2020-07-26T10:56:37|ERROR|FakeCameraMeasurement|fake_camera_image Failed to update figure1: <built-in method emit of PyQt5.QtCore.pyqtBoundSignal object at 0x000001A1AC4FC468> returned a result with an error set. ['Traceback (most recent call last):\n', '  File "C:\\Users\\Andrea Bassi\\anaconda3\\envs\\scopefoundry\\lib\\site-packages\\pyqtgraph\\graphicsItems\\HistogramLUTItem.py", line 195, in imageChanged\n    h = self.imageItem().getHistogram()\n', '  File "C:\\Users\\Andrea Bassi\\anaconda3\\envs\\scopefoundry\\lib\\site-packages\\pyqtgraph\\graphicsItems\\ImageItem.py", line 464, in getHistogram\n    bins = np.arange(mn, mx+1.01*step, step, dtype=np.int)\n', 'ValueError: arange: cannot compute length\n', '\nThe above exception was the direct cause of the following exception:\n\n', 'Traceback (most recent call last):\n', '  File "C:\\Users\\Andrea Bassi\\anaconda3\\envs\\scopefoundry\\lib\\site-packages\\ScopeFoundry\\measurement.py", line 273, in _on_display_update_timer\n    self.update_display()\n', '  File "C:\\Users\\Andrea Bassi\\OneDrive - Politecnico di Milano\\Documenti\\PythonProjects\\BassiScopeFoundryMicroscopes\\Microscopes\\CellRecongnitionMicroscope\\FakeCameraMeasurement.py", line 80, in update_display\n    self.imv.setImage((self.displayed_image), autoLevels=True, autoRange=self.settings.autoRange.val)\n', '  File "C:\\Users\\Andrea Bassi\\anaconda3\\envs\\scopefoundry\\lib\\site-packages\\pyqtgraph\\imageview\\ImageView.py", line 301, in setImage\n    self.updateImage(autoHistogramRange=autoHistogramRange)\n', '  File "C:\\Users\\Andrea Bassi\\anaconda3\\envs\\scopefoundry\\lib\\site-packages\\pyqtgraph\\imageview\\ImageView.py", line 676, in updateImage\n    self.imageItem.updateImage(image)\n', '  File "C:\\Users\\Andrea Bassi\\anaconda3\\envs\\scopefoundry\\lib\\site-packages\\pyqtgraph\\graphicsItems\\ImageItem.py", line 342, in updateImage\n    return self.setImage(*args, **defaults)\n', '  File "C:\\Users\\Andrea Bassi\\anaconda3\\envs\\scopefoundry\\lib\\site-packages\\pyqtgraph\\graphicsItems\\ImageItem.py", line 283, in setImage\n    self.sigImageChanged.emit()\n', 'SystemError: <built-in method emit of PyQt5.QtCore.pyqtBoundSignal object at 0x000001A1AC4FC468> returned a result with an error set\n']
2020-07-26T10:56:37|ERROR|FakeCameraMeasurement|fake_camera_image Failed to update figure1: <built-in method emit of PyQt5.QtCore.pyqtBoundSignal object at 0x000001A1AC4FC468> returned a result with an error set. ['Traceback (most recent call last):\n', '  File "C:\\Users\\Andrea Bassi\\anaconda3\\envs\\scopefoundry\\lib\\site-packages\\pyqtgraph\\graphicsItems\\HistogramLUTItem.py", line 195, in imageChanged\n    h = self.imageItem().getHistogram()\n', '  File "C:\\Users\\Andrea Bassi\\anaconda3\\envs\\scopefoundry\\lib\\site-packages\\pyqtgraph\\graphicsItems\\ImageItem.py", line 464, in getHistogram\n    bins = np.arange(mn, mx+1.01*step, step, dtype=np.int)\n', 'ValueError: arange: cannot compute length\n', '\nThe above exception was the direct cause of the following exception:\n\n', 'Traceback (most recent call last):\n', '  File "C:\\Users\\Andrea Bassi\\anaconda3\\envs\\scopefoundry\\lib\\site-packages\\ScopeFoundry\\measurement.py", line 273, in _on_display_update_timer\n    self.update_display()\n', '  File "C:\\Users\\Andrea Bassi\\OneDrive - Politecnico di Milano\\Documenti\\PythonProjects\\BassiScopeFoundryMicroscopes\\Microscopes\\CellRecongnitionMicroscope\\FakeCameraMeasurement.py", line 80, in update_display\n    self.imv.setImage((self.displayed_image), autoLevels=True, autoRange=self.settings.autoRange.val)\n', '  File "C:\\Users\\Andrea Bassi\\anaconda3\\envs\\scopefoundry\\lib\\site-packages\\pyqtgraph\\imageview\\ImageView.py", line 301, in setImage\n    self.updateImage(autoHistogramRange=autoHistogramRange)\n', '  File "C:\\Users\\Andrea Bassi\\anaconda3\\envs\\scopefoundry\\lib\\site-packages\\pyqtgraph\\imageview\\ImageView.py", line 676, in updateImage\n    self.imageItem.updateImage(image)\n', '  File "C:\\Users\\Andrea Bassi\\anaconda3\\envs\\scopefoundry\\lib\\site-packages\\pyqtgraph\\graphicsItems\\ImageItem.py", line 342, in updateImage\n    return self.setImage(*args, **defaults)\n', '  File "C:\\Users\\Andrea Bassi\\anaconda3\\envs\\scopefoundry\\lib\\site-packages\\pyqtgraph\\graphicsItems\\ImageItem.py", line 283, in setImage\n    self.sigImageChanged.emit()\n', 'SystemError: <built-in method emit of PyQt5.QtCore.pyqtBoundSignal object at 0x000001A1AC4FC468> returned a result with an error set\n']
2020-07-26T10:56:37|ERROR|FakeCameraMeasurement|fake_camera_image Failed to update figure1: <built-in method emit of PyQt5.QtCore.pyqtBoundSignal object at 0x000001A1AC4FC468> returned a result with an error set. ['Traceback (most recent call last):\n', '  File "C:\\Users\\Andrea Bassi\\anaconda3\\envs\\scopefoundry\\lib\\site-packages\\pyqtgraph\\graphicsItems\\HistogramLUTItem.py", line 195, in imageChanged\n    h = self.imageItem().getHistogram()\n', '  File "C:\\Users\\Andrea Bassi\\anaconda3\\envs\\scopefoundry\\lib\\site-packages\\pyqtgraph\\graphicsItems\\ImageItem.py", line 464, in getHistogram\n    bins = np.arange(mn, mx+1.01*step, step, dtype=np.int)\n', 'ValueError: arange: cannot compute length\n', '\nThe above exception was the direct cause of the following exception:\n\n', 'Traceback (most recent call last):\n', '  File "C:\\Users\\Andrea Bassi\\anaconda3\\envs\\scopefoundry\\lib\\site-packages\\ScopeFoundry\\measurement.py", line 273, in _on_display_update_timer\n    self.update_display()\n', '  File "C:\\Users\\Andrea Bassi\\OneDrive - Politecnico di Milano\\Documenti\\PythonProjects\\BassiScopeFoundryMicroscopes\\Microscopes\\CellRecongnitionMicroscope\\FakeCameraMeasurement.py", line 80, in update_display\n    self.imv.setImage((self.displayed_image), autoLevels=True, autoRange=self.settings.autoRange.val)\n', '  File "C:\\Users\\Andrea Bassi\\anaconda3\\envs\\scopefoundry\\lib\\site-packages\\pyqtgraph\\imageview\\ImageView.py", line 301, in setImage\n    self.updateImage(autoHistogramRange=autoHistogramRange)\n', '  File "C:\\Users\\Andrea Bassi\\anaconda3\\envs\\scopefoundry\\lib\\site-packages\\pyqtgraph\\imageview\\ImageView.py", line 676, in updateImage\n    self.imageItem.updateImage(image)\n', '  File "C:\\Users\\Andrea Bassi\\anaconda3\\envs\\scopefoundry\\lib\\site-packages\\pyqtgraph\\graphicsItems\\ImageItem.py", line 342, in updateImage\n    return self.setImage(*args, **defaults)\n', '  File "C:\\Users\\Andrea Bassi\\anaconda3\\envs\\scopefoundry\\lib\\site-packages\\pyqtgraph\\graphicsItems\\ImageItem.py", line 283, in setImage\n    self.sigImageChanged.emit()\n', 'SystemError: <built-in method emit of PyQt5.QtCore.pyqtBoundSignal object at 0x000001A1AC4FC468> returned a result with an error set\n']
2020-07-26T10:56:37|ERROR|FakeCameraMeasurement|fake_camera_image Failed to update figure1: <built-in method emit of PyQt5.QtCore.pyqtBoundSignal object at 0x000001A1AC4FC468> returned a result with an error set. ['Traceback (most recent call last):\n', '  File "C:\\Users\\Andrea Bassi\\anaconda3\\envs\\scopefoundry\\lib\\site-packages\\pyqtgraph\\graphicsItems\\HistogramLUTItem.py", line 195, in imageChanged\n    h = self.imageItem().getHistogram()\n', '  File "C:\\Users\\Andrea Bassi\\anaconda3\\envs\\scopefoundry\\lib\\site-packages\\pyqtgraph\\graphicsItems\\ImageItem.py", line 464, in getHistogram\n    bins = np.arange(mn, mx+1.01*step, step, dtype=np.int)\n', 'ValueError: arange: cannot compute length\n', '\nThe above exception was the direct cause of the following exception:\n\n', 'Traceback (most recent call last):\n', '  File "C:\\Users\\Andrea Bassi\\anaconda3\\envs\\scopefoundry\\lib\\site-packages\\ScopeFoundry\\measurement.py", line 273, in _on_display_update_timer\n    self.update_display()\n', '  File "C:\\Users\\Andrea Bassi\\OneDrive - Politecnico di Milano\\Documenti\\PythonProjects\\BassiScopeFoundryMicroscopes\\Microscopes\\CellRecongnitionMicroscope\\FakeCameraMeasurement.py", line 80, in update_display\n    self.imv.setImage((self.displayed_image), autoLevels=True, autoRange=self.settings.autoRange.val)\n', '  File "C:\\Users\\Andrea Bassi\\anaconda3\\envs\\scopefoundry\\lib\\site-packages\\pyqtgraph\\imageview\\ImageView.py", line 301, in setImage\n    self.updateImage(autoHistogramRange=autoHistogramRange)\n', '  File "C:\\Users\\Andrea Bassi\\anaconda3\\envs\\scopefoundry\\lib\\site-packages\\pyqtgraph\\imageview\\ImageView.py", line 676, in updateImage\n    self.imageItem.updateImage(image)\n', '  File "C:\\Users\\Andrea Bassi\\anaconda3\\envs\\scopefoundry\\lib\\site-packages\\pyqtgraph\\graphicsItems\\ImageItem.py", line 342, in updateImage\n    return self.setImage(*args, **defaults)\n', '  File "C:\\Users\\Andrea Bassi\\anaconda3\\envs\\scopefoundry\\lib\\site-packages\\pyqtgraph\\graphicsItems\\ImageItem.py", line 283, in setImage\n    self.sigImageChanged.emit()\n', 'SystemError: <built-in method emit of PyQt5.QtCore.pyqtBoundSignal object at 0x000001A1AC4FC468> returned a result with an error set\n']
2020-07-26T10:56:37|ERROR|FakeCameraMeasurement|fake_camera_image Failed to update figure1: <built-in method emit of PyQt5.QtCore.pyqtBoundSignal object at 0x000001A1AC4FC468> returned a result with an error set. ['Traceback (most recent call last):\n', '  File "C:\\Users\\Andrea Bassi\\anaconda3\\envs\\scopefoundry\\lib\\site-packages\\pyqtgraph\\graphicsItems\\HistogramLUTItem.py", line 195, in imageChanged\n    h = self.imageItem().getHistogram()\n', '  File "C:\\Users\\Andrea Bassi\\anaconda3\\envs\\scopefoundry\\lib\\site-packages\\pyqtgraph\\graphicsItems\\ImageItem.py", line 464, in getHistogram\n    bins = np.arange(mn, mx+1.01*step, step, dtype=np.int)\n', 'ValueError: arange: cannot compute length\n', '\nThe above exception was the direct cause of the following exception:\n\n', 'Traceback (most recent call last):\n', '  File "C:\\Users\\Andrea Bassi\\anaconda3\\envs\\scopefoundry\\lib\\site-packages\\ScopeFoundry\\measurement.py", line 273, in _on_display_update_timer\n    self.update_display()\n', '  File "C:\\Users\\Andrea Bassi\\OneDrive - Politecnico di Milano\\Documenti\\PythonProjects\\BassiScopeFoundryMicroscopes\\Microscopes\\CellRecongnitionMicroscope\\FakeCameraMeasurement.py", line 80, in update_display\n    self.imv.setImage((self.displayed_image), autoLevels=True, autoRange=self.settings.autoRange.val)\n', '  File "C:\\Users\\Andrea Bassi\\anaconda3\\envs\\scopefoundry\\lib\\site-packages\\pyqtgraph\\imageview\\ImageView.py", line 301, in setImage\n    self.updateImage(autoHistogramRange=autoHistogramRange)\n', '  File "C:\\Users\\Andrea Bassi\\anaconda3\\envs\\scopefoundry\\lib\\site-packages\\pyqtgraph\\imageview\\ImageView.py", line 676, in updateImage\n    self.imageItem.updateImage(image)\n', '  File "C:\\Users\\Andrea Bassi\\anaconda3\\envs\\scopefoundry\\lib\\site-packages\\pyqtgraph\\graphicsItems\\ImageItem.py", line 342, in updateImage\n    return self.setImage(*args, **defaults)\n', '  File "C:\\Users\\Andrea Bassi\\anaconda3\\envs\\scopefoundry\\lib\\site-packages\\pyqtgraph\\graphicsItems\\ImageItem.py", line 283, in setImage\n    self.sigImageChanged.emit()\n', 'SystemError: <built-in method emit of PyQt5.QtCore.pyqtBoundSignal object at 0x000001A1AC4FC468> returned a result with an error set\n']
2020-07-26T10:56:37|ERROR|FakeCameraMeasurement|fake_camera_image Failed to update figure1: <built-in method emit of PyQt5.QtCore.pyqtBoundSignal object at 0x000001A1AC4FC468> returned a result with an error set. ['Traceback (most recent call last):\n', '  File "C:\\Users\\Andrea Bassi\\anaconda3\\envs\\scopefoundry\\lib\\site-packages\\pyqtgraph\\graphicsItems\\HistogramLUTItem.py", line 195, in imageChanged\n    h = self.imageItem().getHistogram()\n', '  File "C:\\Users\\Andrea Bassi\\anaconda3\\envs\\scopefoundry\\lib\\site-packages\\pyqtgraph\\graphicsItems\\ImageItem.py", line 464, in getHistogram\n    bins = np.arange(mn, mx+1.01*step, step, dtype=np.int)\n', 'ValueError: arange: cannot compute length\n', '\nThe above exception was the direct cause of the following exception:\n\n', 'Traceback (most recent call last):\n', '  File "C:\\Users\\Andrea Bassi\\anaconda3\\envs\\scopefoundry\\lib\\site-packages\\ScopeFoundry\\measurement.py", line 273, in _on_display_update_timer\n    self.update_display()\n', '  File "C:\\Users\\Andrea Bassi\\OneDrive - Politecnico di Milano\\Documenti\\PythonProjects\\BassiScopeFoundryMicroscopes\\Microscopes\\CellRecongnitionMicroscope\\FakeCameraMeasurement.py", line 80, in update_display\n    self.imv.setImage((self.displayed_image), autoLevels=True, autoRange=self.settings.autoRange.val)\n', '  File "C:\\Users\\Andrea Bassi\\anaconda3\\envs\\scopefoundry\\lib\\site-packages\\pyqtgraph\\imageview\\ImageView.py", line 301, in setImage\n    self.updateImage(autoHistogramRange=autoHistogramRange)\n', '  File "C:\\Users\\Andrea Bassi\\anaconda3\\envs\\scopefoundry\\lib\\site-packages\\pyqtgraph\\imageview\\ImageView.py", line 676, in updateImage\n    self.imageItem.updateImage(image)\n', '  File "C:\\Users\\Andrea Bassi\\anaconda3\\envs\\scopefoundry\\lib\\site-packages\\pyqtgraph\\graphicsItems\\ImageItem.py", line 342, in updateImage\n    return self.setImage(*args, **defaults)\n', '  File "C:\\Users\\Andrea Bassi\\anaconda3\\envs\\scopefoundry\\lib\\site-packages\\pyqtgraph\\graphicsItems\\ImageItem.py", line 283, in setImage\n    self.sigImageChanged.emit()\n', 'SystemError: <built-in method emit of PyQt5.QtCore.pyqtBoundSignal object at 0x000001A1AC4FC468> returned a result with an error set\n']
2020-07-26T10:56:37|ERROR|FakeCameraMeasurement|fake_camera_image Failed to update figure1: <built-in method emit of PyQt5.QtCore.pyqtBoundSignal object at 0x000001A1AC4FC468> returned a result with an error set. ['Traceback (most recent call last):\n', '  File "C:\\Users\\Andrea Bassi\\anaconda3\\envs\\scopefoundry\\lib\\site-packages\\pyqtgraph\\graphicsItems\\HistogramLUTItem.py", line 195, in imageChanged\n    h = self.imageItem().getHistogram()\n', '  File "C:\\Users\\Andrea Bassi\\anaconda3\\envs\\scopefoundry\\lib\\site-packages\\pyqtgraph\\graphicsItems\\ImageItem.py", line 464, in getHistogram\n    bins = np.arange(mn, mx+1.01*step, step, dtype=np.int)\n', 'ValueError: arange: cannot compute length\n', '\nThe above exception was the direct cause of the following exception:\n\n', 'Traceback (most recent call last):\n', '  File "C:\\Users\\Andrea Bassi\\anaconda3\\envs\\scopefoundry\\lib\\site-packages\\ScopeFoundry\\measurement.py", line 273, in _on_display_update_timer\n    self.update_display()\n', '  File "C:\\Users\\Andrea Bassi\\OneDrive - Politecnico di Milano\\Documenti\\PythonProjects\\BassiScopeFoundryMicroscopes\\Microscopes\\CellRecongnitionMicroscope\\FakeCameraMeasurement.py", line 80, in update_display\n    self.imv.setImage((self.displayed_image), autoLevels=True, autoRange=self.settings.autoRange.val)\n', '  File "C:\\Users\\Andrea Bassi\\anaconda3\\envs\\scopefoundry\\lib\\site-packages\\pyqtgraph\\imageview\\ImageView.py", line 301, in setImage\n    self.updateImage(autoHistogramRange=autoHistogramRange)\n', '  File "C:\\Users\\Andrea Bassi\\anaconda3\\envs\\scopefoundry\\lib\\site-packages\\pyqtgraph\\imageview\\ImageView.py", line 676, in updateImage\n    self.imageItem.updateImage(image)\n', '  File "C:\\Users\\Andrea Bassi\\anaconda3\\envs\\scopefoundry\\lib\\site-packages\\pyqtgraph\\graphicsItems\\ImageItem.py", line 342, in updateImage\n    return self.setImage(*args, **defaults)\n', '  File "C:\\Users\\Andrea Bassi\\anaconda3\\envs\\scopefoundry\\lib\\site-packages\\pyqtgraph\\graphicsItems\\ImageItem.py", line 283, in setImage\n    self.sigImageChanged.emit()\n', 'SystemError: <built-in method emit of PyQt5.QtCore.pyqtBoundSignal object at 0x000001A1AC4FC468> returned a result with an error set\n']
2020-07-26T10:56:38|ERROR|FakeCameraMeasurement|fake_camera_image Failed to update figure1: <built-in method emit of PyQt5.QtCore.pyqtBoundSignal object at 0x000001A1AC4FC468> returned a result with an error set. ['Traceback (most recent call last):\n', '  File "C:\\Users\\Andrea Bassi\\anaconda3\\envs\\scopefoundry\\lib\\site-packages\\pyqtgraph\\graphicsItems\\HistogramLUTItem.py", line 195, in imageChanged\n    h = self.imageItem().getHistogram()\n', '  File "C:\\Users\\Andrea Bassi\\anaconda3\\envs\\scopefoundry\\lib\\site-packages\\pyqtgraph\\graphicsItems\\ImageItem.py", line 464, in getHistogram\n    bins = np.arange(mn, mx+1.01*step, step, dtype=np.int)\n', 'ValueError: arange: cannot compute length\n', '\nThe above exception was the direct cause of the following exception:\n\n', 'Traceback (most recent call last):\n', '  File "C:\\Users\\Andrea Bassi\\anaconda3\\envs\\scopefoundry\\lib\\site-packages\\ScopeFoundry\\measurement.py", line 273, in _on_display_update_timer\n    self.update_display()\n', '  File "C:\\Users\\Andrea Bassi\\OneDrive - Politecnico di Milano\\Documenti\\PythonProjects\\BassiScopeFoundryMicroscopes\\Microscopes\\CellRecongnitionMicroscope\\FakeCameraMeasurement.py", line 80, in update_display\n    self.imv.setImage((self.displayed_image), autoLevels=True, autoRange=self.settings.autoRange.val)\n', '  File "C:\\Users\\Andrea Bassi\\anaconda3\\envs\\scopefoundry\\lib\\site-packages\\pyqtgraph\\imageview\\ImageView.py", line 301, in setImage\n    self.updateImage(autoHistogramRange=autoHistogramRange)\n', '  File "C:\\Users\\Andrea Bassi\\anaconda3\\envs\\scopefoundry\\lib\\site-packages\\pyqtgraph\\imageview\\ImageView.py", line 676, in updateImage\n    self.imageItem.updateImage(image)\n', '  File "C:\\Users\\Andrea Bassi\\anaconda3\\envs\\scopefoundry\\lib\\site-packages\\pyqtgraph\\graphicsItems\\ImageItem.py", line 342, in updateImage\n    return self.setImage(*args, **defaults)\n', '  File "C:\\Users\\Andrea Bassi\\anaconda3\\envs\\scopefoundry\\lib\\site-packages\\pyqtgraph\\graphicsItems\\ImageItem.py", line 283, in setImage\n    self.sigImageChanged.emit()\n', 'SystemError: <built-in method emit of PyQt5.QtCore.pyqtBoundSignal object at 0x000001A1AC4FC468> returned a result with an error set\n']
2020-07-26T10:56:38|ERROR|FakeCameraMeasurement|fake_camera_image Failed to update figure1: <built-in method emit of PyQt5.QtCore.pyqtBoundSignal object at 0x000001A1AC4FC468> returned a result with an error set. ['Traceback (most recent call last):\n', '  File "C:\\Users\\Andrea Bassi\\anaconda3\\envs\\scopefoundry\\lib\\site-packages\\pyqtgraph\\graphicsItems\\HistogramLUTItem.py", line 195, in imageChanged\n    h = self.imageItem().getHistogram()\n', '  File "C:\\Users\\Andrea Bassi\\anaconda3\\envs\\scopefoundry\\lib\\site-packages\\pyqtgraph\\graphicsItems\\ImageItem.py", line 464, in getHistogram\n    bins = np.arange(mn, mx+1.01*step, step, dtype=np.int)\n', 'ValueError: arange: cannot compute length\n', '\nThe above exception was the direct cause of the following exception:\n\n', 'Traceback (most recent call last):\n', '  File "C:\\Users\\Andrea Bassi\\anaconda3\\envs\\scopefoundry\\lib\\site-packages\\ScopeFoundry\\measurement.py", line 273, in _on_display_update_timer\n    self.update_display()\n', '  File "C:\\Users\\Andrea Bassi\\OneDrive - Politecnico di Milano\\Documenti\\PythonProjects\\BassiScopeFoundryMicroscopes\\Microscopes\\CellRecongnitionMicroscope\\FakeCameraMeasurement.py", line 80, in update_display\n    self.imv.setImage((self.displayed_image), autoLevels=True, autoRange=self.settings.autoRange.val)\n', '  File "C:\\Users\\Andrea Bassi\\anaconda3\\envs\\scopefoundry\\lib\\site-packages\\pyqtgraph\\imageview\\ImageView.py", line 301, in setImage\n    self.updateImage(autoHistogramRange=autoHistogramRange)\n', '  File "C:\\Users\\Andrea Bassi\\anaconda3\\envs\\scopefoundry\\lib\\site-packages\\pyqtgraph\\imageview\\ImageView.py", line 676, in updateImage\n    self.imageItem.updateImage(image)\n', '  File "C:\\Users\\Andrea Bassi\\anaconda3\\envs\\scopefoundry\\lib\\site-packages\\pyqtgraph\\graphicsItems\\ImageItem.py", line 342, in updateImage\n    return self.setImage(*args, **defaults)\n', '  File "C:\\Users\\Andrea Bassi\\anaconda3\\envs\\scopefoundry\\lib\\site-packages\\pyqtgraph\\graphicsItems\\ImageItem.py", line 283, in setImage\n    self.sigImageChanged.emit()\n', 'SystemError: <built-in method emit of PyQt5.QtCore.pyqtBoundSignal object at 0x000001A1AC4FC468> returned a result with an error set\n']
2020-07-26T10:56:38|ERROR|FakeCameraMeasurement|fake_camera_image Failed to update figure1: <built-in method emit of PyQt5.QtCore.pyqtBoundSignal object at 0x000001A1AC4FC468> returned a result with an error set. ['Traceback (most recent call last):\n', '  File "C:\\Users\\Andrea Bassi\\anaconda3\\envs\\scopefoundry\\lib\\site-packages\\pyqtgraph\\graphicsItems\\HistogramLUTItem.py", line 195, in imageChanged\n    h = self.imageItem().getHistogram()\n', '  File "C:\\Users\\Andrea Bassi\\anaconda3\\envs\\scopefoundry\\lib\\site-packages\\pyqtgraph\\graphicsItems\\ImageItem.py", line 464, in getHistogram\n    bins = np.arange(mn, mx+1.01*step, step, dtype=np.int)\n', 'ValueError: arange: cannot compute length\n', '\nThe above exception was the direct cause of the following exception:\n\n', 'Traceback (most recent call last):\n', '  File "C:\\Users\\Andrea Bassi\\anaconda3\\envs\\scopefoundry\\lib\\site-packages\\ScopeFoundry\\measurement.py", line 273, in _on_display_update_timer\n    self.update_display()\n', '  File "C:\\Users\\Andrea Bassi\\OneDrive - Politecnico di Milano\\Documenti\\PythonProjects\\BassiScopeFoundryMicroscopes\\Microscopes\\CellRecongnitionMicroscope\\FakeCameraMeasurement.py", line 80, in update_display\n    self.imv.setImage((self.displayed_image), autoLevels=True, autoRange=self.settings.autoRange.val)\n', '  File "C:\\Users\\Andrea Bassi\\anaconda3\\envs\\scopefoundry\\lib\\site-packages\\pyqtgraph\\imageview\\ImageView.py", line 301, in setImage\n    self.updateImage(autoHistogramRange=autoHistogramRange)\n', '  File "C:\\Users\\Andrea Bassi\\anaconda3\\envs\\scopefoundry\\lib\\site-packages\\pyqtgraph\\imageview\\ImageView.py", line 676, in updateImage\n    self.imageItem.updateImage(image)\n', '  File "C:\\Users\\Andrea Bassi\\anaconda3\\envs\\scopefoundry\\lib\\site-packages\\pyqtgraph\\graphicsItems\\ImageItem.py", line 342, in updateImage\n    return self.setImage(*args, **defaults)\n', '  File "C:\\Users\\Andrea Bassi\\anaconda3\\envs\\scopefoundry\\lib\\site-packages\\pyqtgraph\\graphicsItems\\ImageItem.py", line 283, in setImage\n    self.sigImageChanged.emit()\n', 'SystemError: <built-in method emit of PyQt5.QtCore.pyqtBoundSignal object at 0x000001A1AC4FC468> returned a result with an error set\n']
2020-07-26T10:56:38|ERROR|FakeCameraMeasurement|fake_camera_image Failed to update figure1: <built-in method emit of PyQt5.QtCore.pyqtBoundSignal object at 0x000001A1AC4FC468> returned a result with an error set. ['Traceback (most recent call last):\n', '  File "C:\\Users\\Andrea Bassi\\anaconda3\\envs\\scopefoundry\\lib\\site-packages\\pyqtgraph\\graphicsItems\\HistogramLUTItem.py", line 195, in imageChanged\n    h = self.imageItem().getHistogram()\n', '  File "C:\\Users\\Andrea Bassi\\anaconda3\\envs\\scopefoundry\\lib\\site-packages\\pyqtgraph\\graphicsItems\\ImageItem.py", line 464, in getHistogram\n    bins = np.arange(mn, mx+1.01*step, step, dtype=np.int)\n', 'ValueError: arange: cannot compute length\n', '\nThe above exception was the direct cause of the following exception:\n\n', 'Traceback (most recent call last):\n', '  File "C:\\Users\\Andrea Bassi\\anaconda3\\envs\\scopefoundry\\lib\\site-packages\\ScopeFoundry\\measurement.py", line 273, in _on_display_update_timer\n    self.update_display()\n', '  File "C:\\Users\\Andrea Bassi\\OneDrive - Politecnico di Milano\\Documenti\\PythonProjects\\BassiScopeFoundryMicroscopes\\Microscopes\\CellRecongnitionMicroscope\\FakeCameraMeasurement.py", line 80, in update_display\n    self.imv.setImage((self.displayed_image), autoLevels=True, autoRange=self.settings.autoRange.val)\n', '  File "C:\\Users\\Andrea Bassi\\anaconda3\\envs\\scopefoundry\\lib\\site-packages\\pyqtgraph\\imageview\\ImageView.py", line 301, in setImage\n    self.updateImage(autoHistogramRange=autoHistogramRange)\n', '  File "C:\\Users\\Andrea Bassi\\anaconda3\\envs\\scopefoundry\\lib\\site-packages\\pyqtgraph\\imageview\\ImageView.py", line 676, in updateImage\n    self.imageItem.updateImage(image)\n', '  File "C:\\Users\\Andrea Bassi\\anaconda3\\envs\\scopefoundry\\lib\\site-packages\\pyqtgraph\\graphicsItems\\ImageItem.py", line 342, in updateImage\n    return self.setImage(*args, **defaults)\n', '  File "C:\\Users\\Andrea Bassi\\anaconda3\\envs\\scopefoundry\\lib\\site-packages\\pyqtgraph\\graphicsItems\\ImageItem.py", line 283, in setImage\n    self.sigImageChanged.emit()\n', 'SystemError: <built-in method emit of PyQt5.QtCore.pyqtBoundSignal object at 0x000001A1AC4FC468> returned a result with an error set\n']
2020-07-26T10:56:38|ERROR|FakeCameraMeasurement|fake_camera_image Failed to update figure1: <built-in method emit of PyQt5.QtCore.pyqtBoundSignal object at 0x000001A1AC4FC468> returned a result with an error set. ['Traceback (most recent call last):\n', '  File "C:\\Users\\Andrea Bassi\\anaconda3\\envs\\scopefoundry\\lib\\site-packages\\pyqtgraph\\graphicsItems\\HistogramLUTItem.py", line 195, in imageChanged\n    h = self.imageItem().getHistogram()\n', '  File "C:\\Users\\Andrea Bassi\\anaconda3\\envs\\scopefoundry\\lib\\site-packages\\pyqtgraph\\graphicsItems\\ImageItem.py", line 464, in getHistogram\n    bins = np.arange(mn, mx+1.01*step, step, dtype=np.int)\n', 'ValueError: arange: cannot compute length\n', '\nThe above exception was the direct cause of the following exception:\n\n', 'Traceback (most recent call last):\n', '  File "C:\\Users\\Andrea Bassi\\anaconda3\\envs\\scopefoundry\\lib\\site-packages\\ScopeFoundry\\measurement.py", line 273, in _on_display_update_timer\n    self.update_display()\n', '  File "C:\\Users\\Andrea Bassi\\OneDrive - Politecnico di Milano\\Documenti\\PythonProjects\\BassiScopeFoundryMicroscopes\\Microscopes\\CellRecongnitionMicroscope\\FakeCameraMeasurement.py", line 80, in update_display\n    self.imv.setImage((self.displayed_image), autoLevels=True, autoRange=self.settings.autoRange.val)\n', '  File "C:\\Users\\Andrea Bassi\\anaconda3\\envs\\scopefoundry\\lib\\site-packages\\pyqtgraph\\imageview\\ImageView.py", line 301, in setImage\n    self.updateImage(autoHistogramRange=autoHistogramRange)\n', '  File "C:\\Users\\Andrea Bassi\\anaconda3\\envs\\scopefoundry\\lib\\site-packages\\pyqtgraph\\imageview\\ImageView.py", line 676, in updateImage\n    self.imageItem.updateImage(image)\n', '  File "C:\\Users\\Andrea Bassi\\anaconda3\\envs\\scopefoundry\\lib\\site-packages\\pyqtgraph\\graphicsItems\\ImageItem.py", line 342, in updateImage\n    return self.setImage(*args, **defaults)\n', '  File "C:\\Users\\Andrea Bassi\\anaconda3\\envs\\scopefoundry\\lib\\site-packages\\pyqtgraph\\graphicsItems\\ImageItem.py", line 283, in setImage\n    self.sigImageChanged.emit()\n', 'SystemError: <built-in method emit of PyQt5.QtCore.pyqtBoundSignal object at 0x000001A1AC4FC468> returned a result with an error set\n']
2020-07-26T10:56:38|ERROR|FakeCameraMeasurement|fake_camera_image Failed to update figure1: <built-in method emit of PyQt5.QtCore.pyqtBoundSignal object at 0x000001A1AC4FC468> returned a result with an error set. ['Traceback (most recent call last):\n', '  File "C:\\Users\\Andrea Bassi\\anaconda3\\envs\\scopefoundry\\lib\\site-packages\\pyqtgraph\\graphicsItems\\HistogramLUTItem.py", line 195, in imageChanged\n    h = self.imageItem().getHistogram()\n', '  File "C:\\Users\\Andrea Bassi\\anaconda3\\envs\\scopefoundry\\lib\\site-packages\\pyqtgraph\\graphicsItems\\ImageItem.py", line 464, in getHistogram\n    bins = np.arange(mn, mx+1.01*step, step, dtype=np.int)\n', 'ValueError: arange: cannot compute length\n', '\nThe above exception was the direct cause of the following exception:\n\n', 'Traceback (most recent call last):\n', '  File "C:\\Users\\Andrea Bassi\\anaconda3\\envs\\scopefoundry\\lib\\site-packages\\ScopeFoundry\\measurement.py", line 273, in _on_display_update_timer\n    self.update_display()\n', '  File "C:\\Users\\Andrea Bassi\\OneDrive - Politecnico di Milano\\Documenti\\PythonProjects\\BassiScopeFoundryMicroscopes\\Microscopes\\CellRecongnitionMicroscope\\FakeCameraMeasurement.py", line 80, in update_display\n    self.imv.setImage((self.displayed_image), autoLevels=True, autoRange=self.settings.autoRange.val)\n', '  File "C:\\Users\\Andrea Bassi\\anaconda3\\envs\\scopefoundry\\lib\\site-packages\\pyqtgraph\\imageview\\ImageView.py", line 301, in setImage\n    self.updateImage(autoHistogramRange=autoHistogramRange)\n', '  File "C:\\Users\\Andrea Bassi\\anaconda3\\envs\\scopefoundry\\lib\\site-packages\\pyqtgraph\\imageview\\ImageView.py", line 676, in updateImage\n    self.imageItem.updateImage(image)\n', '  File "C:\\Users\\Andrea Bassi\\anaconda3\\envs\\scopefoundry\\lib\\site-packages\\pyqtgraph\\graphicsItems\\ImageItem.py", line 342, in updateImage\n    return self.setImage(*args, **defaults)\n', '  File "C:\\Users\\Andrea Bassi\\anaconda3\\envs\\scopefoundry\\lib\\site-packages\\pyqtgraph\\graphicsItems\\ImageItem.py", line 283, in setImage\n    self.sigImageChanged.emit()\n', 'SystemError: <built-in method emit of PyQt5.QtCore.pyqtBoundSignal object at 0x000001A1AC4FC468> returned a result with an error set\n']
2020-07-26T10:56:38|ERROR|FakeCameraMeasurement|fake_camera_image Failed to update figure1: <built-in method emit of PyQt5.QtCore.pyqtBoundSignal object at 0x000001A1AC4FC468> returned a result with an error set. ['Traceback (most recent call last):\n', '  File "C:\\Users\\Andrea Bassi\\anaconda3\\envs\\scopefoundry\\lib\\site-packages\\pyqtgraph\\graphicsItems\\HistogramLUTItem.py", line 195, in imageChanged\n    h = self.imageItem().getHistogram()\n', '  File "C:\\Users\\Andrea Bassi\\anaconda3\\envs\\scopefoundry\\lib\\site-packages\\pyqtgraph\\graphicsItems\\ImageItem.py", line 464, in getHistogram\n    bins = np.arange(mn, mx+1.01*step, step, dtype=np.int)\n', 'ValueError: arange: cannot compute length\n', '\nThe above exception was the direct cause of the following exception:\n\n', 'Traceback (most recent call last):\n', '  File "C:\\Users\\Andrea Bassi\\anaconda3\\envs\\scopefoundry\\lib\\site-packages\\ScopeFoundry\\measurement.py", line 273, in _on_display_update_timer\n    self.update_display()\n', '  File "C:\\Users\\Andrea Bassi\\OneDrive - Politecnico di Milano\\Documenti\\PythonProjects\\BassiScopeFoundryMicroscopes\\Microscopes\\CellRecongnitionMicroscope\\FakeCameraMeasurement.py", line 80, in update_display\n    self.imv.setImage((self.displayed_image), autoLevels=True, autoRange=self.settings.autoRange.val)\n', '  File "C:\\Users\\Andrea Bassi\\anaconda3\\envs\\scopefoundry\\lib\\site-packages\\pyqtgraph\\imageview\\ImageView.py", line 301, in setImage\n    self.updateImage(autoHistogramRange=autoHistogramRange)\n', '  File "C:\\Users\\Andrea Bassi\\anaconda3\\envs\\scopefoundry\\lib\\site-packages\\pyqtgraph\\imageview\\ImageView.py", line 676, in updateImage\n    self.imageItem.updateImage(image)\n', '  File "C:\\Users\\Andrea Bassi\\anaconda3\\envs\\scopefoundry\\lib\\site-packages\\pyqtgraph\\graphicsItems\\ImageItem.py", line 342, in updateImage\n    return self.setImage(*args, **defaults)\n', '  File "C:\\Users\\Andrea Bassi\\anaconda3\\envs\\scopefoundry\\lib\\site-packages\\pyqtgraph\\graphicsItems\\ImageItem.py", line 283, in setImage\n    self.sigImageChanged.emit()\n', 'SystemError: <built-in method emit of PyQt5.QtCore.pyqtBoundSignal object at 0x000001A1AC4FC468> returned a result with an error set\n']
2020-07-26T10:56:38|ERROR|FakeCameraMeasurement|fake_camera_image Failed to update figure1: <built-in method emit of PyQt5.QtCore.pyqtBoundSignal object at 0x000001A1AC4FC468> returned a result with an error set. ['Traceback (most recent call last):\n', '  File "C:\\Users\\Andrea Bassi\\anaconda3\\envs\\scopefoundry\\lib\\site-packages\\pyqtgraph\\graphicsItems\\HistogramLUTItem.py", line 195, in imageChanged\n    h = self.imageItem().getHistogram()\n', '  File "C:\\Users\\Andrea Bassi\\anaconda3\\envs\\scopefoundry\\lib\\site-packages\\pyqtgraph\\graphicsItems\\ImageItem.py", line 464, in getHistogram\n    bins = np.arange(mn, mx+1.01*step, step, dtype=np.int)\n', 'ValueError: arange: cannot compute length\n', '\nThe above exception was the direct cause of the following exception:\n\n', 'Traceback (most recent call last):\n', '  File "C:\\Users\\Andrea Bassi\\anaconda3\\envs\\scopefoundry\\lib\\site-packages\\ScopeFoundry\\measurement.py", line 273, in _on_display_update_timer\n    self.update_display()\n', '  File "C:\\Users\\Andrea Bassi\\OneDrive - Politecnico di Milano\\Documenti\\PythonProjects\\BassiScopeFoundryMicroscopes\\Microscopes\\CellRecongnitionMicroscope\\FakeCameraMeasurement.py", line 80, in update_display\n    self.imv.setImage((self.displayed_image), autoLevels=True, autoRange=self.settings.autoRange.val)\n', '  File "C:\\Users\\Andrea Bassi\\anaconda3\\envs\\scopefoundry\\lib\\site-packages\\pyqtgraph\\imageview\\ImageView.py", line 301, in setImage\n    self.updateImage(autoHistogramRange=autoHistogramRange)\n', '  File "C:\\Users\\Andrea Bassi\\anaconda3\\envs\\scopefoundry\\lib\\site-packages\\pyqtgraph\\imageview\\ImageView.py", line 676, in updateImage\n    self.imageItem.updateImage(image)\n', '  File "C:\\Users\\Andrea Bassi\\anaconda3\\envs\\scopefoundry\\lib\\site-packages\\pyqtgraph\\graphicsItems\\ImageItem.py", line 342, in updateImage\n    return self.setImage(*args, **defaults)\n', '  File "C:\\Users\\Andrea Bassi\\anaconda3\\envs\\scopefoundry\\lib\\site-packages\\pyqtgraph\\graphicsItems\\ImageItem.py", line 283, in setImage\n    self.sigImageChanged.emit()\n', 'SystemError: <built-in method emit of PyQt5.QtCore.pyqtBoundSignal object at 0x000001A1AC4FC468> returned a result with an error set\n']
2020-07-26T10:56:38|ERROR|FakeCameraMeasurement|fake_camera_image Failed to update figure1: <built-in method emit of PyQt5.QtCore.pyqtBoundSignal object at 0x000001A1AC4FC468> returned a result with an error set. ['Traceback (most recent call last):\n', '  File "C:\\Users\\Andrea Bassi\\anaconda3\\envs\\scopefoundry\\lib\\site-packages\\pyqtgraph\\graphicsItems\\HistogramLUTItem.py", line 195, in imageChanged\n    h = self.imageItem().getHistogram()\n', '  File "C:\\Users\\Andrea Bassi\\anaconda3\\envs\\scopefoundry\\lib\\site-packages\\pyqtgraph\\graphicsItems\\ImageItem.py", line 464, in getHistogram\n    bins = np.arange(mn, mx+1.01*step, step, dtype=np.int)\n', 'ValueError: arange: cannot compute length\n', '\nThe above exception was the direct cause of the following exception:\n\n', 'Traceback (most recent call last):\n', '  File "C:\\Users\\Andrea Bassi\\anaconda3\\envs\\scopefoundry\\lib\\site-packages\\ScopeFoundry\\measurement.py", line 273, in _on_display_update_timer\n    self.update_display()\n', '  File "C:\\Users\\Andrea Bassi\\OneDrive - Politecnico di Milano\\Documenti\\PythonProjects\\BassiScopeFoundryMicroscopes\\Microscopes\\CellRecongnitionMicroscope\\FakeCameraMeasurement.py", line 80, in update_display\n    self.imv.setImage((self.displayed_image), autoLevels=True, autoRange=self.settings.autoRange.val)\n', '  File "C:\\Users\\Andrea Bassi\\anaconda3\\envs\\scopefoundry\\lib\\site-packages\\pyqtgraph\\imageview\\ImageView.py", line 301, in setImage\n    self.updateImage(autoHistogramRange=autoHistogramRange)\n', '  File "C:\\Users\\Andrea Bassi\\anaconda3\\envs\\scopefoundry\\lib\\site-packages\\pyqtgraph\\imageview\\ImageView.py", line 676, in updateImage\n    self.imageItem.updateImage(image)\n', '  File "C:\\Users\\Andrea Bassi\\anaconda3\\envs\\scopefoundry\\lib\\site-packages\\pyqtgraph\\graphicsItems\\ImageItem.py", line 342, in updateImage\n    return self.setImage(*args, **defaults)\n', '  File "C:\\Users\\Andrea Bassi\\anaconda3\\envs\\scopefoundry\\lib\\site-packages\\pyqtgraph\\graphicsItems\\ImageItem.py", line 283, in setImage\n    self.sigImageChanged.emit()\n', 'SystemError: <built-in method emit of PyQt5.QtCore.pyqtBoundSignal object at 0x000001A1AC4FC468> returned a result with an error set\n']
2020-07-26T10:56:38|ERROR|FakeCameraMeasurement|fake_camera_image Failed to update figure1: <built-in method emit of PyQt5.QtCore.pyqtBoundSignal object at 0x000001A1AC4FC468> returned a result with an error set. ['Traceback (most recent call last):\n', '  File "C:\\Users\\Andrea Bassi\\anaconda3\\envs\\scopefoundry\\lib\\site-packages\\pyqtgraph\\graphicsItems\\HistogramLUTItem.py", line 195, in imageChanged\n    h = self.imageItem().getHistogram()\n', '  File "C:\\Users\\Andrea Bassi\\anaconda3\\envs\\scopefoundry\\lib\\site-packages\\pyqtgraph\\graphicsItems\\ImageItem.py", line 464, in getHistogram\n    bins = np.arange(mn, mx+1.01*step, step, dtype=np.int)\n', 'ValueError: arange: cannot compute length\n', '\nThe above exception was the direct cause of the following exception:\n\n', 'Traceback (most recent call last):\n', '  File "C:\\Users\\Andrea Bassi\\anaconda3\\envs\\scopefoundry\\lib\\site-packages\\ScopeFoundry\\measurement.py", line 273, in _on_display_update_timer\n    self.update_display()\n', '  File "C:\\Users\\Andrea Bassi\\OneDrive - Politecnico di Milano\\Documenti\\PythonProjects\\BassiScopeFoundryMicroscopes\\Microscopes\\CellRecongnitionMicroscope\\FakeCameraMeasurement.py", line 80, in update_display\n    self.imv.setImage((self.displayed_image), autoLevels=True, autoRange=self.settings.autoRange.val)\n', '  File "C:\\Users\\Andrea Bassi\\anaconda3\\envs\\scopefoundry\\lib\\site-packages\\pyqtgraph\\imageview\\ImageView.py", line 301, in setImage\n    self.updateImage(autoHistogramRange=autoHistogramRange)\n', '  File "C:\\Users\\Andrea Bassi\\anaconda3\\envs\\scopefoundry\\lib\\site-packages\\pyqtgraph\\imageview\\ImageView.py", line 676, in updateImage\n    self.imageItem.updateImage(image)\n', '  File "C:\\Users\\Andrea Bassi\\anaconda3\\envs\\scopefoundry\\lib\\site-packages\\pyqtgraph\\graphicsItems\\ImageItem.py", line 342, in updateImage\n    return self.setImage(*args, **defaults)\n', '  File "C:\\Users\\Andrea Bassi\\anaconda3\\envs\\scopefoundry\\lib\\site-packages\\pyqtgraph\\graphicsItems\\ImageItem.py", line 283, in setImage\n    self.sigImageChanged.emit()\n', 'SystemError: <built-in method emit of PyQt5.QtCore.pyqtBoundSignal object at 0x000001A1AC4FC468> returned a result with an error set\n']
2020-07-26T10:56:38|ERROR|FakeCameraMeasurement|fake_camera_image Failed to update figure1: <built-in method emit of PyQt5.QtCore.pyqtBoundSignal object at 0x000001A1AC4FC468> returned a result with an error set. ['Traceback (most recent call last):\n', '  File "C:\\Users\\Andrea Bassi\\anaconda3\\envs\\scopefoundry\\lib\\site-packages\\pyqtgraph\\graphicsItems\\HistogramLUTItem.py", line 195, in imageChanged\n    h = self.imageItem().getHistogram()\n', '  File "C:\\Users\\Andrea Bassi\\anaconda3\\envs\\scopefoundry\\lib\\site-packages\\pyqtgraph\\graphicsItems\\ImageItem.py", line 464, in getHistogram\n    bins = np.arange(mn, mx+1.01*step, step, dtype=np.int)\n', 'ValueError: arange: cannot compute length\n', '\nThe above exception was the direct cause of the following exception:\n\n', 'Traceback (most recent call last):\n', '  File "C:\\Users\\Andrea Bassi\\anaconda3\\envs\\scopefoundry\\lib\\site-packages\\ScopeFoundry\\measurement.py", line 273, in _on_display_update_timer\n    self.update_display()\n', '  File "C:\\Users\\Andrea Bassi\\OneDrive - Politecnico di Milano\\Documenti\\PythonProjects\\BassiScopeFoundryMicroscopes\\Microscopes\\CellRecongnitionMicroscope\\FakeCameraMeasurement.py", line 80, in update_display\n    self.imv.setImage((self.displayed_image), autoLevels=True, autoRange=self.settings.autoRange.val)\n', '  File "C:\\Users\\Andrea Bassi\\anaconda3\\envs\\scopefoundry\\lib\\site-packages\\pyqtgraph\\imageview\\ImageView.py", line 301, in setImage\n    self.updateImage(autoHistogramRange=autoHistogramRange)\n', '  File "C:\\Users\\Andrea Bassi\\anaconda3\\envs\\scopefoundry\\lib\\site-packages\\pyqtgraph\\imageview\\ImageView.py", line 676, in updateImage\n    self.imageItem.updateImage(image)\n', '  File "C:\\Users\\Andrea Bassi\\anaconda3\\envs\\scopefoundry\\lib\\site-packages\\pyqtgraph\\graphicsItems\\ImageItem.py", line 342, in updateImage\n    return self.setImage(*args, **defaults)\n', '  File "C:\\Users\\Andrea Bassi\\anaconda3\\envs\\scopefoundry\\lib\\site-packages\\pyqtgraph\\graphicsItems\\ImageItem.py", line 283, in setImage\n    self.sigImageChanged.emit()\n', 'SystemError: <built-in method emit of PyQt5.QtCore.pyqtBoundSignal object at 0x000001A1AC4FC468> returned a result with an error set\n']
2020-07-26T10:56:38|ERROR|FakeCameraMeasurement|fake_camera_image Failed to update figure1: <built-in method emit of PyQt5.QtCore.pyqtBoundSignal object at 0x000001A1AC4FC468> returned a result with an error set. ['Traceback (most recent call last):\n', '  File "C:\\Users\\Andrea Bassi\\anaconda3\\envs\\scopefoundry\\lib\\site-packages\\pyqtgraph\\graphicsItems\\HistogramLUTItem.py", line 195, in imageChanged\n    h = self.imageItem().getHistogram()\n', '  File "C:\\Users\\Andrea Bassi\\anaconda3\\envs\\scopefoundry\\lib\\site-packages\\pyqtgraph\\graphicsItems\\ImageItem.py", line 464, in getHistogram\n    bins = np.arange(mn, mx+1.01*step, step, dtype=np.int)\n', 'ValueError: arange: cannot compute length\n', '\nThe above exception was the direct cause of the following exception:\n\n', 'Traceback (most recent call last):\n', '  File "C:\\Users\\Andrea Bassi\\anaconda3\\envs\\scopefoundry\\lib\\site-packages\\ScopeFoundry\\measurement.py", line 273, in _on_display_update_timer\n    self.update_display()\n', '  File "C:\\Users\\Andrea Bassi\\OneDrive - Politecnico di Milano\\Documenti\\PythonProjects\\BassiScopeFoundryMicroscopes\\Microscopes\\CellRecongnitionMicroscope\\FakeCameraMeasurement.py", line 80, in update_display\n    self.imv.setImage((self.displayed_image), autoLevels=True, autoRange=self.settings.autoRange.val)\n', '  File "C:\\Users\\Andrea Bassi\\anaconda3\\envs\\scopefoundry\\lib\\site-packages\\pyqtgraph\\imageview\\ImageView.py", line 301, in setImage\n    self.updateImage(autoHistogramRange=autoHistogramRange)\n', '  File "C:\\Users\\Andrea Bassi\\anaconda3\\envs\\scopefoundry\\lib\\site-packages\\pyqtgraph\\imageview\\ImageView.py", line 676, in updateImage\n    self.imageItem.updateImage(image)\n', '  File "C:\\Users\\Andrea Bassi\\anaconda3\\envs\\scopefoundry\\lib\\site-packages\\pyqtgraph\\graphicsItems\\ImageItem.py", line 342, in updateImage\n    return self.setImage(*args, **defaults)\n', '  File "C:\\Users\\Andrea Bassi\\anaconda3\\envs\\scopefoundry\\lib\\site-packages\\pyqtgraph\\graphicsItems\\ImageItem.py", line 283, in setImage\n    self.sigImageChanged.emit()\n', 'SystemError: <built-in method emit of PyQt5.QtCore.pyqtBoundSignal object at 0x000001A1AC4FC468> returned a result with an error set\n']
2020-07-26T10:56:38|ERROR|FakeCameraMeasurement|fake_camera_image Failed to update figure1: <built-in method emit of PyQt5.QtCore.pyqtBoundSignal object at 0x000001A1AC4FC468> returned a result with an error set. ['Traceback (most recent call last):\n', '  File "C:\\Users\\Andrea Bassi\\anaconda3\\envs\\scopefoundry\\lib\\site-packages\\pyqtgraph\\graphicsItems\\HistogramLUTItem.py", line 195, in imageChanged\n    h = self.imageItem().getHistogram()\n', '  File "C:\\Users\\Andrea Bassi\\anaconda3\\envs\\scopefoundry\\lib\\site-packages\\pyqtgraph\\graphicsItems\\ImageItem.py", line 464, in getHistogram\n    bins = np.arange(mn, mx+1.01*step, step, dtype=np.int)\n', 'ValueError: arange: cannot compute length\n', '\nThe above exception was the direct cause of the following exception:\n\n', 'Traceback (most recent call last):\n', '  File "C:\\Users\\Andrea Bassi\\anaconda3\\envs\\scopefoundry\\lib\\site-packages\\ScopeFoundry\\measurement.py", line 273, in _on_display_update_timer\n    self.update_display()\n', '  File "C:\\Users\\Andrea Bassi\\OneDrive - Politecnico di Milano\\Documenti\\PythonProjects\\BassiScopeFoundryMicroscopes\\Microscopes\\CellRecongnitionMicroscope\\FakeCameraMeasurement.py", line 80, in update_display\n    self.imv.setImage((self.displayed_image), autoLevels=True, autoRange=self.settings.autoRange.val)\n', '  File "C:\\Users\\Andrea Bassi\\anaconda3\\envs\\scopefoundry\\lib\\site-packages\\pyqtgraph\\imageview\\ImageView.py", line 301, in setImage\n    self.updateImage(autoHistogramRange=autoHistogramRange)\n', '  File "C:\\Users\\Andrea Bassi\\anaconda3\\envs\\scopefoundry\\lib\\site-packages\\pyqtgraph\\imageview\\ImageView.py", line 676, in updateImage\n    self.imageItem.updateImage(image)\n', '  File "C:\\Users\\Andrea Bassi\\anaconda3\\envs\\scopefoundry\\lib\\site-packages\\pyqtgraph\\graphicsItems\\ImageItem.py", line 342, in updateImage\n    return self.setImage(*args, **defaults)\n', '  File "C:\\Users\\Andrea Bassi\\anaconda3\\envs\\scopefoundry\\lib\\site-packages\\pyqtgraph\\graphicsItems\\ImageItem.py", line 283, in setImage\n    self.sigImageChanged.emit()\n', 'SystemError: <built-in method emit of PyQt5.QtCore.pyqtBoundSignal object at 0x000001A1AC4FC468> returned a result with an error set\n']
2020-07-26T10:56:38|ERROR|FakeCameraMeasurement|fake_camera_image Failed to update figure1: <built-in method emit of PyQt5.QtCore.pyqtBoundSignal object at 0x000001A1AC4FC468> returned a result with an error set. ['Traceback (most recent call last):\n', '  File "C:\\Users\\Andrea Bassi\\anaconda3\\envs\\scopefoundry\\lib\\site-packages\\pyqtgraph\\graphicsItems\\HistogramLUTItem.py", line 195, in imageChanged\n    h = self.imageItem().getHistogram()\n', '  File "C:\\Users\\Andrea Bassi\\anaconda3\\envs\\scopefoundry\\lib\\site-packages\\pyqtgraph\\graphicsItems\\ImageItem.py", line 464, in getHistogram\n    bins = np.arange(mn, mx+1.01*step, step, dtype=np.int)\n', 'ValueError: arange: cannot compute length\n', '\nThe above exception was the direct cause of the following exception:\n\n', 'Traceback (most recent call last):\n', '  File "C:\\Users\\Andrea Bassi\\anaconda3\\envs\\scopefoundry\\lib\\site-packages\\ScopeFoundry\\measurement.py", line 273, in _on_display_update_timer\n    self.update_display()\n', '  File "C:\\Users\\Andrea Bassi\\OneDrive - Politecnico di Milano\\Documenti\\PythonProjects\\BassiScopeFoundryMicroscopes\\Microscopes\\CellRecongnitionMicroscope\\FakeCameraMeasurement.py", line 80, in update_display\n    self.imv.setImage((self.displayed_image), autoLevels=True, autoRange=self.settings.autoRange.val)\n', '  File "C:\\Users\\Andrea Bassi\\anaconda3\\envs\\scopefoundry\\lib\\site-packages\\pyqtgraph\\imageview\\ImageView.py", line 301, in setImage\n    self.updateImage(autoHistogramRange=autoHistogramRange)\n', '  File "C:\\Users\\Andrea Bassi\\anaconda3\\envs\\scopefoundry\\lib\\site-packages\\pyqtgraph\\imageview\\ImageView.py", line 676, in updateImage\n    self.imageItem.updateImage(image)\n', '  File "C:\\Users\\Andrea Bassi\\anaconda3\\envs\\scopefoundry\\lib\\site-packages\\pyqtgraph\\graphicsItems\\ImageItem.py", line 342, in updateImage\n    return self.setImage(*args, **defaults)\n', '  File "C:\\Users\\Andrea Bassi\\anaconda3\\envs\\scopefoundry\\lib\\site-packages\\pyqtgraph\\graphicsItems\\ImageItem.py", line 283, in setImage\n    self.sigImageChanged.emit()\n', 'SystemError: <built-in method emit of PyQt5.QtCore.pyqtBoundSignal object at 0x000001A1AC4FC468> returned a result with an error set\n']
2020-07-26T10:56:38|ERROR|FakeCameraMeasurement|fake_camera_image Failed to update figure1: <built-in method emit of PyQt5.QtCore.pyqtBoundSignal object at 0x000001A1AC4FC468> returned a result with an error set. ['Traceback (most recent call last):\n', '  File "C:\\Users\\Andrea Bassi\\anaconda3\\envs\\scopefoundry\\lib\\site-packages\\pyqtgraph\\graphicsItems\\HistogramLUTItem.py", line 195, in imageChanged\n    h = self.imageItem().getHistogram()\n', '  File "C:\\Users\\Andrea Bassi\\anaconda3\\envs\\scopefoundry\\lib\\site-packages\\pyqtgraph\\graphicsItems\\ImageItem.py", line 464, in getHistogram\n    bins = np.arange(mn, mx+1.01*step, step, dtype=np.int)\n', 'ValueError: arange: cannot compute length\n', '\nThe above exception was the direct cause of the following exception:\n\n', 'Traceback (most recent call last):\n', '  File "C:\\Users\\Andrea Bassi\\anaconda3\\envs\\scopefoundry\\lib\\site-packages\\ScopeFoundry\\measurement.py", line 273, in _on_display_update_timer\n    self.update_display()\n', '  File "C:\\Users\\Andrea Bassi\\OneDrive - Politecnico di Milano\\Documenti\\PythonProjects\\BassiScopeFoundryMicroscopes\\Microscopes\\CellRecongnitionMicroscope\\FakeCameraMeasurement.py", line 80, in update_display\n    self.imv.setImage((self.displayed_image), autoLevels=True, autoRange=self.settings.autoRange.val)\n', '  File "C:\\Users\\Andrea Bassi\\anaconda3\\envs\\scopefoundry\\lib\\site-packages\\pyqtgraph\\imageview\\ImageView.py", line 301, in setImage\n    self.updateImage(autoHistogramRange=autoHistogramRange)\n', '  File "C:\\Users\\Andrea Bassi\\anaconda3\\envs\\scopefoundry\\lib\\site-packages\\pyqtgraph\\imageview\\ImageView.py", line 676, in updateImage\n    self.imageItem.updateImage(image)\n', '  File "C:\\Users\\Andrea Bassi\\anaconda3\\envs\\scopefoundry\\lib\\site-packages\\pyqtgraph\\graphicsItems\\ImageItem.py", line 342, in updateImage\n    return self.setImage(*args, **defaults)\n', '  File "C:\\Users\\Andrea Bassi\\anaconda3\\envs\\scopefoundry\\lib\\site-packages\\pyqtgraph\\graphicsItems\\ImageItem.py", line 283, in setImage\n    self.sigImageChanged.emit()\n', 'SystemError: <built-in method emit of PyQt5.QtCore.pyqtBoundSignal object at 0x000001A1AC4FC468> returned a result with an error set\n']
2020-07-26T10:56:38|ERROR|FakeCameraMeasurement|fake_camera_image Failed to update figure1: <built-in method emit of PyQt5.QtCore.pyqtBoundSignal object at 0x000001A1AC4FC468> returned a result with an error set. ['Traceback (most recent call last):\n', '  File "C:\\Users\\Andrea Bassi\\anaconda3\\envs\\scopefoundry\\lib\\site-packages\\pyqtgraph\\graphicsItems\\HistogramLUTItem.py", line 195, in imageChanged\n    h = self.imageItem().getHistogram()\n', '  File "C:\\Users\\Andrea Bassi\\anaconda3\\envs\\scopefoundry\\lib\\site-packages\\pyqtgraph\\graphicsItems\\ImageItem.py", line 464, in getHistogram\n    bins = np.arange(mn, mx+1.01*step, step, dtype=np.int)\n', 'ValueError: arange: cannot compute length\n', '\nThe above exception was the direct cause of the following exception:\n\n', 'Traceback (most recent call last):\n', '  File "C:\\Users\\Andrea Bassi\\anaconda3\\envs\\scopefoundry\\lib\\site-packages\\ScopeFoundry\\measurement.py", line 273, in _on_display_update_timer\n    self.update_display()\n', '  File "C:\\Users\\Andrea Bassi\\OneDrive - Politecnico di Milano\\Documenti\\PythonProjects\\BassiScopeFoundryMicroscopes\\Microscopes\\CellRecongnitionMicroscope\\FakeCameraMeasurement.py", line 80, in update_display\n    self.imv.setImage((self.displayed_image), autoLevels=True, autoRange=self.settings.autoRange.val)\n', '  File "C:\\Users\\Andrea Bassi\\anaconda3\\envs\\scopefoundry\\lib\\site-packages\\pyqtgraph\\imageview\\ImageView.py", line 301, in setImage\n    self.updateImage(autoHistogramRange=autoHistogramRange)\n', '  File "C:\\Users\\Andrea Bassi\\anaconda3\\envs\\scopefoundry\\lib\\site-packages\\pyqtgraph\\imageview\\ImageView.py", line 676, in updateImage\n    self.imageItem.updateImage(image)\n', '  File "C:\\Users\\Andrea Bassi\\anaconda3\\envs\\scopefoundry\\lib\\site-packages\\pyqtgraph\\graphicsItems\\ImageItem.py", line 342, in updateImage\n    return self.setImage(*args, **defaults)\n', '  File "C:\\Users\\Andrea Bassi\\anaconda3\\envs\\scopefoundry\\lib\\site-packages\\pyqtgraph\\graphicsItems\\ImageItem.py", line 283, in setImage\n    self.sigImageChanged.emit()\n', 'SystemError: <built-in method emit of PyQt5.QtCore.pyqtBoundSignal object at 0x000001A1AC4FC468> returned a result with an error set\n']
2020-07-26T10:56:38|ERROR|FakeCameraMeasurement|fake_camera_image Failed to update figure1: <built-in method emit of PyQt5.QtCore.pyqtBoundSignal object at 0x000001A1AC4FC468> returned a result with an error set. ['Traceback (most recent call last):\n', '  File "C:\\Users\\Andrea Bassi\\anaconda3\\envs\\scopefoundry\\lib\\site-packages\\pyqtgraph\\graphicsItems\\HistogramLUTItem.py", line 195, in imageChanged\n    h = self.imageItem().getHistogram()\n', '  File "C:\\Users\\Andrea Bassi\\anaconda3\\envs\\scopefoundry\\lib\\site-packages\\pyqtgraph\\graphicsItems\\ImageItem.py", line 464, in getHistogram\n    bins = np.arange(mn, mx+1.01*step, step, dtype=np.int)\n', 'ValueError: arange: cannot compute length\n', '\nThe above exception was the direct cause of the following exception:\n\n', 'Traceback (most recent call last):\n', '  File "C:\\Users\\Andrea Bassi\\anaconda3\\envs\\scopefoundry\\lib\\site-packages\\ScopeFoundry\\measurement.py", line 273, in _on_display_update_timer\n    self.update_display()\n', '  File "C:\\Users\\Andrea Bassi\\OneDrive - Politecnico di Milano\\Documenti\\PythonProjects\\BassiScopeFoundryMicroscopes\\Microscopes\\CellRecongnitionMicroscope\\FakeCameraMeasurement.py", line 80, in update_display\n    self.imv.setImage((self.displayed_image), autoLevels=True, autoRange=self.settings.autoRange.val)\n', '  File "C:\\Users\\Andrea Bassi\\anaconda3\\envs\\scopefoundry\\lib\\site-packages\\pyqtgraph\\imageview\\ImageView.py", line 301, in setImage\n    self.updateImage(autoHistogramRange=autoHistogramRange)\n', '  File "C:\\Users\\Andrea Bassi\\anaconda3\\envs\\scopefoundry\\lib\\site-packages\\pyqtgraph\\imageview\\ImageView.py", line 676, in updateImage\n    self.imageItem.updateImage(image)\n', '  File "C:\\Users\\Andrea Bassi\\anaconda3\\envs\\scopefoundry\\lib\\site-packages\\pyqtgraph\\graphicsItems\\ImageItem.py", line 342, in updateImage\n    return self.setImage(*args, **defaults)\n', '  File "C:\\Users\\Andrea Bassi\\anaconda3\\envs\\scopefoundry\\lib\\site-packages\\pyqtgraph\\graphicsItems\\ImageItem.py", line 283, in setImage\n    self.sigImageChanged.emit()\n', 'SystemError: <built-in method emit of PyQt5.QtCore.pyqtBoundSignal object at 0x000001A1AC4FC468> returned a result with an error set\n']
2020-07-26T10:56:38|ERROR|FakeCameraMeasurement|fake_camera_image Failed to update figure1: <built-in method emit of PyQt5.QtCore.pyqtBoundSignal object at 0x000001A1AC4FC468> returned a result with an error set. ['Traceback (most recent call last):\n', '  File "C:\\Users\\Andrea Bassi\\anaconda3\\envs\\scopefoundry\\lib\\site-packages\\pyqtgraph\\graphicsItems\\HistogramLUTItem.py", line 195, in imageChanged\n    h = self.imageItem().getHistogram()\n', '  File "C:\\Users\\Andrea Bassi\\anaconda3\\envs\\scopefoundry\\lib\\site-packages\\pyqtgraph\\graphicsItems\\ImageItem.py", line 464, in getHistogram\n    bins = np.arange(mn, mx+1.01*step, step, dtype=np.int)\n', 'ValueError: arange: cannot compute length\n', '\nThe above exception was the direct cause of the following exception:\n\n', 'Traceback (most recent call last):\n', '  File "C:\\Users\\Andrea Bassi\\anaconda3\\envs\\scopefoundry\\lib\\site-packages\\ScopeFoundry\\measurement.py", line 273, in _on_display_update_timer\n    self.update_display()\n', '  File "C:\\Users\\Andrea Bassi\\OneDrive - Politecnico di Milano\\Documenti\\PythonProjects\\BassiScopeFoundryMicroscopes\\Microscopes\\CellRecongnitionMicroscope\\FakeCameraMeasurement.py", line 80, in update_display\n    self.imv.setImage((self.displayed_image), autoLevels=True, autoRange=self.settings.autoRange.val)\n', '  File "C:\\Users\\Andrea Bassi\\anaconda3\\envs\\scopefoundry\\lib\\site-packages\\pyqtgraph\\imageview\\ImageView.py", line 301, in setImage\n    self.updateImage(autoHistogramRange=autoHistogramRange)\n', '  File "C:\\Users\\Andrea Bassi\\anaconda3\\envs\\scopefoundry\\lib\\site-packages\\pyqtgraph\\imageview\\ImageView.py", line 676, in updateImage\n    self.imageItem.updateImage(image)\n', '  File "C:\\Users\\Andrea Bassi\\anaconda3\\envs\\scopefoundry\\lib\\site-packages\\pyqtgraph\\graphicsItems\\ImageItem.py", line 342, in updateImage\n    return self.setImage(*args, **defaults)\n', '  File "C:\\Users\\Andrea Bassi\\anaconda3\\envs\\scopefoundry\\lib\\site-packages\\pyqtgraph\\graphicsItems\\ImageItem.py", line 283, in setImage\n    self.sigImageChanged.emit()\n', 'SystemError: <built-in method emit of PyQt5.QtCore.pyqtBoundSignal object at 0x000001A1AC4FC468> returned a result with an error set\n']
2020-07-26T10:56:38|ERROR|FakeCameraMeasurement|fake_camera_image Failed to update figure1: <built-in method emit of PyQt5.QtCore.pyqtBoundSignal object at 0x000001A1AC4FC468> returned a result with an error set. ['Traceback (most recent call last):\n', '  File "C:\\Users\\Andrea Bassi\\anaconda3\\envs\\scopefoundry\\lib\\site-packages\\pyqtgraph\\graphicsItems\\HistogramLUTItem.py", line 195, in imageChanged\n    h = self.imageItem().getHistogram()\n', '  File "C:\\Users\\Andrea Bassi\\anaconda3\\envs\\scopefoundry\\lib\\site-packages\\pyqtgraph\\graphicsItems\\ImageItem.py", line 464, in getHistogram\n    bins = np.arange(mn, mx+1.01*step, step, dtype=np.int)\n', 'ValueError: arange: cannot compute length\n', '\nThe above exception was the direct cause of the following exception:\n\n', 'Traceback (most recent call last):\n', '  File "C:\\Users\\Andrea Bassi\\anaconda3\\envs\\scopefoundry\\lib\\site-packages\\ScopeFoundry\\measurement.py", line 273, in _on_display_update_timer\n    self.update_display()\n', '  File "C:\\Users\\Andrea Bassi\\OneDrive - Politecnico di Milano\\Documenti\\PythonProjects\\BassiScopeFoundryMicroscopes\\Microscopes\\CellRecongnitionMicroscope\\FakeCameraMeasurement.py", line 80, in update_display\n    self.imv.setImage((self.displayed_image), autoLevels=True, autoRange=self.settings.autoRange.val)\n', '  File "C:\\Users\\Andrea Bassi\\anaconda3\\envs\\scopefoundry\\lib\\site-packages\\pyqtgraph\\imageview\\ImageView.py", line 301, in setImage\n    self.updateImage(autoHistogramRange=autoHistogramRange)\n', '  File "C:\\Users\\Andrea Bassi\\anaconda3\\envs\\scopefoundry\\lib\\site-packages\\pyqtgraph\\imageview\\ImageView.py", line 676, in updateImage\n    self.imageItem.updateImage(image)\n', '  File "C:\\Users\\Andrea Bassi\\anaconda3\\envs\\scopefoundry\\lib\\site-packages\\pyqtgraph\\graphicsItems\\ImageItem.py", line 342, in updateImage\n    return self.setImage(*args, **defaults)\n', '  File "C:\\Users\\Andrea Bassi\\anaconda3\\envs\\scopefoundry\\lib\\site-packages\\pyqtgraph\\graphicsItems\\ImageItem.py", line 283, in setImage\n    self.sigImageChanged.emit()\n', 'SystemError: <built-in method emit of PyQt5.QtCore.pyqtBoundSignal object at 0x000001A1AC4FC468> returned a result with an error set\n']
2020-07-26T10:56:38|ERROR|FakeCameraMeasurement|fake_camera_image Failed to update figure1: <built-in method emit of PyQt5.QtCore.pyqtBoundSignal object at 0x000001A1AC4FC468> returned a result with an error set. ['Traceback (most recent call last):\n', '  File "C:\\Users\\Andrea Bassi\\anaconda3\\envs\\scopefoundry\\lib\\site-packages\\pyqtgraph\\graphicsItems\\HistogramLUTItem.py", line 195, in imageChanged\n    h = self.imageItem().getHistogram()\n', '  File "C:\\Users\\Andrea Bassi\\anaconda3\\envs\\scopefoundry\\lib\\site-packages\\pyqtgraph\\graphicsItems\\ImageItem.py", line 464, in getHistogram\n    bins = np.arange(mn, mx+1.01*step, step, dtype=np.int)\n', 'ValueError: arange: cannot compute length\n', '\nThe above exception was the direct cause of the following exception:\n\n', 'Traceback (most recent call last):\n', '  File "C:\\Users\\Andrea Bassi\\anaconda3\\envs\\scopefoundry\\lib\\site-packages\\ScopeFoundry\\measurement.py", line 273, in _on_display_update_timer\n    self.update_display()\n', '  File "C:\\Users\\Andrea Bassi\\OneDrive - Politecnico di Milano\\Documenti\\PythonProjects\\BassiScopeFoundryMicroscopes\\Microscopes\\CellRecongnitionMicroscope\\FakeCameraMeasurement.py", line 80, in update_display\n    self.imv.setImage((self.displayed_image), autoLevels=True, autoRange=self.settings.autoRange.val)\n', '  File "C:\\Users\\Andrea Bassi\\anaconda3\\envs\\scopefoundry\\lib\\site-packages\\pyqtgraph\\imageview\\ImageView.py", line 301, in setImage\n    self.updateImage(autoHistogramRange=autoHistogramRange)\n', '  File "C:\\Users\\Andrea Bassi\\anaconda3\\envs\\scopefoundry\\lib\\site-packages\\pyqtgraph\\imageview\\ImageView.py", line 676, in updateImage\n    self.imageItem.updateImage(image)\n', '  File "C:\\Users\\Andrea Bassi\\anaconda3\\envs\\scopefoundry\\lib\\site-packages\\pyqtgraph\\graphicsItems\\ImageItem.py", line 342, in updateImage\n    return self.setImage(*args, **defaults)\n', '  File "C:\\Users\\Andrea Bassi\\anaconda3\\envs\\scopefoundry\\lib\\site-packages\\pyqtgraph\\graphicsItems\\ImageItem.py", line 283, in setImage\n    self.sigImageChanged.emit()\n', 'SystemError: <built-in method emit of PyQt5.QtCore.pyqtBoundSignal object at 0x000001A1AC4FC468> returned a result with an error set\n']
2020-07-26T10:56:38|CRITICAL|root|Unhandled exception:Traceback (most recent call last):
  File "C:\Users\Andrea Bassi\anaconda3\envs\scopefoundry\lib\site-packages\ScopeFoundry\measurement.py", line 25, in run
    self.measurement._thread_run()
  File "C:\Users\Andrea Bassi\anaconda3\envs\scopefoundry\lib\site-packages\ScopeFoundry\measurement.py", line 179, in _thread_run
    self.run()
  File "C:\Users\Andrea Bassi\OneDrive - Politecnico di Milano\Documenti\PythonProjects\BassiScopeFoundryMicroscopes\Microscopes\CellRecongnitionMicroscope\FakeCameraMeasurement.py", line 100, in run
    self.image = self.camera.fakecamera.get_image()
AttributeError: 'FakeCameraHardware' object has no attribute 'fakecamera'

2020-07-26T10:56:39|CRITICAL|root|Unhandled exception:Traceback (most recent call last):
  File "C:\Users\Andrea Bassi\anaconda3\envs\scopefoundry\lib\site-packages\pyqtgraph\graphicsItems\HistogramLUTItem.py", line 195, in imageChanged
    h = self.imageItem().getHistogram()
  File "C:\Users\Andrea Bassi\anaconda3\envs\scopefoundry\lib\site-packages\pyqtgraph\graphicsItems\ImageItem.py", line 464, in getHistogram
    bins = np.arange(mn, mx+1.01*step, step, dtype=np.int)
ValueError: arange: cannot compute length

2020-07-26T10:57:17|CRITICAL|root|Unhandled exception:Traceback (most recent call last):
  File "C:\Users\Andrea Bassi\anaconda3\envs\scopefoundry\lib\site-packages\pyqtgraph\graphicsItems\HistogramLUTItem.py", line 195, in imageChanged
    h = self.imageItem().getHistogram()
  File "C:\Users\Andrea Bassi\anaconda3\envs\scopefoundry\lib\site-packages\pyqtgraph\graphicsItems\ImageItem.py", line 464, in getHistogram
    bins = np.arange(mn, mx+1.01*step, step, dtype=np.int)
ValueError: arange: cannot compute length

2020-07-26T11:33:27|ERROR|FakeCameraMeasurement|fake_camera_image Failed to update figure1: 'ImageView' object has no attribute 'tVals'. ['Traceback (most recent call last):\n', '  File "C:\\Users\\Andrea Bassi\\anaconda3\\envs\\scopefoundry\\lib\\site-packages\\ScopeFoundry\\measurement.py", line 273, in _on_display_update_timer\n    self.update_display()\n', '  File "C:\\Users\\Andrea Bassi\\OneDrive - Politecnico di Milano\\Documenti\\PythonProjects\\BassiScopeFoundryMicroscopes\\Microscopes\\CellRecongnitionMicroscope\\FakeCameraMeasurement.py", line 82, in update_display\n    self.imv.setImage((self.displayed_image), autoLevels=False, autoRange=self.settings.autoRange.val, levels=(self.settings.level_min.val, self.settings.level_max.val))\n', '  File "C:\\Users\\Andrea Bassi\\anaconda3\\envs\\scopefoundry\\lib\\site-packages\\pyqtgraph\\imageview\\ImageView.py", line 308, in setImage\n    self.roiChanged()\n', '  File "C:\\Users\\Andrea Bassi\\anaconda3\\envs\\scopefoundry\\lib\\site-packages\\pyqtgraph\\imageview\\ImageView.py", line 572, in roiChanged\n    self.roiCurve.setData(y=data, x=self.tVals)\n', "AttributeError: 'ImageView' object has no attribute 'tVals'\n"]
2020-07-26T11:33:27|ERROR|FakeCameraMeasurement|fake_camera_image Failed to update figure1: 'ImageView' object has no attribute 'tVals'. ['Traceback (most recent call last):\n', '  File "C:\\Users\\Andrea Bassi\\anaconda3\\envs\\scopefoundry\\lib\\site-packages\\ScopeFoundry\\measurement.py", line 273, in _on_display_update_timer\n    self.update_display()\n', '  File "C:\\Users\\Andrea Bassi\\OneDrive - Politecnico di Milano\\Documenti\\PythonProjects\\BassiScopeFoundryMicroscopes\\Microscopes\\CellRecongnitionMicroscope\\FakeCameraMeasurement.py", line 82, in update_display\n    self.imv.setImage((self.displayed_image), autoLevels=False, autoRange=self.settings.autoRange.val, levels=(self.settings.level_min.val, self.settings.level_max.val))\n', '  File "C:\\Users\\Andrea Bassi\\anaconda3\\envs\\scopefoundry\\lib\\site-packages\\pyqtgraph\\imageview\\ImageView.py", line 308, in setImage\n    self.roiChanged()\n', '  File "C:\\Users\\Andrea Bassi\\anaconda3\\envs\\scopefoundry\\lib\\site-packages\\pyqtgraph\\imageview\\ImageView.py", line 572, in roiChanged\n    self.roiCurve.setData(y=data, x=self.tVals)\n', "AttributeError: 'ImageView' object has no attribute 'tVals'\n"]
2020-07-26T11:33:27|ERROR|FakeCameraMeasurement|fake_camera_image Failed to update figure1: 'ImageView' object has no attribute 'tVals'. ['Traceback (most recent call last):\n', '  File "C:\\Users\\Andrea Bassi\\anaconda3\\envs\\scopefoundry\\lib\\site-packages\\ScopeFoundry\\measurement.py", line 273, in _on_display_update_timer\n    self.update_display()\n', '  File "C:\\Users\\Andrea Bassi\\OneDrive - Politecnico di Milano\\Documenti\\PythonProjects\\BassiScopeFoundryMicroscopes\\Microscopes\\CellRecongnitionMicroscope\\FakeCameraMeasurement.py", line 82, in update_display\n    self.imv.setImage((self.displayed_image), autoLevels=False, autoRange=self.settings.autoRange.val, levels=(self.settings.level_min.val, self.settings.level_max.val))\n', '  File "C:\\Users\\Andrea Bassi\\anaconda3\\envs\\scopefoundry\\lib\\site-packages\\pyqtgraph\\imageview\\ImageView.py", line 308, in setImage\n    self.roiChanged()\n', '  File "C:\\Users\\Andrea Bassi\\anaconda3\\envs\\scopefoundry\\lib\\site-packages\\pyqtgraph\\imageview\\ImageView.py", line 572, in roiChanged\n    self.roiCurve.setData(y=data, x=self.tVals)\n', "AttributeError: 'ImageView' object has no attribute 'tVals'\n"]
2020-07-26T11:33:27|ERROR|FakeCameraMeasurement|fake_camera_image Failed to update figure1: 'ImageView' object has no attribute 'tVals'. ['Traceback (most recent call last):\n', '  File "C:\\Users\\Andrea Bassi\\anaconda3\\envs\\scopefoundry\\lib\\site-packages\\ScopeFoundry\\measurement.py", line 273, in _on_display_update_timer\n    self.update_display()\n', '  File "C:\\Users\\Andrea Bassi\\OneDrive - Politecnico di Milano\\Documenti\\PythonProjects\\BassiScopeFoundryMicroscopes\\Microscopes\\CellRecongnitionMicroscope\\FakeCameraMeasurement.py", line 82, in update_display\n    self.imv.setImage((self.displayed_image), autoLevels=False, autoRange=self.settings.autoRange.val, levels=(self.settings.level_min.val, self.settings.level_max.val))\n', '  File "C:\\Users\\Andrea Bassi\\anaconda3\\envs\\scopefoundry\\lib\\site-packages\\pyqtgraph\\imageview\\ImageView.py", line 308, in setImage\n    self.roiChanged()\n', '  File "C:\\Users\\Andrea Bassi\\anaconda3\\envs\\scopefoundry\\lib\\site-packages\\pyqtgraph\\imageview\\ImageView.py", line 572, in roiChanged\n    self.roiCurve.setData(y=data, x=self.tVals)\n', "AttributeError: 'ImageView' object has no attribute 'tVals'\n"]
2020-07-26T11:33:27|ERROR|FakeCameraMeasurement|fake_camera_image Failed to update figure1: 'ImageView' object has no attribute 'tVals'. ['Traceback (most recent call last):\n', '  File "C:\\Users\\Andrea Bassi\\anaconda3\\envs\\scopefoundry\\lib\\site-packages\\ScopeFoundry\\measurement.py", line 273, in _on_display_update_timer\n    self.update_display()\n', '  File "C:\\Users\\Andrea Bassi\\OneDrive - Politecnico di Milano\\Documenti\\PythonProjects\\BassiScopeFoundryMicroscopes\\Microscopes\\CellRecongnitionMicroscope\\FakeCameraMeasurement.py", line 82, in update_display\n    self.imv.setImage((self.displayed_image), autoLevels=False, autoRange=self.settings.autoRange.val, levels=(self.settings.level_min.val, self.settings.level_max.val))\n', '  File "C:\\Users\\Andrea Bassi\\anaconda3\\envs\\scopefoundry\\lib\\site-packages\\pyqtgraph\\imageview\\ImageView.py", line 308, in setImage\n    self.roiChanged()\n', '  File "C:\\Users\\Andrea Bassi\\anaconda3\\envs\\scopefoundry\\lib\\site-packages\\pyqtgraph\\imageview\\ImageView.py", line 572, in roiChanged\n    self.roiCurve.setData(y=data, x=self.tVals)\n', "AttributeError: 'ImageView' object has no attribute 'tVals'\n"]
2020-07-26T11:33:27|ERROR|FakeCameraMeasurement|fake_camera_image Failed to update figure1: 'ImageView' object has no attribute 'tVals'. ['Traceback (most recent call last):\n', '  File "C:\\Users\\Andrea Bassi\\anaconda3\\envs\\scopefoundry\\lib\\site-packages\\ScopeFoundry\\measurement.py", line 273, in _on_display_update_timer\n    self.update_display()\n', '  File "C:\\Users\\Andrea Bassi\\OneDrive - Politecnico di Milano\\Documenti\\PythonProjects\\BassiScopeFoundryMicroscopes\\Microscopes\\CellRecongnitionMicroscope\\FakeCameraMeasurement.py", line 82, in update_display\n    self.imv.setImage((self.displayed_image), autoLevels=False, autoRange=self.settings.autoRange.val, levels=(self.settings.level_min.val, self.settings.level_max.val))\n', '  File "C:\\Users\\Andrea Bassi\\anaconda3\\envs\\scopefoundry\\lib\\site-packages\\pyqtgraph\\imageview\\ImageView.py", line 308, in setImage\n    self.roiChanged()\n', '  File "C:\\Users\\Andrea Bassi\\anaconda3\\envs\\scopefoundry\\lib\\site-packages\\pyqtgraph\\imageview\\ImageView.py", line 572, in roiChanged\n    self.roiCurve.setData(y=data, x=self.tVals)\n', "AttributeError: 'ImageView' object has no attribute 'tVals'\n"]
2020-07-26T11:33:27|ERROR|FakeCameraMeasurement|fake_camera_image Failed to update figure1: 'ImageView' object has no attribute 'tVals'. ['Traceback (most recent call last):\n', '  File "C:\\Users\\Andrea Bassi\\anaconda3\\envs\\scopefoundry\\lib\\site-packages\\ScopeFoundry\\measurement.py", line 273, in _on_display_update_timer\n    self.update_display()\n', '  File "C:\\Users\\Andrea Bassi\\OneDrive - Politecnico di Milano\\Documenti\\PythonProjects\\BassiScopeFoundryMicroscopes\\Microscopes\\CellRecongnitionMicroscope\\FakeCameraMeasurement.py", line 82, in update_display\n    self.imv.setImage((self.displayed_image), autoLevels=False, autoRange=self.settings.autoRange.val, levels=(self.settings.level_min.val, self.settings.level_max.val))\n', '  File "C:\\Users\\Andrea Bassi\\anaconda3\\envs\\scopefoundry\\lib\\site-packages\\pyqtgraph\\imageview\\ImageView.py", line 308, in setImage\n    self.roiChanged()\n', '  File "C:\\Users\\Andrea Bassi\\anaconda3\\envs\\scopefoundry\\lib\\site-packages\\pyqtgraph\\imageview\\ImageView.py", line 572, in roiChanged\n    self.roiCurve.setData(y=data, x=self.tVals)\n', "AttributeError: 'ImageView' object has no attribute 'tVals'\n"]
2020-07-26T11:33:27|ERROR|FakeCameraMeasurement|fake_camera_image Failed to update figure1: 'ImageView' object has no attribute 'tVals'. ['Traceback (most recent call last):\n', '  File "C:\\Users\\Andrea Bassi\\anaconda3\\envs\\scopefoundry\\lib\\site-packages\\ScopeFoundry\\measurement.py", line 273, in _on_display_update_timer\n    self.update_display()\n', '  File "C:\\Users\\Andrea Bassi\\OneDrive - Politecnico di Milano\\Documenti\\PythonProjects\\BassiScopeFoundryMicroscopes\\Microscopes\\CellRecongnitionMicroscope\\FakeCameraMeasurement.py", line 82, in update_display\n    self.imv.setImage((self.displayed_image), autoLevels=False, autoRange=self.settings.autoRange.val, levels=(self.settings.level_min.val, self.settings.level_max.val))\n', '  File "C:\\Users\\Andrea Bassi\\anaconda3\\envs\\scopefoundry\\lib\\site-packages\\pyqtgraph\\imageview\\ImageView.py", line 308, in setImage\n    self.roiChanged()\n', '  File "C:\\Users\\Andrea Bassi\\anaconda3\\envs\\scopefoundry\\lib\\site-packages\\pyqtgraph\\imageview\\ImageView.py", line 572, in roiChanged\n    self.roiCurve.setData(y=data, x=self.tVals)\n', "AttributeError: 'ImageView' object has no attribute 'tVals'\n"]
2020-07-26T11:33:27|ERROR|FakeCameraMeasurement|fake_camera_image Failed to update figure1: 'ImageView' object has no attribute 'tVals'. ['Traceback (most recent call last):\n', '  File "C:\\Users\\Andrea Bassi\\anaconda3\\envs\\scopefoundry\\lib\\site-packages\\ScopeFoundry\\measurement.py", line 273, in _on_display_update_timer\n    self.update_display()\n', '  File "C:\\Users\\Andrea Bassi\\OneDrive - Politecnico di Milano\\Documenti\\PythonProjects\\BassiScopeFoundryMicroscopes\\Microscopes\\CellRecongnitionMicroscope\\FakeCameraMeasurement.py", line 82, in update_display\n    self.imv.setImage((self.displayed_image), autoLevels=False, autoRange=self.settings.autoRange.val, levels=(self.settings.level_min.val, self.settings.level_max.val))\n', '  File "C:\\Users\\Andrea Bassi\\anaconda3\\envs\\scopefoundry\\lib\\site-packages\\pyqtgraph\\imageview\\ImageView.py", line 308, in setImage\n    self.roiChanged()\n', '  File "C:\\Users\\Andrea Bassi\\anaconda3\\envs\\scopefoundry\\lib\\site-packages\\pyqtgraph\\imageview\\ImageView.py", line 572, in roiChanged\n    self.roiCurve.setData(y=data, x=self.tVals)\n', "AttributeError: 'ImageView' object has no attribute 'tVals'\n"]
2020-07-26T11:33:27|ERROR|FakeCameraMeasurement|fake_camera_image Failed to update figure1: 'ImageView' object has no attribute 'tVals'. ['Traceback (most recent call last):\n', '  File "C:\\Users\\Andrea Bassi\\anaconda3\\envs\\scopefoundry\\lib\\site-packages\\ScopeFoundry\\measurement.py", line 273, in _on_display_update_timer\n    self.update_display()\n', '  File "C:\\Users\\Andrea Bassi\\OneDrive - Politecnico di Milano\\Documenti\\PythonProjects\\BassiScopeFoundryMicroscopes\\Microscopes\\CellRecongnitionMicroscope\\FakeCameraMeasurement.py", line 82, in update_display\n    self.imv.setImage((self.displayed_image), autoLevels=False, autoRange=self.settings.autoRange.val, levels=(self.settings.level_min.val, self.settings.level_max.val))\n', '  File "C:\\Users\\Andrea Bassi\\anaconda3\\envs\\scopefoundry\\lib\\site-packages\\pyqtgraph\\imageview\\ImageView.py", line 308, in setImage\n    self.roiChanged()\n', '  File "C:\\Users\\Andrea Bassi\\anaconda3\\envs\\scopefoundry\\lib\\site-packages\\pyqtgraph\\imageview\\ImageView.py", line 572, in roiChanged\n    self.roiCurve.setData(y=data, x=self.tVals)\n', "AttributeError: 'ImageView' object has no attribute 'tVals'\n"]
2020-07-26T11:33:27|ERROR|FakeCameraMeasurement|fake_camera_image Failed to update figure1: 'ImageView' object has no attribute 'tVals'. ['Traceback (most recent call last):\n', '  File "C:\\Users\\Andrea Bassi\\anaconda3\\envs\\scopefoundry\\lib\\site-packages\\ScopeFoundry\\measurement.py", line 273, in _on_display_update_timer\n    self.update_display()\n', '  File "C:\\Users\\Andrea Bassi\\OneDrive - Politecnico di Milano\\Documenti\\PythonProjects\\BassiScopeFoundryMicroscopes\\Microscopes\\CellRecongnitionMicroscope\\FakeCameraMeasurement.py", line 82, in update_display\n    self.imv.setImage((self.displayed_image), autoLevels=False, autoRange=self.settings.autoRange.val, levels=(self.settings.level_min.val, self.settings.level_max.val))\n', '  File "C:\\Users\\Andrea Bassi\\anaconda3\\envs\\scopefoundry\\lib\\site-packages\\pyqtgraph\\imageview\\ImageView.py", line 308, in setImage\n    self.roiChanged()\n', '  File "C:\\Users\\Andrea Bassi\\anaconda3\\envs\\scopefoundry\\lib\\site-packages\\pyqtgraph\\imageview\\ImageView.py", line 572, in roiChanged\n    self.roiCurve.setData(y=data, x=self.tVals)\n', "AttributeError: 'ImageView' object has no attribute 'tVals'\n"]
2020-07-26T11:33:27|ERROR|FakeCameraMeasurement|fake_camera_image Failed to update figure1: 'ImageView' object has no attribute 'tVals'. ['Traceback (most recent call last):\n', '  File "C:\\Users\\Andrea Bassi\\anaconda3\\envs\\scopefoundry\\lib\\site-packages\\ScopeFoundry\\measurement.py", line 273, in _on_display_update_timer\n    self.update_display()\n', '  File "C:\\Users\\Andrea Bassi\\OneDrive - Politecnico di Milano\\Documenti\\PythonProjects\\BassiScopeFoundryMicroscopes\\Microscopes\\CellRecongnitionMicroscope\\FakeCameraMeasurement.py", line 82, in update_display\n    self.imv.setImage((self.displayed_image), autoLevels=False, autoRange=self.settings.autoRange.val, levels=(self.settings.level_min.val, self.settings.level_max.val))\n', '  File "C:\\Users\\Andrea Bassi\\anaconda3\\envs\\scopefoundry\\lib\\site-packages\\pyqtgraph\\imageview\\ImageView.py", line 308, in setImage\n    self.roiChanged()\n', '  File "C:\\Users\\Andrea Bassi\\anaconda3\\envs\\scopefoundry\\lib\\site-packages\\pyqtgraph\\imageview\\ImageView.py", line 572, in roiChanged\n    self.roiCurve.setData(y=data, x=self.tVals)\n', "AttributeError: 'ImageView' object has no attribute 'tVals'\n"]
2020-07-26T11:33:28|ERROR|FakeCameraMeasurement|fake_camera_image Failed to update figure1: 'ImageView' object has no attribute 'tVals'. ['Traceback (most recent call last):\n', '  File "C:\\Users\\Andrea Bassi\\anaconda3\\envs\\scopefoundry\\lib\\site-packages\\ScopeFoundry\\measurement.py", line 273, in _on_display_update_timer\n    self.update_display()\n', '  File "C:\\Users\\Andrea Bassi\\OneDrive - Politecnico di Milano\\Documenti\\PythonProjects\\BassiScopeFoundryMicroscopes\\Microscopes\\CellRecongnitionMicroscope\\FakeCameraMeasurement.py", line 82, in update_display\n    self.imv.setImage((self.displayed_image), autoLevels=False, autoRange=self.settings.autoRange.val, levels=(self.settings.level_min.val, self.settings.level_max.val))\n', '  File "C:\\Users\\Andrea Bassi\\anaconda3\\envs\\scopefoundry\\lib\\site-packages\\pyqtgraph\\imageview\\ImageView.py", line 308, in setImage\n    self.roiChanged()\n', '  File "C:\\Users\\Andrea Bassi\\anaconda3\\envs\\scopefoundry\\lib\\site-packages\\pyqtgraph\\imageview\\ImageView.py", line 572, in roiChanged\n    self.roiCurve.setData(y=data, x=self.tVals)\n', "AttributeError: 'ImageView' object has no attribute 'tVals'\n"]
2020-07-26T11:33:28|ERROR|FakeCameraMeasurement|fake_camera_image Failed to update figure1: 'ImageView' object has no attribute 'tVals'. ['Traceback (most recent call last):\n', '  File "C:\\Users\\Andrea Bassi\\anaconda3\\envs\\scopefoundry\\lib\\site-packages\\ScopeFoundry\\measurement.py", line 273, in _on_display_update_timer\n    self.update_display()\n', '  File "C:\\Users\\Andrea Bassi\\OneDrive - Politecnico di Milano\\Documenti\\PythonProjects\\BassiScopeFoundryMicroscopes\\Microscopes\\CellRecongnitionMicroscope\\FakeCameraMeasurement.py", line 82, in update_display\n    self.imv.setImage((self.displayed_image), autoLevels=False, autoRange=self.settings.autoRange.val, levels=(self.settings.level_min.val, self.settings.level_max.val))\n', '  File "C:\\Users\\Andrea Bassi\\anaconda3\\envs\\scopefoundry\\lib\\site-packages\\pyqtgraph\\imageview\\ImageView.py", line 308, in setImage\n    self.roiChanged()\n', '  File "C:\\Users\\Andrea Bassi\\anaconda3\\envs\\scopefoundry\\lib\\site-packages\\pyqtgraph\\imageview\\ImageView.py", line 572, in roiChanged\n    self.roiCurve.setData(y=data, x=self.tVals)\n', "AttributeError: 'ImageView' object has no attribute 'tVals'\n"]
2020-07-26T11:33:28|ERROR|FakeCameraMeasurement|fake_camera_image Failed to update figure1: 'ImageView' object has no attribute 'tVals'. ['Traceback (most recent call last):\n', '  File "C:\\Users\\Andrea Bassi\\anaconda3\\envs\\scopefoundry\\lib\\site-packages\\ScopeFoundry\\measurement.py", line 273, in _on_display_update_timer\n    self.update_display()\n', '  File "C:\\Users\\Andrea Bassi\\OneDrive - Politecnico di Milano\\Documenti\\PythonProjects\\BassiScopeFoundryMicroscopes\\Microscopes\\CellRecongnitionMicroscope\\FakeCameraMeasurement.py", line 82, in update_display\n    self.imv.setImage((self.displayed_image), autoLevels=False, autoRange=self.settings.autoRange.val, levels=(self.settings.level_min.val, self.settings.level_max.val))\n', '  File "C:\\Users\\Andrea Bassi\\anaconda3\\envs\\scopefoundry\\lib\\site-packages\\pyqtgraph\\imageview\\ImageView.py", line 308, in setImage\n    self.roiChanged()\n', '  File "C:\\Users\\Andrea Bassi\\anaconda3\\envs\\scopefoundry\\lib\\site-packages\\pyqtgraph\\imageview\\ImageView.py", line 572, in roiChanged\n    self.roiCurve.setData(y=data, x=self.tVals)\n', "AttributeError: 'ImageView' object has no attribute 'tVals'\n"]
2020-07-26T11:33:28|ERROR|FakeCameraMeasurement|fake_camera_image Failed to update figure1: 'ImageView' object has no attribute 'tVals'. ['Traceback (most recent call last):\n', '  File "C:\\Users\\Andrea Bassi\\anaconda3\\envs\\scopefoundry\\lib\\site-packages\\ScopeFoundry\\measurement.py", line 273, in _on_display_update_timer\n    self.update_display()\n', '  File "C:\\Users\\Andrea Bassi\\OneDrive - Politecnico di Milano\\Documenti\\PythonProjects\\BassiScopeFoundryMicroscopes\\Microscopes\\CellRecongnitionMicroscope\\FakeCameraMeasurement.py", line 82, in update_display\n    self.imv.setImage((self.displayed_image), autoLevels=False, autoRange=self.settings.autoRange.val, levels=(self.settings.level_min.val, self.settings.level_max.val))\n', '  File "C:\\Users\\Andrea Bassi\\anaconda3\\envs\\scopefoundry\\lib\\site-packages\\pyqtgraph\\imageview\\ImageView.py", line 308, in setImage\n    self.roiChanged()\n', '  File "C:\\Users\\Andrea Bassi\\anaconda3\\envs\\scopefoundry\\lib\\site-packages\\pyqtgraph\\imageview\\ImageView.py", line 572, in roiChanged\n    self.roiCurve.setData(y=data, x=self.tVals)\n', "AttributeError: 'ImageView' object has no attribute 'tVals'\n"]
2020-07-26T11:33:28|ERROR|FakeCameraMeasurement|fake_camera_image Failed to update figure1: 'ImageView' object has no attribute 'tVals'. ['Traceback (most recent call last):\n', '  File "C:\\Users\\Andrea Bassi\\anaconda3\\envs\\scopefoundry\\lib\\site-packages\\ScopeFoundry\\measurement.py", line 273, in _on_display_update_timer\n    self.update_display()\n', '  File "C:\\Users\\Andrea Bassi\\OneDrive - Politecnico di Milano\\Documenti\\PythonProjects\\BassiScopeFoundryMicroscopes\\Microscopes\\CellRecongnitionMicroscope\\FakeCameraMeasurement.py", line 82, in update_display\n    self.imv.setImage((self.displayed_image), autoLevels=False, autoRange=self.settings.autoRange.val, levels=(self.settings.level_min.val, self.settings.level_max.val))\n', '  File "C:\\Users\\Andrea Bassi\\anaconda3\\envs\\scopefoundry\\lib\\site-packages\\pyqtgraph\\imageview\\ImageView.py", line 308, in setImage\n    self.roiChanged()\n', '  File "C:\\Users\\Andrea Bassi\\anaconda3\\envs\\scopefoundry\\lib\\site-packages\\pyqtgraph\\imageview\\ImageView.py", line 572, in roiChanged\n    self.roiCurve.setData(y=data, x=self.tVals)\n', "AttributeError: 'ImageView' object has no attribute 'tVals'\n"]
2020-07-26T11:33:28|ERROR|FakeCameraMeasurement|fake_camera_image Failed to update figure1: 'ImageView' object has no attribute 'tVals'. ['Traceback (most recent call last):\n', '  File "C:\\Users\\Andrea Bassi\\anaconda3\\envs\\scopefoundry\\lib\\site-packages\\ScopeFoundry\\measurement.py", line 273, in _on_display_update_timer\n    self.update_display()\n', '  File "C:\\Users\\Andrea Bassi\\OneDrive - Politecnico di Milano\\Documenti\\PythonProjects\\BassiScopeFoundryMicroscopes\\Microscopes\\CellRecongnitionMicroscope\\FakeCameraMeasurement.py", line 82, in update_display\n    self.imv.setImage((self.displayed_image), autoLevels=False, autoRange=self.settings.autoRange.val, levels=(self.settings.level_min.val, self.settings.level_max.val))\n', '  File "C:\\Users\\Andrea Bassi\\anaconda3\\envs\\scopefoundry\\lib\\site-packages\\pyqtgraph\\imageview\\ImageView.py", line 308, in setImage\n    self.roiChanged()\n', '  File "C:\\Users\\Andrea Bassi\\anaconda3\\envs\\scopefoundry\\lib\\site-packages\\pyqtgraph\\imageview\\ImageView.py", line 572, in roiChanged\n    self.roiCurve.setData(y=data, x=self.tVals)\n', "AttributeError: 'ImageView' object has no attribute 'tVals'\n"]
2020-07-26T11:33:28|ERROR|FakeCameraMeasurement|fake_camera_image Failed to update figure1: 'ImageView' object has no attribute 'tVals'. ['Traceback (most recent call last):\n', '  File "C:\\Users\\Andrea Bassi\\anaconda3\\envs\\scopefoundry\\lib\\site-packages\\ScopeFoundry\\measurement.py", line 273, in _on_display_update_timer\n    self.update_display()\n', '  File "C:\\Users\\Andrea Bassi\\OneDrive - Politecnico di Milano\\Documenti\\PythonProjects\\BassiScopeFoundryMicroscopes\\Microscopes\\CellRecongnitionMicroscope\\FakeCameraMeasurement.py", line 82, in update_display\n    self.imv.setImage((self.displayed_image), autoLevels=False, autoRange=self.settings.autoRange.val, levels=(self.settings.level_min.val, self.settings.level_max.val))\n', '  File "C:\\Users\\Andrea Bassi\\anaconda3\\envs\\scopefoundry\\lib\\site-packages\\pyqtgraph\\imageview\\ImageView.py", line 308, in setImage\n    self.roiChanged()\n', '  File "C:\\Users\\Andrea Bassi\\anaconda3\\envs\\scopefoundry\\lib\\site-packages\\pyqtgraph\\imageview\\ImageView.py", line 572, in roiChanged\n    self.roiCurve.setData(y=data, x=self.tVals)\n', "AttributeError: 'ImageView' object has no attribute 'tVals'\n"]
2020-07-26T11:33:28|ERROR|FakeCameraMeasurement|fake_camera_image Failed to update figure1: 'ImageView' object has no attribute 'tVals'. ['Traceback (most recent call last):\n', '  File "C:\\Users\\Andrea Bassi\\anaconda3\\envs\\scopefoundry\\lib\\site-packages\\ScopeFoundry\\measurement.py", line 273, in _on_display_update_timer\n    self.update_display()\n', '  File "C:\\Users\\Andrea Bassi\\OneDrive - Politecnico di Milano\\Documenti\\PythonProjects\\BassiScopeFoundryMicroscopes\\Microscopes\\CellRecongnitionMicroscope\\FakeCameraMeasurement.py", line 82, in update_display\n    self.imv.setImage((self.displayed_image), autoLevels=False, autoRange=self.settings.autoRange.val, levels=(self.settings.level_min.val, self.settings.level_max.val))\n', '  File "C:\\Users\\Andrea Bassi\\anaconda3\\envs\\scopefoundry\\lib\\site-packages\\pyqtgraph\\imageview\\ImageView.py", line 308, in setImage\n    self.roiChanged()\n', '  File "C:\\Users\\Andrea Bassi\\anaconda3\\envs\\scopefoundry\\lib\\site-packages\\pyqtgraph\\imageview\\ImageView.py", line 572, in roiChanged\n    self.roiCurve.setData(y=data, x=self.tVals)\n', "AttributeError: 'ImageView' object has no attribute 'tVals'\n"]
2020-07-26T11:33:28|ERROR|FakeCameraMeasurement|fake_camera_image Failed to update figure1: 'ImageView' object has no attribute 'tVals'. ['Traceback (most recent call last):\n', '  File "C:\\Users\\Andrea Bassi\\anaconda3\\envs\\scopefoundry\\lib\\site-packages\\ScopeFoundry\\measurement.py", line 273, in _on_display_update_timer\n    self.update_display()\n', '  File "C:\\Users\\Andrea Bassi\\OneDrive - Politecnico di Milano\\Documenti\\PythonProjects\\BassiScopeFoundryMicroscopes\\Microscopes\\CellRecongnitionMicroscope\\FakeCameraMeasurement.py", line 82, in update_display\n    self.imv.setImage((self.displayed_image), autoLevels=False, autoRange=self.settings.autoRange.val, levels=(self.settings.level_min.val, self.settings.level_max.val))\n', '  File "C:\\Users\\Andrea Bassi\\anaconda3\\envs\\scopefoundry\\lib\\site-packages\\pyqtgraph\\imageview\\ImageView.py", line 308, in setImage\n    self.roiChanged()\n', '  File "C:\\Users\\Andrea Bassi\\anaconda3\\envs\\scopefoundry\\lib\\site-packages\\pyqtgraph\\imageview\\ImageView.py", line 572, in roiChanged\n    self.roiCurve.setData(y=data, x=self.tVals)\n', "AttributeError: 'ImageView' object has no attribute 'tVals'\n"]
2020-07-26T11:33:28|ERROR|FakeCameraMeasurement|fake_camera_image Failed to update figure1: 'ImageView' object has no attribute 'tVals'. ['Traceback (most recent call last):\n', '  File "C:\\Users\\Andrea Bassi\\anaconda3\\envs\\scopefoundry\\lib\\site-packages\\ScopeFoundry\\measurement.py", line 273, in _on_display_update_timer\n    self.update_display()\n', '  File "C:\\Users\\Andrea Bassi\\OneDrive - Politecnico di Milano\\Documenti\\PythonProjects\\BassiScopeFoundryMicroscopes\\Microscopes\\CellRecongnitionMicroscope\\FakeCameraMeasurement.py", line 82, in update_display\n    self.imv.setImage((self.displayed_image), autoLevels=False, autoRange=self.settings.autoRange.val, levels=(self.settings.level_min.val, self.settings.level_max.val))\n', '  File "C:\\Users\\Andrea Bassi\\anaconda3\\envs\\scopefoundry\\lib\\site-packages\\pyqtgraph\\imageview\\ImageView.py", line 308, in setImage\n    self.roiChanged()\n', '  File "C:\\Users\\Andrea Bassi\\anaconda3\\envs\\scopefoundry\\lib\\site-packages\\pyqtgraph\\imageview\\ImageView.py", line 572, in roiChanged\n    self.roiCurve.setData(y=data, x=self.tVals)\n', "AttributeError: 'ImageView' object has no attribute 'tVals'\n"]
2020-07-26T11:33:28|ERROR|FakeCameraMeasurement|fake_camera_image Failed to update figure1: 'ImageView' object has no attribute 'tVals'. ['Traceback (most recent call last):\n', '  File "C:\\Users\\Andrea Bassi\\anaconda3\\envs\\scopefoundry\\lib\\site-packages\\ScopeFoundry\\measurement.py", line 273, in _on_display_update_timer\n    self.update_display()\n', '  File "C:\\Users\\Andrea Bassi\\OneDrive - Politecnico di Milano\\Documenti\\PythonProjects\\BassiScopeFoundryMicroscopes\\Microscopes\\CellRecongnitionMicroscope\\FakeCameraMeasurement.py", line 82, in update_display\n    self.imv.setImage((self.displayed_image), autoLevels=False, autoRange=self.settings.autoRange.val, levels=(self.settings.level_min.val, self.settings.level_max.val))\n', '  File "C:\\Users\\Andrea Bassi\\anaconda3\\envs\\scopefoundry\\lib\\site-packages\\pyqtgraph\\imageview\\ImageView.py", line 308, in setImage\n    self.roiChanged()\n', '  File "C:\\Users\\Andrea Bassi\\anaconda3\\envs\\scopefoundry\\lib\\site-packages\\pyqtgraph\\imageview\\ImageView.py", line 572, in roiChanged\n    self.roiCurve.setData(y=data, x=self.tVals)\n', "AttributeError: 'ImageView' object has no attribute 'tVals'\n"]
2020-07-26T11:33:28|ERROR|FakeCameraMeasurement|fake_camera_image Failed to update figure1: 'ImageView' object has no attribute 'tVals'. ['Traceback (most recent call last):\n', '  File "C:\\Users\\Andrea Bassi\\anaconda3\\envs\\scopefoundry\\lib\\site-packages\\ScopeFoundry\\measurement.py", line 273, in _on_display_update_timer\n    self.update_display()\n', '  File "C:\\Users\\Andrea Bassi\\OneDrive - Politecnico di Milano\\Documenti\\PythonProjects\\BassiScopeFoundryMicroscopes\\Microscopes\\CellRecongnitionMicroscope\\FakeCameraMeasurement.py", line 82, in update_display\n    self.imv.setImage((self.displayed_image), autoLevels=False, autoRange=self.settings.autoRange.val, levels=(self.settings.level_min.val, self.settings.level_max.val))\n', '  File "C:\\Users\\Andrea Bassi\\anaconda3\\envs\\scopefoundry\\lib\\site-packages\\pyqtgraph\\imageview\\ImageView.py", line 308, in setImage\n    self.roiChanged()\n', '  File "C:\\Users\\Andrea Bassi\\anaconda3\\envs\\scopefoundry\\lib\\site-packages\\pyqtgraph\\imageview\\ImageView.py", line 572, in roiChanged\n    self.roiCurve.setData(y=data, x=self.tVals)\n', "AttributeError: 'ImageView' object has no attribute 'tVals'\n"]
2020-07-26T11:33:28|ERROR|FakeCameraMeasurement|fake_camera_image Failed to update figure1: 'ImageView' object has no attribute 'tVals'. ['Traceback (most recent call last):\n', '  File "C:\\Users\\Andrea Bassi\\anaconda3\\envs\\scopefoundry\\lib\\site-packages\\ScopeFoundry\\measurement.py", line 273, in _on_display_update_timer\n    self.update_display()\n', '  File "C:\\Users\\Andrea Bassi\\OneDrive - Politecnico di Milano\\Documenti\\PythonProjects\\BassiScopeFoundryMicroscopes\\Microscopes\\CellRecongnitionMicroscope\\FakeCameraMeasurement.py", line 82, in update_display\n    self.imv.setImage((self.displayed_image), autoLevels=False, autoRange=self.settings.autoRange.val, levels=(self.settings.level_min.val, self.settings.level_max.val))\n', '  File "C:\\Users\\Andrea Bassi\\anaconda3\\envs\\scopefoundry\\lib\\site-packages\\pyqtgraph\\imageview\\ImageView.py", line 308, in setImage\n    self.roiChanged()\n', '  File "C:\\Users\\Andrea Bassi\\anaconda3\\envs\\scopefoundry\\lib\\site-packages\\pyqtgraph\\imageview\\ImageView.py", line 572, in roiChanged\n    self.roiCurve.setData(y=data, x=self.tVals)\n', "AttributeError: 'ImageView' object has no attribute 'tVals'\n"]
2020-07-26T11:33:28|ERROR|FakeCameraMeasurement|fake_camera_image Failed to update figure1: 'ImageView' object has no attribute 'tVals'. ['Traceback (most recent call last):\n', '  File "C:\\Users\\Andrea Bassi\\anaconda3\\envs\\scopefoundry\\lib\\site-packages\\ScopeFoundry\\measurement.py", line 273, in _on_display_update_timer\n    self.update_display()\n', '  File "C:\\Users\\Andrea Bassi\\OneDrive - Politecnico di Milano\\Documenti\\PythonProjects\\BassiScopeFoundryMicroscopes\\Microscopes\\CellRecongnitionMicroscope\\FakeCameraMeasurement.py", line 82, in update_display\n    self.imv.setImage((self.displayed_image), autoLevels=False, autoRange=self.settings.autoRange.val, levels=(self.settings.level_min.val, self.settings.level_max.val))\n', '  File "C:\\Users\\Andrea Bassi\\anaconda3\\envs\\scopefoundry\\lib\\site-packages\\pyqtgraph\\imageview\\ImageView.py", line 308, in setImage\n    self.roiChanged()\n', '  File "C:\\Users\\Andrea Bassi\\anaconda3\\envs\\scopefoundry\\lib\\site-packages\\pyqtgraph\\imageview\\ImageView.py", line 572, in roiChanged\n    self.roiCurve.setData(y=data, x=self.tVals)\n', "AttributeError: 'ImageView' object has no attribute 'tVals'\n"]
2020-07-26T11:33:28|ERROR|FakeCameraMeasurement|fake_camera_image Failed to update figure1: 'ImageView' object has no attribute 'tVals'. ['Traceback (most recent call last):\n', '  File "C:\\Users\\Andrea Bassi\\anaconda3\\envs\\scopefoundry\\lib\\site-packages\\ScopeFoundry\\measurement.py", line 273, in _on_display_update_timer\n    self.update_display()\n', '  File "C:\\Users\\Andrea Bassi\\OneDrive - Politecnico di Milano\\Documenti\\PythonProjects\\BassiScopeFoundryMicroscopes\\Microscopes\\CellRecongnitionMicroscope\\FakeCameraMeasurement.py", line 82, in update_display\n    self.imv.setImage((self.displayed_image), autoLevels=False, autoRange=self.settings.autoRange.val, levels=(self.settings.level_min.val, self.settings.level_max.val))\n', '  File "C:\\Users\\Andrea Bassi\\anaconda3\\envs\\scopefoundry\\lib\\site-packages\\pyqtgraph\\imageview\\ImageView.py", line 308, in setImage\n    self.roiChanged()\n', '  File "C:\\Users\\Andrea Bassi\\anaconda3\\envs\\scopefoundry\\lib\\site-packages\\pyqtgraph\\imageview\\ImageView.py", line 572, in roiChanged\n    self.roiCurve.setData(y=data, x=self.tVals)\n', "AttributeError: 'ImageView' object has no attribute 'tVals'\n"]
2020-07-26T11:33:28|ERROR|FakeCameraMeasurement|fake_camera_image Failed to update figure1: 'ImageView' object has no attribute 'tVals'. ['Traceback (most recent call last):\n', '  File "C:\\Users\\Andrea Bassi\\anaconda3\\envs\\scopefoundry\\lib\\site-packages\\ScopeFoundry\\measurement.py", line 273, in _on_display_update_timer\n    self.update_display()\n', '  File "C:\\Users\\Andrea Bassi\\OneDrive - Politecnico di Milano\\Documenti\\PythonProjects\\BassiScopeFoundryMicroscopes\\Microscopes\\CellRecongnitionMicroscope\\FakeCameraMeasurement.py", line 82, in update_display\n    self.imv.setImage((self.displayed_image), autoLevels=False, autoRange=self.settings.autoRange.val, levels=(self.settings.level_min.val, self.settings.level_max.val))\n', '  File "C:\\Users\\Andrea Bassi\\anaconda3\\envs\\scopefoundry\\lib\\site-packages\\pyqtgraph\\imageview\\ImageView.py", line 308, in setImage\n    self.roiChanged()\n', '  File "C:\\Users\\Andrea Bassi\\anaconda3\\envs\\scopefoundry\\lib\\site-packages\\pyqtgraph\\imageview\\ImageView.py", line 572, in roiChanged\n    self.roiCurve.setData(y=data, x=self.tVals)\n', "AttributeError: 'ImageView' object has no attribute 'tVals'\n"]
2020-07-26T11:33:28|ERROR|FakeCameraMeasurement|fake_camera_image Failed to update figure1: 'ImageView' object has no attribute 'tVals'. ['Traceback (most recent call last):\n', '  File "C:\\Users\\Andrea Bassi\\anaconda3\\envs\\scopefoundry\\lib\\site-packages\\ScopeFoundry\\measurement.py", line 273, in _on_display_update_timer\n    self.update_display()\n', '  File "C:\\Users\\Andrea Bassi\\OneDrive - Politecnico di Milano\\Documenti\\PythonProjects\\BassiScopeFoundryMicroscopes\\Microscopes\\CellRecongnitionMicroscope\\FakeCameraMeasurement.py", line 82, in update_display\n    self.imv.setImage((self.displayed_image), autoLevels=False, autoRange=self.settings.autoRange.val, levels=(self.settings.level_min.val, self.settings.level_max.val))\n', '  File "C:\\Users\\Andrea Bassi\\anaconda3\\envs\\scopefoundry\\lib\\site-packages\\pyqtgraph\\imageview\\ImageView.py", line 308, in setImage\n    self.roiChanged()\n', '  File "C:\\Users\\Andrea Bassi\\anaconda3\\envs\\scopefoundry\\lib\\site-packages\\pyqtgraph\\imageview\\ImageView.py", line 572, in roiChanged\n    self.roiCurve.setData(y=data, x=self.tVals)\n', "AttributeError: 'ImageView' object has no attribute 'tVals'\n"]
2020-07-26T11:33:28|ERROR|FakeCameraMeasurement|fake_camera_image Failed to update figure1: 'ImageView' object has no attribute 'tVals'. ['Traceback (most recent call last):\n', '  File "C:\\Users\\Andrea Bassi\\anaconda3\\envs\\scopefoundry\\lib\\site-packages\\ScopeFoundry\\measurement.py", line 273, in _on_display_update_timer\n    self.update_display()\n', '  File "C:\\Users\\Andrea Bassi\\OneDrive - Politecnico di Milano\\Documenti\\PythonProjects\\BassiScopeFoundryMicroscopes\\Microscopes\\CellRecongnitionMicroscope\\FakeCameraMeasurement.py", line 82, in update_display\n    self.imv.setImage((self.displayed_image), autoLevels=False, autoRange=self.settings.autoRange.val, levels=(self.settings.level_min.val, self.settings.level_max.val))\n', '  File "C:\\Users\\Andrea Bassi\\anaconda3\\envs\\scopefoundry\\lib\\site-packages\\pyqtgraph\\imageview\\ImageView.py", line 308, in setImage\n    self.roiChanged()\n', '  File "C:\\Users\\Andrea Bassi\\anaconda3\\envs\\scopefoundry\\lib\\site-packages\\pyqtgraph\\imageview\\ImageView.py", line 572, in roiChanged\n    self.roiCurve.setData(y=data, x=self.tVals)\n', "AttributeError: 'ImageView' object has no attribute 'tVals'\n"]
2020-07-26T11:33:28|ERROR|FakeCameraMeasurement|fake_camera_image Failed to update figure1: 'ImageView' object has no attribute 'tVals'. ['Traceback (most recent call last):\n', '  File "C:\\Users\\Andrea Bassi\\anaconda3\\envs\\scopefoundry\\lib\\site-packages\\ScopeFoundry\\measurement.py", line 273, in _on_display_update_timer\n    self.update_display()\n', '  File "C:\\Users\\Andrea Bassi\\OneDrive - Politecnico di Milano\\Documenti\\PythonProjects\\BassiScopeFoundryMicroscopes\\Microscopes\\CellRecongnitionMicroscope\\FakeCameraMeasurement.py", line 82, in update_display\n    self.imv.setImage((self.displayed_image), autoLevels=False, autoRange=self.settings.autoRange.val, levels=(self.settings.level_min.val, self.settings.level_max.val))\n', '  File "C:\\Users\\Andrea Bassi\\anaconda3\\envs\\scopefoundry\\lib\\site-packages\\pyqtgraph\\imageview\\ImageView.py", line 308, in setImage\n    self.roiChanged()\n', '  File "C:\\Users\\Andrea Bassi\\anaconda3\\envs\\scopefoundry\\lib\\site-packages\\pyqtgraph\\imageview\\ImageView.py", line 572, in roiChanged\n    self.roiCurve.setData(y=data, x=self.tVals)\n', "AttributeError: 'ImageView' object has no attribute 'tVals'\n"]
2020-07-26T11:33:28|ERROR|FakeCameraMeasurement|fake_camera_image Failed to update figure1: 'ImageView' object has no attribute 'tVals'. ['Traceback (most recent call last):\n', '  File "C:\\Users\\Andrea Bassi\\anaconda3\\envs\\scopefoundry\\lib\\site-packages\\ScopeFoundry\\measurement.py", line 273, in _on_display_update_timer\n    self.update_display()\n', '  File "C:\\Users\\Andrea Bassi\\OneDrive - Politecnico di Milano\\Documenti\\PythonProjects\\BassiScopeFoundryMicroscopes\\Microscopes\\CellRecongnitionMicroscope\\FakeCameraMeasurement.py", line 82, in update_display\n    self.imv.setImage((self.displayed_image), autoLevels=False, autoRange=self.settings.autoRange.val, levels=(self.settings.level_min.val, self.settings.level_max.val))\n', '  File "C:\\Users\\Andrea Bassi\\anaconda3\\envs\\scopefoundry\\lib\\site-packages\\pyqtgraph\\imageview\\ImageView.py", line 308, in setImage\n    self.roiChanged()\n', '  File "C:\\Users\\Andrea Bassi\\anaconda3\\envs\\scopefoundry\\lib\\site-packages\\pyqtgraph\\imageview\\ImageView.py", line 572, in roiChanged\n    self.roiCurve.setData(y=data, x=self.tVals)\n', "AttributeError: 'ImageView' object has no attribute 'tVals'\n"]
2020-07-26T11:33:28|ERROR|FakeCameraMeasurement|fake_camera_image Failed to update figure1: 'ImageView' object has no attribute 'tVals'. ['Traceback (most recent call last):\n', '  File "C:\\Users\\Andrea Bassi\\anaconda3\\envs\\scopefoundry\\lib\\site-packages\\ScopeFoundry\\measurement.py", line 273, in _on_display_update_timer\n    self.update_display()\n', '  File "C:\\Users\\Andrea Bassi\\OneDrive - Politecnico di Milano\\Documenti\\PythonProjects\\BassiScopeFoundryMicroscopes\\Microscopes\\CellRecongnitionMicroscope\\FakeCameraMeasurement.py", line 82, in update_display\n    self.imv.setImage((self.displayed_image), autoLevels=False, autoRange=self.settings.autoRange.val, levels=(self.settings.level_min.val, self.settings.level_max.val))\n', '  File "C:\\Users\\Andrea Bassi\\anaconda3\\envs\\scopefoundry\\lib\\site-packages\\pyqtgraph\\imageview\\ImageView.py", line 308, in setImage\n    self.roiChanged()\n', '  File "C:\\Users\\Andrea Bassi\\anaconda3\\envs\\scopefoundry\\lib\\site-packages\\pyqtgraph\\imageview\\ImageView.py", line 572, in roiChanged\n    self.roiCurve.setData(y=data, x=self.tVals)\n', "AttributeError: 'ImageView' object has no attribute 'tVals'\n"]
2020-07-26T11:33:28|ERROR|FakeCameraMeasurement|fake_camera_image Failed to update figure1: 'ImageView' object has no attribute 'tVals'. ['Traceback (most recent call last):\n', '  File "C:\\Users\\Andrea Bassi\\anaconda3\\envs\\scopefoundry\\lib\\site-packages\\ScopeFoundry\\measurement.py", line 273, in _on_display_update_timer\n    self.update_display()\n', '  File "C:\\Users\\Andrea Bassi\\OneDrive - Politecnico di Milano\\Documenti\\PythonProjects\\BassiScopeFoundryMicroscopes\\Microscopes\\CellRecongnitionMicroscope\\FakeCameraMeasurement.py", line 82, in update_display\n    self.imv.setImage((self.displayed_image), autoLevels=False, autoRange=self.settings.autoRange.val, levels=(self.settings.level_min.val, self.settings.level_max.val))\n', '  File "C:\\Users\\Andrea Bassi\\anaconda3\\envs\\scopefoundry\\lib\\site-packages\\pyqtgraph\\imageview\\ImageView.py", line 308, in setImage\n    self.roiChanged()\n', '  File "C:\\Users\\Andrea Bassi\\anaconda3\\envs\\scopefoundry\\lib\\site-packages\\pyqtgraph\\imageview\\ImageView.py", line 572, in roiChanged\n    self.roiCurve.setData(y=data, x=self.tVals)\n', "AttributeError: 'ImageView' object has no attribute 'tVals'\n"]
2020-07-26T11:33:28|ERROR|FakeCameraMeasurement|fake_camera_image Failed to update figure1: 'ImageView' object has no attribute 'tVals'. ['Traceback (most recent call last):\n', '  File "C:\\Users\\Andrea Bassi\\anaconda3\\envs\\scopefoundry\\lib\\site-packages\\ScopeFoundry\\measurement.py", line 273, in _on_display_update_timer\n    self.update_display()\n', '  File "C:\\Users\\Andrea Bassi\\OneDrive - Politecnico di Milano\\Documenti\\PythonProjects\\BassiScopeFoundryMicroscopes\\Microscopes\\CellRecongnitionMicroscope\\FakeCameraMeasurement.py", line 82, in update_display\n    self.imv.setImage((self.displayed_image), autoLevels=False, autoRange=self.settings.autoRange.val, levels=(self.settings.level_min.val, self.settings.level_max.val))\n', '  File "C:\\Users\\Andrea Bassi\\anaconda3\\envs\\scopefoundry\\lib\\site-packages\\pyqtgraph\\imageview\\ImageView.py", line 308, in setImage\n    self.roiChanged()\n', '  File "C:\\Users\\Andrea Bassi\\anaconda3\\envs\\scopefoundry\\lib\\site-packages\\pyqtgraph\\imageview\\ImageView.py", line 572, in roiChanged\n    self.roiCurve.setData(y=data, x=self.tVals)\n', "AttributeError: 'ImageView' object has no attribute 'tVals'\n"]
2020-07-26T11:33:28|ERROR|FakeCameraMeasurement|fake_camera_image Failed to update figure1: 'ImageView' object has no attribute 'tVals'. ['Traceback (most recent call last):\n', '  File "C:\\Users\\Andrea Bassi\\anaconda3\\envs\\scopefoundry\\lib\\site-packages\\ScopeFoundry\\measurement.py", line 273, in _on_display_update_timer\n    self.update_display()\n', '  File "C:\\Users\\Andrea Bassi\\OneDrive - Politecnico di Milano\\Documenti\\PythonProjects\\BassiScopeFoundryMicroscopes\\Microscopes\\CellRecongnitionMicroscope\\FakeCameraMeasurement.py", line 82, in update_display\n    self.imv.setImage((self.displayed_image), autoLevels=False, autoRange=self.settings.autoRange.val, levels=(self.settings.level_min.val, self.settings.level_max.val))\n', '  File "C:\\Users\\Andrea Bassi\\anaconda3\\envs\\scopefoundry\\lib\\site-packages\\pyqtgraph\\imageview\\ImageView.py", line 308, in setImage\n    self.roiChanged()\n', '  File "C:\\Users\\Andrea Bassi\\anaconda3\\envs\\scopefoundry\\lib\\site-packages\\pyqtgraph\\imageview\\ImageView.py", line 572, in roiChanged\n    self.roiCurve.setData(y=data, x=self.tVals)\n', "AttributeError: 'ImageView' object has no attribute 'tVals'\n"]
2020-07-26T11:33:28|ERROR|FakeCameraMeasurement|fake_camera_image Failed to update figure1: 'ImageView' object has no attribute 'tVals'. ['Traceback (most recent call last):\n', '  File "C:\\Users\\Andrea Bassi\\anaconda3\\envs\\scopefoundry\\lib\\site-packages\\ScopeFoundry\\measurement.py", line 273, in _on_display_update_timer\n    self.update_display()\n', '  File "C:\\Users\\Andrea Bassi\\OneDrive - Politecnico di Milano\\Documenti\\PythonProjects\\BassiScopeFoundryMicroscopes\\Microscopes\\CellRecongnitionMicroscope\\FakeCameraMeasurement.py", line 82, in update_display\n    self.imv.setImage((self.displayed_image), autoLevels=False, autoRange=self.settings.autoRange.val, levels=(self.settings.level_min.val, self.settings.level_max.val))\n', '  File "C:\\Users\\Andrea Bassi\\anaconda3\\envs\\scopefoundry\\lib\\site-packages\\pyqtgraph\\imageview\\ImageView.py", line 308, in setImage\n    self.roiChanged()\n', '  File "C:\\Users\\Andrea Bassi\\anaconda3\\envs\\scopefoundry\\lib\\site-packages\\pyqtgraph\\imageview\\ImageView.py", line 572, in roiChanged\n    self.roiCurve.setData(y=data, x=self.tVals)\n', "AttributeError: 'ImageView' object has no attribute 'tVals'\n"]
2020-07-26T11:33:29|ERROR|FakeCameraMeasurement|fake_camera_image Failed to update figure1: 'ImageView' object has no attribute 'tVals'. ['Traceback (most recent call last):\n', '  File "C:\\Users\\Andrea Bassi\\anaconda3\\envs\\scopefoundry\\lib\\site-packages\\ScopeFoundry\\measurement.py", line 273, in _on_display_update_timer\n    self.update_display()\n', '  File "C:\\Users\\Andrea Bassi\\OneDrive - Politecnico di Milano\\Documenti\\PythonProjects\\BassiScopeFoundryMicroscopes\\Microscopes\\CellRecongnitionMicroscope\\FakeCameraMeasurement.py", line 82, in update_display\n    self.imv.setImage((self.displayed_image), autoLevels=False, autoRange=self.settings.autoRange.val, levels=(self.settings.level_min.val, self.settings.level_max.val))\n', '  File "C:\\Users\\Andrea Bassi\\anaconda3\\envs\\scopefoundry\\lib\\site-packages\\pyqtgraph\\imageview\\ImageView.py", line 308, in setImage\n    self.roiChanged()\n', '  File "C:\\Users\\Andrea Bassi\\anaconda3\\envs\\scopefoundry\\lib\\site-packages\\pyqtgraph\\imageview\\ImageView.py", line 572, in roiChanged\n    self.roiCurve.setData(y=data, x=self.tVals)\n', "AttributeError: 'ImageView' object has no attribute 'tVals'\n"]
2020-07-26T11:33:29|ERROR|FakeCameraMeasurement|fake_camera_image Failed to update figure1: 'ImageView' object has no attribute 'tVals'. ['Traceback (most recent call last):\n', '  File "C:\\Users\\Andrea Bassi\\anaconda3\\envs\\scopefoundry\\lib\\site-packages\\ScopeFoundry\\measurement.py", line 273, in _on_display_update_timer\n    self.update_display()\n', '  File "C:\\Users\\Andrea Bassi\\OneDrive - Politecnico di Milano\\Documenti\\PythonProjects\\BassiScopeFoundryMicroscopes\\Microscopes\\CellRecongnitionMicroscope\\FakeCameraMeasurement.py", line 82, in update_display\n    self.imv.setImage((self.displayed_image), autoLevels=False, autoRange=self.settings.autoRange.val, levels=(self.settings.level_min.val, self.settings.level_max.val))\n', '  File "C:\\Users\\Andrea Bassi\\anaconda3\\envs\\scopefoundry\\lib\\site-packages\\pyqtgraph\\imageview\\ImageView.py", line 308, in setImage\n    self.roiChanged()\n', '  File "C:\\Users\\Andrea Bassi\\anaconda3\\envs\\scopefoundry\\lib\\site-packages\\pyqtgraph\\imageview\\ImageView.py", line 572, in roiChanged\n    self.roiCurve.setData(y=data, x=self.tVals)\n', "AttributeError: 'ImageView' object has no attribute 'tVals'\n"]
2020-07-26T11:33:29|ERROR|FakeCameraMeasurement|fake_camera_image Failed to update figure1: 'ImageView' object has no attribute 'tVals'. ['Traceback (most recent call last):\n', '  File "C:\\Users\\Andrea Bassi\\anaconda3\\envs\\scopefoundry\\lib\\site-packages\\ScopeFoundry\\measurement.py", line 273, in _on_display_update_timer\n    self.update_display()\n', '  File "C:\\Users\\Andrea Bassi\\OneDrive - Politecnico di Milano\\Documenti\\PythonProjects\\BassiScopeFoundryMicroscopes\\Microscopes\\CellRecongnitionMicroscope\\FakeCameraMeasurement.py", line 82, in update_display\n    self.imv.setImage((self.displayed_image), autoLevels=False, autoRange=self.settings.autoRange.val, levels=(self.settings.level_min.val, self.settings.level_max.val))\n', '  File "C:\\Users\\Andrea Bassi\\anaconda3\\envs\\scopefoundry\\lib\\site-packages\\pyqtgraph\\imageview\\ImageView.py", line 308, in setImage\n    self.roiChanged()\n', '  File "C:\\Users\\Andrea Bassi\\anaconda3\\envs\\scopefoundry\\lib\\site-packages\\pyqtgraph\\imageview\\ImageView.py", line 572, in roiChanged\n    self.roiCurve.setData(y=data, x=self.tVals)\n', "AttributeError: 'ImageView' object has no attribute 'tVals'\n"]
2020-07-26T11:33:29|ERROR|FakeCameraMeasurement|fake_camera_image Failed to update figure1: 'ImageView' object has no attribute 'tVals'. ['Traceback (most recent call last):\n', '  File "C:\\Users\\Andrea Bassi\\anaconda3\\envs\\scopefoundry\\lib\\site-packages\\ScopeFoundry\\measurement.py", line 273, in _on_display_update_timer\n    self.update_display()\n', '  File "C:\\Users\\Andrea Bassi\\OneDrive - Politecnico di Milano\\Documenti\\PythonProjects\\BassiScopeFoundryMicroscopes\\Microscopes\\CellRecongnitionMicroscope\\FakeCameraMeasurement.py", line 82, in update_display\n    self.imv.setImage((self.displayed_image), autoLevels=False, autoRange=self.settings.autoRange.val, levels=(self.settings.level_min.val, self.settings.level_max.val))\n', '  File "C:\\Users\\Andrea Bassi\\anaconda3\\envs\\scopefoundry\\lib\\site-packages\\pyqtgraph\\imageview\\ImageView.py", line 308, in setImage\n    self.roiChanged()\n', '  File "C:\\Users\\Andrea Bassi\\anaconda3\\envs\\scopefoundry\\lib\\site-packages\\pyqtgraph\\imageview\\ImageView.py", line 572, in roiChanged\n    self.roiCurve.setData(y=data, x=self.tVals)\n', "AttributeError: 'ImageView' object has no attribute 'tVals'\n"]
2020-07-26T11:33:29|ERROR|FakeCameraMeasurement|fake_camera_image Failed to update figure1: 'ImageView' object has no attribute 'tVals'. ['Traceback (most recent call last):\n', '  File "C:\\Users\\Andrea Bassi\\anaconda3\\envs\\scopefoundry\\lib\\site-packages\\ScopeFoundry\\measurement.py", line 273, in _on_display_update_timer\n    self.update_display()\n', '  File "C:\\Users\\Andrea Bassi\\OneDrive - Politecnico di Milano\\Documenti\\PythonProjects\\BassiScopeFoundryMicroscopes\\Microscopes\\CellRecongnitionMicroscope\\FakeCameraMeasurement.py", line 82, in update_display\n    self.imv.setImage((self.displayed_image), autoLevels=False, autoRange=self.settings.autoRange.val, levels=(self.settings.level_min.val, self.settings.level_max.val))\n', '  File "C:\\Users\\Andrea Bassi\\anaconda3\\envs\\scopefoundry\\lib\\site-packages\\pyqtgraph\\imageview\\ImageView.py", line 308, in setImage\n    self.roiChanged()\n', '  File "C:\\Users\\Andrea Bassi\\anaconda3\\envs\\scopefoundry\\lib\\site-packages\\pyqtgraph\\imageview\\ImageView.py", line 572, in roiChanged\n    self.roiCurve.setData(y=data, x=self.tVals)\n', "AttributeError: 'ImageView' object has no attribute 'tVals'\n"]
2020-07-26T11:33:29|ERROR|FakeCameraMeasurement|fake_camera_image Failed to update figure1: 'ImageView' object has no attribute 'tVals'. ['Traceback (most recent call last):\n', '  File "C:\\Users\\Andrea Bassi\\anaconda3\\envs\\scopefoundry\\lib\\site-packages\\ScopeFoundry\\measurement.py", line 273, in _on_display_update_timer\n    self.update_display()\n', '  File "C:\\Users\\Andrea Bassi\\OneDrive - Politecnico di Milano\\Documenti\\PythonProjects\\BassiScopeFoundryMicroscopes\\Microscopes\\CellRecongnitionMicroscope\\FakeCameraMeasurement.py", line 82, in update_display\n    self.imv.setImage((self.displayed_image), autoLevels=False, autoRange=self.settings.autoRange.val, levels=(self.settings.level_min.val, self.settings.level_max.val))\n', '  File "C:\\Users\\Andrea Bassi\\anaconda3\\envs\\scopefoundry\\lib\\site-packages\\pyqtgraph\\imageview\\ImageView.py", line 308, in setImage\n    self.roiChanged()\n', '  File "C:\\Users\\Andrea Bassi\\anaconda3\\envs\\scopefoundry\\lib\\site-packages\\pyqtgraph\\imageview\\ImageView.py", line 572, in roiChanged\n    self.roiCurve.setData(y=data, x=self.tVals)\n', "AttributeError: 'ImageView' object has no attribute 'tVals'\n"]
2020-07-26T11:33:29|ERROR|FakeCameraMeasurement|fake_camera_image Failed to update figure1: 'ImageView' object has no attribute 'tVals'. ['Traceback (most recent call last):\n', '  File "C:\\Users\\Andrea Bassi\\anaconda3\\envs\\scopefoundry\\lib\\site-packages\\ScopeFoundry\\measurement.py", line 273, in _on_display_update_timer\n    self.update_display()\n', '  File "C:\\Users\\Andrea Bassi\\OneDrive - Politecnico di Milano\\Documenti\\PythonProjects\\BassiScopeFoundryMicroscopes\\Microscopes\\CellRecongnitionMicroscope\\FakeCameraMeasurement.py", line 82, in update_display\n    self.imv.setImage((self.displayed_image), autoLevels=False, autoRange=self.settings.autoRange.val, levels=(self.settings.level_min.val, self.settings.level_max.val))\n', '  File "C:\\Users\\Andrea Bassi\\anaconda3\\envs\\scopefoundry\\lib\\site-packages\\pyqtgraph\\imageview\\ImageView.py", line 308, in setImage\n    self.roiChanged()\n', '  File "C:\\Users\\Andrea Bassi\\anaconda3\\envs\\scopefoundry\\lib\\site-packages\\pyqtgraph\\imageview\\ImageView.py", line 572, in roiChanged\n    self.roiCurve.setData(y=data, x=self.tVals)\n', "AttributeError: 'ImageView' object has no attribute 'tVals'\n"]
2020-07-26T11:33:29|ERROR|FakeCameraMeasurement|fake_camera_image Failed to update figure1: 'ImageView' object has no attribute 'tVals'. ['Traceback (most recent call last):\n', '  File "C:\\Users\\Andrea Bassi\\anaconda3\\envs\\scopefoundry\\lib\\site-packages\\ScopeFoundry\\measurement.py", line 273, in _on_display_update_timer\n    self.update_display()\n', '  File "C:\\Users\\Andrea Bassi\\OneDrive - Politecnico di Milano\\Documenti\\PythonProjects\\BassiScopeFoundryMicroscopes\\Microscopes\\CellRecongnitionMicroscope\\FakeCameraMeasurement.py", line 82, in update_display\n    self.imv.setImage((self.displayed_image), autoLevels=False, autoRange=self.settings.autoRange.val, levels=(self.settings.level_min.val, self.settings.level_max.val))\n', '  File "C:\\Users\\Andrea Bassi\\anaconda3\\envs\\scopefoundry\\lib\\site-packages\\pyqtgraph\\imageview\\ImageView.py", line 308, in setImage\n    self.roiChanged()\n', '  File "C:\\Users\\Andrea Bassi\\anaconda3\\envs\\scopefoundry\\lib\\site-packages\\pyqtgraph\\imageview\\ImageView.py", line 572, in roiChanged\n    self.roiCurve.setData(y=data, x=self.tVals)\n', "AttributeError: 'ImageView' object has no attribute 'tVals'\n"]
2020-07-26T11:33:29|ERROR|FakeCameraMeasurement|fake_camera_image Failed to update figure1: 'ImageView' object has no attribute 'tVals'. ['Traceback (most recent call last):\n', '  File "C:\\Users\\Andrea Bassi\\anaconda3\\envs\\scopefoundry\\lib\\site-packages\\ScopeFoundry\\measurement.py", line 273, in _on_display_update_timer\n    self.update_display()\n', '  File "C:\\Users\\Andrea Bassi\\OneDrive - Politecnico di Milano\\Documenti\\PythonProjects\\BassiScopeFoundryMicroscopes\\Microscopes\\CellRecongnitionMicroscope\\FakeCameraMeasurement.py", line 82, in update_display\n    self.imv.setImage((self.displayed_image), autoLevels=False, autoRange=self.settings.autoRange.val, levels=(self.settings.level_min.val, self.settings.level_max.val))\n', '  File "C:\\Users\\Andrea Bassi\\anaconda3\\envs\\scopefoundry\\lib\\site-packages\\pyqtgraph\\imageview\\ImageView.py", line 308, in setImage\n    self.roiChanged()\n', '  File "C:\\Users\\Andrea Bassi\\anaconda3\\envs\\scopefoundry\\lib\\site-packages\\pyqtgraph\\imageview\\ImageView.py", line 572, in roiChanged\n    self.roiCurve.setData(y=data, x=self.tVals)\n', "AttributeError: 'ImageView' object has no attribute 'tVals'\n"]
2020-07-26T11:33:29|ERROR|FakeCameraMeasurement|fake_camera_image Failed to update figure1: 'ImageView' object has no attribute 'tVals'. ['Traceback (most recent call last):\n', '  File "C:\\Users\\Andrea Bassi\\anaconda3\\envs\\scopefoundry\\lib\\site-packages\\ScopeFoundry\\measurement.py", line 273, in _on_display_update_timer\n    self.update_display()\n', '  File "C:\\Users\\Andrea Bassi\\OneDrive - Politecnico di Milano\\Documenti\\PythonProjects\\BassiScopeFoundryMicroscopes\\Microscopes\\CellRecongnitionMicroscope\\FakeCameraMeasurement.py", line 82, in update_display\n    self.imv.setImage((self.displayed_image), autoLevels=False, autoRange=self.settings.autoRange.val, levels=(self.settings.level_min.val, self.settings.level_max.val))\n', '  File "C:\\Users\\Andrea Bassi\\anaconda3\\envs\\scopefoundry\\lib\\site-packages\\pyqtgraph\\imageview\\ImageView.py", line 308, in setImage\n    self.roiChanged()\n', '  File "C:\\Users\\Andrea Bassi\\anaconda3\\envs\\scopefoundry\\lib\\site-packages\\pyqtgraph\\imageview\\ImageView.py", line 572, in roiChanged\n    self.roiCurve.setData(y=data, x=self.tVals)\n', "AttributeError: 'ImageView' object has no attribute 'tVals'\n"]
2020-07-26T11:33:29|ERROR|FakeCameraMeasurement|fake_camera_image Failed to update figure1: 'ImageView' object has no attribute 'tVals'. ['Traceback (most recent call last):\n', '  File "C:\\Users\\Andrea Bassi\\anaconda3\\envs\\scopefoundry\\lib\\site-packages\\ScopeFoundry\\measurement.py", line 273, in _on_display_update_timer\n    self.update_display()\n', '  File "C:\\Users\\Andrea Bassi\\OneDrive - Politecnico di Milano\\Documenti\\PythonProjects\\BassiScopeFoundryMicroscopes\\Microscopes\\CellRecongnitionMicroscope\\FakeCameraMeasurement.py", line 82, in update_display\n    self.imv.setImage((self.displayed_image), autoLevels=False, autoRange=self.settings.autoRange.val, levels=(self.settings.level_min.val, self.settings.level_max.val))\n', '  File "C:\\Users\\Andrea Bassi\\anaconda3\\envs\\scopefoundry\\lib\\site-packages\\pyqtgraph\\imageview\\ImageView.py", line 308, in setImage\n    self.roiChanged()\n', '  File "C:\\Users\\Andrea Bassi\\anaconda3\\envs\\scopefoundry\\lib\\site-packages\\pyqtgraph\\imageview\\ImageView.py", line 572, in roiChanged\n    self.roiCurve.setData(y=data, x=self.tVals)\n', "AttributeError: 'ImageView' object has no attribute 'tVals'\n"]
2020-07-26T11:33:29|ERROR|FakeCameraMeasurement|fake_camera_image Failed to update figure1: 'ImageView' object has no attribute 'tVals'. ['Traceback (most recent call last):\n', '  File "C:\\Users\\Andrea Bassi\\anaconda3\\envs\\scopefoundry\\lib\\site-packages\\ScopeFoundry\\measurement.py", line 273, in _on_display_update_timer\n    self.update_display()\n', '  File "C:\\Users\\Andrea Bassi\\OneDrive - Politecnico di Milano\\Documenti\\PythonProjects\\BassiScopeFoundryMicroscopes\\Microscopes\\CellRecongnitionMicroscope\\FakeCameraMeasurement.py", line 82, in update_display\n    self.imv.setImage((self.displayed_image), autoLevels=False, autoRange=self.settings.autoRange.val, levels=(self.settings.level_min.val, self.settings.level_max.val))\n', '  File "C:\\Users\\Andrea Bassi\\anaconda3\\envs\\scopefoundry\\lib\\site-packages\\pyqtgraph\\imageview\\ImageView.py", line 308, in setImage\n    self.roiChanged()\n', '  File "C:\\Users\\Andrea Bassi\\anaconda3\\envs\\scopefoundry\\lib\\site-packages\\pyqtgraph\\imageview\\ImageView.py", line 572, in roiChanged\n    self.roiCurve.setData(y=data, x=self.tVals)\n', "AttributeError: 'ImageView' object has no attribute 'tVals'\n"]
2020-07-26T11:33:29|ERROR|FakeCameraMeasurement|fake_camera_image Failed to update figure1: 'ImageView' object has no attribute 'tVals'. ['Traceback (most recent call last):\n', '  File "C:\\Users\\Andrea Bassi\\anaconda3\\envs\\scopefoundry\\lib\\site-packages\\ScopeFoundry\\measurement.py", line 273, in _on_display_update_timer\n    self.update_display()\n', '  File "C:\\Users\\Andrea Bassi\\OneDrive - Politecnico di Milano\\Documenti\\PythonProjects\\BassiScopeFoundryMicroscopes\\Microscopes\\CellRecongnitionMicroscope\\FakeCameraMeasurement.py", line 82, in update_display\n    self.imv.setImage((self.displayed_image), autoLevels=False, autoRange=self.settings.autoRange.val, levels=(self.settings.level_min.val, self.settings.level_max.val))\n', '  File "C:\\Users\\Andrea Bassi\\anaconda3\\envs\\scopefoundry\\lib\\site-packages\\pyqtgraph\\imageview\\ImageView.py", line 308, in setImage\n    self.roiChanged()\n', '  File "C:\\Users\\Andrea Bassi\\anaconda3\\envs\\scopefoundry\\lib\\site-packages\\pyqtgraph\\imageview\\ImageView.py", line 572, in roiChanged\n    self.roiCurve.setData(y=data, x=self.tVals)\n', "AttributeError: 'ImageView' object has no attribute 'tVals'\n"]
2020-07-26T11:33:29|ERROR|FakeCameraMeasurement|fake_camera_image Failed to update figure1: 'ImageView' object has no attribute 'tVals'. ['Traceback (most recent call last):\n', '  File "C:\\Users\\Andrea Bassi\\anaconda3\\envs\\scopefoundry\\lib\\site-packages\\ScopeFoundry\\measurement.py", line 273, in _on_display_update_timer\n    self.update_display()\n', '  File "C:\\Users\\Andrea Bassi\\OneDrive - Politecnico di Milano\\Documenti\\PythonProjects\\BassiScopeFoundryMicroscopes\\Microscopes\\CellRecongnitionMicroscope\\FakeCameraMeasurement.py", line 82, in update_display\n    self.imv.setImage((self.displayed_image), autoLevels=False, autoRange=self.settings.autoRange.val, levels=(self.settings.level_min.val, self.settings.level_max.val))\n', '  File "C:\\Users\\Andrea Bassi\\anaconda3\\envs\\scopefoundry\\lib\\site-packages\\pyqtgraph\\imageview\\ImageView.py", line 308, in setImage\n    self.roiChanged()\n', '  File "C:\\Users\\Andrea Bassi\\anaconda3\\envs\\scopefoundry\\lib\\site-packages\\pyqtgraph\\imageview\\ImageView.py", line 572, in roiChanged\n    self.roiCurve.setData(y=data, x=self.tVals)\n', "AttributeError: 'ImageView' object has no attribute 'tVals'\n"]
2020-07-26T11:33:29|ERROR|FakeCameraMeasurement|fake_camera_image Failed to update figure1: 'ImageView' object has no attribute 'tVals'. ['Traceback (most recent call last):\n', '  File "C:\\Users\\Andrea Bassi\\anaconda3\\envs\\scopefoundry\\lib\\site-packages\\ScopeFoundry\\measurement.py", line 273, in _on_display_update_timer\n    self.update_display()\n', '  File "C:\\Users\\Andrea Bassi\\OneDrive - Politecnico di Milano\\Documenti\\PythonProjects\\BassiScopeFoundryMicroscopes\\Microscopes\\CellRecongnitionMicroscope\\FakeCameraMeasurement.py", line 82, in update_display\n    self.imv.setImage((self.displayed_image), autoLevels=False, autoRange=self.settings.autoRange.val, levels=(self.settings.level_min.val, self.settings.level_max.val))\n', '  File "C:\\Users\\Andrea Bassi\\anaconda3\\envs\\scopefoundry\\lib\\site-packages\\pyqtgraph\\imageview\\ImageView.py", line 308, in setImage\n    self.roiChanged()\n', '  File "C:\\Users\\Andrea Bassi\\anaconda3\\envs\\scopefoundry\\lib\\site-packages\\pyqtgraph\\imageview\\ImageView.py", line 572, in roiChanged\n    self.roiCurve.setData(y=data, x=self.tVals)\n', "AttributeError: 'ImageView' object has no attribute 'tVals'\n"]
2020-07-26T11:33:29|ERROR|FakeCameraMeasurement|fake_camera_image Failed to update figure1: 'ImageView' object has no attribute 'tVals'. ['Traceback (most recent call last):\n', '  File "C:\\Users\\Andrea Bassi\\anaconda3\\envs\\scopefoundry\\lib\\site-packages\\ScopeFoundry\\measurement.py", line 273, in _on_display_update_timer\n    self.update_display()\n', '  File "C:\\Users\\Andrea Bassi\\OneDrive - Politecnico di Milano\\Documenti\\PythonProjects\\BassiScopeFoundryMicroscopes\\Microscopes\\CellRecongnitionMicroscope\\FakeCameraMeasurement.py", line 82, in update_display\n    self.imv.setImage((self.displayed_image), autoLevels=False, autoRange=self.settings.autoRange.val, levels=(self.settings.level_min.val, self.settings.level_max.val))\n', '  File "C:\\Users\\Andrea Bassi\\anaconda3\\envs\\scopefoundry\\lib\\site-packages\\pyqtgraph\\imageview\\ImageView.py", line 308, in setImage\n    self.roiChanged()\n', '  File "C:\\Users\\Andrea Bassi\\anaconda3\\envs\\scopefoundry\\lib\\site-packages\\pyqtgraph\\imageview\\ImageView.py", line 572, in roiChanged\n    self.roiCurve.setData(y=data, x=self.tVals)\n', "AttributeError: 'ImageView' object has no attribute 'tVals'\n"]
2020-07-26T11:33:29|ERROR|FakeCameraMeasurement|fake_camera_image Failed to update figure1: 'ImageView' object has no attribute 'tVals'. ['Traceback (most recent call last):\n', '  File "C:\\Users\\Andrea Bassi\\anaconda3\\envs\\scopefoundry\\lib\\site-packages\\ScopeFoundry\\measurement.py", line 273, in _on_display_update_timer\n    self.update_display()\n', '  File "C:\\Users\\Andrea Bassi\\OneDrive - Politecnico di Milano\\Documenti\\PythonProjects\\BassiScopeFoundryMicroscopes\\Microscopes\\CellRecongnitionMicroscope\\FakeCameraMeasurement.py", line 82, in update_display\n    self.imv.setImage((self.displayed_image), autoLevels=False, autoRange=self.settings.autoRange.val, levels=(self.settings.level_min.val, self.settings.level_max.val))\n', '  File "C:\\Users\\Andrea Bassi\\anaconda3\\envs\\scopefoundry\\lib\\site-packages\\pyqtgraph\\imageview\\ImageView.py", line 308, in setImage\n    self.roiChanged()\n', '  File "C:\\Users\\Andrea Bassi\\anaconda3\\envs\\scopefoundry\\lib\\site-packages\\pyqtgraph\\imageview\\ImageView.py", line 572, in roiChanged\n    self.roiCurve.setData(y=data, x=self.tVals)\n', "AttributeError: 'ImageView' object has no attribute 'tVals'\n"]
2020-07-26T11:33:30|ERROR|FakeCameraMeasurement|fake_camera_image Failed to update figure1: 'ImageView' object has no attribute 'tVals'. ['Traceback (most recent call last):\n', '  File "C:\\Users\\Andrea Bassi\\anaconda3\\envs\\scopefoundry\\lib\\site-packages\\ScopeFoundry\\measurement.py", line 273, in _on_display_update_timer\n    self.update_display()\n', '  File "C:\\Users\\Andrea Bassi\\OneDrive - Politecnico di Milano\\Documenti\\PythonProjects\\BassiScopeFoundryMicroscopes\\Microscopes\\CellRecongnitionMicroscope\\FakeCameraMeasurement.py", line 82, in update_display\n    self.imv.setImage((self.displayed_image), autoLevels=False, autoRange=self.settings.autoRange.val, levels=(self.settings.level_min.val, self.settings.level_max.val))\n', '  File "C:\\Users\\Andrea Bassi\\anaconda3\\envs\\scopefoundry\\lib\\site-packages\\pyqtgraph\\imageview\\ImageView.py", line 308, in setImage\n    self.roiChanged()\n', '  File "C:\\Users\\Andrea Bassi\\anaconda3\\envs\\scopefoundry\\lib\\site-packages\\pyqtgraph\\imageview\\ImageView.py", line 572, in roiChanged\n    self.roiCurve.setData(y=data, x=self.tVals)\n', "AttributeError: 'ImageView' object has no attribute 'tVals'\n"]
2020-07-26T11:33:32|ERROR|FakeCameraMeasurement|fake_camera_image Failed to update figure1: 'ImageView' object has no attribute 'tVals'. ['Traceback (most recent call last):\n', '  File "C:\\Users\\Andrea Bassi\\anaconda3\\envs\\scopefoundry\\lib\\site-packages\\ScopeFoundry\\measurement.py", line 273, in _on_display_update_timer\n    self.update_display()\n', '  File "C:\\Users\\Andrea Bassi\\OneDrive - Politecnico di Milano\\Documenti\\PythonProjects\\BassiScopeFoundryMicroscopes\\Microscopes\\CellRecongnitionMicroscope\\FakeCameraMeasurement.py", line 82, in update_display\n    self.imv.setImage((self.displayed_image), autoLevels=False, autoRange=self.settings.autoRange.val, levels=(self.settings.level_min.val, self.settings.level_max.val))\n', '  File "C:\\Users\\Andrea Bassi\\anaconda3\\envs\\scopefoundry\\lib\\site-packages\\pyqtgraph\\imageview\\ImageView.py", line 308, in setImage\n    self.roiChanged()\n', '  File "C:\\Users\\Andrea Bassi\\anaconda3\\envs\\scopefoundry\\lib\\site-packages\\pyqtgraph\\imageview\\ImageView.py", line 572, in roiChanged\n    self.roiCurve.setData(y=data, x=self.tVals)\n', "AttributeError: 'ImageView' object has no attribute 'tVals'\n"]
2020-07-26T11:33:39|ERROR|FakeCameraMeasurement|fake_camera_image Failed to update figure1: 'ImageView' object has no attribute 'tVals'. ['Traceback (most recent call last):\n', '  File "C:\\Users\\Andrea Bassi\\anaconda3\\envs\\scopefoundry\\lib\\site-packages\\ScopeFoundry\\measurement.py", line 273, in _on_display_update_timer\n    self.update_display()\n', '  File "C:\\Users\\Andrea Bassi\\OneDrive - Politecnico di Milano\\Documenti\\PythonProjects\\BassiScopeFoundryMicroscopes\\Microscopes\\CellRecongnitionMicroscope\\FakeCameraMeasurement.py", line 82, in update_display\n    self.imv.setImage((self.displayed_image), autoLevels=False, autoRange=self.settings.autoRange.val, levels=(self.settings.level_min.val, self.settings.level_max.val))\n', '  File "C:\\Users\\Andrea Bassi\\anaconda3\\envs\\scopefoundry\\lib\\site-packages\\pyqtgraph\\imageview\\ImageView.py", line 308, in setImage\n    self.roiChanged()\n', '  File "C:\\Users\\Andrea Bassi\\anaconda3\\envs\\scopefoundry\\lib\\site-packages\\pyqtgraph\\imageview\\ImageView.py", line 572, in roiChanged\n    self.roiCurve.setData(y=data, x=self.tVals)\n', "AttributeError: 'ImageView' object has no attribute 'tVals'\n"]
2020-07-26T14:09:22|ERROR|FakeCameraMeasurement|fake_camera_image Failed to update figure1: 'LQCollection' object has no attribute 'autoRange'. ['Traceback (most recent call last):\n', '  File "C:\\Users\\Andrea Bassi\\anaconda3\\envs\\scopefoundry\\lib\\site-packages\\ScopeFoundry\\measurement.py", line 273, in _on_display_update_timer\n    self.update_display()\n', '  File "C:\\Users\\Andrea Bassi\\OneDrive - Politecnico di Milano\\Documenti\\PythonProjects\\BassiScopeFoundryMicroscopes\\Microscopes\\CellRecongnitionMicroscope\\FakeCameraMeasurement.py", line 80, in update_display\n    self.imv.setImage((self.displayed_image), autoLevels=False, autoRange=self.settings.autoRange.val, levels=(self.settings.level_min.val, self.settings.level_max.val))\n', "AttributeError: 'LQCollection' object has no attribute 'autoRange'\n"]
2020-07-26T14:50:46|ERROR|FakeCameraMeasurement|fake_camera_image Failed to update figure1: 'FakeCameraMeasurement' object has no attribute 'cnt'. ['Traceback (most recent call last):\n', '  File "C:\\Users\\Andrea Bassi\\anaconda3\\envs\\scopefoundry\\lib\\site-packages\\ScopeFoundry\\measurement.py", line 273, in _on_display_update_timer\n    self.update_display()\n', '  File "C:\\Users\\Andrea Bassi\\OneDrive - Politecnico di Milano\\Documenti\\PythonProjects\\BassiScopeFoundryMicroscopes\\Microscopes\\CellRecongnitionMicroscope\\FakeCameraMeasurement.py", line 87, in update_display\n    self.displayed_image = self.draw_contours(image8bit_autoleveled,self.cnt,self.cx,self.cy)\n', "AttributeError: 'FakeCameraMeasurement' object has no attribute 'cnt'\n"]
2020-07-26T15:14:47|ERROR|FakeCameraMeasurement|fake_camera_image Failed to update figure1: 'int' object has no attribute 'val'. ['Traceback (most recent call last):\n', '  File "C:\\Users\\Andrea Bassi\\anaconda3\\envs\\scopefoundry\\lib\\site-packages\\ScopeFoundry\\measurement.py", line 273, in _on_display_update_timer\n    self.update_display()\n', '  File "C:\\Users\\Andrea Bassi\\OneDrive - Politecnico di Milano\\Documenti\\PythonProjects\\BassiScopeFoundryMicroscopes\\Microscopes\\CellRecongnitionMicroscope\\FakeCameraMeasurement.py", line 86, in update_display\n    levels=(int(level_min.val), int(level_max.val))\n', "AttributeError: 'int' object has no attribute 'val'\n"]
2020-07-26T15:14:53|ERROR|FakeCameraMeasurement|fake_camera_image Failed to update figure1: 'numpy.uint16' object has no attribute 'val'. ['Traceback (most recent call last):\n', '  File "C:\\Users\\Andrea Bassi\\anaconda3\\envs\\scopefoundry\\lib\\site-packages\\ScopeFoundry\\measurement.py", line 273, in _on_display_update_timer\n    self.update_display()\n', '  File "C:\\Users\\Andrea Bassi\\OneDrive - Politecnico di Milano\\Documenti\\PythonProjects\\BassiScopeFoundryMicroscopes\\Microscopes\\CellRecongnitionMicroscope\\FakeCameraMeasurement.py", line 86, in update_display\n    levels=(int(level_min.val), int(level_max.val))\n', "AttributeError: 'numpy.uint16' object has no attribute 'val'\n"]
2020-07-26T15:14:55|ERROR|FakeCameraMeasurement|fake_camera_image Failed to update figure1: 'numpy.uint16' object has no attribute 'val'. ['Traceback (most recent call last):\n', '  File "C:\\Users\\Andrea Bassi\\anaconda3\\envs\\scopefoundry\\lib\\site-packages\\ScopeFoundry\\measurement.py", line 273, in _on_display_update_timer\n    self.update_display()\n', '  File "C:\\Users\\Andrea Bassi\\OneDrive - Politecnico di Milano\\Documenti\\PythonProjects\\BassiScopeFoundryMicroscopes\\Microscopes\\CellRecongnitionMicroscope\\FakeCameraMeasurement.py", line 86, in update_display\n    levels=(int(level_min.val), int(level_max.val))\n', "AttributeError: 'numpy.uint16' object has no attribute 'val'\n"]
2020-07-26T15:14:57|ERROR|FakeCameraMeasurement|fake_camera_image Failed to update figure1: 'numpy.uint16' object has no attribute 'val'. ['Traceback (most recent call last):\n', '  File "C:\\Users\\Andrea Bassi\\anaconda3\\envs\\scopefoundry\\lib\\site-packages\\ScopeFoundry\\measurement.py", line 273, in _on_display_update_timer\n    self.update_display()\n', '  File "C:\\Users\\Andrea Bassi\\OneDrive - Politecnico di Milano\\Documenti\\PythonProjects\\BassiScopeFoundryMicroscopes\\Microscopes\\CellRecongnitionMicroscope\\FakeCameraMeasurement.py", line 86, in update_display\n    levels=(int(level_min.val), int(level_max.val))\n', "AttributeError: 'numpy.uint16' object has no attribute 'val'\n"]
2020-07-26T15:14:58|ERROR|FakeCameraMeasurement|fake_camera_image Failed to update figure1: 'numpy.uint16' object has no attribute 'val'. ['Traceback (most recent call last):\n', '  File "C:\\Users\\Andrea Bassi\\anaconda3\\envs\\scopefoundry\\lib\\site-packages\\ScopeFoundry\\measurement.py", line 273, in _on_display_update_timer\n    self.update_display()\n', '  File "C:\\Users\\Andrea Bassi\\OneDrive - Politecnico di Milano\\Documenti\\PythonProjects\\BassiScopeFoundryMicroscopes\\Microscopes\\CellRecongnitionMicroscope\\FakeCameraMeasurement.py", line 86, in update_display\n    levels=(int(level_min.val), int(level_max.val))\n', "AttributeError: 'numpy.uint16' object has no attribute 'val'\n"]
2020-07-26T15:15:00|ERROR|FakeCameraMeasurement|fake_camera_image Failed to update figure1: 'numpy.uint16' object has no attribute 'val'. ['Traceback (most recent call last):\n', '  File "C:\\Users\\Andrea Bassi\\anaconda3\\envs\\scopefoundry\\lib\\site-packages\\ScopeFoundry\\measurement.py", line 273, in _on_display_update_timer\n    self.update_display()\n', '  File "C:\\Users\\Andrea Bassi\\OneDrive - Politecnico di Milano\\Documenti\\PythonProjects\\BassiScopeFoundryMicroscopes\\Microscopes\\CellRecongnitionMicroscope\\FakeCameraMeasurement.py", line 86, in update_display\n    levels=(int(level_min.val), int(level_max.val))\n', "AttributeError: 'numpy.uint16' object has no attribute 'val'\n"]
2020-07-26T15:21:32|ERROR|FakeCameraMeasurement|fake_camera_image Failed to update figure1: 'FakeCameraMeasurement' object has no attribute 'setting'. ['Traceback (most recent call last):\n', '  File "C:\\Users\\Andrea Bassi\\anaconda3\\envs\\scopefoundry\\lib\\site-packages\\ScopeFoundry\\measurement.py", line 273, in _on_display_update_timer\n    self.update_display()\n', '  File "C:\\Users\\Andrea Bassi\\OneDrive - Politecnico di Milano\\Documenti\\PythonProjects\\BassiScopeFoundryMicroscopes\\Microscopes\\CellRecongnitionMicroscope\\FakeCameraMeasurement.py", line 85, in update_display\n    if self.setting.autolevels:\n', "AttributeError: 'FakeCameraMeasurement' object has no attribute 'setting'\n"]
2020-07-26T15:21:34|ERROR|FakeCameraMeasurement|fake_camera_image Failed to update figure1: 'FakeCameraMeasurement' object has no attribute 'setting'. ['Traceback (most recent call last):\n', '  File "C:\\Users\\Andrea Bassi\\anaconda3\\envs\\scopefoundry\\lib\\site-packages\\ScopeFoundry\\measurement.py", line 273, in _on_display_update_timer\n    self.update_display()\n', '  File "C:\\Users\\Andrea Bassi\\OneDrive - Politecnico di Milano\\Documenti\\PythonProjects\\BassiScopeFoundryMicroscopes\\Microscopes\\CellRecongnitionMicroscope\\FakeCameraMeasurement.py", line 85, in update_display\n    if self.setting.autolevels:\n', "AttributeError: 'FakeCameraMeasurement' object has no attribute 'setting'\n"]
2020-07-26T15:21:36|ERROR|FakeCameraMeasurement|fake_camera_image Failed to update figure1: 'FakeCameraMeasurement' object has no attribute 'setting'. ['Traceback (most recent call last):\n', '  File "C:\\Users\\Andrea Bassi\\anaconda3\\envs\\scopefoundry\\lib\\site-packages\\ScopeFoundry\\measurement.py", line 273, in _on_display_update_timer\n    self.update_display()\n', '  File "C:\\Users\\Andrea Bassi\\OneDrive - Politecnico di Milano\\Documenti\\PythonProjects\\BassiScopeFoundryMicroscopes\\Microscopes\\CellRecongnitionMicroscope\\FakeCameraMeasurement.py", line 85, in update_display\n    if self.setting.autolevels:\n', "AttributeError: 'FakeCameraMeasurement' object has no attribute 'setting'\n"]
2020-07-26T15:21:38|ERROR|FakeCameraMeasurement|fake_camera_image Failed to update figure1: 'FakeCameraMeasurement' object has no attribute 'setting'. ['Traceback (most recent call last):\n', '  File "C:\\Users\\Andrea Bassi\\anaconda3\\envs\\scopefoundry\\lib\\site-packages\\ScopeFoundry\\measurement.py", line 273, in _on_display_update_timer\n    self.update_display()\n', '  File "C:\\Users\\Andrea Bassi\\OneDrive - Politecnico di Milano\\Documenti\\PythonProjects\\BassiScopeFoundryMicroscopes\\Microscopes\\CellRecongnitionMicroscope\\FakeCameraMeasurement.py", line 85, in update_display\n    if self.setting.autolevels:\n', "AttributeError: 'FakeCameraMeasurement' object has no attribute 'setting'\n"]
2020-07-26T15:21:40|ERROR|FakeCameraMeasurement|fake_camera_image Failed to update figure1: 'FakeCameraMeasurement' object has no attribute 'setting'. ['Traceback (most recent call last):\n', '  File "C:\\Users\\Andrea Bassi\\anaconda3\\envs\\scopefoundry\\lib\\site-packages\\ScopeFoundry\\measurement.py", line 273, in _on_display_update_timer\n    self.update_display()\n', '  File "C:\\Users\\Andrea Bassi\\OneDrive - Politecnico di Milano\\Documenti\\PythonProjects\\BassiScopeFoundryMicroscopes\\Microscopes\\CellRecongnitionMicroscope\\FakeCameraMeasurement.py", line 85, in update_display\n    if self.setting.autolevels:\n', "AttributeError: 'FakeCameraMeasurement' object has no attribute 'setting'\n"]
2020-07-26T15:21:41|ERROR|FakeCameraMeasurement|fake_camera_image Failed to update figure1: 'FakeCameraMeasurement' object has no attribute 'setting'. ['Traceback (most recent call last):\n', '  File "C:\\Users\\Andrea Bassi\\anaconda3\\envs\\scopefoundry\\lib\\site-packages\\ScopeFoundry\\measurement.py", line 273, in _on_display_update_timer\n    self.update_display()\n', '  File "C:\\Users\\Andrea Bassi\\OneDrive - Politecnico di Milano\\Documenti\\PythonProjects\\BassiScopeFoundryMicroscopes\\Microscopes\\CellRecongnitionMicroscope\\FakeCameraMeasurement.py", line 85, in update_display\n    if self.setting.autolevels:\n', "AttributeError: 'FakeCameraMeasurement' object has no attribute 'setting'\n"]
2020-07-26T15:21:43|ERROR|FakeCameraMeasurement|fake_camera_image Failed to update figure1: 'FakeCameraMeasurement' object has no attribute 'setting'. ['Traceback (most recent call last):\n', '  File "C:\\Users\\Andrea Bassi\\anaconda3\\envs\\scopefoundry\\lib\\site-packages\\ScopeFoundry\\measurement.py", line 273, in _on_display_update_timer\n    self.update_display()\n', '  File "C:\\Users\\Andrea Bassi\\OneDrive - Politecnico di Milano\\Documenti\\PythonProjects\\BassiScopeFoundryMicroscopes\\Microscopes\\CellRecongnitionMicroscope\\FakeCameraMeasurement.py", line 85, in update_display\n    if self.setting.autolevels:\n', "AttributeError: 'FakeCameraMeasurement' object has no attribute 'setting'\n"]
2020-07-26T15:22:16|ERROR|FakeCameraMeasurement|fake_camera_image Failed to update figure1: 'LQCollection' object has no attribute 'autolevels'. ['Traceback (most recent call last):\n', '  File "C:\\Users\\Andrea Bassi\\anaconda3\\envs\\scopefoundry\\lib\\site-packages\\ScopeFoundry\\measurement.py", line 273, in _on_display_update_timer\n    self.update_display()\n', '  File "C:\\Users\\Andrea Bassi\\OneDrive - Politecnico di Milano\\Documenti\\PythonProjects\\BassiScopeFoundryMicroscopes\\Microscopes\\CellRecongnitionMicroscope\\FakeCameraMeasurement.py", line 85, in update_display\n    if self.settings.autolevels:\n', "AttributeError: 'LQCollection' object has no attribute 'autolevels'\n"]
2020-07-26T15:22:18|ERROR|FakeCameraMeasurement|fake_camera_image Failed to update figure1: 'LQCollection' object has no attribute 'autolevels'. ['Traceback (most recent call last):\n', '  File "C:\\Users\\Andrea Bassi\\anaconda3\\envs\\scopefoundry\\lib\\site-packages\\ScopeFoundry\\measurement.py", line 273, in _on_display_update_timer\n    self.update_display()\n', '  File "C:\\Users\\Andrea Bassi\\OneDrive - Politecnico di Milano\\Documenti\\PythonProjects\\BassiScopeFoundryMicroscopes\\Microscopes\\CellRecongnitionMicroscope\\FakeCameraMeasurement.py", line 85, in update_display\n    if self.settings.autolevels:\n', "AttributeError: 'LQCollection' object has no attribute 'autolevels'\n"]
2020-07-26T15:22:19|ERROR|FakeCameraMeasurement|fake_camera_image Failed to update figure1: 'LQCollection' object has no attribute 'autolevels'. ['Traceback (most recent call last):\n', '  File "C:\\Users\\Andrea Bassi\\anaconda3\\envs\\scopefoundry\\lib\\site-packages\\ScopeFoundry\\measurement.py", line 273, in _on_display_update_timer\n    self.update_display()\n', '  File "C:\\Users\\Andrea Bassi\\OneDrive - Politecnico di Milano\\Documenti\\PythonProjects\\BassiScopeFoundryMicroscopes\\Microscopes\\CellRecongnitionMicroscope\\FakeCameraMeasurement.py", line 85, in update_display\n    if self.settings.autolevels:\n', "AttributeError: 'LQCollection' object has no attribute 'autolevels'\n"]
2020-07-26T15:22:22|ERROR|FakeCameraMeasurement|fake_camera_image Failed to update figure1: 'LQCollection' object has no attribute 'autolevels'. ['Traceback (most recent call last):\n', '  File "C:\\Users\\Andrea Bassi\\anaconda3\\envs\\scopefoundry\\lib\\site-packages\\ScopeFoundry\\measurement.py", line 273, in _on_display_update_timer\n    self.update_display()\n', '  File "C:\\Users\\Andrea Bassi\\OneDrive - Politecnico di Milano\\Documenti\\PythonProjects\\BassiScopeFoundryMicroscopes\\Microscopes\\CellRecongnitionMicroscope\\FakeCameraMeasurement.py", line 85, in update_display\n    if self.settings.autolevels:\n', "AttributeError: 'LQCollection' object has no attribute 'autolevels'\n"]
2020-07-26T15:22:24|ERROR|FakeCameraMeasurement|fake_camera_image Failed to update figure1: 'LQCollection' object has no attribute 'autolevels'. ['Traceback (most recent call last):\n', '  File "C:\\Users\\Andrea Bassi\\anaconda3\\envs\\scopefoundry\\lib\\site-packages\\ScopeFoundry\\measurement.py", line 273, in _on_display_update_timer\n    self.update_display()\n', '  File "C:\\Users\\Andrea Bassi\\OneDrive - Politecnico di Milano\\Documenti\\PythonProjects\\BassiScopeFoundryMicroscopes\\Microscopes\\CellRecongnitionMicroscope\\FakeCameraMeasurement.py", line 85, in update_display\n    if self.settings.autolevels:\n', "AttributeError: 'LQCollection' object has no attribute 'autolevels'\n"]
2020-07-26T15:22:26|ERROR|FakeCameraMeasurement|fake_camera_image Failed to update figure1: 'LQCollection' object has no attribute 'autolevels'. ['Traceback (most recent call last):\n', '  File "C:\\Users\\Andrea Bassi\\anaconda3\\envs\\scopefoundry\\lib\\site-packages\\ScopeFoundry\\measurement.py", line 273, in _on_display_update_timer\n    self.update_display()\n', '  File "C:\\Users\\Andrea Bassi\\OneDrive - Politecnico di Milano\\Documenti\\PythonProjects\\BassiScopeFoundryMicroscopes\\Microscopes\\CellRecongnitionMicroscope\\FakeCameraMeasurement.py", line 85, in update_display\n    if self.settings.autolevels:\n', "AttributeError: 'LQCollection' object has no attribute 'autolevels'\n"]
2020-07-26T15:22:28|ERROR|FakeCameraMeasurement|fake_camera_image Failed to update figure1: 'LQCollection' object has no attribute 'autolevels'. ['Traceback (most recent call last):\n', '  File "C:\\Users\\Andrea Bassi\\anaconda3\\envs\\scopefoundry\\lib\\site-packages\\ScopeFoundry\\measurement.py", line 273, in _on_display_update_timer\n    self.update_display()\n', '  File "C:\\Users\\Andrea Bassi\\OneDrive - Politecnico di Milano\\Documenti\\PythonProjects\\BassiScopeFoundryMicroscopes\\Microscopes\\CellRecongnitionMicroscope\\FakeCameraMeasurement.py", line 85, in update_display\n    if self.settings.autolevels:\n', "AttributeError: 'LQCollection' object has no attribute 'autolevels'\n"]
2020-07-26T15:22:30|ERROR|FakeCameraMeasurement|fake_camera_image Failed to update figure1: 'LQCollection' object has no attribute 'autolevels'. ['Traceback (most recent call last):\n', '  File "C:\\Users\\Andrea Bassi\\anaconda3\\envs\\scopefoundry\\lib\\site-packages\\ScopeFoundry\\measurement.py", line 273, in _on_display_update_timer\n    self.update_display()\n', '  File "C:\\Users\\Andrea Bassi\\OneDrive - Politecnico di Milano\\Documenti\\PythonProjects\\BassiScopeFoundryMicroscopes\\Microscopes\\CellRecongnitionMicroscope\\FakeCameraMeasurement.py", line 85, in update_display\n    if self.settings.autolevels:\n', "AttributeError: 'LQCollection' object has no attribute 'autolevels'\n"]
2020-07-26T15:22:32|ERROR|FakeCameraMeasurement|fake_camera_image Failed to update figure1: 'LQCollection' object has no attribute 'autolevels'. ['Traceback (most recent call last):\n', '  File "C:\\Users\\Andrea Bassi\\anaconda3\\envs\\scopefoundry\\lib\\site-packages\\ScopeFoundry\\measurement.py", line 273, in _on_display_update_timer\n    self.update_display()\n', '  File "C:\\Users\\Andrea Bassi\\OneDrive - Politecnico di Milano\\Documenti\\PythonProjects\\BassiScopeFoundryMicroscopes\\Microscopes\\CellRecongnitionMicroscope\\FakeCameraMeasurement.py", line 85, in update_display\n    if self.settings.autolevels:\n', "AttributeError: 'LQCollection' object has no attribute 'autolevels'\n"]
2020-07-26T15:22:34|ERROR|FakeCameraMeasurement|fake_camera_image Failed to update figure1: 'LQCollection' object has no attribute 'autolevels'. ['Traceback (most recent call last):\n', '  File "C:\\Users\\Andrea Bassi\\anaconda3\\envs\\scopefoundry\\lib\\site-packages\\ScopeFoundry\\measurement.py", line 273, in _on_display_update_timer\n    self.update_display()\n', '  File "C:\\Users\\Andrea Bassi\\OneDrive - Politecnico di Milano\\Documenti\\PythonProjects\\BassiScopeFoundryMicroscopes\\Microscopes\\CellRecongnitionMicroscope\\FakeCameraMeasurement.py", line 85, in update_display\n    if self.settings.autolevels:\n', "AttributeError: 'LQCollection' object has no attribute 'autolevels'\n"]
2020-07-26T15:22:36|ERROR|FakeCameraMeasurement|fake_camera_image Failed to update figure1: 'LQCollection' object has no attribute 'autolevels'. ['Traceback (most recent call last):\n', '  File "C:\\Users\\Andrea Bassi\\anaconda3\\envs\\scopefoundry\\lib\\site-packages\\ScopeFoundry\\measurement.py", line 273, in _on_display_update_timer\n    self.update_display()\n', '  File "C:\\Users\\Andrea Bassi\\OneDrive - Politecnico di Milano\\Documenti\\PythonProjects\\BassiScopeFoundryMicroscopes\\Microscopes\\CellRecongnitionMicroscope\\FakeCameraMeasurement.py", line 85, in update_display\n    if self.settings.autolevels:\n', "AttributeError: 'LQCollection' object has no attribute 'autolevels'\n"]
2020-07-26T15:22:38|ERROR|FakeCameraMeasurement|fake_camera_image Failed to update figure1: 'LQCollection' object has no attribute 'autolevels'. ['Traceback (most recent call last):\n', '  File "C:\\Users\\Andrea Bassi\\anaconda3\\envs\\scopefoundry\\lib\\site-packages\\ScopeFoundry\\measurement.py", line 273, in _on_display_update_timer\n    self.update_display()\n', '  File "C:\\Users\\Andrea Bassi\\OneDrive - Politecnico di Milano\\Documenti\\PythonProjects\\BassiScopeFoundryMicroscopes\\Microscopes\\CellRecongnitionMicroscope\\FakeCameraMeasurement.py", line 85, in update_display\n    if self.settings.autolevels:\n', "AttributeError: 'LQCollection' object has no attribute 'autolevels'\n"]
2020-07-26T15:22:40|ERROR|FakeCameraMeasurement|fake_camera_image Failed to update figure1: 'LQCollection' object has no attribute 'autolevels'. ['Traceback (most recent call last):\n', '  File "C:\\Users\\Andrea Bassi\\anaconda3\\envs\\scopefoundry\\lib\\site-packages\\ScopeFoundry\\measurement.py", line 273, in _on_display_update_timer\n    self.update_display()\n', '  File "C:\\Users\\Andrea Bassi\\OneDrive - Politecnico di Milano\\Documenti\\PythonProjects\\BassiScopeFoundryMicroscopes\\Microscopes\\CellRecongnitionMicroscope\\FakeCameraMeasurement.py", line 85, in update_display\n    if self.settings.autolevels:\n', "AttributeError: 'LQCollection' object has no attribute 'autolevels'\n"]
2020-07-26T15:24:03|ERROR|FakeCameraMeasurement|fake_camera_image Failed to update figure1: 'LQCollection' object has no attribute 'autolevels'. ['Traceback (most recent call last):\n', '  File "C:\\Users\\Andrea Bassi\\anaconda3\\envs\\scopefoundry\\lib\\site-packages\\ScopeFoundry\\measurement.py", line 273, in _on_display_update_timer\n    self.update_display()\n', '  File "C:\\Users\\Andrea Bassi\\OneDrive - Politecnico di Milano\\Documenti\\PythonProjects\\BassiScopeFoundryMicroscopes\\Microscopes\\CellRecongnitionMicroscope\\FakeCameraMeasurement.py", line 85, in update_display\n    if self.settings.autolevels.val:\n', "AttributeError: 'LQCollection' object has no attribute 'autolevels'\n"]
2020-07-26T15:24:05|ERROR|FakeCameraMeasurement|fake_camera_image Failed to update figure1: 'LQCollection' object has no attribute 'autolevels'. ['Traceback (most recent call last):\n', '  File "C:\\Users\\Andrea Bassi\\anaconda3\\envs\\scopefoundry\\lib\\site-packages\\ScopeFoundry\\measurement.py", line 273, in _on_display_update_timer\n    self.update_display()\n', '  File "C:\\Users\\Andrea Bassi\\OneDrive - Politecnico di Milano\\Documenti\\PythonProjects\\BassiScopeFoundryMicroscopes\\Microscopes\\CellRecongnitionMicroscope\\FakeCameraMeasurement.py", line 85, in update_display\n    if self.settings.autolevels.val:\n', "AttributeError: 'LQCollection' object has no attribute 'autolevels'\n"]
2020-07-26T15:24:08|ERROR|FakeCameraMeasurement|fake_camera_image Failed to update figure1: 'LQCollection' object has no attribute 'autolevels'. ['Traceback (most recent call last):\n', '  File "C:\\Users\\Andrea Bassi\\anaconda3\\envs\\scopefoundry\\lib\\site-packages\\ScopeFoundry\\measurement.py", line 273, in _on_display_update_timer\n    self.update_display()\n', '  File "C:\\Users\\Andrea Bassi\\OneDrive - Politecnico di Milano\\Documenti\\PythonProjects\\BassiScopeFoundryMicroscopes\\Microscopes\\CellRecongnitionMicroscope\\FakeCameraMeasurement.py", line 85, in update_display\n    if self.settings.autolevels.val:\n', "AttributeError: 'LQCollection' object has no attribute 'autolevels'\n"]
2020-07-26T15:24:10|ERROR|FakeCameraMeasurement|fake_camera_image Failed to update figure1: 'LQCollection' object has no attribute 'autolevels'. ['Traceback (most recent call last):\n', '  File "C:\\Users\\Andrea Bassi\\anaconda3\\envs\\scopefoundry\\lib\\site-packages\\ScopeFoundry\\measurement.py", line 273, in _on_display_update_timer\n    self.update_display()\n', '  File "C:\\Users\\Andrea Bassi\\OneDrive - Politecnico di Milano\\Documenti\\PythonProjects\\BassiScopeFoundryMicroscopes\\Microscopes\\CellRecongnitionMicroscope\\FakeCameraMeasurement.py", line 85, in update_display\n    if self.settings.autolevels.val:\n', "AttributeError: 'LQCollection' object has no attribute 'autolevels'\n"]
2020-07-26T15:24:13|ERROR|FakeCameraMeasurement|fake_camera_image Failed to update figure1: 'LQCollection' object has no attribute 'autolevels'. ['Traceback (most recent call last):\n', '  File "C:\\Users\\Andrea Bassi\\anaconda3\\envs\\scopefoundry\\lib\\site-packages\\ScopeFoundry\\measurement.py", line 273, in _on_display_update_timer\n    self.update_display()\n', '  File "C:\\Users\\Andrea Bassi\\OneDrive - Politecnico di Milano\\Documenti\\PythonProjects\\BassiScopeFoundryMicroscopes\\Microscopes\\CellRecongnitionMicroscope\\FakeCameraMeasurement.py", line 85, in update_display\n    if self.settings.autolevels.val:\n', "AttributeError: 'LQCollection' object has no attribute 'autolevels'\n"]
2020-07-26T15:24:16|ERROR|FakeCameraMeasurement|fake_camera_image Failed to update figure1: 'LQCollection' object has no attribute 'autolevels'. ['Traceback (most recent call last):\n', '  File "C:\\Users\\Andrea Bassi\\anaconda3\\envs\\scopefoundry\\lib\\site-packages\\ScopeFoundry\\measurement.py", line 273, in _on_display_update_timer\n    self.update_display()\n', '  File "C:\\Users\\Andrea Bassi\\OneDrive - Politecnico di Milano\\Documenti\\PythonProjects\\BassiScopeFoundryMicroscopes\\Microscopes\\CellRecongnitionMicroscope\\FakeCameraMeasurement.py", line 85, in update_display\n    if self.settings.autolevels.val:\n', "AttributeError: 'LQCollection' object has no attribute 'autolevels'\n"]
2020-07-26T15:24:18|ERROR|FakeCameraMeasurement|fake_camera_image Failed to update figure1: 'LQCollection' object has no attribute 'autolevels'. ['Traceback (most recent call last):\n', '  File "C:\\Users\\Andrea Bassi\\anaconda3\\envs\\scopefoundry\\lib\\site-packages\\ScopeFoundry\\measurement.py", line 273, in _on_display_update_timer\n    self.update_display()\n', '  File "C:\\Users\\Andrea Bassi\\OneDrive - Politecnico di Milano\\Documenti\\PythonProjects\\BassiScopeFoundryMicroscopes\\Microscopes\\CellRecongnitionMicroscope\\FakeCameraMeasurement.py", line 85, in update_display\n    if self.settings.autolevels.val:\n', "AttributeError: 'LQCollection' object has no attribute 'autolevels'\n"]
2020-07-26T15:24:21|ERROR|FakeCameraMeasurement|fake_camera_image Failed to update figure1: 'LQCollection' object has no attribute 'autolevels'. ['Traceback (most recent call last):\n', '  File "C:\\Users\\Andrea Bassi\\anaconda3\\envs\\scopefoundry\\lib\\site-packages\\ScopeFoundry\\measurement.py", line 273, in _on_display_update_timer\n    self.update_display()\n', '  File "C:\\Users\\Andrea Bassi\\OneDrive - Politecnico di Milano\\Documenti\\PythonProjects\\BassiScopeFoundryMicroscopes\\Microscopes\\CellRecongnitionMicroscope\\FakeCameraMeasurement.py", line 85, in update_display\n    if self.settings.autolevels.val:\n', "AttributeError: 'LQCollection' object has no attribute 'autolevels'\n"]
2020-07-26T15:24:23|ERROR|FakeCameraMeasurement|fake_camera_image Failed to update figure1: 'LQCollection' object has no attribute 'autolevels'. ['Traceback (most recent call last):\n', '  File "C:\\Users\\Andrea Bassi\\anaconda3\\envs\\scopefoundry\\lib\\site-packages\\ScopeFoundry\\measurement.py", line 273, in _on_display_update_timer\n    self.update_display()\n', '  File "C:\\Users\\Andrea Bassi\\OneDrive - Politecnico di Milano\\Documenti\\PythonProjects\\BassiScopeFoundryMicroscopes\\Microscopes\\CellRecongnitionMicroscope\\FakeCameraMeasurement.py", line 85, in update_display\n    if self.settings.autolevels.val:\n', "AttributeError: 'LQCollection' object has no attribute 'autolevels'\n"]
2020-07-26T15:24:25|ERROR|FakeCameraMeasurement|fake_camera_image Failed to update figure1: 'LQCollection' object has no attribute 'autolevels'. ['Traceback (most recent call last):\n', '  File "C:\\Users\\Andrea Bassi\\anaconda3\\envs\\scopefoundry\\lib\\site-packages\\ScopeFoundry\\measurement.py", line 273, in _on_display_update_timer\n    self.update_display()\n', '  File "C:\\Users\\Andrea Bassi\\OneDrive - Politecnico di Milano\\Documenti\\PythonProjects\\BassiScopeFoundryMicroscopes\\Microscopes\\CellRecongnitionMicroscope\\FakeCameraMeasurement.py", line 85, in update_display\n    if self.settings.autolevels.val:\n', "AttributeError: 'LQCollection' object has no attribute 'autolevels'\n"]
2020-07-26T15:24:28|ERROR|FakeCameraMeasurement|fake_camera_image Failed to update figure1: 'LQCollection' object has no attribute 'autolevels'. ['Traceback (most recent call last):\n', '  File "C:\\Users\\Andrea Bassi\\anaconda3\\envs\\scopefoundry\\lib\\site-packages\\ScopeFoundry\\measurement.py", line 273, in _on_display_update_timer\n    self.update_display()\n', '  File "C:\\Users\\Andrea Bassi\\OneDrive - Politecnico di Milano\\Documenti\\PythonProjects\\BassiScopeFoundryMicroscopes\\Microscopes\\CellRecongnitionMicroscope\\FakeCameraMeasurement.py", line 85, in update_display\n    if self.settings.autolevels.val:\n', "AttributeError: 'LQCollection' object has no attribute 'autolevels'\n"]
2020-07-26T15:24:31|ERROR|FakeCameraMeasurement|fake_camera_image Failed to update figure1: 'LQCollection' object has no attribute 'autolevels'. ['Traceback (most recent call last):\n', '  File "C:\\Users\\Andrea Bassi\\anaconda3\\envs\\scopefoundry\\lib\\site-packages\\ScopeFoundry\\measurement.py", line 273, in _on_display_update_timer\n    self.update_display()\n', '  File "C:\\Users\\Andrea Bassi\\OneDrive - Politecnico di Milano\\Documenti\\PythonProjects\\BassiScopeFoundryMicroscopes\\Microscopes\\CellRecongnitionMicroscope\\FakeCameraMeasurement.py", line 85, in update_display\n    if self.settings.autolevels.val:\n', "AttributeError: 'LQCollection' object has no attribute 'autolevels'\n"]
2020-07-26T16:00:13|WARNING|LoggedQuantity|level_min read_from_hardware called when not connected to hardware
2020-07-26T16:00:15|WARNING|LoggedQuantity|level_min read_from_hardware called when not connected to hardware
2020-07-26T16:00:18|WARNING|LoggedQuantity|level_min read_from_hardware called when not connected to hardware
2020-07-26T16:00:20|WARNING|LoggedQuantity|level_min read_from_hardware called when not connected to hardware
2020-07-26T16:07:45|ERROR|FakeCameraMeasurement|fake_camera_image Failed to update figure1: int() argument must be a string, a bytes-like object or a number, not 'LoggedQuantity'. ['Traceback (most recent call last):\n', '  File "C:\\Users\\Andrea Bassi\\anaconda3\\envs\\scopefoundry\\lib\\site-packages\\ScopeFoundry\\measurement.py", line 273, in _on_display_update_timer\n    self.update_display()\n', '  File "C:\\Users\\Andrea Bassi\\OneDrive - Politecnico di Milano\\Documenti\\PythonProjects\\BassiScopeFoundryMicroscopes\\Microscopes\\CellRecongnitionMicroscope\\FakeCameraMeasurement.py", line 79, in update_display\n    level_min, level_max = self.get_levels(self.image, self.settings.auto_levels.val)\n', '  File "C:\\Users\\Andrea Bassi\\OneDrive - Politecnico di Milano\\Documenti\\PythonProjects\\BassiScopeFoundryMicroscopes\\Microscopes\\CellRecongnitionMicroscope\\FakeCameraMeasurement.py", line 127, in get_levels\n    self.settings.level_min.read_from_hardware()\n', '  File "C:\\Users\\Andrea Bassi\\anaconda3\\envs\\scopefoundry\\lib\\site-packages\\ScopeFoundry\\logged_quantity.py", line 162, in read_from_hardware\n    self.update_value(new_val=val, update_hardware=False, send_signal=send_signal)\n', '  File "C:\\Users\\Andrea Bassi\\anaconda3\\envs\\scopefoundry\\lib\\site-packages\\ScopeFoundry\\logged_quantity.py", line 223, in update_value\n    new_val = self.coerce_to_type(new_val)\n', '  File "C:\\Users\\Andrea Bassi\\anaconda3\\envs\\scopefoundry\\lib\\site-packages\\ScopeFoundry\\logged_quantity.py", line 135, in coerce_to_type\n    return self.dtype(x)\n', "TypeError: int() argument must be a string, a bytes-like object or a number, not 'LoggedQuantity'\n"]
2020-07-26T16:07:48|ERROR|FakeCameraMeasurement|fake_camera_image Failed to update figure1: int() argument must be a string, a bytes-like object or a number, not 'LoggedQuantity'. ['Traceback (most recent call last):\n', '  File "C:\\Users\\Andrea Bassi\\anaconda3\\envs\\scopefoundry\\lib\\site-packages\\ScopeFoundry\\measurement.py", line 273, in _on_display_update_timer\n    self.update_display()\n', '  File "C:\\Users\\Andrea Bassi\\OneDrive - Politecnico di Milano\\Documenti\\PythonProjects\\BassiScopeFoundryMicroscopes\\Microscopes\\CellRecongnitionMicroscope\\FakeCameraMeasurement.py", line 79, in update_display\n    level_min, level_max = self.get_levels(self.image, self.settings.auto_levels.val)\n', '  File "C:\\Users\\Andrea Bassi\\OneDrive - Politecnico di Milano\\Documenti\\PythonProjects\\BassiScopeFoundryMicroscopes\\Microscopes\\CellRecongnitionMicroscope\\FakeCameraMeasurement.py", line 127, in get_levels\n    self.settings.level_min.read_from_hardware()\n', '  File "C:\\Users\\Andrea Bassi\\anaconda3\\envs\\scopefoundry\\lib\\site-packages\\ScopeFoundry\\logged_quantity.py", line 162, in read_from_hardware\n    self.update_value(new_val=val, update_hardware=False, send_signal=send_signal)\n', '  File "C:\\Users\\Andrea Bassi\\anaconda3\\envs\\scopefoundry\\lib\\site-packages\\ScopeFoundry\\logged_quantity.py", line 223, in update_value\n    new_val = self.coerce_to_type(new_val)\n', '  File "C:\\Users\\Andrea Bassi\\anaconda3\\envs\\scopefoundry\\lib\\site-packages\\ScopeFoundry\\logged_quantity.py", line 135, in coerce_to_type\n    return self.dtype(x)\n', "TypeError: int() argument must be a string, a bytes-like object or a number, not 'LoggedQuantity'\n"]
2020-07-26T16:07:53|ERROR|FakeCameraMeasurement|fake_camera_image Failed to update figure1: int() argument must be a string, a bytes-like object or a number, not 'LoggedQuantity'. ['Traceback (most recent call last):\n', '  File "C:\\Users\\Andrea Bassi\\anaconda3\\envs\\scopefoundry\\lib\\site-packages\\ScopeFoundry\\measurement.py", line 273, in _on_display_update_timer\n    self.update_display()\n', '  File "C:\\Users\\Andrea Bassi\\OneDrive - Politecnico di Milano\\Documenti\\PythonProjects\\BassiScopeFoundryMicroscopes\\Microscopes\\CellRecongnitionMicroscope\\FakeCameraMeasurement.py", line 79, in update_display\n    level_min, level_max = self.get_levels(self.image, self.settings.auto_levels.val)\n', '  File "C:\\Users\\Andrea Bassi\\OneDrive - Politecnico di Milano\\Documenti\\PythonProjects\\BassiScopeFoundryMicroscopes\\Microscopes\\CellRecongnitionMicroscope\\FakeCameraMeasurement.py", line 127, in get_levels\n    self.settings.level_min.read_from_hardware()\n', '  File "C:\\Users\\Andrea Bassi\\anaconda3\\envs\\scopefoundry\\lib\\site-packages\\ScopeFoundry\\logged_quantity.py", line 162, in read_from_hardware\n    self.update_value(new_val=val, update_hardware=False, send_signal=send_signal)\n', '  File "C:\\Users\\Andrea Bassi\\anaconda3\\envs\\scopefoundry\\lib\\site-packages\\ScopeFoundry\\logged_quantity.py", line 223, in update_value\n    new_val = self.coerce_to_type(new_val)\n', '  File "C:\\Users\\Andrea Bassi\\anaconda3\\envs\\scopefoundry\\lib\\site-packages\\ScopeFoundry\\logged_quantity.py", line 135, in coerce_to_type\n    return self.dtype(x)\n', "TypeError: int() argument must be a string, a bytes-like object or a number, not 'LoggedQuantity'\n"]
2020-07-26T16:07:56|ERROR|FakeCameraMeasurement|fake_camera_image Failed to update figure1: int() argument must be a string, a bytes-like object or a number, not 'LoggedQuantity'. ['Traceback (most recent call last):\n', '  File "C:\\Users\\Andrea Bassi\\anaconda3\\envs\\scopefoundry\\lib\\site-packages\\ScopeFoundry\\measurement.py", line 273, in _on_display_update_timer\n    self.update_display()\n', '  File "C:\\Users\\Andrea Bassi\\OneDrive - Politecnico di Milano\\Documenti\\PythonProjects\\BassiScopeFoundryMicroscopes\\Microscopes\\CellRecongnitionMicroscope\\FakeCameraMeasurement.py", line 79, in update_display\n    level_min, level_max = self.get_levels(self.image, self.settings.auto_levels.val)\n', '  File "C:\\Users\\Andrea Bassi\\OneDrive - Politecnico di Milano\\Documenti\\PythonProjects\\BassiScopeFoundryMicroscopes\\Microscopes\\CellRecongnitionMicroscope\\FakeCameraMeasurement.py", line 127, in get_levels\n    self.settings.level_min.read_from_hardware()\n', '  File "C:\\Users\\Andrea Bassi\\anaconda3\\envs\\scopefoundry\\lib\\site-packages\\ScopeFoundry\\logged_quantity.py", line 162, in read_from_hardware\n    self.update_value(new_val=val, update_hardware=False, send_signal=send_signal)\n', '  File "C:\\Users\\Andrea Bassi\\anaconda3\\envs\\scopefoundry\\lib\\site-packages\\ScopeFoundry\\logged_quantity.py", line 223, in update_value\n    new_val = self.coerce_to_type(new_val)\n', '  File "C:\\Users\\Andrea Bassi\\anaconda3\\envs\\scopefoundry\\lib\\site-packages\\ScopeFoundry\\logged_quantity.py", line 135, in coerce_to_type\n    return self.dtype(x)\n', "TypeError: int() argument must be a string, a bytes-like object or a number, not 'LoggedQuantity'\n"]
2020-07-26T16:08:01|ERROR|FakeCameraMeasurement|fake_camera_image Failed to update figure1: int() argument must be a string, a bytes-like object or a number, not 'LoggedQuantity'. ['Traceback (most recent call last):\n', '  File "C:\\Users\\Andrea Bassi\\anaconda3\\envs\\scopefoundry\\lib\\site-packages\\ScopeFoundry\\measurement.py", line 273, in _on_display_update_timer\n    self.update_display()\n', '  File "C:\\Users\\Andrea Bassi\\OneDrive - Politecnico di Milano\\Documenti\\PythonProjects\\BassiScopeFoundryMicroscopes\\Microscopes\\CellRecongnitionMicroscope\\FakeCameraMeasurement.py", line 79, in update_display\n    level_min, level_max = self.get_levels(self.image, self.settings.auto_levels.val)\n', '  File "C:\\Users\\Andrea Bassi\\OneDrive - Politecnico di Milano\\Documenti\\PythonProjects\\BassiScopeFoundryMicroscopes\\Microscopes\\CellRecongnitionMicroscope\\FakeCameraMeasurement.py", line 127, in get_levels\n    self.settings.level_min.read_from_hardware()\n', '  File "C:\\Users\\Andrea Bassi\\anaconda3\\envs\\scopefoundry\\lib\\site-packages\\ScopeFoundry\\logged_quantity.py", line 162, in read_from_hardware\n    self.update_value(new_val=val, update_hardware=False, send_signal=send_signal)\n', '  File "C:\\Users\\Andrea Bassi\\anaconda3\\envs\\scopefoundry\\lib\\site-packages\\ScopeFoundry\\logged_quantity.py", line 223, in update_value\n    new_val = self.coerce_to_type(new_val)\n', '  File "C:\\Users\\Andrea Bassi\\anaconda3\\envs\\scopefoundry\\lib\\site-packages\\ScopeFoundry\\logged_quantity.py", line 135, in coerce_to_type\n    return self.dtype(x)\n', "TypeError: int() argument must be a string, a bytes-like object or a number, not 'LoggedQuantity'\n"]
2020-07-26T16:08:05|ERROR|FakeCameraMeasurement|fake_camera_image Failed to update figure1: int() argument must be a string, a bytes-like object or a number, not 'LoggedQuantity'. ['Traceback (most recent call last):\n', '  File "C:\\Users\\Andrea Bassi\\anaconda3\\envs\\scopefoundry\\lib\\site-packages\\ScopeFoundry\\measurement.py", line 273, in _on_display_update_timer\n    self.update_display()\n', '  File "C:\\Users\\Andrea Bassi\\OneDrive - Politecnico di Milano\\Documenti\\PythonProjects\\BassiScopeFoundryMicroscopes\\Microscopes\\CellRecongnitionMicroscope\\FakeCameraMeasurement.py", line 79, in update_display\n    level_min, level_max = self.get_levels(self.image, self.settings.auto_levels.val)\n', '  File "C:\\Users\\Andrea Bassi\\OneDrive - Politecnico di Milano\\Documenti\\PythonProjects\\BassiScopeFoundryMicroscopes\\Microscopes\\CellRecongnitionMicroscope\\FakeCameraMeasurement.py", line 127, in get_levels\n    self.settings.level_min.read_from_hardware()\n', '  File "C:\\Users\\Andrea Bassi\\anaconda3\\envs\\scopefoundry\\lib\\site-packages\\ScopeFoundry\\logged_quantity.py", line 162, in read_from_hardware\n    self.update_value(new_val=val, update_hardware=False, send_signal=send_signal)\n', '  File "C:\\Users\\Andrea Bassi\\anaconda3\\envs\\scopefoundry\\lib\\site-packages\\ScopeFoundry\\logged_quantity.py", line 223, in update_value\n    new_val = self.coerce_to_type(new_val)\n', '  File "C:\\Users\\Andrea Bassi\\anaconda3\\envs\\scopefoundry\\lib\\site-packages\\ScopeFoundry\\logged_quantity.py", line 135, in coerce_to_type\n    return self.dtype(x)\n', "TypeError: int() argument must be a string, a bytes-like object or a number, not 'LoggedQuantity'\n"]
